Workbook
Name A_1: [1]IMS!$J$67
Name A_2: [1]IMS!$O$67
Name A_3: [1]IMS!$T$67
Name A_4: [1]IMS!$Y$67
Name AC: [2]DatiIndici!A$9
Name Acc: [2]DatiIndici!A$28
Name Am: [2]DatiIndici!A$8
Name AP: [1]SI!$E$13
Name Beni: [3]!B[Bene]
Name C_1: [1]IMS!$J$29
Name C_2: [1]IMS!$O$29
Name C_3: [1]IMS!$T$29
Name C_4: [1]IMS!$Y$29
Name Cat: [3]!Gruppi[Cat]
Name cf: [4]Prospetto!$F$5
Name cg: 8-WEEKDAY([5]Calcoli!XFD1,2)
Name Ci: [2]DatiIndici!A$10
Name CodTrib: Codici[Codice]
Name Cr: [2]DatiIndici!A$5
Name da: RISULTATI!$E$12
Name DAD: [4]Calcoli!$D$14
Name DAT: [4]Calcoli!$D$15
Name descp: [1]SI!$F$10
Name dp: [1]SI!$E$11
Name dr: [4]Calcoli!$G$29
Name Ei: [2]DatiIndici!A$30
Name En: [2]DatiIndici!A$29
Name F_1: [1]IMS!$J$11
Name F_2: [1]IMS!$O$11
Name F_3: [1]IMS!$T$11
Name F_4: [1]IMS!$Y$11
Name Fa: [2]DatiIndici!A$17
Name g: [1]SI!$F$11
Name i: [4]Calcoli!$D$12
Name ia: [4]Prospetto!$C$5
Name II: [2]DatiIndici!A$31
Name Im: [2]DatiIndici!A$3
Name Imm: [2]DatiIndici!A$32
Name L: 42369
Name m: [1]T!$H$1
Name MOL: [2]DatiIndici!A$25
Name NUMCART: Tabella1[NUMERO CARTELLA]
Name NUMCART: Tabella1[NUMERO CARTELLA]
Name Of: [2]DatiIndici!A$26
Name p: [3]DATI!#REF!
Name P_1: [1]IMS!$J$47
Name P_2: [1]IMS!$O$47
Name P_3: [1]IMS!$T$47
Name P_4: [1]IMS!$Y$47
Name par: [1]SI!$E$9
Name Pb: [2]DatiIndici!A$14
Name pe: [1]T!$G$3:$G$11
Name Pers: [2]DatiIndici!A$27
Name Pfn: [2]DatiIndici!A$16
Name PI: [1]PI!$A$10:$AE$91
Name Pl: [2]DatiIndici!A$13
Name Pn: [2]DatiIndici!A$12
Name PROT: MENU!$F$25
Name rate: #REF!
Name RATEA: #REF!

Sheet MENU
C10: Studio | F10: Cliente
C12: Ind. Studio | F12: Indirizzo
C14: Cap-Città | F14: Cap-Città
C16: P. IVA - C.F. | F16: P. IVA - C.F.
D23: Capitale da rateizzare | F23: =+ROTP -> 7899.8
D24: Massima rateazione concessa | F24: =+MAX(1,MIN(54,TRUNC(F23/100))) -> 54 | J24: Importo residuo dovuto | O24: =+RISULTATI!D10 -> 11918.8
D25: Numero di rate scelte | F25: 17 | J25: Risparmio con rottamazione | O25: =+SUMIF(RISULTATI!C:C,J25,RISULTATI!E:E) -> 4019
J26: Interessi per rateazione | O26: =+G87 -> 316.4376
E30: Piano di rateazione
E31: Data versamento | F31: Rata Capitale | G31: Importo rata
C32: 1 | E32: =+IF(PROT>0,"31/07/2026","") -> 31/07/2026 | F32: =+IF(PROT>0,IF(PROT>=C32,ROTP/PROT,""),"") -> 464.69412 | G32: =+IF(PROT>0,IF(PROT>=C32,F23/PROT,""),"") -> 464.69412
C33: =+IFERROR(IF(C32+1<=PROT,C32+1,""),"") -> 2 | E33: =+IFERROR(EOMONTH(start,(C33-1)*2),"") -> 46295 | F33: =+IF(PROT>0,IF(PROT>=C33,ROTP/PROT,""),"") -> 464.69412 | G33: =+IFERROR((E33-E32)/365*SUM(F33:$F$85)*3%+F33,"") -> 501.9715
C34: =+IFERROR(IF(C33+1<=PROT,C33+1,""),"") -> 3 | E34: =+IFERROR(EOMONTH(start,(C34-1)*2),"") -> 46356 | F34: =+IF(PROT>0,IF(PROT>=C34,ROTP/PROT,""),"") -> 464.69412 | G34: =+IFERROR((E34-E33)/365*SUM(F34:$F$85)*3%+F34,"") -> 499.64166
C35: =+IFERROR(IF(C34+1<=PROT,C34+1,""),"") -> 4 | E35: =+IFERROR(EOMONTH(start,(C35-1)*2),"") -> 46418 | F35: =+IF(PROT>0,IF(PROT>=C35,ROTP/PROT,""),"") -> 464.69412 | G35: =+IFERROR((E35-E34)/365*SUM(F35:$F$85)*3%+F35,"") -> 497.84654
C36: =+IFERROR(IF(C35+1<=PROT,C35+1,""),"") -> 5 | E36: =+IFERROR(EOMONTH(start,(C36-1)*2),"") -> 46477 | F36: =+IF(PROT>0,IF(PROT>=C36,ROTP/PROT,""),"") -> 464.69412 | G36: =+IFERROR((E36-E35)/365*SUM(F36:$F$85)*3%+F36,"") -> 493.98894
C37: =+IFERROR(IF(C36+1<=PROT,C36+1,""),"") -> 6 | E37: =+IFERROR(EOMONTH(start,(C37-1)*2),"") -> 46538 | F37: =+IF(PROT>0,IF(PROT>=C37,ROTP/PROT,""),"") -> 464.69412 | G37: =+IFERROR((E37-E36)/365*SUM(F37:$F$85)*3%+F37,"") -> 492.65215
C38: =+IFERROR(IF(C37+1<=PROT,C37+1,""),"") -> 7 | E38: =+IFERROR(EOMONTH(start,(C38-1)*2),"") -> 46599 | F38: =+IF(PROT>0,IF(PROT>=C38,ROTP/PROT,""),"") -> 464.69412 | G38: =+IFERROR((E38-E37)/365*SUM(F38:$F$85)*3%+F38,"") -> 490.32232
C39: =+IFERROR(IF(C38+1<=PROT,C38+1,""),"") -> 8 | E39: =+IFERROR(EOMONTH(start,(C39-1)*2),"") -> 46660 | F39: =+IF(PROT>0,IF(PROT>=C39,ROTP/PROT,""),"") -> 464.69412 | G39: =+IFERROR((E39-E38)/365*SUM(F39:$F$85)*3%+F39,"") -> 487.99248
C40: =+IFERROR(IF(C39+1<=PROT,C39+1,""),"") -> 9 | E40: =+IFERROR(EOMONTH(start,(C40-1)*2),"") -> 46721 | F40: =+IF(PROT>0,IF(PROT>=C40,ROTP/PROT,""),"") -> 464.69412 | G40: =+IFERROR((E40-E39)/365*SUM(F40:$F$85)*3%+F40,"") -> 485.66264
C41: =+IFERROR(IF(C40+1<=PROT,C40+1,""),"") -> 10 | E41: =+IFERROR(EOMONTH(start,(C41-1)*2),"") -> 46783 | F41: =+IF(PROT>0,IF(PROT>=C41,ROTP/PROT,""),"") -> 464.69412 | G41: =+IFERROR((E41-E40)/365*SUM(F41:$F$85)*3%+F41,"") -> 483.63836
C42: =+IFERROR(IF(C41+1<=PROT,C41+1,""),"") -> 11 | E42: =+IFERROR(EOMONTH(start,(C42-1)*2),"") -> 46843 | F42: =+IF(PROT>0,IF(PROT>=C42,ROTP/PROT,""),"") -> 464.69412 | G42: =+IFERROR((E42-E41)/365*SUM(F42:$F$85)*3%+F42,"") -> 480.73561
C43: =+IFERROR(IF(C42+1<=PROT,C42+1,""),"") -> 12 | E43: =+IFERROR(EOMONTH(start,(C43-1)*2),"") -> 46904 | F43: =+IF(PROT>0,IF(PROT>=C43,ROTP/PROT,""),"") -> 464.69412 | G43: =+IFERROR((E43-E42)/365*SUM(F43:$F$85)*3%+F43,"") -> 478.67314
C44: =+IFERROR(IF(C43+1<=PROT,C43+1,""),"") -> 13 | E44: =+IFERROR(EOMONTH(start,(C44-1)*2),"") -> 46965 | F44: =+IF(PROT>0,IF(PROT>=C44,ROTP/PROT,""),"") -> 464.69412 | G44: =+IFERROR((E44-E43)/365*SUM(F44:$F$85)*3%+F44,"") -> 476.3433
... C85: =+IFERROR(IF(C84+1<=PROT,C84+1,""),"") | E85: =+IFERROR(EOMONTH(start,(C85-1)*2),"") | F85: =+IF(PROT>0,IF(PROT>=C85,ROTP/PROT,""),"") | G85: =+IFERROR((E85-E84)/365*SUM(F85:$F$85)*3%+F85,"")
E86: TOTALE VERSATO CON PAGAMENTO RATEALE | G86: =SUM(G32:G85) -> 8216.2376
E87: - DI CUI INTERESSI | G87: =+G86-ROTP -> 316.4376
E105: Importo finanziato se diverso dal totale
E107: RATE | F107: 120
E109: TASSO | F109: 0.05
F111: Rata mensile | G111: Importo annuale
E112: RATA IPOTIZZATA | F112: =-PMT(F109/12,F107,IF(F105>0,F105,#REF!)) -> #REF! | G112: =+F112*12 -> #REF!
F114: Totale restituito | G114: Di cui interessi
F115: =+F112*F107 -> #REF! | G115: =+F112*F107-(IF(F105>0,F105,#REF!)) -> #REF!

Sheet DATI
L11: Inserisci codice tributo | M11: 5490
L12: =+VLOOKUP(M11,Codici[],3,0) -> Sanzione amministrativa l.24/11/1981 n,689 circoscrizione aeroportuale
B14: TOTALE CARTELLE DA ROTTAMARE | C14: =SUM(Tabella1[TOTALE CARTELLA]) -> 11918.8
B16: NUMERO CARTELLA | C16: LA CARTELLA RIPORTA CARICHI INCLUSI NELLA TABELLA SOTTOSTANTE | D16: DATA AFFIDAMENTO AGENZIA DELLE ENTRATE - RISCOSSIONE | E16: IMPOSTE | F16: SANZIONI | G16: INTERESSI DI MORA | H16: INTERESSI DI DILAZIONE | I16: INTERESSI RITARDATA ISCRIZIONE A RUOLO | J16: ONERI DI RISCOSSIONE (AGGIO) | K16: SPESE DI NOTIFICA | L16: SPESE PER PROCEDURE ESECUTIVE | M16: TOTALE CARTELLA | N16: DATA NOTIFICA | O16: NOTE | P16: TIPO RATEAZIONE
B17: 097 2023 000123456789 | C17: No | D17: 45089 | E17: 7890 | F17: 2367 | G17: 421 | H17: 278 | I17: 139 | J17: 814 | K17: 9.8 | M17: =SUM(Tabella1[[#This Row],[IMPOSTE]:[SPESE PER PROCEDURE ESECUTIVE]]) -> 11918.8 | N17: 45110 | O17: =+IF(Tabella1[[#This Row],[LA CARTELLA RIPORTA CARICHI INCLUSI NELLA TABELLA SOTTOSTANTE]]="","",+IF(Tabella1[[#This Row],[LA CARTELLA RIPORTA CARICHI INCLUSI NELLA TABELLA SOTTOSTANTE]]="Sì","RUOLO ESCLUSO DALLA DEFINIZIONE AGEVOLATA","RUOLO ROTTAMABILE")) -> RUOLO ROTTAMABILE | P17: =+IF(Tabella1[[#This Row],[DATA AFFIDAMENTO AGENZIA DELLE ENTRATE - RISCOSSIONE]]<42736,1,2) -> 2
M18: =SUM(Tabella1[[#This Row],[IMPOSTE]:[SPESE PER PROCEDURE ESECUTIVE]]) -> 0 | O18: =+IF(Tabella1[[#This Row],[LA CARTELLA RIPORTA CARICHI INCLUSI NELLA TABELLA SOTTOSTANTE]]="","",+IF(Tabella1[[#This Row],[LA CARTELLA RIPORTA CARICHI INCLUSI NELLA TABELLA SOTTOSTANTE]]="Sì","RUOLO ESCLUSO DALLA DEFINIZIONE AGEVOLATA","RUOLO ROTTAMABILE")) | P18: =+IF(Tabella1[[#This Row],[DATA AFFIDAMENTO AGENZIA DELLE ENTRATE - RISCOSSIONE]]<42736,1,2) -> 1
M19: =SUM(Tabella1[[#This Row],[IMPOSTE]:[SPESE PER PROCEDURE ESECUTIVE]]) -> 0 | O19: =+IF(Tabella1[[#This Row],[LA CARTELLA RIPORTA CARICHI INCLUSI NELLA TABELLA SOTTOSTANTE]]="","",+IF(Tabella1[[#This Row],[LA CARTELLA RIPORTA CARICHI INCLUSI NELLA TABELLA SOTTOSTANTE]]="Sì","RUOLO ESCLUSO DALLA DEFINIZIONE AGEVOLATA","RUOLO ROTTAMABILE")) | P19: =+IF(Tabella1[[#This Row],[DATA AFFIDAMENTO AGENZIA DELLE ENTRATE - RISCOSSIONE]]<42736,1,2) -> 1
M20: =SUM(Tabella1[[#This Row],[IMPOSTE]:[SPESE PER PROCEDURE ESECUTIVE]]) -> 0 | O20: =+IF(Tabella1[[#This Row],[LA CARTELLA RIPORTA CARICHI INCLUSI NELLA TABELLA SOTTOSTANTE]]="","",+IF(Tabella1[[#This Row],[LA CARTELLA RIPORTA CARICHI INCLUSI NELLA TABELLA SOTTOSTANTE]]="Sì","RUOLO ESCLUSO DALLA DEFINIZIONE AGEVOLATA","RUOLO ROTTAMABILE")) | P20: =+IF(Tabella1[[#This Row],[DATA AFFIDAMENTO AGENZIA DELLE ENTRATE - RISCOSSIONE]]<42736,1,2) -> 1
M21: =SUM(Tabella1[[#This Row],[IMPOSTE]:[SPESE PER PROCEDURE ESECUTIVE]]) -> 0 | O21: =+IF(Tabella1[[#This Row],[LA CARTELLA RIPORTA CARICHI INCLUSI NELLA TABELLA SOTTOSTANTE]]="","",+IF(Tabella1[[#This Row],[LA CARTELLA RIPORTA CARICHI INCLUSI NELLA TABELLA SOTTOSTANTE]]="Sì","RUOLO ESCLUSO DALLA DEFINIZIONE AGEVOLATA","RUOLO ROTTAMABILE")) | P21: =+IF(Tabella1[[#This Row],[DATA AFFIDAMENTO AGENZIA DELLE ENTRATE - RISCOSSIONE]]<42736,1,2) -> 1
M22: =SUM(Tabella1[[#This Row],[IMPOSTE]:[SPESE PER PROCEDURE ESECUTIVE]]) -> 0 | O22: =+IF(Tabella1[[#This Row],[LA CARTELLA RIPORTA CARICHI INCLUSI NELLA TABELLA SOTTOSTANTE]]="","",+IF(Tabella1[[#This Row],[LA CARTELLA RIPORTA CARICHI INCLUSI NELLA TABELLA SOTTOSTANTE]]="Sì","RUOLO ESCLUSO DALLA DEFINIZIONE AGEVOLATA","RUOLO ROTTAMABILE")) | P22: =+IF(Tabella1[[#This Row],[DATA AFFIDAMENTO AGENZIA DELLE ENTRATE - RISCOSSIONE]]<42736,1,2) -> 1
M23: =SUM(Tabella1[[#This Row],[IMPOSTE]:[SPESE PER PROCEDURE ESECUTIVE]]) -> 0 | O23: =+IF(Tabella1[[#This Row],[LA CARTELLA RIPORTA CARICHI INCLUSI NELLA TABELLA SOTTOSTANTE]]="","",+IF(Tabella1[[#This Row],[LA CARTELLA RIPORTA CARICHI INCLUSI NELLA TABELLA SOTTOSTANTE]]="Sì","RUOLO ESCLUSO DALLA DEFINIZIONE AGEVOLATA","RUOLO ROTTAMABILE")) | P23: =+IF(Tabella1[[#This Row],[DATA AFFIDAMENTO AGENZIA DELLE ENTRATE - RISCOSSIONE]]<42736,1,2) -> 1
M24: =SUM(Tabella1[[#This Row],[IMPOSTE]:[SPESE PER PROCEDURE ESECUTIVE]]) -> 0 | O24: =+IF(Tabella1[[#This Row],[LA CARTELLA RIPORTA CARICHI INCLUSI NELLA TABELLA SOTTOSTANTE]]="","",+IF(Tabella1[[#This Row],[LA CARTELLA RIPORTA CARICHI INCLUSI NELLA TABELLA SOTTOSTANTE]]="Sì","RUOLO ESCLUSO DALLA DEFINIZIONE AGEVOLATA","RUOLO ROTTAMABILE")) | P24: =+IF(Tabella1[[#This Row],[DATA AFFIDAMENTO AGENZIA DELLE ENTRATE - RISCOSSIONE]]<42736,1,2) -> 1
M25: =SUM(Tabella1[[#This Row],[IMPOSTE]:[SPESE PER PROCEDURE ESECUTIVE]]) -> 0 | O25: =+IF(Tabella1[[#This Row],[LA CARTELLA RIPORTA CARICHI INCLUSI NELLA TABELLA SOTTOSTANTE]]="","",+IF(Tabella1[[#This Row],[LA CARTELLA RIPORTA CARICHI INCLUSI NELLA TABELLA SOTTOSTANTE]]="Sì","RUOLO ESCLUSO DALLA DEFINIZIONE AGEVOLATA","RUOLO ROTTAMABILE")) | P25: =+IF(Tabella1[[#This Row],[DATA AFFIDAMENTO AGENZIA DELLE ENTRATE - RISCOSSIONE]]<42736,1,2) -> 1
M26: =SUM(Tabella1[[#This Row],[IMPOSTE]:[SPESE PER PROCEDURE ESECUTIVE]]) -> 0 | O26: =+IF(Tabella1[[#This Row],[LA CARTELLA RIPORTA CARICHI INCLUSI NELLA TABELLA SOTTOSTANTE]]="","",+IF(Tabella1[[#This Row],[LA CARTELLA RIPORTA CARICHI INCLUSI NELLA TABELLA SOTTOSTANTE]]="Sì","RUOLO ESCLUSO DALLA DEFINIZIONE AGEVOLATA","RUOLO ROTTAMABILE")) | P26: =+IF(Tabella1[[#This Row],[DATA AFFIDAMENTO AGENZIA DELLE ENTRATE - RISCOSSIONE]]<42736,1,2) -> 1
M27: =SUM(Tabella1[[#This Row],[IMPOSTE]:[SPESE PER PROCEDURE ESECUTIVE]]) -> 0 | O27: =+IF(Tabella1[[#This Row],[LA CARTELLA RIPORTA CARICHI INCLUSI NELLA TABELLA SOTTOSTANTE]]="","",+IF(Tabella1[[#This Row],[LA CARTELLA RIPORTA CARICHI INCLUSI NELLA TABELLA SOTTOSTANTE]]="Sì","RUOLO ESCLUSO DALLA DEFINIZIONE AGEVOLATA","RUOLO ROTTAMABILE")) | P27: =+IF(Tabella1[[#This Row],[DATA AFFIDAMENTO AGENZIA DELLE ENTRATE - RISCOSSIONE]]<42736,1,2) -> 1
M28: =SUM(Tabella1[[#This Row],[IMPOSTE]:[SPESE PER PROCEDURE ESECUTIVE]]) -> 0 | O28: =+IF(Tabella1[[#This Row],[LA CARTELLA RIPORTA CARICHI INCLUSI NELLA TABELLA SOTTOSTANTE]]="","",+IF(Tabella1[[#This Row],[LA CARTELLA RIPORTA CARICHI INCLUSI NELLA TABELLA SOTTOSTANTE]]="Sì","RUOLO ESCLUSO DALLA DEFINIZIONE AGEVOLATA","RUOLO ROTTAMABILE")) | P28: =+IF(Tabella1[[#This Row],[DATA AFFIDAMENTO AGENZIA DELLE ENTRATE - RISCOSSIONE]]<42736,1,2) -> 1
B29: TOTALE | E29: =SUBTOTAL(109,Tabella1[IMPOSTE]) -> 7890 | F29: =SUBTOTAL(109,Tabella1[SANZIONI]) -> 2367 | G29: =SUBTOTAL(109,Tabella1[INTERESSI DI MORA]) -> 421 | H29: =SUBTOTAL(109,Tabella1[INTERESSI DI DILAZIONE]) -> 278 | I29: =SUBTOTAL(109,Tabella1[INTERESSI RITARDATA ISCRIZIONE A RUOLO]) -> 139 | J29: =SUBTOTAL(109,Tabella1[ONERI DI RISCOSSIONE (AGGIO)]) -> 814 | K29: =SUBTOTAL(109,Tabella1[SPESE DI NOTIFICA]) -> 9.8 | L29: =SUBTOTAL(109,Tabella1[SPESE PER PROCEDURE ESECUTIVE]) -> 0 | M29: =SUBTOTAL(109,Tabella1[TOTALE CARTELLA]) -> 11918.8
C30: CARICHI ESCLUSI DALLA DEFINIZIONE AGEVOLATA
C31: Risorse proprie tradizionali previste dall’articolo 2, paragrafo 1, lettera a), delle decisioni 2007/436/CE/Euratom del Consiglio, del 7 giugno 2007, e 2014/335/UE/Euratom del Consiglio, del 26 maggio 2014
C32: IVA riscossa all'importazione
C33: Somme dovute a titolo di recupero di aiuti di Stato ai sensi dell’articolo 16 del regolamento (UE) n. 2015/1589 del Consiglio, del 13 luglio 2015
C34: Carichi emessi per il recupero di crediti tributari sorti in uno Stato membro dell’Unione Europea, in uno Stato estero aderente alla Convenzione OCSE/CoE o in uno Stato estero con cui l’Italia ha stipulato una convenzione bilaterale in materia di assistenza alla riscossione
C35: Crediti derivanti da pronunce di condanna della Corte dei conti
C36: Multe, ammende e sanzioni pecuniarie dovute a seguito di provvedimenti e sentenze penali di condanna
C37: Altre sanzioni diverse da quelle irrogate per violazioni tributarie
C38: Carichi già inclusi in precedenti definizioni agevolate con piano regolarmente in corso.

Sheet RATEAZIONI
B12: RATEAZIONE CARTELLE
B16: INS CARTELLA | C16: Cartella2 | D16: N° RATA | E16: DATA VERSAMENTO | F16: IMPORTO VERSATO | G16: Quota imposta | H16: Quota Sanzioni | I16: Quota Int. Mora | J16: Quota Int. di dilazione | K16: Quota Interessi per rit. Iscr. a ruolo | L16: Oneri di riscossione (aggio esattoriale) | M16: Spese per procedure esecutive | N16: X | O16: Spese di Notifica
B17: 1 | C17: =+IF(Tabella24[[#This Row],[INS CARTELLA]]="",C16,+VLOOKUP(Tabella24[[#This Row],[INS CARTELLA]],Tabella1[[NUMERO CARTELLA]:[IMPOSTE]],1,0)) -> #N/A | D17: 1 | E17: 44255 | F17: 1500 | G17: =+IFERROR(+Tabella24[[#This Row],[IMPORTO VERSATO]]/SUMIF(DATI!B:B,Tabella24[[#This Row],[Cartella2]],DATI!M:M)*SUMIF(DATI!B:B,Tabella24[[#This Row],[Cartella2]],DATI!E:E),"") | H17: =+IFERROR(+Tabella24[[#This Row],[IMPORTO VERSATO]]/SUMIF(DATI!$B:$B,Tabella24[[#This Row],[Cartella2]],DATI!$M:$M)*SUMIF(DATI!$B:$B,Tabella24[[#This Row],[Cartella2]],DATI!$F:$F),"") | I17: =+IFERROR(+Tabella24[[#This Row],[IMPORTO VERSATO]]/SUMIF(DATI!$B:$B,Tabella24[[#This Row],[Cartella2]],DATI!$M:$M)*SUMIF(DATI!$B:$B,Tabella24[[#This Row],[Cartella2]],DATI!$G:$G),"") | J17: =+IFERROR(+Tabella24[[#This Row],[IMPORTO VERSATO]]/SUMIF(DATI!$B:$B,Tabella24[[#This Row],[Cartella2]],DATI!$M:$M)*SUMIF(DATI!$B:$B,Tabella24[[#This Row],[Cartella2]],DATI!$H:$H),"") | K17: =+IFERROR(+Tabella24[[#This Row],[IMPORTO VERSATO]]/SUMIF(DATI!$B:$B,Tabella24[[#This Row],[Cartella2]],DATI!$M:$M)*SUMIF(DATI!$B:$B,Tabella24[[#This Row],[Cartella2]],DATI!$I:$I),"") | L17: =+IFERROR(+Tabella24[[#This Row],[IMPORTO VERSATO]]/SUMIF(DATI!$B:$B,Tabella24[[#This Row],[Cartella2]],DATI!$M:$M)*SUMIF(DATI!$B:$B,Tabella24[[#This Row],[Cartella2]],DATI!$J:$J),"") | M17: =+IFERROR(+Tabella24[[#This Row],[IMPORTO VERSATO]]/SUMIF(DATI!$B:$B,Tabella24[[#This Row],[Cartella2]],DATI!$M:$M)*SUMIF(DATI!$B:$B,Tabella24[[#This Row],[Cartella2]],DATI!$L:$L),"") | O17: =+IFERROR(+Tabella24[[#This Row],[IMPORTO VERSATO]]/SUMIF(DATI!$B:$B,Tabella24[[#This Row],[Cartella2]],DATI!$M:$M)*SUMIF(DATI!$B:$B,Tabella24[[#This Row],[Cartella2]],DATI!$K:$K),"")
C18: =+IF(Tabella24[[#This Row],[INS CARTELLA]]="",C17,+VLOOKUP(Tabella24[[#This Row],[INS CARTELLA]],Tabella1[[NUMERO CARTELLA]:[IMPOSTE]],1,0)) -> #N/A | D18: 2 | E18: 44286 | F18: 1500 | G18: =+IFERROR(+Tabella24[[#This Row],[IMPORTO VERSATO]]/SUMIF(DATI!B:B,Tabella24[[#This Row],[Cartella2]],DATI!M:M)*SUMIF(DATI!B:B,Tabella24[[#This Row],[Cartella2]],DATI!E:E),"") | H18: =+IFERROR(+Tabella24[[#This Row],[IMPORTO VERSATO]]/SUMIF(DATI!$B:$B,Tabella24[[#This Row],[Cartella2]],DATI!$M:$M)*SUMIF(DATI!$B:$B,Tabella24[[#This Row],[Cartella2]],DATI!$F:$F),"") | I18: =+IFERROR(+Tabella24[[#This Row],[IMPORTO VERSATO]]/SUMIF(DATI!$B:$B,Tabella24[[#This Row],[Cartella2]],DATI!$M:$M)*SUMIF(DATI!$B:$B,Tabella24[[#This Row],[Cartella2]],DATI!$G:$G),"") | J18: =+IFERROR(+Tabella24[[#This Row],[IMPORTO VERSATO]]/SUMIF(DATI!$B:$B,Tabella24[[#This Row],[Cartella2]],DATI!$M:$M)*SUMIF(DATI!$B:$B,Tabella24[[#This Row],[Cartella2]],DATI!$H:$H),"") | K18: =+IFERROR(+Tabella24[[#This Row],[IMPORTO VERSATO]]/SUMIF(DATI!$B:$B,Tabella24[[#This Row],[Cartella2]],DATI!$M:$M)*SUMIF(DATI!$B:$B,Tabella24[[#This Row],[Cartella2]],DATI!$I:$I),"") | L18: =+IFERROR(+Tabella24[[#This Row],[IMPORTO VERSATO]]/SUMIF(DATI!$B:$B,Tabella24[[#This Row],[Cartella2]],DATI!$M:$M)*SUMIF(DATI!$B:$B,Tabella24[[#This Row],[Cartella2]],DATI!$J:$J),"") | M18: =+IFERROR(+Tabella24[[#This Row],[IMPORTO VERSATO]]/SUMIF(DATI!$B:$B,Tabella24[[#This Row],[Cartella2]],DATI!$M:$M)*SUMIF(DATI!$B:$B,Tabella24[[#This Row],[Cartella2]],DATI!$L:$L),"") | O18: =+IFERROR(+Tabella24[[#This Row],[IMPORTO VERSATO]]/SUMIF(DATI!$B:$B,Tabella24[[#This Row],[Cartella2]],DATI!$M:$M)*SUMIF(DATI!$B:$B,Tabella24[[#This Row],[Cartella2]],DATI!$K:$K),"")
C19: =+IF(Tabella24[[#This Row],[INS CARTELLA]]="",C18,+VLOOKUP(Tabella24[[#This Row],[INS CARTELLA]],Tabella1[[NUMERO CARTELLA]:[IMPOSTE]],1,0)) -> #N/A | D19: 3 | E19: 44316 | F19: 1500 | G19: =+IFERROR(+Tabella24[[#This Row],[IMPORTO VERSATO]]/SUMIF(DATI!B:B,Tabella24[[#This Row],[Cartella2]],DATI!M:M)*SUMIF(DATI!B:B,Tabella24[[#This Row],[Cartella2]],DATI!E:E),"") | H19: =+IFERROR(+Tabella24[[#This Row],[IMPORTO VERSATO]]/SUMIF(DATI!$B:$B,Tabella24[[#This Row],[Cartella2]],DATI!$M:$M)*SUMIF(DATI!$B:$B,Tabella24[[#This Row],[Cartella2]],DATI!$F:$F),"") | I19: =+IFERROR(+Tabella24[[#This Row],[IMPORTO VERSATO]]/SUMIF(DATI!$B:$B,Tabella24[[#This Row],[Cartella2]],DATI!$M:$M)*SUMIF(DATI!$B:$B,Tabella24[[#This Row],[Cartella2]],DATI!$G:$G),"") | J19: =+IFERROR(+Tabella24[[#This Row],[IMPORTO VERSATO]]/SUMIF(DATI!$B:$B,Tabella24[[#This Row],[Cartella2]],DATI!$M:$M)*SUMIF(DATI!$B:$B,Tabella24[[#This Row],[Cartella2]],DATI!$H:$H),"") | K19: =+IFERROR(+Tabella24[[#This Row],[IMPORTO VERSATO]]/SUMIF(DATI!$B:$B,Tabella24[[#This Row],[Cartella2]],DATI!$M:$M)*SUMIF(DATI!$B:$B,Tabella24[[#This Row],[Cartella2]],DATI!$I:$I),"") | L19: =+IFERROR(+Tabella24[[#This Row],[IMPORTO VERSATO]]/SUMIF(DATI!$B:$B,Tabella24[[#This Row],[Cartella2]],DATI!$M:$M)*SUMIF(DATI!$B:$B,Tabella24[[#This Row],[Cartella2]],DATI!$J:$J),"") | M19: =+IFERROR(+Tabella24[[#This Row],[IMPORTO VERSATO]]/SUMIF(DATI!$B:$B,Tabella24[[#This Row],[Cartella2]],DATI!$M:$M)*SUMIF(DATI!$B:$B,Tabella24[[#This Row],[Cartella2]],DATI!$L:$L),"") | O19: =+IFERROR(+Tabella24[[#This Row],[IMPORTO VERSATO]]/SUMIF(DATI!$B:$B,Tabella24[[#This Row],[Cartella2]],DATI!$M:$M)*SUMIF(DATI!$B:$B,Tabella24[[#This Row],[Cartella2]],DATI!$K:$K),"")
B20: 2 | C20: =+IF(Tabella24[[#This Row],[INS CARTELLA]]="",C19,+VLOOKUP(Tabella24[[#This Row],[INS CARTELLA]],Tabella1[[NUMERO CARTELLA]:[IMPOSTE]],1,0)) -> #N/A | D20: 1 | E20: 44469 | F20: 500 | G20: =+IFERROR(+Tabella24[[#This Row],[IMPORTO VERSATO]]/SUMIF(DATI!B:B,Tabella24[[#This Row],[Cartella2]],DATI!M:M)*SUMIF(DATI!B:B,Tabella24[[#This Row],[Cartella2]],DATI!E:E),"") | H20: =+IFERROR(+Tabella24[[#This Row],[IMPORTO VERSATO]]/SUMIF(DATI!$B:$B,Tabella24[[#This Row],[Cartella2]],DATI!$M:$M)*SUMIF(DATI!$B:$B,Tabella24[[#This Row],[Cartella2]],DATI!$F:$F),"") | I20: =+IFERROR(+Tabella24[[#This Row],[IMPORTO VERSATO]]/SUMIF(DATI!$B:$B,Tabella24[[#This Row],[Cartella2]],DATI!$M:$M)*SUMIF(DATI!$B:$B,Tabella24[[#This Row],[Cartella2]],DATI!$G:$G),"") | J20: =+IFERROR(+Tabella24[[#This Row],[IMPORTO VERSATO]]/SUMIF(DATI!$B:$B,Tabella24[[#This Row],[Cartella2]],DATI!$M:$M)*SUMIF(DATI!$B:$B,Tabella24[[#This Row],[Cartella2]],DATI!$H:$H),"") | K20: =+IFERROR(+Tabella24[[#This Row],[IMPORTO VERSATO]]/SUMIF(DATI!$B:$B,Tabella24[[#This Row],[Cartella2]],DATI!$M:$M)*SUMIF(DATI!$B:$B,Tabella24[[#This Row],[Cartella2]],DATI!$I:$I),"") | L20: =+IFERROR(+Tabella24[[#This Row],[IMPORTO VERSATO]]/SUMIF(DATI!$B:$B,Tabella24[[#This Row],[Cartella2]],DATI!$M:$M)*SUMIF(DATI!$B:$B,Tabella24[[#This Row],[Cartella2]],DATI!$J:$J),"") | M20: =+IFERROR(+Tabella24[[#This Row],[IMPORTO VERSATO]]/SUMIF(DATI!$B:$B,Tabella24[[#This Row],[Cartella2]],DATI!$M:$M)*SUMIF(DATI!$B:$B,Tabella24[[#This Row],[Cartella2]],DATI!$L:$L),"") | O20: =+IFERROR(+Tabella24[[#This Row],[IMPORTO VERSATO]]/SUMIF(DATI!$B:$B,Tabella24[[#This Row],[Cartella2]],DATI!$M:$M)*SUMIF(DATI!$B:$B,Tabella24[[#This Row],[Cartella2]],DATI!$K:$K),"")
C21: =+IF(Tabella24[[#This Row],[INS CARTELLA]]="",C20,+VLOOKUP(Tabella24[[#This Row],[INS CARTELLA]],Tabella1[[NUMERO CARTELLA]:[IMPOSTE]],1,0)) -> #N/A | D21: 2 | E21: 44500 | F21: 500 | G21: =+IFERROR(+Tabella24[[#This Row],[IMPORTO VERSATO]]/SUMIF(DATI!B:B,Tabella24[[#This Row],[Cartella2]],DATI!M:M)*SUMIF(DATI!B:B,Tabella24[[#This Row],[Cartella2]],DATI!E:E),"") | H21: =+IFERROR(+Tabella24[[#This Row],[IMPORTO VERSATO]]/SUMIF(DATI!$B:$B,Tabella24[[#This Row],[Cartella2]],DATI!$M:$M)*SUMIF(DATI!$B:$B,Tabella24[[#This Row],[Cartella2]],DATI!$F:$F),"") | I21: =+IFERROR(+Tabella24[[#This Row],[IMPORTO VERSATO]]/SUMIF(DATI!$B:$B,Tabella24[[#This Row],[Cartella2]],DATI!$M:$M)*SUMIF(DATI!$B:$B,Tabella24[[#This Row],[Cartella2]],DATI!$G:$G),"") | J21: =+IFERROR(+Tabella24[[#This Row],[IMPORTO VERSATO]]/SUMIF(DATI!$B:$B,Tabella24[[#This Row],[Cartella2]],DATI!$M:$M)*SUMIF(DATI!$B:$B,Tabella24[[#This Row],[Cartella2]],DATI!$H:$H),"") | K21: =+IFERROR(+Tabella24[[#This Row],[IMPORTO VERSATO]]/SUMIF(DATI!$B:$B,Tabella24[[#This Row],[Cartella2]],DATI!$M:$M)*SUMIF(DATI!$B:$B,Tabella24[[#This Row],[Cartella2]],DATI!$I:$I),"") | L21: =+IFERROR(+Tabella24[[#This Row],[IMPORTO VERSATO]]/SUMIF(DATI!$B:$B,Tabella24[[#This Row],[Cartella2]],DATI!$M:$M)*SUMIF(DATI!$B:$B,Tabella24[[#This Row],[Cartella2]],DATI!$J:$J),"") | M21: =+IFERROR(+Tabella24[[#This Row],[IMPORTO VERSATO]]/SUMIF(DATI!$B:$B,Tabella24[[#This Row],[Cartella2]],DATI!$M:$M)*SUMIF(DATI!$B:$B,Tabella24[[#This Row],[Cartella2]],DATI!$L:$L),"") | O21: =+IFERROR(+Tabella24[[#This Row],[IMPORTO VERSATO]]/SUMIF(DATI!$B:$B,Tabella24[[#This Row],[Cartella2]],DATI!$M:$M)*SUMIF(DATI!$B:$B,Tabella24[[#This Row],[Cartella2]],DATI!$K:$K),"")
C22: =+IF(Tabella24[[#This Row],[INS CARTELLA]]="",C21,+VLOOKUP(Tabella24[[#This Row],[INS CARTELLA]],Tabella1[[NUMERO CARTELLA]:[IMPOSTE]],1,0)) -> #N/A | D22: 3 | E22: 44530 | F22: 500 | G22: =+IFERROR(+Tabella24[[#This Row],[IMPORTO VERSATO]]/SUMIF(DATI!B:B,Tabella24[[#This Row],[Cartella2]],DATI!M:M)*SUMIF(DATI!B:B,Tabella24[[#This Row],[Cartella2]],DATI!E:E),"") | H22: =+IFERROR(+Tabella24[[#This Row],[IMPORTO VERSATO]]/SUMIF(DATI!$B:$B,Tabella24[[#This Row],[Cartella2]],DATI!$M:$M)*SUMIF(DATI!$B:$B,Tabella24[[#This Row],[Cartella2]],DATI!$F:$F),"") | I22: =+IFERROR(+Tabella24[[#This Row],[IMPORTO VERSATO]]/SUMIF(DATI!$B:$B,Tabella24[[#This Row],[Cartella2]],DATI!$M:$M)*SUMIF(DATI!$B:$B,Tabella24[[#This Row],[Cartella2]],DATI!$G:$G),"") | J22: =+IFERROR(+Tabella24[[#This Row],[IMPORTO VERSATO]]/SUMIF(DATI!$B:$B,Tabella24[[#This Row],[Cartella2]],DATI!$M:$M)*SUMIF(DATI!$B:$B,Tabella24[[#This Row],[Cartella2]],DATI!$H:$H),"") | K22: =+IFERROR(+Tabella24[[#This Row],[IMPORTO VERSATO]]/SUMIF(DATI!$B:$B,Tabella24[[#This Row],[Cartella2]],DATI!$M:$M)*SUMIF(DATI!$B:$B,Tabella24[[#This Row],[Cartella2]],DATI!$I:$I),"") | L22: =+IFERROR(+Tabella24[[#This Row],[IMPORTO VERSATO]]/SUMIF(DATI!$B:$B,Tabella24[[#This Row],[Cartella2]],DATI!$M:$M)*SUMIF(DATI!$B:$B,Tabella24[[#This Row],[Cartella2]],DATI!$J:$J),"") | M22: =+IFERROR(+Tabella24[[#This Row],[IMPORTO VERSATO]]/SUMIF(DATI!$B:$B,Tabella24[[#This Row],[Cartella2]],DATI!$M:$M)*SUMIF(DATI!$B:$B,Tabella24[[#This Row],[Cartella2]],DATI!$L:$L),"") | O22: =+IFERROR(+Tabella24[[#This Row],[IMPORTO VERSATO]]/SUMIF(DATI!$B:$B,Tabella24[[#This Row],[Cartella2]],DATI!$M:$M)*SUMIF(DATI!$B:$B,Tabella24[[#This Row],[Cartella2]],DATI!$K:$K),"")
C23: =+IF(Tabella24[[#This Row],[INS CARTELLA]]="",C22,+VLOOKUP(Tabella24[[#This Row],[INS CARTELLA]],Tabella1[[NUMERO CARTELLA]:[IMPOSTE]],1,0)) -> #N/A | G23: =+IFERROR(+Tabella24[[#This Row],[IMPORTO VERSATO]]/SUMIF(DATI!B:B,Tabella24[[#This Row],[Cartella2]],DATI!M:M)*SUMIF(DATI!B:B,Tabella24[[#This Row],[Cartella2]],DATI!E:E),"") | H23: =+IFERROR(+Tabella24[[#This Row],[IMPORTO VERSATO]]/SUMIF(DATI!$B:$B,Tabella24[[#This Row],[Cartella2]],DATI!$M:$M)*SUMIF(DATI!$B:$B,Tabella24[[#This Row],[Cartella2]],DATI!$F:$F),"") | I23: =+IFERROR(+Tabella24[[#This Row],[IMPORTO VERSATO]]/SUMIF(DATI!$B:$B,Tabella24[[#This Row],[Cartella2]],DATI!$M:$M)*SUMIF(DATI!$B:$B,Tabella24[[#This Row],[Cartella2]],DATI!$G:$G),"") | J23: =+IFERROR(+Tabella24[[#This Row],[IMPORTO VERSATO]]/SUMIF(DATI!$B:$B,Tabella24[[#This Row],[Cartella2]],DATI!$M:$M)*SUMIF(DATI!$B:$B,Tabella24[[#This Row],[Cartella2]],DATI!$H:$H),"") | K23: =+IFERROR(+Tabella24[[#This Row],[IMPORTO VERSATO]]/SUMIF(DATI!$B:$B,Tabella24[[#This Row],[Cartella2]],DATI!$M:$M)*SUMIF(DATI!$B:$B,Tabella24[[#This Row],[Cartella2]],DATI!$I:$I),"") | L23: =+IFERROR(+Tabella24[[#This Row],[IMPORTO VERSATO]]/SUMIF(DATI!$B:$B,Tabella24[[#This Row],[Cartella2]],DATI!$M:$M)*SUMIF(DATI!$B:$B,Tabella24[[#This Row],[Cartella2]],DATI!$J:$J),"") | M23: =+IFERROR(+Tabella24[[#This Row],[IMPORTO VERSATO]]/SUMIF(DATI!$B:$B,Tabella24[[#This Row],[Cartella2]],DATI!$M:$M)*SUMIF(DATI!$B:$B,Tabella24[[#This Row],[Cartella2]],DATI!$L:$L),"") | O23: =+IFERROR(+Tabella24[[#This Row],[IMPORTO VERSATO]]/SUMIF(DATI!$B:$B,Tabella24[[#This Row],[Cartella2]],DATI!$M:$M)*SUMIF(DATI!$B:$B,Tabella24[[#This Row],[Cartella2]],DATI!$K:$K),"")
C24: =+IF(Tabella24[[#This Row],[INS CARTELLA]]="",C23,+VLOOKUP(Tabella24[[#This Row],[INS CARTELLA]],Tabella1[[NUMERO CARTELLA]:[IMPOSTE]],1,0)) -> #N/A | G24: =+IFERROR(+Tabella24[[#This Row],[IMPORTO VERSATO]]/SUMIF(DATI!B:B,Tabella24[[#This Row],[Cartella2]],DATI!M:M)*SUMIF(DATI!B:B,Tabella24[[#This Row],[Cartella2]],DATI!E:E),"") | H24: =+IFERROR(+Tabella24[[#This Row],[IMPORTO VERSATO]]/SUMIF(DATI!$B:$B,Tabella24[[#This Row],[Cartella2]],DATI!$M:$M)*SUMIF(DATI!$B:$B,Tabella24[[#This Row],[Cartella2]],DATI!$F:$F),"") | I24: =+IFERROR(+Tabella24[[#This Row],[IMPORTO VERSATO]]/SUMIF(DATI!$B:$B,Tabella24[[#This Row],[Cartella2]],DATI!$M:$M)*SUMIF(DATI!$B:$B,Tabella24[[#This Row],[Cartella2]],DATI!$G:$G),"") | J24: =+IFERROR(+Tabella24[[#This Row],[IMPORTO VERSATO]]/SUMIF(DATI!$B:$B,Tabella24[[#This Row],[Cartella2]],DATI!$M:$M)*SUMIF(DATI!$B:$B,Tabella24[[#This Row],[Cartella2]],DATI!$H:$H),"") | K24: =+IFERROR(+Tabella24[[#This Row],[IMPORTO VERSATO]]/SUMIF(DATI!$B:$B,Tabella24[[#This Row],[Cartella2]],DATI!$M:$M)*SUMIF(DATI!$B:$B,Tabella24[[#This Row],[Cartella2]],DATI!$I:$I),"") | L24: =+IFERROR(+Tabella24[[#This Row],[IMPORTO VERSATO]]/SUMIF(DATI!$B:$B,Tabella24[[#This Row],[Cartella2]],DATI!$M:$M)*SUMIF(DATI!$B:$B,Tabella24[[#This Row],[Cartella2]],DATI!$J:$J),"") | M24: =+IFERROR(+Tabella24[[#This Row],[IMPORTO VERSATO]]/SUMIF(DATI!$B:$B,Tabella24[[#This Row],[Cartella2]],DATI!$M:$M)*SUMIF(DATI!$B:$B,Tabella24[[#This Row],[Cartella2]],DATI!$L:$L),"") | O24: =+IFERROR(+Tabella24[[#This Row],[IMPORTO VERSATO]]/SUMIF(DATI!$B:$B,Tabella24[[#This Row],[Cartella2]],DATI!$M:$M)*SUMIF(DATI!$B:$B,Tabella24[[#This Row],[Cartella2]],DATI!$K:$K),"")
C25: =+IF(Tabella24[[#This Row],[INS CARTELLA]]="",C24,+VLOOKUP(Tabella24[[#This Row],[INS CARTELLA]],Tabella1[[NUMERO CARTELLA]:[IMPOSTE]],1,0)) -> #N/A | G25: =+IFERROR(+Tabella24[[#This Row],[IMPORTO VERSATO]]/SUMIF(DATI!B:B,Tabella24[[#This Row],[Cartella2]],DATI!M:M)*SUMIF(DATI!B:B,Tabella24[[#This Row],[Cartella2]],DATI!E:E),"") | H25: =+IFERROR(+Tabella24[[#This Row],[IMPORTO VERSATO]]/SUMIF(DATI!$B:$B,Tabella24[[#This Row],[Cartella2]],DATI!$M:$M)*SUMIF(DATI!$B:$B,Tabella24[[#This Row],[Cartella2]],DATI!$F:$F),"") | I25: =+IFERROR(+Tabella24[[#This Row],[IMPORTO VERSATO]]/SUMIF(DATI!$B:$B,Tabella24[[#This Row],[Cartella2]],DATI!$M:$M)*SUMIF(DATI!$B:$B,Tabella24[[#This Row],[Cartella2]],DATI!$G:$G),"") | J25: =+IFERROR(+Tabella24[[#This Row],[IMPORTO VERSATO]]/SUMIF(DATI!$B:$B,Tabella24[[#This Row],[Cartella2]],DATI!$M:$M)*SUMIF(DATI!$B:$B,Tabella24[[#This Row],[Cartella2]],DATI!$H:$H),"") | K25: =+IFERROR(+Tabella24[[#This Row],[IMPORTO VERSATO]]/SUMIF(DATI!$B:$B,Tabella24[[#This Row],[Cartella2]],DATI!$M:$M)*SUMIF(DATI!$B:$B,Tabella24[[#This Row],[Cartella2]],DATI!$I:$I),"") | L25: =+IFERROR(+Tabella24[[#This Row],[IMPORTO VERSATO]]/SUMIF(DATI!$B:$B,Tabella24[[#This Row],[Cartella2]],DATI!$M:$M)*SUMIF(DATI!$B:$B,Tabella24[[#This Row],[Cartella2]],DATI!$J:$J),"") | M25: =+IFERROR(+Tabella24[[#This Row],[IMPORTO VERSATO]]/SUMIF(DATI!$B:$B,Tabella24[[#This Row],[Cartella2]],DATI!$M:$M)*SUMIF(DATI!$B:$B,Tabella24[[#This Row],[Cartella2]],DATI!$L:$L),"") | O25: =+IFERROR(+Tabella24[[#This Row],[IMPORTO VERSATO]]/SUMIF(DATI!$B:$B,Tabella24[[#This Row],[Cartella2]],DATI!$M:$M)*SUMIF(DATI!$B:$B,Tabella24[[#This Row],[Cartella2]],DATI!$K:$K),"")
C26: =+IF(Tabella24[[#This Row],[INS CARTELLA]]="",C25,+VLOOKUP(Tabella24[[#This Row],[INS CARTELLA]],Tabella1[[NUMERO CARTELLA]:[IMPOSTE]],1,0)) -> #N/A | G26: =+IFERROR(+Tabella24[[#This Row],[IMPORTO VERSATO]]/SUMIF(DATI!B:B,Tabella24[[#This Row],[Cartella2]],DATI!M:M)*SUMIF(DATI!B:B,Tabella24[[#This Row],[Cartella2]],DATI!E:E),"") | H26: =+IFERROR(+Tabella24[[#This Row],[IMPORTO VERSATO]]/SUMIF(DATI!$B:$B,Tabella24[[#This Row],[Cartella2]],DATI!$M:$M)*SUMIF(DATI!$B:$B,Tabella24[[#This Row],[Cartella2]],DATI!$F:$F),"") | I26: =+IFERROR(+Tabella24[[#This Row],[IMPORTO VERSATO]]/SUMIF(DATI!$B:$B,Tabella24[[#This Row],[Cartella2]],DATI!$M:$M)*SUMIF(DATI!$B:$B,Tabella24[[#This Row],[Cartella2]],DATI!$G:$G),"") | J26: =+IFERROR(+Tabella24[[#This Row],[IMPORTO VERSATO]]/SUMIF(DATI!$B:$B,Tabella24[[#This Row],[Cartella2]],DATI!$M:$M)*SUMIF(DATI!$B:$B,Tabella24[[#This Row],[Cartella2]],DATI!$H:$H),"") | K26: =+IFERROR(+Tabella24[[#This Row],[IMPORTO VERSATO]]/SUMIF(DATI!$B:$B,Tabella24[[#This Row],[Cartella2]],DATI!$M:$M)*SUMIF(DATI!$B:$B,Tabella24[[#This Row],[Cartella2]],DATI!$I:$I),"") | L26: =+IFERROR(+Tabella24[[#This Row],[IMPORTO VERSATO]]/SUMIF(DATI!$B:$B,Tabella24[[#This Row],[Cartella2]],DATI!$M:$M)*SUMIF(DATI!$B:$B,Tabella24[[#This Row],[Cartella2]],DATI!$J:$J),"") | M26: =+IFERROR(+Tabella24[[#This Row],[IMPORTO VERSATO]]/SUMIF(DATI!$B:$B,Tabella24[[#This Row],[Cartella2]],DATI!$M:$M)*SUMIF(DATI!$B:$B,Tabella24[[#This Row],[Cartella2]],DATI!$L:$L),"") | O26: =+IFERROR(+Tabella24[[#This Row],[IMPORTO VERSATO]]/SUMIF(DATI!$B:$B,Tabella24[[#This Row],[Cartella2]],DATI!$M:$M)*SUMIF(DATI!$B:$B,Tabella24[[#This Row],[Cartella2]],DATI!$K:$K),"")
C27: =+IF(Tabella24[[#This Row],[INS CARTELLA]]="",C26,+VLOOKUP(Tabella24[[#This Row],[INS CARTELLA]],Tabella1[[NUMERO CARTELLA]:[IMPOSTE]],1,0)) -> #N/A | G27: =+IFERROR(+Tabella24[[#This Row],[IMPORTO VERSATO]]/SUMIF(DATI!B:B,Tabella24[[#This Row],[Cartella2]],DATI!M:M)*SUMIF(DATI!B:B,Tabella24[[#This Row],[Cartella2]],DATI!E:E),"") | H27: =+IFERROR(+Tabella24[[#This Row],[IMPORTO VERSATO]]/SUMIF(DATI!$B:$B,Tabella24[[#This Row],[Cartella2]],DATI!$M:$M)*SUMIF(DATI!$B:$B,Tabella24[[#This Row],[Cartella2]],DATI!$F:$F),"") | I27: =+IFERROR(+Tabella24[[#This Row],[IMPORTO VERSATO]]/SUMIF(DATI!$B:$B,Tabella24[[#This Row],[Cartella2]],DATI!$M:$M)*SUMIF(DATI!$B:$B,Tabella24[[#This Row],[Cartella2]],DATI!$G:$G),"") | J27: =+IFERROR(+Tabella24[[#This Row],[IMPORTO VERSATO]]/SUMIF(DATI!$B:$B,Tabella24[[#This Row],[Cartella2]],DATI!$M:$M)*SUMIF(DATI!$B:$B,Tabella24[[#This Row],[Cartella2]],DATI!$H:$H),"") | K27: =+IFERROR(+Tabella24[[#This Row],[IMPORTO VERSATO]]/SUMIF(DATI!$B:$B,Tabella24[[#This Row],[Cartella2]],DATI!$M:$M)*SUMIF(DATI!$B:$B,Tabella24[[#This Row],[Cartella2]],DATI!$I:$I),"") | L27: =+IFERROR(+Tabella24[[#This Row],[IMPORTO VERSATO]]/SUMIF(DATI!$B:$B,Tabella24[[#This Row],[Cartella2]],DATI!$M:$M)*SUMIF(DATI!$B:$B,Tabella24[[#This Row],[Cartella2]],DATI!$J:$J),"") | M27: =+IFERROR(+Tabella24[[#This Row],[IMPORTO VERSATO]]/SUMIF(DATI!$B:$B,Tabella24[[#This Row],[Cartella2]],DATI!$M:$M)*SUMIF(DATI!$B:$B,Tabella24[[#This Row],[Cartella2]],DATI!$L:$L),"") | O27: =+IFERROR(+Tabella24[[#This Row],[IMPORTO VERSATO]]/SUMIF(DATI!$B:$B,Tabella24[[#This Row],[Cartella2]],DATI!$M:$M)*SUMIF(DATI!$B:$B,Tabella24[[#This Row],[Cartella2]],DATI!$K:$K),"")
C28: =+IF(Tabella24[[#This Row],[INS CARTELLA]]="",C27,+VLOOKUP(Tabella24[[#This Row],[INS CARTELLA]],Tabella1[[NUMERO CARTELLA]:[IMPOSTE]],1,0)) -> #N/A | G28: =+IFERROR(+Tabella24[[#This Row],[IMPORTO VERSATO]]/SUMIF(DATI!B:B,Tabella24[[#This Row],[Cartella2]],DATI!M:M)*SUMIF(DATI!B:B,Tabella24[[#This Row],[Cartella2]],DATI!E:E),"") | H28: =+IFERROR(+Tabella24[[#This Row],[IMPORTO VERSATO]]/SUMIF(DATI!$B:$B,Tabella24[[#This Row],[Cartella2]],DATI!$M:$M)*SUMIF(DATI!$B:$B,Tabella24[[#This Row],[Cartella2]],DATI!$F:$F),"") | I28: =+IFERROR(+Tabella24[[#This Row],[IMPORTO VERSATO]]/SUMIF(DATI!$B:$B,Tabella24[[#This Row],[Cartella2]],DATI!$M:$M)*SUMIF(DATI!$B:$B,Tabella24[[#This Row],[Cartella2]],DATI!$G:$G),"") | J28: =+IFERROR(+Tabella24[[#This Row],[IMPORTO VERSATO]]/SUMIF(DATI!$B:$B,Tabella24[[#This Row],[Cartella2]],DATI!$M:$M)*SUMIF(DATI!$B:$B,Tabella24[[#This Row],[Cartella2]],DATI!$H:$H),"") | K28: =+IFERROR(+Tabella24[[#This Row],[IMPORTO VERSATO]]/SUMIF(DATI!$B:$B,Tabella24[[#This Row],[Cartella2]],DATI!$M:$M)*SUMIF(DATI!$B:$B,Tabella24[[#This Row],[Cartella2]],DATI!$I:$I),"") | L28: =+IFERROR(+Tabella24[[#This Row],[IMPORTO VERSATO]]/SUMIF(DATI!$B:$B,Tabella24[[#This Row],[Cartella2]],DATI!$M:$M)*SUMIF(DATI!$B:$B,Tabella24[[#This Row],[Cartella2]],DATI!$J:$J),"") | M28: =+IFERROR(+Tabella24[[#This Row],[IMPORTO VERSATO]]/SUMIF(DATI!$B:$B,Tabella24[[#This Row],[Cartella2]],DATI!$M:$M)*SUMIF(DATI!$B:$B,Tabella24[[#This Row],[Cartella2]],DATI!$L:$L),"") | O28: =+IFERROR(+Tabella24[[#This Row],[IMPORTO VERSATO]]/SUMIF(DATI!$B:$B,Tabella24[[#This Row],[Cartella2]],DATI!$M:$M)*SUMIF(DATI!$B:$B,Tabella24[[#This Row],[Cartella2]],DATI!$K:$K),"")
C29: =+IF(Tabella24[[#This Row],[INS CARTELLA]]="",C28,+VLOOKUP(Tabella24[[#This Row],[INS CARTELLA]],Tabella1[[NUMERO CARTELLA]:[IMPOSTE]],1,0)) -> #N/A | G29: =+IFERROR(+Tabella24[[#This Row],[IMPORTO VERSATO]]/SUMIF(DATI!B:B,Tabella24[[#This Row],[Cartella2]],DATI!M:M)*SUMIF(DATI!B:B,Tabella24[[#This Row],[Cartella2]],DATI!E:E),"") | H29: =+IFERROR(+Tabella24[[#This Row],[IMPORTO VERSATO]]/SUMIF(DATI!$B:$B,Tabella24[[#This Row],[Cartella2]],DATI!$M:$M)*SUMIF(DATI!$B:$B,Tabella24[[#This Row],[Cartella2]],DATI!$F:$F),"") | I29: =+IFERROR(+Tabella24[[#This Row],[IMPORTO VERSATO]]/SUMIF(DATI!$B:$B,Tabella24[[#This Row],[Cartella2]],DATI!$M:$M)*SUMIF(DATI!$B:$B,Tabella24[[#This Row],[Cartella2]],DATI!$G:$G),"") | J29: =+IFERROR(+Tabella24[[#This Row],[IMPORTO VERSATO]]/SUMIF(DATI!$B:$B,Tabella24[[#This Row],[Cartella2]],DATI!$M:$M)*SUMIF(DATI!$B:$B,Tabella24[[#This Row],[Cartella2]],DATI!$H:$H),"") | K29: =+IFERROR(+Tabella24[[#This Row],[IMPORTO VERSATO]]/SUMIF(DATI!$B:$B,Tabella24[[#This Row],[Cartella2]],DATI!$M:$M)*SUMIF(DATI!$B:$B,Tabella24[[#This Row],[Cartella2]],DATI!$I:$I),"") | L29: =+IFERROR(+Tabella24[[#This Row],[IMPORTO VERSATO]]/SUMIF(DATI!$B:$B,Tabella24[[#This Row],[Cartella2]],DATI!$M:$M)*SUMIF(DATI!$B:$B,Tabella24[[#This Row],[Cartella2]],DATI!$J:$J),"") | M29: =+IFERROR(+Tabella24[[#This Row],[IMPORTO VERSATO]]/SUMIF(DATI!$B:$B,Tabella24[[#This Row],[Cartella2]],DATI!$M:$M)*SUMIF(DATI!$B:$B,Tabella24[[#This Row],[Cartella2]],DATI!$L:$L),"") | N29: =+IF(COUNTIF($C$17:C29,Tabella24[[#This Row],[Cartella2]])=1,"X","") | O29: =+IFERROR(+Tabella24[[#This Row],[IMPORTO VERSATO]]/SUMIF(DATI!$B:$B,Tabella24[[#This Row],[Cartella2]],DATI!$M:$M)*SUMIF(DATI!$B:$B,Tabella24[[#This Row],[Cartella2]],DATI!$K:$K),"")
C30: =+IF(Tabella24[[#This Row],[INS CARTELLA]]="",C29,+VLOOKUP(Tabella24[[#This Row],[INS CARTELLA]],Tabella1[[NUMERO CARTELLA]:[IMPOSTE]],1,0)) -> #N/A | G30: =+IFERROR(+Tabella24[[#This Row],[IMPORTO VERSATO]]/SUMIF(DATI!B:B,Tabella24[[#This Row],[Cartella2]],DATI!M:M)*SUMIF(DATI!B:B,Tabella24[[#This Row],[Cartella2]],DATI!E:E),"") | H30: =+IFERROR(+Tabella24[[#This Row],[IMPORTO VERSATO]]/SUMIF(DATI!$B:$B,Tabella24[[#This Row],[Cartella2]],DATI!$M:$M)*SUMIF(DATI!$B:$B,Tabella24[[#This Row],[Cartella2]],DATI!$F:$F),"") | I30: =+IFERROR(+Tabella24[[#This Row],[IMPORTO VERSATO]]/SUMIF(DATI!$B:$B,Tabella24[[#This Row],[Cartella2]],DATI!$M:$M)*SUMIF(DATI!$B:$B,Tabella24[[#This Row],[Cartella2]],DATI!$G:$G),"") | J30: =+IFERROR(+Tabella24[[#This Row],[IMPORTO VERSATO]]/SUMIF(DATI!$B:$B,Tabella24[[#This Row],[Cartella2]],DATI!$M:$M)*SUMIF(DATI!$B:$B,Tabella24[[#This Row],[Cartella2]],DATI!$H:$H),"") | K30: =+IFERROR(+Tabella24[[#This Row],[IMPORTO VERSATO]]/SUMIF(DATI!$B:$B,Tabella24[[#This Row],[Cartella2]],DATI!$M:$M)*SUMIF(DATI!$B:$B,Tabella24[[#This Row],[Cartella2]],DATI!$I:$I),"") | L30: =+IFERROR(+Tabella24[[#This Row],[IMPORTO VERSATO]]/SUMIF(DATI!$B:$B,Tabella24[[#This Row],[Cartella2]],DATI!$M:$M)*SUMIF(DATI!$B:$B,Tabella24[[#This Row],[Cartella2]],DATI!$J:$J),"") | M30: =+IFERROR(+Tabella24[[#This Row],[IMPORTO VERSATO]]/SUMIF(DATI!$B:$B,Tabella24[[#This Row],[Cartella2]],DATI!$M:$M)*SUMIF(DATI!$B:$B,Tabella24[[#This Row],[Cartella2]],DATI!$L:$L),"") | N30: =+IF(COUNTIF($C$17:C30,Tabella24[[#This Row],[Cartella2]])=1,"X","") | O30: =+IFERROR(+Tabella24[[#This Row],[IMPORTO VERSATO]]/SUMIF(DATI!$B:$B,Tabella24[[#This Row],[Cartella2]],DATI!$M:$M)*SUMIF(DATI!$B:$B,Tabella24[[#This Row],[Cartella2]],DATI!$K:$K),"")
C31: =+IF(Tabella24[[#This Row],[INS CARTELLA]]="",C30,+VLOOKUP(Tabella24[[#This Row],[INS CARTELLA]],Tabella1[[NUMERO CARTELLA]:[IMPOSTE]],1,0)) -> #N/A | G31: =+IFERROR(+Tabella24[[#This Row],[IMPORTO VERSATO]]/SUMIF(DATI!B:B,Tabella24[[#This Row],[Cartella2]],DATI!M:M)*SUMIF(DATI!B:B,Tabella24[[#This Row],[Cartella2]],DATI!E:E),"") | H31: =+IFERROR(+Tabella24[[#This Row],[IMPORTO VERSATO]]/SUMIF(DATI!$B:$B,Tabella24[[#This Row],[Cartella2]],DATI!$M:$M)*SUMIF(DATI!$B:$B,Tabella24[[#This Row],[Cartella2]],DATI!$F:$F),"") | I31: =+IFERROR(+Tabella24[[#This Row],[IMPORTO VERSATO]]/SUMIF(DATI!$B:$B,Tabella24[[#This Row],[Cartella2]],DATI!$M:$M)*SUMIF(DATI!$B:$B,Tabella24[[#This Row],[Cartella2]],DATI!$G:$G),"") | J31: =+IFERROR(+Tabella24[[#This Row],[IMPORTO VERSATO]]/SUMIF(DATI!$B:$B,Tabella24[[#This Row],[Cartella2]],DATI!$M:$M)*SUMIF(DATI!$B:$B,Tabella24[[#This Row],[Cartella2]],DATI!$H:$H),"") | K31: =+IFERROR(+Tabella24[[#This Row],[IMPORTO VERSATO]]/SUMIF(DATI!$B:$B,Tabella24[[#This Row],[Cartella2]],DATI!$M:$M)*SUMIF(DATI!$B:$B,Tabella24[[#This Row],[Cartella2]],DATI!$I:$I),"") | L31: =+IFERROR(+Tabella24[[#This Row],[IMPORTO VERSATO]]/SUMIF(DATI!$B:$B,Tabella24[[#This Row],[Cartella2]],DATI!$M:$M)*SUMIF(DATI!$B:$B,Tabella24[[#This Row],[Cartella2]],DATI!$J:$J),"") | M31: =+IFERROR(+Tabella24[[#This Row],[IMPORTO VERSATO]]/SUMIF(DATI!$B:$B,Tabella24[[#This Row],[Cartella2]],DATI!$M:$M)*SUMIF(DATI!$B:$B,Tabella24[[#This Row],[Cartella2]],DATI!$L:$L),"") | N31: =+IF(COUNTIF($C$17:C31,Tabella24[[#This Row],[Cartella2]])=1,"X","") | O31: =+IFERROR(+Tabella24[[#This Row],[IMPORTO VERSATO]]/SUMIF(DATI!$B:$B,Tabella24[[#This Row],[Cartella2]],DATI!$M:$M)*SUMIF(DATI!$B:$B,Tabella24[[#This Row],[Cartella2]],DATI!$K:$K),"")
C32: =+IF(Tabella24[[#This Row],[INS CARTELLA]]="",C31,+VLOOKUP(Tabella24[[#This Row],[INS CARTELLA]],Tabella1[[NUMERO CARTELLA]:[IMPOSTE]],1,0)) -> #N/A | G32: =+IFERROR(+Tabella24[[#This Row],[IMPORTO VERSATO]]/SUMIF(DATI!B:B,Tabella24[[#This Row],[Cartella2]],DATI!M:M)*SUMIF(DATI!B:B,Tabella24[[#This Row],[Cartella2]],DATI!E:E),"") | H32: =+IFERROR(+Tabella24[[#This Row],[IMPORTO VERSATO]]/SUMIF(DATI!$B:$B,Tabella24[[#This Row],[Cartella2]],DATI!$M:$M)*SUMIF(DATI!$B:$B,Tabella24[[#This Row],[Cartella2]],DATI!$F:$F),"") | I32: =+IFERROR(+Tabella24[[#This Row],[IMPORTO VERSATO]]/SUMIF(DATI!$B:$B,Tabella24[[#This Row],[Cartella2]],DATI!$M:$M)*SUMIF(DATI!$B:$B,Tabella24[[#This Row],[Cartella2]],DATI!$G:$G),"") | J32: =+IFERROR(+Tabella24[[#This Row],[IMPORTO VERSATO]]/SUMIF(DATI!$B:$B,Tabella24[[#This Row],[Cartella2]],DATI!$M:$M)*SUMIF(DATI!$B:$B,Tabella24[[#This Row],[Cartella2]],DATI!$H:$H),"") | K32: =+IFERROR(+Tabella24[[#This Row],[IMPORTO VERSATO]]/SUMIF(DATI!$B:$B,Tabella24[[#This Row],[Cartella2]],DATI!$M:$M)*SUMIF(DATI!$B:$B,Tabella24[[#This Row],[Cartella2]],DATI!$I:$I),"") | L32: =+IFERROR(+Tabella24[[#This Row],[IMPORTO VERSATO]]/SUMIF(DATI!$B:$B,Tabella24[[#This Row],[Cartella2]],DATI!$M:$M)*SUMIF(DATI!$B:$B,Tabella24[[#This Row],[Cartella2]],DATI!$J:$J),"") | M32: =+IFERROR(+Tabella24[[#This Row],[IMPORTO VERSATO]]/SUMIF(DATI!$B:$B,Tabella24[[#This Row],[Cartella2]],DATI!$M:$M)*SUMIF(DATI!$B:$B,Tabella24[[#This Row],[Cartella2]],DATI!$L:$L),"") | N32: =+IF(COUNTIF($C$17:C32,Tabella24[[#This Row],[Cartella2]])=1,"X","") | O32: =+IFERROR(+Tabella24[[#This Row],[IMPORTO VERSATO]]/SUMIF(DATI!$B:$B,Tabella24[[#This Row],[Cartella2]],DATI!$M:$M)*SUMIF(DATI!$B:$B,Tabella24[[#This Row],[Cartella2]],DATI!$K:$K),"")
C33: =+IF(Tabella24[[#This Row],[INS CARTELLA]]="",C32,+VLOOKUP(Tabella24[[#This Row],[INS CARTELLA]],Tabella1[[NUMERO CARTELLA]:[IMPOSTE]],1,0)) -> #N/A | G33: =+IFERROR(+Tabella24[[#This Row],[IMPORTO VERSATO]]/SUMIF(DATI!B:B,Tabella24[[#This Row],[Cartella2]],DATI!M:M)*SUMIF(DATI!B:B,Tabella24[[#This Row],[Cartella2]],DATI!E:E),"") | H33: =+IFERROR(+Tabella24[[#This Row],[IMPORTO VERSATO]]/SUMIF(DATI!$B:$B,Tabella24[[#This Row],[Cartella2]],DATI!$M:$M)*SUMIF(DATI!$B:$B,Tabella24[[#This Row],[Cartella2]],DATI!$F:$F),"") | I33: =+IFERROR(+Tabella24[[#This Row],[IMPORTO VERSATO]]/SUMIF(DATI!$B:$B,Tabella24[[#This Row],[Cartella2]],DATI!$M:$M)*SUMIF(DATI!$B:$B,Tabella24[[#This Row],[Cartella2]],DATI!$G:$G),"") | J33: =+IFERROR(+Tabella24[[#This Row],[IMPORTO VERSATO]]/SUMIF(DATI!$B:$B,Tabella24[[#This Row],[Cartella2]],DATI!$M:$M)*SUMIF(DATI!$B:$B,Tabella24[[#This Row],[Cartella2]],DATI!$H:$H),"") | K33: =+IFERROR(+Tabella24[[#This Row],[IMPORTO VERSATO]]/SUMIF(DATI!$B:$B,Tabella24[[#This Row],[Cartella2]],DATI!$M:$M)*SUMIF(DATI!$B:$B,Tabella24[[#This Row],[Cartella2]],DATI!$I:$I),"") | L33: =+IFERROR(+Tabella24[[#This Row],[IMPORTO VERSATO]]/SUMIF(DATI!$B:$B,Tabella24[[#This Row],[Cartella2]],DATI!$M:$M)*SUMIF(DATI!$B:$B,Tabella24[[#This Row],[Cartella2]],DATI!$J:$J),"") | M33: =+IFERROR(+Tabella24[[#This Row],[IMPORTO VERSATO]]/SUMIF(DATI!$B:$B,Tabella24[[#This Row],[Cartella2]],DATI!$M:$M)*SUMIF(DATI!$B:$B,Tabella24[[#This Row],[Cartella2]],DATI!$L:$L),"") | N33: =+IF(COUNTIF($C$17:C33,Tabella24[[#This Row],[Cartella2]])=1,"X","") | O33: =+IFERROR(+Tabella24[[#This Row],[IMPORTO VERSATO]]/SUMIF(DATI!$B:$B,Tabella24[[#This Row],[Cartella2]],DATI!$M:$M)*SUMIF(DATI!$B:$B,Tabella24[[#This Row],[Cartella2]],DATI!$K:$K),"")
C34: =+IF(Tabella24[[#This Row],[INS CARTELLA]]="",C33,+VLOOKUP(Tabella24[[#This Row],[INS CARTELLA]],Tabella1[[NUMERO CARTELLA]:[IMPOSTE]],1,0)) -> #N/A | G34: =+IFERROR(+Tabella24[[#This Row],[IMPORTO VERSATO]]/SUMIF(DATI!B:B,Tabella24[[#This Row],[Cartella2]],DATI!M:M)*SUMIF(DATI!B:B,Tabella24[[#This Row],[Cartella2]],DATI!E:E),"") | H34: =+IFERROR(+Tabella24[[#This Row],[IMPORTO VERSATO]]/SUMIF(DATI!$B:$B,Tabella24[[#This Row],[Cartella2]],DATI!$M:$M)*SUMIF(DATI!$B:$B,Tabella24[[#This Row],[Cartella2]],DATI!$F:$F),"") | I34: =+IFERROR(+Tabella24[[#This Row],[IMPORTO VERSATO]]/SUMIF(DATI!$B:$B,Tabella24[[#This Row],[Cartella2]],DATI!$M:$M)*SUMIF(DATI!$B:$B,Tabella24[[#This Row],[Cartella2]],DATI!$G:$G),"") | J34: =+IFERROR(+Tabella24[[#This Row],[IMPORTO VERSATO]]/SUMIF(DATI!$B:$B,Tabella24[[#This Row],[Cartella2]],DATI!$M:$M)*SUMIF(DATI!$B:$B,Tabella24[[#This Row],[Cartella2]],DATI!$H:$H),"") | K34: =+IFERROR(+Tabella24[[#This Row],[IMPORTO VERSATO]]/SUMIF(DATI!$B:$B,Tabella24[[#This Row],[Cartella2]],DATI!$M:$M)*SUMIF(DATI!$B:$B,Tabella24[[#This Row],[Cartella2]],DATI!$I:$I),"") | L34: =+IFERROR(+Tabella24[[#This Row],[IMPORTO VERSATO]]/SUMIF(DATI!$B:$B,Tabella24[[#This Row],[Cartella2]],DATI!$M:$M)*SUMIF(DATI!$B:$B,Tabella24[[#This Row],[Cartella2]],DATI!$J:$J),"") | M34: =+IFERROR(+Tabella24[[#This Row],[IMPORTO VERSATO]]/SUMIF(DATI!$B:$B,Tabella24[[#This Row],[Cartella2]],DATI!$M:$M)*SUMIF(DATI!$B:$B,Tabella24[[#This Row],[Cartella2]],DATI!$L:$L),"") | N34: =+IF(COUNTIF($C$17:C34,Tabella24[[#This Row],[Cartella2]])=1,"X","") | O34: =+IFERROR(+Tabella24[[#This Row],[IMPORTO VERSATO]]/SUMIF(DATI!$B:$B,Tabella24[[#This Row],[Cartella2]],DATI!$M:$M)*SUMIF(DATI!$B:$B,Tabella24[[#This Row],[Cartella2]],DATI!$K:$K),"")
C35: =+IF(Tabella24[[#This Row],[INS CARTELLA]]="",C34,+VLOOKUP(Tabella24[[#This Row],[INS CARTELLA]],Tabella1[[NUMERO CARTELLA]:[IMPOSTE]],1,0)) -> #N/A | G35: =+IFERROR(+Tabella24[[#This Row],[IMPORTO VERSATO]]/SUMIF(DATI!B:B,Tabella24[[#This Row],[Cartella2]],DATI!M:M)*SUMIF(DATI!B:B,Tabella24[[#This Row],[Cartella2]],DATI!E:E),"") | H35: =+IFERROR(+Tabella24[[#This Row],[IMPORTO VERSATO]]/SUMIF(DATI!$B:$B,Tabella24[[#This Row],[Cartella2]],DATI!$M:$M)*SUMIF(DATI!$B:$B,Tabella24[[#This Row],[Cartella2]],DATI!$F:$F),"") | I35: =+IFERROR(+Tabella24[[#This Row],[IMPORTO VERSATO]]/SUMIF(DATI!$B:$B,Tabella24[[#This Row],[Cartella2]],DATI!$M:$M)*SUMIF(DATI!$B:$B,Tabella24[[#This Row],[Cartella2]],DATI!$G:$G),"") | J35: =+IFERROR(+Tabella24[[#This Row],[IMPORTO VERSATO]]/SUMIF(DATI!$B:$B,Tabella24[[#This Row],[Cartella2]],DATI!$M:$M)*SUMIF(DATI!$B:$B,Tabella24[[#This Row],[Cartella2]],DATI!$H:$H),"") | K35: =+IFERROR(+Tabella24[[#This Row],[IMPORTO VERSATO]]/SUMIF(DATI!$B:$B,Tabella24[[#This Row],[Cartella2]],DATI!$M:$M)*SUMIF(DATI!$B:$B,Tabella24[[#This Row],[Cartella2]],DATI!$I:$I),"") | L35: =+IFERROR(+Tabella24[[#This Row],[IMPORTO VERSATO]]/SUMIF(DATI!$B:$B,Tabella24[[#This Row],[Cartella2]],DATI!$M:$M)*SUMIF(DATI!$B:$B,Tabella24[[#This Row],[Cartella2]],DATI!$J:$J),"") | M35: =+IFERROR(+Tabella24[[#This Row],[IMPORTO VERSATO]]/SUMIF(DATI!$B:$B,Tabella24[[#This Row],[Cartella2]],DATI!$M:$M)*SUMIF(DATI!$B:$B,Tabella24[[#This Row],[Cartella2]],DATI!$L:$L),"") | N35: =+IF(COUNTIF($C$17:C35,Tabella24[[#This Row],[Cartella2]])=1,"X","") | O35: =+IFERROR(+Tabella24[[#This Row],[IMPORTO VERSATO]]/SUMIF(DATI!$B:$B,Tabella24[[#This Row],[Cartella2]],DATI!$M:$M)*SUMIF(DATI!$B:$B,Tabella24[[#This Row],[Cartella2]],DATI!$K:$K),"")
C36: =+IF(Tabella24[[#This Row],[INS CARTELLA]]="",C35,+VLOOKUP(Tabella24[[#This Row],[INS CARTELLA]],Tabella1[[NUMERO CARTELLA]:[IMPOSTE]],1,0)) -> #N/A | G36: =+IFERROR(+Tabella24[[#This Row],[IMPORTO VERSATO]]/SUMIF(DATI!B:B,Tabella24[[#This Row],[Cartella2]],DATI!M:M)*SUMIF(DATI!B:B,Tabella24[[#This Row],[Cartella2]],DATI!E:E),"") | H36: =+IFERROR(+Tabella24[[#This Row],[IMPORTO VERSATO]]/SUMIF(DATI!$B:$B,Tabella24[[#This Row],[Cartella2]],DATI!$M:$M)*SUMIF(DATI!$B:$B,Tabella24[[#This Row],[Cartella2]],DATI!$F:$F),"") | I36: =+IFERROR(+Tabella24[[#This Row],[IMPORTO VERSATO]]/SUMIF(DATI!$B:$B,Tabella24[[#This Row],[Cartella2]],DATI!$M:$M)*SUMIF(DATI!$B:$B,Tabella24[[#This Row],[Cartella2]],DATI!$G:$G),"") | J36: =+IFERROR(+Tabella24[[#This Row],[IMPORTO VERSATO]]/SUMIF(DATI!$B:$B,Tabella24[[#This Row],[Cartella2]],DATI!$M:$M)*SUMIF(DATI!$B:$B,Tabella24[[#This Row],[Cartella2]],DATI!$H:$H),"") | K36: =+IFERROR(+Tabella24[[#This Row],[IMPORTO VERSATO]]/SUMIF(DATI!$B:$B,Tabella24[[#This Row],[Cartella2]],DATI!$M:$M)*SUMIF(DATI!$B:$B,Tabella24[[#This Row],[Cartella2]],DATI!$I:$I),"") | L36: =+IFERROR(+Tabella24[[#This Row],[IMPORTO VERSATO]]/SUMIF(DATI!$B:$B,Tabella24[[#This Row],[Cartella2]],DATI!$M:$M)*SUMIF(DATI!$B:$B,Tabella24[[#This Row],[Cartella2]],DATI!$J:$J),"") | M36: =+IFERROR(+Tabella24[[#This Row],[IMPORTO VERSATO]]/SUMIF(DATI!$B:$B,Tabella24[[#This Row],[Cartella2]],DATI!$M:$M)*SUMIF(DATI!$B:$B,Tabella24[[#This Row],[Cartella2]],DATI!$L:$L),"") | N36: =+IF(COUNTIF($C$17:C36,Tabella24[[#This Row],[Cartella2]])=1,"X","") | O36: =+IFERROR(+Tabella24[[#This Row],[IMPORTO VERSATO]]/SUMIF(DATI!$B:$B,Tabella24[[#This Row],[Cartella2]],DATI!$M:$M)*SUMIF(DATI!$B:$B,Tabella24[[#This Row],[Cartella2]],DATI!$K:$K),"")
C37: =+IF(Tabella24[[#This Row],[INS CARTELLA]]="",C36,+VLOOKUP(Tabella24[[#This Row],[INS CARTELLA]],Tabella1[[NUMERO CARTELLA]:[IMPOSTE]],1,0)) -> #N/A | G37: =+IFERROR(+Tabella24[[#This Row],[IMPORTO VERSATO]]/SUMIF(DATI!B:B,Tabella24[[#This Row],[Cartella2]],DATI!M:M)*SUMIF(DATI!B:B,Tabella24[[#This Row],[Cartella2]],DATI!E:E),"") | H37: =+IFERROR(+Tabella24[[#This Row],[IMPORTO VERSATO]]/SUMIF(DATI!$B:$B,Tabella24[[#This Row],[Cartella2]],DATI!$M:$M)*SUMIF(DATI!$B:$B,Tabella24[[#This Row],[Cartella2]],DATI!$F:$F),"") | I37: =+IFERROR(+Tabella24[[#This Row],[IMPORTO VERSATO]]/SUMIF(DATI!$B:$B,Tabella24[[#This Row],[Cartella2]],DATI!$M:$M)*SUMIF(DATI!$B:$B,Tabella24[[#This Row],[Cartella2]],DATI!$G:$G),"") | J37: =+IFERROR(+Tabella24[[#This Row],[IMPORTO VERSATO]]/SUMIF(DATI!$B:$B,Tabella24[[#This Row],[Cartella2]],DATI!$M:$M)*SUMIF(DATI!$B:$B,Tabella24[[#This Row],[Cartella2]],DATI!$H:$H),"") | K37: =+IFERROR(+Tabella24[[#This Row],[IMPORTO VERSATO]]/SUMIF(DATI!$B:$B,Tabella24[[#This Row],[Cartella2]],DATI!$M:$M)*SUMIF(DATI!$B:$B,Tabella24[[#This Row],[Cartella2]],DATI!$I:$I),"") | L37: =+IFERROR(+Tabella24[[#This Row],[IMPORTO VERSATO]]/SUMIF(DATI!$B:$B,Tabella24[[#This Row],[Cartella2]],DATI!$M:$M)*SUMIF(DATI!$B:$B,Tabella24[[#This Row],[Cartella2]],DATI!$J:$J),"") | M37: =+IFERROR(+Tabella24[[#This Row],[IMPORTO VERSATO]]/SUMIF(DATI!$B:$B,Tabella24[[#This Row],[Cartella2]],DATI!$M:$M)*SUMIF(DATI!$B:$B,Tabella24[[#This Row],[Cartella2]],DATI!$L:$L),"") | N37: =+IF(COUNTIF($C$17:C37,Tabella24[[#This Row],[Cartella2]])=1,"X","") | O37: =+IFERROR(+Tabella24[[#This Row],[IMPORTO VERSATO]]/SUMIF(DATI!$B:$B,Tabella24[[#This Row],[Cartella2]],DATI!$M:$M)*SUMIF(DATI!$B:$B,Tabella24[[#This Row],[Cartella2]],DATI!$K:$K),"")
C38: =+IF(Tabella24[[#This Row],[INS CARTELLA]]="",C37,+VLOOKUP(Tabella24[[#This Row],[INS CARTELLA]],Tabella1[[NUMERO CARTELLA]:[IMPOSTE]],1,0)) -> #N/A | G38: =+IFERROR(+Tabella24[[#This Row],[IMPORTO VERSATO]]/SUMIF(DATI!B:B,Tabella24[[#This Row],[Cartella2]],DATI!M:M)*SUMIF(DATI!B:B,Tabella24[[#This Row],[Cartella2]],DATI!E:E),"") | H38: =+IFERROR(+Tabella24[[#This Row],[IMPORTO VERSATO]]/SUMIF(DATI!$B:$B,Tabella24[[#This Row],[Cartella2]],DATI!$M:$M)*SUMIF(DATI!$B:$B,Tabella24[[#This Row],[Cartella2]],DATI!$F:$F),"") | I38: =+IFERROR(+Tabella24[[#This Row],[IMPORTO VERSATO]]/SUMIF(DATI!$B:$B,Tabella24[[#This Row],[Cartella2]],DATI!$M:$M)*SUMIF(DATI!$B:$B,Tabella24[[#This Row],[Cartella2]],DATI!$G:$G),"") | J38: =+IFERROR(+Tabella24[[#This Row],[IMPORTO VERSATO]]/SUMIF(DATI!$B:$B,Tabella24[[#This Row],[Cartella2]],DATI!$M:$M)*SUMIF(DATI!$B:$B,Tabella24[[#This Row],[Cartella2]],DATI!$H:$H),"") | K38: =+IFERROR(+Tabella24[[#This Row],[IMPORTO VERSATO]]/SUMIF(DATI!$B:$B,Tabella24[[#This Row],[Cartella2]],DATI!$M:$M)*SUMIF(DATI!$B:$B,Tabella24[[#This Row],[Cartella2]],DATI!$I:$I),"") | L38: =+IFERROR(+Tabella24[[#This Row],[IMPORTO VERSATO]]/SUMIF(DATI!$B:$B,Tabella24[[#This Row],[Cartella2]],DATI!$M:$M)*SUMIF(DATI!$B:$B,Tabella24[[#This Row],[Cartella2]],DATI!$J:$J),"") | M38: =+IFERROR(+Tabella24[[#This Row],[IMPORTO VERSATO]]/SUMIF(DATI!$B:$B,Tabella24[[#This Row],[Cartella2]],DATI!$M:$M)*SUMIF(DATI!$B:$B,Tabella24[[#This Row],[Cartella2]],DATI!$L:$L),"") | N38: =+IF(COUNTIF($C$17:C38,Tabella24[[#This Row],[Cartella2]])=1,"X","") | O38: =+IFERROR(+Tabella24[[#This Row],[IMPORTO VERSATO]]/SUMIF(DATI!$B:$B,Tabella24[[#This Row],[Cartella2]],DATI!$M:$M)*SUMIF(DATI!$B:$B,Tabella24[[#This Row],[Cartella2]],DATI!$K:$K),"")
C39: =+IF(Tabella24[[#This Row],[INS CARTELLA]]="",C38,+VLOOKUP(Tabella24[[#This Row],[INS CARTELLA]],Tabella1[[NUMERO CARTELLA]:[IMPOSTE]],1,0)) -> #N/A | G39: =+IFERROR(+Tabella24[[#This Row],[IMPORTO VERSATO]]/SUMIF(DATI!B:B,Tabella24[[#This Row],[Cartella2]],DATI!M:M)*SUMIF(DATI!B:B,Tabella24[[#This Row],[Cartella2]],DATI!E:E),"") | H39: =+IFERROR(+Tabella24[[#This Row],[IMPORTO VERSATO]]/SUMIF(DATI!$B:$B,Tabella24[[#This Row],[Cartella2]],DATI!$M:$M)*SUMIF(DATI!$B:$B,Tabella24[[#This Row],[Cartella2]],DATI!$F:$F),"") | I39: =+IFERROR(+Tabella24[[#This Row],[IMPORTO VERSATO]]/SUMIF(DATI!$B:$B,Tabella24[[#This Row],[Cartella2]],DATI!$M:$M)*SUMIF(DATI!$B:$B,Tabella24[[#This Row],[Cartella2]],DATI!$G:$G),"") | J39: =+IFERROR(+Tabella24[[#This Row],[IMPORTO VERSATO]]/SUMIF(DATI!$B:$B,Tabella24[[#This Row],[Cartella2]],DATI!$M:$M)*SUMIF(DATI!$B:$B,Tabella24[[#This Row],[Cartella2]],DATI!$H:$H),"") | K39: =+IFERROR(+Tabella24[[#This Row],[IMPORTO VERSATO]]/SUMIF(DATI!$B:$B,Tabella24[[#This Row],[Cartella2]],DATI!$M:$M)*SUMIF(DATI!$B:$B,Tabella24[[#This Row],[Cartella2]],DATI!$I:$I),"") | L39: =+IFERROR(+Tabella24[[#This Row],[IMPORTO VERSATO]]/SUMIF(DATI!$B:$B,Tabella24[[#This Row],[Cartella2]],DATI!$M:$M)*SUMIF(DATI!$B:$B,Tabella24[[#This Row],[Cartella2]],DATI!$J:$J),"") | M39: =+IFERROR(+Tabella24[[#This Row],[IMPORTO VERSATO]]/SUMIF(DATI!$B:$B,Tabella24[[#This Row],[Cartella2]],DATI!$M:$M)*SUMIF(DATI!$B:$B,Tabella24[[#This Row],[Cartella2]],DATI!$L:$L),"") | N39: =+IF(COUNTIF($C$17:C39,Tabella24[[#This Row],[Cartella2]])=1,"X","") | O39: =+IFERROR(+Tabella24[[#This Row],[IMPORTO VERSATO]]/SUMIF(DATI!$B:$B,Tabella24[[#This Row],[Cartella2]],DATI!$M:$M)*SUMIF(DATI!$B:$B,Tabella24[[#This Row],[Cartella2]],DATI!$K:$K),"")
C40: =+IF(Tabella24[[#This Row],[INS CARTELLA]]="",C39,+VLOOKUP(Tabella24[[#This Row],[INS CARTELLA]],Tabella1[[NUMERO CARTELLA]:[IMPOSTE]],1,0)) -> #N/A | G40: =+IFERROR(+Tabella24[[#This Row],[IMPORTO VERSATO]]/SUMIF(DATI!B:B,Tabella24[[#This Row],[Cartella2]],DATI!M:M)*SUMIF(DATI!B:B,Tabella24[[#This Row],[Cartella2]],DATI!E:E),"") | H40: =+IFERROR(+Tabella24[[#This Row],[IMPORTO VERSATO]]/SUMIF(DATI!$B:$B,Tabella24[[#This Row],[Cartella2]],DATI!$M:$M)*SUMIF(DATI!$B:$B,Tabella24[[#This Row],[Cartella2]],DATI!$F:$F),"") | I40: =+IFERROR(+Tabella24[[#This Row],[IMPORTO VERSATO]]/SUMIF(DATI!$B:$B,Tabella24[[#This Row],[Cartella2]],DATI!$M:$M)*SUMIF(DATI!$B:$B,Tabella24[[#This Row],[Cartella2]],DATI!$G:$G),"") | J40: =+IFERROR(+Tabella24[[#This Row],[IMPORTO VERSATO]]/SUMIF(DATI!$B:$B,Tabella24[[#This Row],[Cartella2]],DATI!$M:$M)*SUMIF(DATI!$B:$B,Tabella24[[#This Row],[Cartella2]],DATI!$H:$H),"") | K40: =+IFERROR(+Tabella24[[#This Row],[IMPORTO VERSATO]]/SUMIF(DATI!$B:$B,Tabella24[[#This Row],[Cartella2]],DATI!$M:$M)*SUMIF(DATI!$B:$B,Tabella24[[#This Row],[Cartella2]],DATI!$I:$I),"") | L40: =+IFERROR(+Tabella24[[#This Row],[IMPORTO VERSATO]]/SUMIF(DATI!$B:$B,Tabella24[[#This Row],[Cartella2]],DATI!$M:$M)*SUMIF(DATI!$B:$B,Tabella24[[#This Row],[Cartella2]],DATI!$J:$J),"") | M40: =+IFERROR(+Tabella24[[#This Row],[IMPORTO VERSATO]]/SUMIF(DATI!$B:$B,Tabella24[[#This Row],[Cartella2]],DATI!$M:$M)*SUMIF(DATI!$B:$B,Tabella24[[#This Row],[Cartella2]],DATI!$L:$L),"") | N40: =+IF(COUNTIF($C$17:C40,Tabella24[[#This Row],[Cartella2]])=1,"X","") | O40: =+IFERROR(+Tabella24[[#This Row],[IMPORTO VERSATO]]/SUMIF(DATI!$B:$B,Tabella24[[#This Row],[Cartella2]],DATI!$M:$M)*SUMIF(DATI!$B:$B,Tabella24[[#This Row],[Cartella2]],DATI!$K:$K),"")
... C1436: =+IF(Tabella24[[#This Row],[INS CARTELLA]]="",C1435,+VLOOKUP(Tabella24[[#This Row],[INS CARTELLA]],Tabella1[[NUMERO CARTELLA]:[IMPOSTE]],1,0)) -> #N/A | G1436: =+IFERROR(+Tabella24[[#This Row],[IMPORTO VERSATO]]/SUMIF(DATI!B:B,Tabella24[[#This Row],[Cartella2]],DATI!M:M)*SUMIF(DATI!B:B,Tabella24[[#This Row],[Cartella2]],DATI!E:E),"") | H1436: =+IFERROR(+Tabella24[[#This Row],[IMPORTO VERSATO]]/SUMIF(DATI!$B:$B,Tabella24[[#This Row],[Cartella2]],DATI!$M:$M)*SUMIF(DATI!$B:$B,Tabella24[[#This Row],[Cartella2]],DATI!$F:$F),"") | I1436: =+IFERROR(+Tabella24[[#This Row],[IMPORTO VERSATO]]/SUMIF(DATI!$B:$B,Tabella24[[#This Row],[Cartella2]],DATI!$M:$M)*SUMIF(DATI!$B:$B,Tabella24[[#This Row],[Cartella2]],DATI!$G:$G),"") | J1436: =+IFERROR(+Tabella24[[#This Row],[IMPORTO VERSATO]]/SUMIF(DATI!$B:$B,Tabella24[[#This Row],[Cartella2]],DATI!$M:$M)*SUMIF(DATI!$B:$B,Tabella24[[#This Row],[Cartella2]],DATI!$H:$H),"") | K1436: =+IFERROR(+Tabella24[[#This Row],[IMPORTO VERSATO]]/SUMIF(DATI!$B:$B,Tabella24[[#This Row],[Cartella2]],DATI!$M:$M)*SUMIF(DATI!$B:$B,Tabella24[[#This Row],[Cartella2]],DATI!$I:$I),"") | L1436: =+IFERROR(+Tabella24[[#This Row],[IMPORTO VERSATO]]/SUMIF(DATI!$B:$B,Tabella24[[#This Row],[Cartella2]],DATI!$M:$M)*SUMIF(DATI!$B:$B,Tabella24[[#This Row],[Cartella2]],DATI!$J:$J),"") | M1436: =+IFERROR(+Tabella24[[#This Row],[IMPORTO VERSATO]]/SUMIF(DATI!$B:$B,Tabella24[[#This Row],[Cartella2]],DATI!$M:$M)*SUMIF(DATI!$B:$B,Tabella24[[#This Row],[Cartella2]],DATI!$L:$L),"") | N1436: =+IF(COUNTIF($C$17:C1436,Tabella24[[#This Row],[Cartella2]])=1,"X","") | O1436: =+IFERROR(+Tabella24[[#This Row],[IMPORTO VERSATO]]/SUMIF(DATI!$B:$B,Tabella24[[#This Row],[Cartella2]],DATI!$M:$M)*SUMIF(DATI!$B:$B,Tabella24[[#This Row],[Cartella2]],DATI!$K:$K),"")
C1437: =+IF(Tabella24[[#This Row],[INS CARTELLA]]="",C1436,+VLOOKUP(Tabella24[[#This Row],[INS CARTELLA]],Tabella1[[NUMERO CARTELLA]:[IMPOSTE]],1,0)) -> #N/A | G1437: =+IFERROR(+Tabella24[[#This Row],[IMPORTO VERSATO]]/SUMIF(DATI!B:B,Tabella24[[#This Row],[Cartella2]],DATI!M:M)*SUMIF(DATI!B:B,Tabella24[[#This Row],[Cartella2]],DATI!E:E),"") | H1437: =+IFERROR(+Tabella24[[#This Row],[IMPORTO VERSATO]]/SUMIF(DATI!$B:$B,Tabella24[[#This Row],[Cartella2]],DATI!$M:$M)*SUMIF(DATI!$B:$B,Tabella24[[#This Row],[Cartella2]],DATI!$F:$F),"") | I1437: =+IFERROR(+Tabella24[[#This Row],[IMPORTO VERSATO]]/SUMIF(DATI!$B:$B,Tabella24[[#This Row],[Cartella2]],DATI!$M:$M)*SUMIF(DATI!$B:$B,Tabella24[[#This Row],[Cartella2]],DATI!$G:$G),"") | J1437: =+IFERROR(+Tabella24[[#This Row],[IMPORTO VERSATO]]/SUMIF(DATI!$B:$B,Tabella24[[#This Row],[Cartella2]],DATI!$M:$M)*SUMIF(DATI!$B:$B,Tabella24[[#This Row],[Cartella2]],DATI!$H:$H),"") | K1437: =+IFERROR(+Tabella24[[#This Row],[IMPORTO VERSATO]]/SUMIF(DATI!$B:$B,Tabella24[[#This Row],[Cartella2]],DATI!$M:$M)*SUMIF(DATI!$B:$B,Tabella24[[#This Row],[Cartella2]],DATI!$I:$I),"") | L1437: =+IFERROR(+Tabella24[[#This Row],[IMPORTO VERSATO]]/SUMIF(DATI!$B:$B,Tabella24[[#This Row],[Cartella2]],DATI!$M:$M)*SUMIF(DATI!$B:$B,Tabella24[[#This Row],[Cartella2]],DATI!$J:$J),"") | M1437: =+IFERROR(+Tabella24[[#This Row],[IMPORTO VERSATO]]/SUMIF(DATI!$B:$B,Tabella24[[#This Row],[Cartella2]],DATI!$M:$M)*SUMIF(DATI!$B:$B,Tabella24[[#This Row],[Cartella2]],DATI!$L:$L),"") | N1437: =+IF(COUNTIF($C$17:C1502,Tabella24[[#This Row],[Cartella2]])=1,"X","") | O1437: =+IFERROR(+Tabella24[[#This Row],[IMPORTO VERSATO]]/SUMIF(DATI!$B:$B,Tabella24[[#This Row],[Cartella2]],DATI!$M:$M)*SUMIF(DATI!$B:$B,Tabella24[[#This Row],[Cartella2]],DATI!$K:$K),"")
