Workbook
Name a: Score!$E$52
Name aa: LEFT(Score!$F$5,2)*1
Name ATE: ATECO[Cod]
Name BVCEE: OFFSET(BVCC,0,1)
Name cemcc: Score!$AB$43:$AF$68
Name crisi: "ragionevole presunzione di uno stato di crisi"
Name RA: +MATCH(CF,RAZ,0)
Name rateco: Score!$K$8
Name SETT: Tabella139[Desc. Crisi]
Name TBA: IF(ta="Abbreviato Cee",1,IF(ta="CEE",2,3))
Name TitSc: "Analisi indicatori per "

Sheet TabelleCompilate
A1: Indice | B1: Voce | C1: AnnoPrec | D1: AnnoCorr | E1: C | F1: C | G1: Indice | H1: Voce | I1: AnnoPrec | J1: AnnoCorr | K1: C
A2: 10 | B2: Stato patrimoniale | G2: 6 | H2: Conto economico abbreviato
A3: 11 | B3: Attivo | G3: 9 | H3: Conto economico
A4: 12 | B4: A) Crediti verso soci per versamenti ancora dovuti | C4: =+#REF! -> #REF! | D4: =+#REF! -> #REF! | E4: 1 | F4: =+IF(E4>0,"SP"&RIGHT(0&E4,2),"") -> SP01 | G4: 10 | H4: A) Valore della produzione
A5: 13 | B5: B) Immobilizzazioni | C5: =+#REF! -> #REF! | D5: =+#REF! -> #REF! | F5: =+IF(E5>0,"SP"&RIGHT(0&E5,2),"") | G5: 11 | H5: 1) ricavi delle vendite e delle prestazioni | I5: =+#REF! -> #REF! | J5: =+#REF! -> #REF! | K5: 1 | L5: =+IF(K5>0,"CE"&RIGHT(0&K5,2),"") -> CE01
A6: 14 | B6: I - Immobilizzazioni immateriali | C6: =+#REF! -> #REF! | D6: =+#REF! -> #REF! | E6: 2 | F6: =+IF(E6>0,"SP"&RIGHT(0&E6,2),"") -> SP02 | G6: 12 | H6: 2), 3) variazioni delle rimanenze di prodotti in corso di lavorazione, semilavorati e finiti e dei lavori in corso su ordinazione | I6: =+#REF! -> #REF! | J6: =+#REF! -> #REF! | L6: =+IF(K6>0,"CE"&RIGHT(0&K6,2),"")
A7: 15 | B7: II - Immobilizzazioni materiali | C7: =+#REF! -> #REF! | D7: =+#REF! -> #REF! | E7: 3 | F7: =+IF(E7>0,"SP"&RIGHT(0&E7,2),"") -> SP03 | G7: 13 | H7: 2), 3) variazioni delle rimanenze di prodotti in corso di lavorazione, semilavorati e finiti e dei lavori in corso su ordinazione | I7: =+#REF! -> #REF! | J7: =+#REF! -> #REF! | L7: =+IF(K7>0,"CE"&RIGHT(0&K7,2),"")
A8: 16 | B8: III - Immobilizzazioni finanziarie | C8: =+#REF! -> #REF! | D8: =+#REF! -> #REF! | E8: 4 | F8: =+IF(E8>0,"SP"&RIGHT(0&E8,2),"") -> SP04 | G8: 14 | H8: 2) variazioni delle rimanenze di prodotti in corso di lavorazione, semilavorati e finiti | I8: =+#REF! -> #REF! | J8: =+#REF! -> #REF! | K8: 2 | L8: =+IF(K8>0,"CE"&RIGHT(0&K8,2),"") -> CE02
A9: 17 | B9: Totale immobilizzazioni (B) | C9: =+#REF! -> #REF! | D9: =+#REF! -> #REF! | E9: 5 | F9: =+IF(E9>0,"SP"&RIGHT(0&E9,2),"") -> SP05 | G9: 15 | H9: 3) variazioni dei lavori in corso su ordinazione | I9: =+#REF! -> #REF! | J9: =+#REF! -> #REF! | K9: 3 | L9: =+IF(K9>0,"CE"&RIGHT(0&K9,2),"") -> CE03
A10: 18 | B10: C) Attivo circolante | C10: =+#REF! -> #REF! | D10: =+#REF! -> #REF! | F10: =+IF(E10>0,"SP"&RIGHT(0&E10,2),"") | G10: 16 | H10: 4) incrementi di immobilizzazioni per lavori interni | I10: =+#REF! -> #REF! | J10: =+#REF! -> #REF! | K10: 4 | L10: =+IF(K10>0,"CE"&RIGHT(0&K10,2),"") -> CE04
A11: 19 | B11: I - Rimanenze | C11: =+#REF! -> #REF! | D11: =+#REF! -> #REF! | E11: 6 | F11: =+IF(E11>0,"SP"&RIGHT(0&E11,2),"") -> SP06 | G11: 17 | H11: 5) altri ricavi e proventi | I11: =+#REF! -> #REF! | J11: =+#REF! -> #REF! | K11: 5 | L11: =+IF(K11>0,"CE"&RIGHT(0&K11,2),"") -> CE05
A12: 20 | B12: Immobilizzazioni materiali destinate alla vendita | C12: =+#REF! -> #REF! | D12: =+#REF! -> #REF! | F12: =+IF(E12>0,"SP"&RIGHT(0&E12,2),"") | G12: 18 | H12: contributi in conto esercizio | I12: =+#REF! -> #REF! | J12: =+#REF! -> #REF! | L12: =+IF(K12>0,"CE"&RIGHT(0&K12,2),"")
A13: 21 | B13: II - Crediti | C13: =+#REF! -> #REF! | D13: =+#REF! -> #REF! | F13: =+IF(E13>0,"SP"&RIGHT(0&E13,2),"") | G13: 19 | H13: altri | I13: =+#REF! -> #REF! | J13: =+#REF! -> #REF! | L13: =+IF(K13>0,"CE"&RIGHT(0&K13,2),"")
A14: 22 | B14: esigibili entro l'esercizio successivo | C14: =+#REF! -> #REF! | D14: =+#REF! -> #REF! | E14: 7 | F14: =+IF(E14>0,"SP"&RIGHT(0&E14,2),"") -> SP07 | G14: 20 | H14: Totale altri ricavi e proventi | I14: =+#REF! -> #REF! | J14: =+#REF! -> #REF! | L14: =+IF(K14>0,"CE"&RIGHT(0&K14,2),"")
A15: 23 | B15: esigibili oltre l'esercizio successivo | C15: =+#REF! -> #REF! | D15: =+#REF! -> #REF! | E15: 8 | F15: =+IF(E15>0,"SP"&RIGHT(0&E15,2),"") -> SP08 | G15: 21 | H15: Totale valore della produzione | I15: =+#REF! -> #REF! | J15: =+#REF! -> #REF! | K15: 6 | L15: =+IF(K15>0,"CE"&RIGHT(0&K15,2),"") -> CE06
A16: 24 | B16: imposte anticipate | C16: =+#REF! -> #REF! | D16: =+#REF! -> #REF! | F16: =+IF(E16>0,"SP"&RIGHT(0&E16,2),"") | G16: 22 | H16: B) Costi della produzione | I16: =+#REF! -> #REF! | J16: =+#REF! -> #REF! | L16: =+IF(K16>0,"CE"&RIGHT(0&K16,2),"")
A17: 25 | B17: Totale crediti | C17: =+#REF! -> #REF! | D17: =+#REF! -> #REF! | E17: 9 | F17: =+IF(E17>0,"SP"&RIGHT(0&E17,2),"") -> SP09 | G17: 23 | H17: 6) per materie prime, sussidiarie, di consumo e di merci | I17: =+#REF! -> #REF! | J17: =+#REF! -> #REF! | K17: 7 | L17: =+IF(K17>0,"CE"&RIGHT(0&K17,2),"") -> CE07
A18: 26 | B18: III - Attività finanziarie che non costituiscono immobilizzazioni | C18: =+#REF! -> #REF! | D18: =+#REF! -> #REF! | E18: 10 | F18: =+IF(E18>0,"SP"&RIGHT(0&E18,2),"") -> SP10 | G18: 24 | H18: 7) per servizi | I18: =+#REF! -> #REF! | J18: =+#REF! -> #REF! | K18: 8 | L18: =+IF(K18>0,"CE"&RIGHT(0&K18,2),"") -> CE08
A19: 27 | B19: IV - Disponibilità liquide | C19: =+#REF! -> #REF! | D19: =+#REF! -> #REF! | E19: 11 | F19: =+IF(E19>0,"SP"&RIGHT(0&E19,2),"") -> SP11 | G19: 25 | H19: 8) per godimento di beni di terzi | I19: =+#REF! -> #REF! | J19: =+#REF! -> #REF! | K19: 9 | L19: =+IF(K19>0,"CE"&RIGHT(0&K19,2),"") -> CE09
A20: 28 | B20: Totale attivo circolante (C) | C20: =+#REF! -> #REF! | D20: =+#REF! -> #REF! | E20: 12 | F20: =+IF(E20>0,"SP"&RIGHT(0&E20,2),"") -> SP12 | G20: 26 | H20: 9) per il personale | I20: =+#REF! -> #REF! | J20: =+#REF! -> #REF! | L20: =+IF(K20>0,"CE"&RIGHT(0&K20,2),"")
A21: 29 | B21: D) Ratei e risconti | C21: =+#REF! -> #REF! | D21: =+#REF! -> #REF! | E21: 13 | F21: =+IF(E21>0,"SP"&RIGHT(0&E21,2),"") -> SP13 | G21: 27 | H21: a) salari e stipendi | I21: =+#REF! -> #REF! | J21: =+#REF! -> #REF! | L21: =+IF(K21>0,"CE"&RIGHT(0&K21,2),"")
A22: 30 | B22: Totale attivo | C22: =+#REF! -> #REF! | D22: =+#REF! -> #REF! | E22: 14 | F22: =+IF(E22>0,"SP"&RIGHT(0&E22,2),"") -> SP14 | G22: 28 | H22: b) oneri sociali | I22: =+#REF! -> #REF! | J22: =+#REF! -> #REF! | L22: =+IF(K22>0,"CE"&RIGHT(0&K22,2),"")
A23: 31 | B23: Passivo | C23: =+#REF! -> #REF! | D23: =+#REF! -> #REF! | F23: =+IF(E23>0,"SP"&RIGHT(0&E23,2),"") | G23: 29 | H23: c), d), e) trattamento di fine rapporto, trattamento di quiescenza, altri costi del personale | I23: =+#REF! -> #REF! | J23: =+#REF! -> #REF! | L23: =+IF(K23>0,"CE"&RIGHT(0&K23,2),"")
A24: 32 | B24: A) Patrimonio netto | C24: =+#REF! -> #REF! | D24: =+#REF! -> #REF! | F24: =+IF(E24>0,"SP"&RIGHT(0&E24,2),"") | G24: 30 | H24: c), d), e) trattamento di fine rapporto, trattamento di quiescenza, altri costi del personale | I24: =+#REF! -> #REF! | J24: =+#REF! -> #REF! | L24: =+IF(K24>0,"CE"&RIGHT(0&K24,2),"")
A25: 33 | B25: I - Capitale | C25: =+#REF! -> #REF! | D25: =+#REF! -> #REF! | F25: =+IF(E25>0,"SP"&RIGHT(0&E25,2),"") | G25: 31 | H25: c) trattamento di fine rapporto | I25: =+#REF! -> #REF! | J25: =+#REF! -> #REF! | L25: =+IF(K25>0,"CE"&RIGHT(0&K25,2),"")
A26: 34 | B26: II - Riserva da soprapprezzo delle azioni | C26: =+#REF! -> #REF! | D26: =+#REF! -> #REF! | F26: =+IF(E26>0,"SP"&RIGHT(0&E26,2),"") | G26: 32 | H26: d) trattamento di quiescenza e simili | I26: =+#REF! -> #REF! | J26: =+#REF! -> #REF! | L26: =+IF(K26>0,"CE"&RIGHT(0&K26,2),"")
A27: 35 | B27: III - Riserve di rivalutazione | C27: =+#REF! -> #REF! | D27: =+#REF! -> #REF! | F27: =+IF(E27>0,"SP"&RIGHT(0&E27,2),"") | G27: 33 | H27: e) altri costi | I27: =+#REF! -> #REF! | J27: =+#REF! -> #REF! | L27: =+IF(K27>0,"CE"&RIGHT(0&K27,2),"")
A28: 36 | B28: IV - Riserva legale | C28: =+#REF! -> #REF! | D28: =+#REF! -> #REF! | F28: =+IF(E28>0,"SP"&RIGHT(0&E28,2),"") | G28: 34 | H28: Totale costi per il personale | I28: =+#REF! -> #REF! | J28: =+#REF! -> #REF! | K28: 10 | L28: =+IF(K28>0,"CE"&RIGHT(0&K28,2),"") -> CE10
A29: 37 | B29: V - Riserve statutarie | C29: =+#REF! -> #REF! | D29: =+#REF! -> #REF! | F29: =+IF(E29>0,"SP"&RIGHT(0&E29,2),"") | G29: 35 | H29: 10) ammortamenti e svalutazioni | I29: =+#REF! -> #REF! | J29: =+#REF! -> #REF! | L29: =+IF(K29>0,"CE"&RIGHT(0&K29,2),"")
A30: 38 | B30: VI - Altre riserve | C30: =+#REF! -> #REF! | D30: =+#REF! -> #REF! | F30: =+IF(E30>0,"SP"&RIGHT(0&E30,2),"") | G30: 36 | H30: a), b), c) ammortamento delle immobilizzazioni immateriali e materiali, altre svalutazioni delle immobilizzazioni | I30: =+#REF! -> #REF! | J30: =+#REF! -> #REF! | L30: =+IF(K30>0,"CE"&RIGHT(0&K30,2),"")
A31: 39 | B31: VII - Riserva per operazioni di copertura dei flussi finanziari attesi | C31: =+#REF! -> #REF! | D31: =+#REF! -> #REF! | F31: =+IF(E31>0,"SP"&RIGHT(0&E31,2),"") | G31: 37 | H31: a), b), c) ammortamento delle immobilizzazioni immateriali e materiali, altre svalutazioni delle immobilizzazioni | I31: =+#REF! -> #REF! | J31: =+#REF! -> #REF! | L31: =+IF(K31>0,"CE"&RIGHT(0&K31,2),"")
A32: 40 | B32: VIII - Utili (perdite) portati a nuovo | C32: =+#REF! -> #REF! | D32: =+#REF! -> #REF! | F32: =+IF(E32>0,"SP"&RIGHT(0&E32,2),"") | G32: 38 | H32: a) ammortamento delle immobilizzazioni immateriali | I32: =+#REF! -> #REF! | J32: =+#REF! -> #REF! | K32: 11 | L32: =+IF(K32>0,"CE"&RIGHT(0&K32,2),"") -> CE11
A33: 41 | B33: IX - Utile (perdita) dell'esercizio | C33: =+#REF! -> #REF! | D33: =+#REF! -> #REF! | F33: =+IF(E33>0,"SP"&RIGHT(0&E33,2),"") | G33: 39 | H33: b) ammortamento delle immobilizzazioni materiali | I33: =+#REF! -> #REF! | J33: =+#REF! -> #REF! | K33: 12 | L33: =+IF(K33>0,"CE"&RIGHT(0&K33,2),"") -> CE12
A34: 42 | B34: Perdita ripianata nell'esercizio | C34: =+#REF! -> #REF! | D34: =+#REF! -> #REF! | F34: =+IF(E34>0,"SP"&RIGHT(0&E34,2),"") | G34: 40 | H34: c) altre svalutazioni delle immobilizzazioni | I34: =+#REF! -> #REF! | J34: =+#REF! -> #REF! | L34: =+IF(K34>0,"CE"&RIGHT(0&K34,2),"")
A35: 43 | B35: X - Riserva negativa per azioni proprie in portafoglio | C35: =+#REF! -> #REF! | D35: =+#REF! -> #REF! | F35: =+IF(E35>0,"SP"&RIGHT(0&E35,2),"") | G35: 41 | H35: d) svalutazioni dei crediti compresi nell'attivo circolante e delle disponibilità liquide | I35: =+#REF! -> #REF! | J35: =+#REF! -> #REF! | L35: =+IF(K35>0,"CE"&RIGHT(0&K35,2),"")
A36: 44 | B36: Totale patrimonio netto | C36: =+#REF! -> #REF! | D36: =+#REF! -> #REF! | E36: 15 | F36: =+IF(E36>0,"SP"&RIGHT(0&E36,2),"") -> SP15 | G36: 42 | H36: Totale ammortamenti e svalutazioni | I36: =+#REF! -> #REF! | J36: =+#REF! -> #REF! | K36: 13 | L36: =+IF(K36>0,"CE"&RIGHT(0&K36,2),"") -> CE13
A37: 45 | B37: B) Fondi per rischi e oneri | C37: =+#REF! -> #REF! | D37: =+#REF! -> #REF! | E37: 17 | F37: =+IF(E37>0,"SP"&RIGHT(0&E37,2),"") -> SP17 | G37: 43 | H37: 11) variazioni delle rimanenze di materie prime, sussidiarie, di consumo e merci | I37: =+#REF! -> #REF! | J37: =+#REF! -> #REF! | K37: 14 | L37: =+IF(K37>0,"CE"&RIGHT(0&K37,2),"") -> CE14
A38: 46 | B38: C) Trattamento di fine rapporto di lavoro subordinato | C38: =+#REF! -> #REF! | D38: =+#REF! -> #REF! | E38: 18 | F38: =+IF(E38>0,"SP"&RIGHT(0&E38,2),"") -> SP18 | G38: 44 | H38: 12) accantonamenti per rischi | I38: =+#REF! -> #REF! | J38: =+#REF! -> #REF! | K38: 15 | L38: =+IF(K38>0,"CE"&RIGHT(0&K38,2),"") -> CE15
A39: 47 | B39: D) Debiti | C39: =+#REF! -> #REF! | D39: =+#REF! -> #REF! | F39: =+IF(E39>0,"SP"&RIGHT(0&E39,2),"") | G39: 45 | H39: 13) altri accantonamenti | I39: =+#REF! -> #REF! | J39: =+#REF! -> #REF! | K39: 16 | L39: =+IF(K39>0,"CE"&RIGHT(0&K39,2),"") -> CE16
A40: 48 | B40: esigibili entro l'esercizio successivo | C40: =+#REF! -> #REF! | D40: =+#REF! -> #REF! | E40: 19 | F40: =+IF(E40>0,"SP"&RIGHT(0&E40,2),"") -> SP19 | G40: 46 | H40: 14) oneri diversi di gestione | I40: =+#REF! -> #REF! | J40: =+#REF! -> #REF! | K40: 17 | L40: =+IF(K40>0,"CE"&RIGHT(0&K40,2),"") -> CE17
...

Sheet Score
C2: DATI AZIENDA
C3: NOME AZIENDA | D3: Alfa S.r.l.
C5: Tipologia società | D5: S.r.l. | E5: ATECO | F5: 43.21.02 | H5: =+VLOOKUP(F5,ATECO[],2,0) -> Installazione di impianti elettronici (inclusa manutenzione e riparazione)
C6: Limite Capitale | D6: =+IF(D5="S.r.l.",10000,IF(D5="S.p.a.",100000,0)) -> 10000 | E6: Consulta Ateco | F6: SETTORE (IN BASE ATECO) | H6: =+VLOOKUP(F5,ATECO[],3,0) -> F42) Ingegneria civile; F43) Costruzioni specializzate
D7: Periodo n-1 | E7: Periodo n | F7: SETTORE (INSER. MANUALE)
C8: ESERCIZI ANALISI | D8: 45291 | E8: 45657 | F8: SETTORE | H8: =+IF(H7>"",H7,H6) -> F42) Ingegneria civile; F43) Costruzioni specializzate | K8: =+MATCH(H8,Tabella139[Desc. Crisi],0) -> 5
C9: Inizio esercizio se diverso da 1/1 | D9: 44927 | E9: 45292
C10: Inizio esercizio | D10: =+IF(D9>0,D9,DATE(YEAR(D8),1,1)) -> 44927 | E10: =+IF(E9>0,E9,DATE(YEAR(E8),1,1)) -> 45292
C11: Giorni | D11: =+D8-D10+1 -> 365 | E11: =+E8-E10+1 -> 366
C12: Durata esercizio | D12: =+EOMONTH(D10,11)-D10+1 -> 365 | E12: =+EOMONTH(E10,11)-E10+1 -> 366
D13: =+D11/D12 -> 1 | E13: =+E11/E12 -> 1
C14: VALORI DA BILANCIO
C15: CALCOLO INDICATORI
A16: 1 | C16: PATRIMONIO NETTO | F16: 100000
A17: 1 | C17: =+UPPER("Patrimonio netto >"&TEXT(D6,"0.000")) -> PATRIMONIO NETTO >10.000 | F17: =+(F16>$D$6)*1 -> 1
A18: 2 | C18: Calcolo DSCR a sei mesi | F18: =+E8 -> 45657
C19: 1° Approccio
C20: Calcolo Numeratore
C21: Giacenze iniziali cassa | F21: 50000
C22: Entrate previste nei 6 mesi | F22: 300000
C23: Altre entrate | F23: 50000
C24: (Uscite previste esclusi i rimborsi debiti) | F24: 250000
C25: Totale Numeratore (Entrate) | F25: =SUM(F21:F24) -> 650000
C26: Calcolo Denominatore
C27: Rate finanziamenti previste (quota capitale) | F27: 30000
C28: Rateazioni imposte | F28: 20000
C29: Totale Denominatore (Uscite finanziarie) | F29: =SUM(F26:F28) -> 50000
A30: 2 | C30: DSCR risultante 1° Approccio | F30: =+IFERROR(F25/F29,0) -> 13
C31: 2° Approccio
C32: Calcolo Numeratore
C33: Flusso finanziario della gestione reddituale (A) | F33: 100000
C34: Flusso per la gestione degli investimenti e disinv | F34: -40000
C35: - Componenti da escludere e) e f)
C36: a) Flussi operativi al servizio del debito | F36: =SUM(F33:F35) -> 60000
C37: b) Disponibilità liquide iniziali | F37: 50000
C38: c) Linee di credito utilizzabili a 6 mesi | F38: 100000
C39: Totale Numeratore | F39: =SUM(F36:F38) -> 210000
C40: d) Pagamenti previsti, capitali ed interessi deb. Finanziari | F40: 35000
C41: e) debito fiscale o contributivo (+ sanzioni e int.) a sei mesi | F41: 40000
C42: f) debito verso fornitori non fisiologico | F42: 25000
...

Sheet ATECO
A1: CODICE | B1: DESCRIZIONE | C1: COD. CRISI | D1: descr | E1: Soglia1 | F1: Soglia2 | G1: Soglia3 | H1: Soglia4 | I1: Soglia5 | L1: Cod | M1: Descr | N1: Settore | R1: Cod. Crisi | S1: Desc. Crisi | T1: OF/Ric | U1: PN/Tot.Deb | V1: AC/PB | W1: CashFlow/Att | X1: Deb.Trib./Att
A2: A | B2: AGRICOLTURA, SILVICOLTURA E PESCA | C2: 1 | D2: =+VLOOKUP(AtecoCrisi[[#This Row],[COD. CRISI]],Tabella139[],2,0) -> A) Agricoltura silvicoltura e pesca | E2: =+VLOOKUP(C2,$R$2:$X$11,3,FALSE) -> 0.028 | F2: =+VLOOKUP(C2,$R$2:$X$11,4,FALSE) -> 0.094 | G2: =+VLOOKUP(C2,$R$2:$X$11,5,FALSE) -> 0.921 | H2: =+VLOOKUP(C2,$R$2:$X$11,6,FALSE) -> 0.003 | I2: =+VLOOKUP(C2,$R$2:$X$11,7,FALSE) -> 0.056 | L2: 01.11.10 | M2: =+VLOOKUP(L2,A:B,2,0) -> Coltivazione di cereali (escluso il riso) | N2: =+VLOOKUP(L2,A:D,4,0) -> A) Agricoltura silvicoltura e pesca | R2: 1 | S2: A) Agricoltura silvicoltura e pesca | T2: 0.028 | U2: 0.094 | V2: 0.921 | W2: 0.003 | X2: 0.056
A3: 01 | B3: COLTIVAZIONI AGRICOLE E PRODUZIONE DI PRODOTTI ANIMALI, CACCIA E SERVIZI CONNESSI | C3: 1 | D3: =+VLOOKUP(AtecoCrisi[[#This Row],[COD. CRISI]],Tabella139[],2,0) -> A) Agricoltura silvicoltura e pesca | E3: =+VLOOKUP(C3,$R$2:$X$11,3,FALSE) -> 0.028 | F3: =+VLOOKUP(C3,$R$2:$X$11,4,FALSE) -> 0.094 | G3: =+VLOOKUP(C3,$R$2:$X$11,5,FALSE) -> 0.921 | H3: =+VLOOKUP(C3,$R$2:$X$11,6,FALSE) -> 0.003 | I3: =+VLOOKUP(C3,$R$2:$X$11,7,FALSE) -> 0.056 | L3: 01.11.20 | M3: =+VLOOKUP(L3,A:B,2,0) -> Coltivazione di semi oleosi | N3: =+VLOOKUP(L3,A:D,4,0) -> A) Agricoltura silvicoltura e pesca | R3: 2 | S3: B) Estrazione; C) Manifattura; D) Produzione energia/gas | T3: 0.03 | U3: 0.076 | V3: 0.937 | W3: 0.005 | X3: 0.049
A4: 01.11.10 | B4: Coltivazione di cereali (escluso il riso) | C4: 1 | D4: =+VLOOKUP(AtecoCrisi[[#This Row],[COD. CRISI]],Tabella139[],2,0) -> A) Agricoltura silvicoltura e pesca | E4: =+VLOOKUP(C4,$R$2:$X$11,3,FALSE) -> 0.028 | F4: =+VLOOKUP(C4,$R$2:$X$11,4,FALSE) -> 0.094 | G4: =+VLOOKUP(C4,$R$2:$X$11,5,FALSE) -> 0.921 | H4: =+VLOOKUP(C4,$R$2:$X$11,6,FALSE) -> 0.003 | I4: =+VLOOKUP(C4,$R$2:$X$11,7,FALSE) -> 0.056 | L4: 01.11.30 | M4: =+VLOOKUP(L4,A:B,2,0) -> Coltivazione di legumi da granella | N4: =+VLOOKUP(L4,A:D,4,0) -> A) Agricoltura silvicoltura e pesca | R4: 3 | S4: E) Fornitura acqua reti fognarie rifiuti; D) Trasmissione energia/gas | T4: 0.026 | U4: 0.067 | V4: 0.842 | W4: 0.019 | X4: 0.065
A5: 01.11.20 | B5: Coltivazione di semi oleosi | C5: 1 | D5: =+VLOOKUP(AtecoCrisi[[#This Row],[COD. CRISI]],Tabella139[],2,0) -> A) Agricoltura silvicoltura e pesca | E5: =+VLOOKUP(C5,$R$2:$X$11,3,FALSE) -> 0.028 | F5: =+VLOOKUP(C5,$R$2:$X$11,4,FALSE) -> 0.094 | G5: =+VLOOKUP(C5,$R$2:$X$11,5,FALSE) -> 0.921 | H5: =+VLOOKUP(C5,$R$2:$X$11,6,FALSE) -> 0.003 | I5: =+VLOOKUP(C5,$R$2:$X$11,7,FALSE) -> 0.056 | L5: 01.11.40 | M5: =+VLOOKUP(L5,A:B,2,0) -> Coltivazioni miste di cereali, legumi da granella e semi oleosi | N5: =+VLOOKUP(L5,A:D,4,0) -> A) Agricoltura silvicoltura e pesca | R5: 4 | S5: F41) Costruzione di edifici | T5: 0.038 | U5: 0.049 | V5: 1.08 | W5: 0.004 | X5: 0.038
A6: 01.11.30 | B6: Coltivazione di legumi da granella | C6: 1 | D6: =+VLOOKUP(AtecoCrisi[[#This Row],[COD. CRISI]],Tabella139[],2,0) -> A) Agricoltura silvicoltura e pesca | E6: =+VLOOKUP(C6,$R$2:$X$11,3,FALSE) -> 0.028 | F6: =+VLOOKUP(C6,$R$2:$X$11,4,FALSE) -> 0.094 | G6: =+VLOOKUP(C6,$R$2:$X$11,5,FALSE) -> 0.921 | H6: =+VLOOKUP(C6,$R$2:$X$11,6,FALSE) -> 0.003 | I6: =+VLOOKUP(C6,$R$2:$X$11,7,FALSE) -> 0.056 | L6: 01.12.00 | M6: =+VLOOKUP(L6,A:B,2,0) -> Coltivazione di riso | N6: =+VLOOKUP(L6,A:D,4,0) -> A) Agricoltura silvicoltura e pesca | R6: 5 | S6: F42) Ingegneria civile; F43) Costruzioni specializzate | T6: 0.028 | U6: 0.053 | V6: 1.011 | W6: 0.014 | X6: 0.053
A7: 01.11.40 | B7: Coltivazioni miste di cereali, legumi da granella e semi oleosi | C7: 1 | D7: =+VLOOKUP(AtecoCrisi[[#This Row],[COD. CRISI]],Tabella139[],2,0) -> A) Agricoltura silvicoltura e pesca | E7: =+VLOOKUP(C7,$R$2:$X$11,3,FALSE) -> 0.028 | F7: =+VLOOKUP(C7,$R$2:$X$11,4,FALSE) -> 0.094 | G7: =+VLOOKUP(C7,$R$2:$X$11,5,FALSE) -> 0.921 | H7: =+VLOOKUP(C7,$R$2:$X$11,6,FALSE) -> 0.003 | I7: =+VLOOKUP(C7,$R$2:$X$11,7,FALSE) -> 0.056 | L7: 01.13.10 | M7: =+VLOOKUP(L7,A:B,2,0) -> Coltivazione di ortaggi (inclusi i meloni) in foglia, a fusto, a frutto, in radici, bulbi e tuberi in piena aria (escluse barbabietola da zucchero e patate) | N7: =+VLOOKUP(L7,A:D,4,0) -> A) Agricoltura silvicoltura e pesca | R7: 6 | S7: G45) Commercio autoveicoli; G46) Comm. Ingrosso; D) Distr. Energia/gas | T7: 0.021 | U7: 0.063 | V7: 1.014 | W7: 0.006 | X7: 0.029
A8: 01.12.00 | B8: Coltivazione di riso | C8: 1 | D8: =+VLOOKUP(AtecoCrisi[[#This Row],[COD. CRISI]],Tabella139[],2,0) -> A) Agricoltura silvicoltura e pesca | E8: =+VLOOKUP(C8,$R$2:$X$11,3,FALSE) -> 0.028 | F8: =+VLOOKUP(C8,$R$2:$X$11,4,FALSE) -> 0.094 | G8: =+VLOOKUP(C8,$R$2:$X$11,5,FALSE) -> 0.921 | H8: =+VLOOKUP(C8,$R$2:$X$11,6,FALSE) -> 0.003 | I8: =+VLOOKUP(C8,$R$2:$X$11,7,FALSE) -> 0.056 | L8: 01.13.20 | M8: =+VLOOKUP(L8,A:B,2,0) -> Coltivazione di ortaggi (inclusi i meloni) in foglia, a fusto, a frutto, in radici, bulbi e tuberi in colture protette (escluse barbabietola da zucchero e patate) | N8: =+VLOOKUP(L8,A:D,4,0) -> A) Agricoltura silvicoltura e pesca | R8: 7 | S8: G47) Commercio dettaglio; I56) Bar e ristoranti | T8: 0.015 | U8: 0.042 | V8: 0.898 | W8: 0.01 | X8: 0.078
A9: 01.13.10 | B9: Coltivazione di ortaggi (inclusi i meloni) in foglia, a fusto, a frutto, in radici, bulbi e tuberi in piena aria (escluse barbabietola da zucchero e patate) | C9: 1 | D9: =+VLOOKUP(AtecoCrisi[[#This Row],[COD. CRISI]],Tabella139[],2,0) -> A) Agricoltura silvicoltura e pesca | E9: =+VLOOKUP(C9,$R$2:$X$11,3,FALSE) -> 0.028 | F9: =+VLOOKUP(C9,$R$2:$X$11,4,FALSE) -> 0.094 | G9: =+VLOOKUP(C9,$R$2:$X$11,5,FALSE) -> 0.921 | H9: =+VLOOKUP(C9,$R$2:$X$11,6,FALSE) -> 0.003 | I9: =+VLOOKUP(C9,$R$2:$X$11,7,FALSE) -> 0.056 | L9: 01.13.30 | M9: =+VLOOKUP(L9,A:B,2,0) -> Coltivazione di barbabietola da zucchero | N9: =+VLOOKUP(L9,A:D,4,0) -> A) Agricoltura silvicoltura e pesca | R9: 8 | S9: H) Trasporto e magazzinaggio; I55) Hotel | T9: 0.015 | U9: 0.041 | V9: 0.86 | W9: 0.014 | X9: 0.102
A10: 01.13.20 | B10: Coltivazione di ortaggi (inclusi i meloni) in foglia, a fusto, a frutto, in radici, bulbi e tuberi in colture protette (escluse barbabietola da zucchero e patate) | C10: 1 | D10: =+VLOOKUP(AtecoCrisi[[#This Row],[COD. CRISI]],Tabella139[],2,0) -> A) Agricoltura silvicoltura e pesca | E10: =+VLOOKUP(C10,$R$2:$X$11,3,FALSE) -> 0.028 | F10: =+VLOOKUP(C10,$R$2:$X$11,4,FALSE) -> 0.094 | G10: =+VLOOKUP(C10,$R$2:$X$11,5,FALSE) -> 0.921 | H10: =+VLOOKUP(C10,$R$2:$X$11,6,FALSE) -> 0.003 | I10: =+VLOOKUP(C10,$R$2:$X$11,7,FALSE) -> 0.056 | L10: 01.13.40 | M10: =+VLOOKUP(L10,A:B,2,0) -> Coltivazione di patate | N10: =+VLOOKUP(L10,A:D,4,0) -> A) Agricoltura silvicoltura e pesca | R10: 9 | S10: JMN) Servizi alle imprese | T10: 0.018 | U10: 0.052 | V10: 0.954 | W10: 0.017 | X10: 0.119
A11: 01.13.30 | B11: Coltivazione di barbabietola da zucchero | C11: 1 | D11: =+VLOOKUP(AtecoCrisi[[#This Row],[COD. CRISI]],Tabella139[],2,0) -> A) Agricoltura silvicoltura e pesca | E11: =+VLOOKUP(C11,$R$2:$X$11,3,FALSE) -> 0.028 | F11: =+VLOOKUP(C11,$R$2:$X$11,4,FALSE) -> 0.094 | G11: =+VLOOKUP(C11,$R$2:$X$11,5,FALSE) -> 0.921 | H11: =+VLOOKUP(C11,$R$2:$X$11,6,FALSE) -> 0.003 | I11: =+VLOOKUP(C11,$R$2:$X$11,7,FALSE) -> 0.056 | L11: 01.14.00 | M11: =+VLOOKUP(L11,A:B,2,0) -> Coltivazione di canna da zucchero | N11: =+VLOOKUP(L11,A:D,4,0) -> A) Agricoltura silvicoltura e pesca | R11: 10 | S11: PQRS) Servizi alle persone | T11: 0.027 | U11: 0.023 | V11: 0.698 | W11: 0.005 | X11: 0.146
A12: 01.13.40 | B12: Coltivazione di patate | C12: 1 | D12: =+VLOOKUP(AtecoCrisi[[#This Row],[COD. CRISI]],Tabella139[],2,0) -> A) Agricoltura silvicoltura e pesca | E12: =+VLOOKUP(C12,$R$2:$X$11,3,FALSE) -> 0.028 | F12: =+VLOOKUP(C12,$R$2:$X$11,4,FALSE) -> 0.094 | G12: =+VLOOKUP(C12,$R$2:$X$11,5,FALSE) -> 0.921 | H12: =+VLOOKUP(C12,$R$2:$X$11,6,FALSE) -> 0.003 | I12: =+VLOOKUP(C12,$R$2:$X$11,7,FALSE) -> 0.056 | L12: 01.15.00 | M12: =+VLOOKUP(L12,A:B,2,0) -> Coltivazione di tabacco | N12: =+VLOOKUP(L12,A:D,4,0) -> A) Agricoltura silvicoltura e pesca
A13: 01.14.00 | B13: Coltivazione di canna da zucchero | C13: 1 | D13: =+VLOOKUP(AtecoCrisi[[#This Row],[COD. CRISI]],Tabella139[],2,0) -> A) Agricoltura silvicoltura e pesca | E13: =+VLOOKUP(C13,$R$2:$X$11,3,FALSE) -> 0.028 | F13: =+VLOOKUP(C13,$R$2:$X$11,4,FALSE) -> 0.094 | G13: =+VLOOKUP(C13,$R$2:$X$11,5,FALSE) -> 0.921 | H13: =+VLOOKUP(C13,$R$2:$X$11,6,FALSE) -> 0.003 | I13: =+VLOOKUP(C13,$R$2:$X$11,7,FALSE) -> 0.056 | L13: 01.16.00 | M13: =+VLOOKUP(L13,A:B,2,0) -> Coltivazione di piante per la preparazione di fibre tessili | N13: =+VLOOKUP(L13,A:D,4,0) -> A) Agricoltura silvicoltura e pesca
A14: 01.15.00 | B14: Coltivazione di tabacco | C14: 1 | D14: =+VLOOKUP(AtecoCrisi[[#This Row],[COD. CRISI]],Tabella139[],2,0) -> A) Agricoltura silvicoltura e pesca | E14: =+VLOOKUP(C14,$R$2:$X$11,3,FALSE) -> 0.028 | F14: =+VLOOKUP(C14,$R$2:$X$11,4,FALSE) -> 0.094 | G14: =+VLOOKUP(C14,$R$2:$X$11,5,FALSE) -> 0.921 | H14: =+VLOOKUP(C14,$R$2:$X$11,6,FALSE) -> 0.003 | I14: =+VLOOKUP(C14,$R$2:$X$11,7,FALSE) -> 0.056 | L14: 01.19.10 | M14: =+VLOOKUP(L14,A:B,2,0) -> Coltivazione di fiori in piena aria | N14: =+VLOOKUP(L14,A:D,4,0) -> A) Agricoltura silvicoltura e pesca
A15: 01.16.00 | B15: Coltivazione di piante per la preparazione di fibre tessili | C15: 1 | D15: =+VLOOKUP(AtecoCrisi[[#This Row],[COD. CRISI]],Tabella139[],2,0) -> A) Agricoltura silvicoltura e pesca | E15: =+VLOOKUP(C15,$R$2:$X$11,3,FALSE) -> 0.028 | F15: =+VLOOKUP(C15,$R$2:$X$11,4,FALSE) -> 0.094 | G15: =+VLOOKUP(C15,$R$2:$X$11,5,FALSE) -> 0.921 | H15: =+VLOOKUP(C15,$R$2:$X$11,6,FALSE) -> 0.003 | I15: =+VLOOKUP(C15,$R$2:$X$11,7,FALSE) -> 0.056 | L15: 01.19.20 | M15: =+VLOOKUP(L15,A:B,2,0) -> Coltivazione di fiori in colture protette | N15: =+VLOOKUP(L15,A:D,4,0) -> A) Agricoltura silvicoltura e pesca
A16: 01.19.10 | B16: Coltivazione di fiori in piena aria | C16: 1 | D16: =+VLOOKUP(AtecoCrisi[[#This Row],[COD. CRISI]],Tabella139[],2,0) -> A) Agricoltura silvicoltura e pesca | E16: =+VLOOKUP(C16,$R$2:$X$11,3,FALSE) -> 0.028 | F16: =+VLOOKUP(C16,$R$2:$X$11,4,FALSE) -> 0.094 | G16: =+VLOOKUP(C16,$R$2:$X$11,5,FALSE) -> 0.921 | H16: =+VLOOKUP(C16,$R$2:$X$11,6,FALSE) -> 0.003 | I16: =+VLOOKUP(C16,$R$2:$X$11,7,FALSE) -> 0.056 | L16: 01.19.90 | M16: =+VLOOKUP(L16,A:B,2,0) -> Coltivazione di piante da foraggio e di altre colture non permanenti | N16: =+VLOOKUP(L16,A:D,4,0) -> A) Agricoltura silvicoltura e pesca
A17: 01.19.20 | B17: Coltivazione di fiori in colture protette | C17: 1 | D17: =+VLOOKUP(AtecoCrisi[[#This Row],[COD. CRISI]],Tabella139[],2,0) -> A) Agricoltura silvicoltura e pesca | E17: =+VLOOKUP(C17,$R$2:$X$11,3,FALSE) -> 0.028 | F17: =+VLOOKUP(C17,$R$2:$X$11,4,FALSE) -> 0.094 | G17: =+VLOOKUP(C17,$R$2:$X$11,5,FALSE) -> 0.921 | H17: =+VLOOKUP(C17,$R$2:$X$11,6,FALSE) -> 0.003 | I17: =+VLOOKUP(C17,$R$2:$X$11,7,FALSE) -> 0.056 | L17: 01.21.00 | M17: =+VLOOKUP(L17,A:B,2,0) -> Coltivazione di uva | N17: =+VLOOKUP(L17,A:D,4,0) -> A) Agricoltura silvicoltura e pesca
A18: 01.19.90 | B18: Coltivazione di piante da foraggio e di altre colture non permanenti | C18: 1 | D18: =+VLOOKUP(AtecoCrisi[[#This Row],[COD. CRISI]],Tabella139[],2,0) -> A) Agricoltura silvicoltura e pesca | E18: =+VLOOKUP(C18,$R$2:$X$11,3,FALSE) -> 0.028 | F18: =+VLOOKUP(C18,$R$2:$X$11,4,FALSE) -> 0.094 | G18: =+VLOOKUP(C18,$R$2:$X$11,5,FALSE) -> 0.921 | H18: =+VLOOKUP(C18,$R$2:$X$11,6,FALSE) -> 0.003 | I18: =+VLOOKUP(C18,$R$2:$X$11,7,FALSE) -> 0.056 | L18: 01.22.00 | M18: =+VLOOKUP(L18,A:B,2,0) -> Coltivazione di frutta di origine tropicale e subtropicale | N18: =+VLOOKUP(L18,A:D,4,0) -> A) Agricoltura silvicoltura e pesca
A19: 01.21.00 | B19: Coltivazione di uva | C19: 1 | D19: =+VLOOKUP(AtecoCrisi[[#This Row],[COD. CRISI]],Tabella139[],2,0) -> A) Agricoltura silvicoltura e pesca | E19: =+VLOOKUP(C19,$R$2:$X$11,3,FALSE) -> 0.028 | F19: =+VLOOKUP(C19,$R$2:$X$11,4,FALSE) -> 0.094 | G19: =+VLOOKUP(C19,$R$2:$X$11,5,FALSE) -> 0.921 | H19: =+VLOOKUP(C19,$R$2:$X$11,6,FALSE) -> 0.003 | I19: =+VLOOKUP(C19,$R$2:$X$11,7,FALSE) -> 0.056 | L19: 01.23.00 | M19: =+VLOOKUP(L19,A:B,2,0) -> Coltivazione di agrumi | N19: =+VLOOKUP(L19,A:D,4,0) -> A) Agricoltura silvicoltura e pesca
A20: 01.22.00 | B20: Coltivazione di frutta di origine tropicale e subtropicale | C20: 1 | D20: =+VLOOKUP(AtecoCrisi[[#This Row],[COD. CRISI]],Tabella139[],2,0) -> A) Agricoltura silvicoltura e pesca | E20: =+VLOOKUP(C20,$R$2:$X$11,3,FALSE) -> 0.028 | F20: =+VLOOKUP(C20,$R$2:$X$11,4,FALSE) -> 0.094 | G20: =+VLOOKUP(C20,$R$2:$X$11,5,FALSE) -> 0.921 | H20: =+VLOOKUP(C20,$R$2:$X$11,6,FALSE) -> 0.003 | I20: =+VLOOKUP(C20,$R$2:$X$11,7,FALSE) -> 0.056 | L20: 01.24.00 | M20: =+VLOOKUP(L20,A:B,2,0) -> Coltivazione di pomacee e frutta a nocciolo | N20: =+VLOOKUP(L20,A:D,4,0) -> A) Agricoltura silvicoltura e pesca
A21: 01.23.00 | B21: Coltivazione di agrumi | C21: 1 | D21: =+VLOOKUP(AtecoCrisi[[#This Row],[COD. CRISI]],Tabella139[],2,0) -> A) Agricoltura silvicoltura e pesca | E21: =+VLOOKUP(C21,$R$2:$X$11,3,FALSE) -> 0.028 | F21: =+VLOOKUP(C21,$R$2:$X$11,4,FALSE) -> 0.094 | G21: =+VLOOKUP(C21,$R$2:$X$11,5,FALSE) -> 0.921 | H21: =+VLOOKUP(C21,$R$2:$X$11,6,FALSE) -> 0.003 | I21: =+VLOOKUP(C21,$R$2:$X$11,7,FALSE) -> 0.056 | L21: 01.25.00 | M21: =+VLOOKUP(L21,A:B,2,0) -> Coltivazione di altri alberi da frutta, frutti di bosco e frutta in guscio | N21: =+VLOOKUP(L21,A:D,4,0) -> A) Agricoltura silvicoltura e pesca
A22: 01.24.00 | B22: Coltivazione di pomacee e frutta a nocciolo | C22: 1 | D22: =+VLOOKUP(AtecoCrisi[[#This Row],[COD. CRISI]],Tabella139[],2,0) -> A) Agricoltura silvicoltura e pesca | E22: =+VLOOKUP(C22,$R$2:$X$11,3,FALSE) -> 0.028 | F22: =+VLOOKUP(C22,$R$2:$X$11,4,FALSE) -> 0.094 | G22: =+VLOOKUP(C22,$R$2:$X$11,5,FALSE) -> 0.921 | H22: =+VLOOKUP(C22,$R$2:$X$11,6,FALSE) -> 0.003 | I22: =+VLOOKUP(C22,$R$2:$X$11,7,FALSE) -> 0.056 | L22: 01.26.00 | M22: =+VLOOKUP(L22,A:B,2,0) -> Coltivazione di frutti oleosi | N22: =+VLOOKUP(L22,A:D,4,0) -> A) Agricoltura silvicoltura e pesca
A23: 01.25.00 | B23: Coltivazione di altri alberi da frutta, frutti di bosco e frutta in guscio | C23: 1 | D23: =+VLOOKUP(AtecoCrisi[[#This Row],[COD. CRISI]],Tabella139[],2,0) -> A) Agricoltura silvicoltura e pesca | E23: =+VLOOKUP(C23,$R$2:$X$11,3,FALSE) -> 0.028 | F23: =+VLOOKUP(C23,$R$2:$X$11,4,FALSE) -> 0.094 | G23: =+VLOOKUP(C23,$R$2:$X$11,5,FALSE) -> 0.921 | H23: =+VLOOKUP(C23,$R$2:$X$11,6,FALSE) -> 0.003 | I23: =+VLOOKUP(C23,$R$2:$X$11,7,FALSE) -> 0.056 | L23: 01.27.00 | M23: =+VLOOKUP(L23,A:B,2,0) -> Coltivazione di piante per la produzione di bevande | N23: =+VLOOKUP(L23,A:D,4,0) -> A) Agricoltura silvicoltura e pesca
... A499: 33.13.01 | B499: Riparazione e manutenzione di apparecchiature ottiche, fotografiche e cinematografiche (escluse videocamere) | C499: 2 | D499: =+VLOOKUP(AtecoCrisi[[#This Row],[COD. CRISI]],Tabella139[],2,0) -> B) Estrazione; C) Manifattura; D) Produzione energia/gas | E499: =+VLOOKUP(C499,$R$2:$X$11,3,FALSE) -> 0.03 | F499: =+VLOOKUP(C499,$R$2:$X$11,4,FALSE) -> 0.076 | G499: =+VLOOKUP(C499,$R$2:$X$11,5,FALSE) -> 0.937 | H499: =+VLOOKUP(C499,$R$2:$X$11,6,FALSE) -> 0.005 | I499: =+VLOOKUP(C499,$R$2:$X$11,7,FALSE) -> 0.049 | L499: 38.11.00 | M499: =+VLOOKUP(L499,A:B,2,0) -> Raccolta di rifiuti solidi non pericolosi | N499: =+VLOOKUP(L499,A:D,4,0) -> E) Fornitura acqua reti fognarie rifiuti; D) Trasmissione energia/gas
A500: 33.13.02 | C500: 2 | D500: =+VLOOKUP(AtecoCrisi[[#This Row],[COD. CRISI]],Tabella139[],2,0) -> B) Estrazione; C) Manifattura; D) Produzione energia/gas | E500: =+VLOOKUP(C500,$R$2:$X$11,3,FALSE) -> 0.03 | F500: =+VLOOKUP(C500,$R$2:$X$11,4,FALSE) -> 0.076 | G500: =+VLOOKUP(C500,$R$2:$X$11,5,FALSE) -> 0.937 | H500: =+VLOOKUP(C500,$R$2:$X$11,6,FALSE) -> 0.005 | I500: =+VLOOKUP(C500,$R$2:$X$11,7,FALSE) -> 0.049 | L500: 38.12.00 | M500: =+VLOOKUP(L500,A:B,2,0) -> Raccolta di rifiuti pericolosi solidi e non solidi | N500: =+VLOOKUP(L500,A:D,4,0) -> E) Fornitura acqua reti fognarie rifiuti; D) Trasmissione energia/gas
A501: 33.13.03 | B501: Riparazione e manutenzione di apparecchi elettromedicali, di materiale medico-chirurgico e veterinario, di apparecchi e strumenti per odontoiatria | C501: 2 | D501: =+VLOOKUP(AtecoCrisi[[#This Row],[COD. CRISI]],Tabella139[],2,0) -> B) Estrazione; C) Manifattura; D) Produzione energia/gas | E501: =+VLOOKUP(C501,$R$2:$X$11,3,FALSE) -> 0.03 | F501: =+VLOOKUP(C501,$R$2:$X$11,4,FALSE) -> 0.076 | G501: =+VLOOKUP(C501,$R$2:$X$11,5,FALSE) -> 0.937 | H501: =+VLOOKUP(C501,$R$2:$X$11,6,FALSE) -> 0.005 | I501: =+VLOOKUP(C501,$R$2:$X$11,7,FALSE) -> 0.049 | L501: 38.21.01 | M501: =+VLOOKUP(L501,A:B,2,0) -> Produzione di compost | N501: =+VLOOKUP(L501,A:D,4,0) -> E) Fornitura acqua reti fognarie rifiuti; D) Trasmissione energia/gas
A502: 33.13.04 | B502: Riparazione e manutenzione di apparati di distillazione per laboratori, di centrifughe per laboratori e di macchinari per pulizia ad ultrasuoni per laboratori | C502: 2 | D502: =+VLOOKUP(AtecoCrisi[[#This Row],[COD. CRISI]],Tabella139[],2,0) -> B) Estrazione; C) Manifattura; D) Produzione energia/gas | E502: =+VLOOKUP(C502,$R$2:$X$11,3,FALSE) -> 0.03 | F502: =+VLOOKUP(C502,$R$2:$X$11,4,FALSE) -> 0.076 | G502: =+VLOOKUP(C502,$R$2:$X$11,5,FALSE) -> 0.937 | H502: =+VLOOKUP(C502,$R$2:$X$11,6,FALSE) -> 0.005 | I502: =+VLOOKUP(C502,$R$2:$X$11,7,FALSE) -> 0.049 | L502: 38.21.09 | M502: =+VLOOKUP(L502,A:B,2,0) -> Trattamento e smaltimento di altri rifiuti non pericolosi | N502: =+VLOOKUP(L502,A:D,4,0) -> E) Fornitura acqua reti fognarie rifiuti; D) Trasmissione energia/gas
A503: 33.13.09 | B503: Riparazione e manutenzione di altre apparecchiature elettroniche (escluse quelle per le telecomunicazioni ed i computer) | C503: 2 | D503: =+VLOOKUP(AtecoCrisi[[#This Row],[COD. CRISI]],Tabella139[],2,0) -> B) Estrazione; C) Manifattura; D) Produzione energia/gas | E503: =+VLOOKUP(C503,$R$2:$X$11,3,FALSE) -> 0.03 | F503: =+VLOOKUP(C503,$R$2:$X$11,4,FALSE) -> 0.076 | G503: =+VLOOKUP(C503,$R$2:$X$11,5,FALSE) -> 0.937 | H503: =+VLOOKUP(C503,$R$2:$X$11,6,FALSE) -> 0.005 | I503: =+VLOOKUP(C503,$R$2:$X$11,7,FALSE) -> 0.049 | L503: 38.22.00 | M503: =+VLOOKUP(L503,A:B,2,0) -> Trattamento e smaltimento di rifiuti pericolosi | N503: =+VLOOKUP(L503,A:D,4,0) -> E) Fornitura acqua reti fognarie rifiuti; D) Trasmissione energia/gas
A504: 33.14.00 | B504: Riparazione e manutenzione di apparecchiature elettriche (esclusi gli elettrodomestici) | C504: 2 | D504: =+VLOOKUP(AtecoCrisi[[#This Row],[COD. CRISI]],Tabella139[],2,0) -> B) Estrazione; C) Manifattura; D) Produzione energia/gas | E504: =+VLOOKUP(C504,$R$2:$X$11,3,FALSE) -> 0.03 | F504: =+VLOOKUP(C504,$R$2:$X$11,4,FALSE) -> 0.076 | G504: =+VLOOKUP(C504,$R$2:$X$11,5,FALSE) -> 0.937 | H504: =+VLOOKUP(C504,$R$2:$X$11,6,FALSE) -> 0.005 | I504: =+VLOOKUP(C504,$R$2:$X$11,7,FALSE) -> 0.049 | L504: 38.31.10 | M504: =+VLOOKUP(L504,A:B,2,0) -> Demolizione di carcasse | N504: =+VLOOKUP(L504,A:D,4,0) -> E) Fornitura acqua reti fognarie rifiuti; D) Trasmissione energia/gas
A505: 33.14.01 | C505: 2 | D505: =+VLOOKUP(AtecoCrisi[[#This Row],[COD. CRISI]],Tabella139[],2,0) -> B) Estrazione; C) Manifattura; D) Produzione energia/gas | E505: =+VLOOKUP(C505,$R$2:$X$11,3,FALSE) -> 0.03 | F505: =+VLOOKUP(C505,$R$2:$X$11,4,FALSE) -> 0.076 | G505: =+VLOOKUP(C505,$R$2:$X$11,5,FALSE) -> 0.937 | H505: =+VLOOKUP(C505,$R$2:$X$11,6,FALSE) -> 0.005 | I505: =+VLOOKUP(C505,$R$2:$X$11,7,FALSE) -> 0.049 | L505: 38.31.20 | M505: =+VLOOKUP(L505,A:B,2,0) -> Cantieri di demolizione navali | N505: =+VLOOKUP(L505,A:D,4,0) -> E) Fornitura acqua reti fognarie rifiuti; D) Trasmissione energia/gas
A506: 33.14.09 | C506: 2 | D506: =+VLOOKUP(AtecoCrisi[[#This Row],[COD. CRISI]],Tabella139[],2,0) -> B) Estrazione; C) Manifattura; D) Produzione energia/gas | E506: =+VLOOKUP(C506,$R$2:$X$11,3,FALSE) -> 0.03 | F506: =+VLOOKUP(C506,$R$2:$X$11,4,FALSE) -> 0.076 | G506: =+VLOOKUP(C506,$R$2:$X$11,5,FALSE) -> 0.937 | H506: =+VLOOKUP(C506,$R$2:$X$11,6,FALSE) -> 0.005 | I506: =+VLOOKUP(C506,$R$2:$X$11,7,FALSE) -> 0.049 | L506: 38.32.10 | M506: =+VLOOKUP(L506,A:B,2,0) -> Recupero e preparazione per il riciclaggio di cascami e rottami metallici | N506: =+VLOOKUP(L506,A:D,4,0) -> E) Fornitura acqua reti fognarie rifiuti; D) Trasmissione energia/gas
A507: 33.15.00 | B507: Riparazione e manutenzione di navi commerciali e imbarcazioni da diporto (esclusi i loro motori) | C507: 2 | D507: =+VLOOKUP(AtecoCrisi[[#This Row],[COD. CRISI]],Tabella139[],2,0) -> B) Estrazione; C) Manifattura; D) Produzione energia/gas | E507: =+VLOOKUP(C507,$R$2:$X$11,3,FALSE) -> 0.03 | F507: =+VLOOKUP(C507,$R$2:$X$11,4,FALSE) -> 0.076 | G507: =+VLOOKUP(C507,$R$2:$X$11,5,FALSE) -> 0.937 | H507: =+VLOOKUP(C507,$R$2:$X$11,6,FALSE) -> 0.005 | I507: =+VLOOKUP(C507,$R$2:$X$11,7,FALSE) -> 0.049 | L507: 38.32.20 | M507: =+VLOOKUP(L507,A:B,2,0) -> Recupero e preparazione per il riciclaggio di materiale plastico per produzione di materie prime plastiche, resine sintetiche | N507: =+VLOOKUP(L507,A:D,4,0) -> E) Fornitura acqua reti fognarie rifiuti; D) Trasmissione energia/gas
A508: 33.16.00 | B508: Riparazione e manutenzione di aeromobili e di veicoli spaziali | C508: 2 | D508: =+VLOOKUP(AtecoCrisi[[#This Row],[COD. CRISI]],Tabella139[],2,0) -> B) Estrazione; C) Manifattura; D) Produzione energia/gas | E508: =+VLOOKUP(C508,$R$2:$X$11,3,FALSE) -> 0.03 | F508: =+VLOOKUP(C508,$R$2:$X$11,4,FALSE) -> 0.076 | G508: =+VLOOKUP(C508,$R$2:$X$11,5,FALSE) -> 0.937 | H508: =+VLOOKUP(C508,$R$2:$X$11,6,FALSE) -> 0.005 | I508: =+VLOOKUP(C508,$R$2:$X$11,7,FALSE) -> 0.049 | L508: 38.32.30 | M508: =+VLOOKUP(L508,A:B,2,0) -> Recupero e preparazione per il riciclaggio dei rifiuti solidi urbani, industriali e biomasse | N508: =+VLOOKUP(L508,A:D,4,0) -> E) Fornitura acqua reti fognarie rifiuti; D) Trasmissione energia/gas
A509: 33.17.00 | B509: Riparazione e manutenzione di materiale rotabile ferroviario, tranviario, filoviario e per metropolitane (esclusi i loro motori) | C509: 2 | D509: =+VLOOKUP(AtecoCrisi[[#This Row],[COD. CRISI]],Tabella139[],2,0) -> B) Estrazione; C) Manifattura; D) Produzione energia/gas | E509: =+VLOOKUP(C509,$R$2:$X$11,3,FALSE) -> 0.03 | F509: =+VLOOKUP(C509,$R$2:$X$11,4,FALSE) -> 0.076 | G509: =+VLOOKUP(C509,$R$2:$X$11,5,FALSE) -> 0.937 | H509: =+VLOOKUP(C509,$R$2:$X$11,6,FALSE) -> 0.005 | I509: =+VLOOKUP(C509,$R$2:$X$11,7,FALSE) -> 0.049 | L509: 39.00.01 | M509: =+VLOOKUP(L509,A:B,2,0) -> Attività di rimozione di strutture ed elementi in amianto specializzata per l'edilizia | N509: =+VLOOKUP(L509,A:D,4,0) -> E) Fornitura acqua reti fognarie rifiuti; D) Trasmissione energia/gas
A510: 33.19.01 | B510: Riparazioni di pallets e contenitori in legno per trasporto | C510: 2 | D510: =+VLOOKUP(AtecoCrisi[[#This Row],[COD. CRISI]],Tabella139[],2,0) -> B) Estrazione; C) Manifattura; D) Produzione energia/gas | E510: =+VLOOKUP(C510,$R$2:$X$11,3,FALSE) -> 0.03 | F510: =+VLOOKUP(C510,$R$2:$X$11,4,FALSE) -> 0.076 | G510: =+VLOOKUP(C510,$R$2:$X$11,5,FALSE) -> 0.937 | H510: =+VLOOKUP(C510,$R$2:$X$11,6,FALSE) -> 0.005 | I510: =+VLOOKUP(C510,$R$2:$X$11,7,FALSE) -> 0.049 | L510: 39.00.09 | M510: =+VLOOKUP(L510,A:B,2,0) -> Altre attività di risanamento e altri servizi di gestione dei rifiuti | N510: =+VLOOKUP(L510,A:D,4,0) -> E) Fornitura acqua reti fognarie rifiuti; D) Trasmissione energia/gas
A511: 33.19.02 | B511: Riparazione di prodotti in gomma | C511: 2 | D511: =+VLOOKUP(AtecoCrisi[[#This Row],[COD. CRISI]],Tabella139[],2,0) -> B) Estrazione; C) Manifattura; D) Produzione energia/gas | E511: =+VLOOKUP(C511,$R$2:$X$11,3,FALSE) -> 0.03 | F511: =+VLOOKUP(C511,$R$2:$X$11,4,FALSE) -> 0.076 | G511: =+VLOOKUP(C511,$R$2:$X$11,5,FALSE) -> 0.937 | H511: =+VLOOKUP(C511,$R$2:$X$11,6,FALSE) -> 0.005 | I511: =+VLOOKUP(C511,$R$2:$X$11,7,FALSE) -> 0.049 | L511: 41.10.00 | M511: =+VLOOKUP(L511,A:B,2,0) -> Sviluppo di progetti immobiliari senza costruzione | N511: =+VLOOKUP(L511,A:D,4,0) -> F41) Costruzione di edifici
A512: 33.19.03 | B512: Riparazione di articoli in vetro | C512: 2 | D512: =+VLOOKUP(AtecoCrisi[[#This Row],[COD. CRISI]],Tabella139[],2,0) -> B) Estrazione; C) Manifattura; D) Produzione energia/gas | E512: =+VLOOKUP(C512,$R$2:$X$11,3,FALSE) -> 0.03 | F512: =+VLOOKUP(C512,$R$2:$X$11,4,FALSE) -> 0.076 | G512: =+VLOOKUP(C512,$R$2:$X$11,5,FALSE) -> 0.937 | H512: =+VLOOKUP(C512,$R$2:$X$11,6,FALSE) -> 0.005 | I512: =+VLOOKUP(C512,$R$2:$X$11,7,FALSE) -> 0.049 | L512: 41.20.00 | M512: =+VLOOKUP(L512,A:B,2,0) -> Costruzione di edifici residenziali e non residenziali | N512: =+VLOOKUP(L512,A:D,4,0) -> F41) Costruzione di edifici
A513: 33.19.04 | B513: Riparazioni di altri prodotti in legno nca | C513: 2 | D513: =+VLOOKUP(AtecoCrisi[[#This Row],[COD. CRISI]],Tabella139[],2,0) -> B) Estrazione; C) Manifattura; D) Produzione energia/gas | E513: =+VLOOKUP(C513,$R$2:$X$11,3,FALSE) -> 0.03 | F513: =+VLOOKUP(C513,$R$2:$X$11,4,FALSE) -> 0.076 | G513: =+VLOOKUP(C513,$R$2:$X$11,5,FALSE) -> 0.937 | H513: =+VLOOKUP(C513,$R$2:$X$11,6,FALSE) -> 0.005 | I513: =+VLOOKUP(C513,$R$2:$X$11,7,FALSE) -> 0.049 | L513: 42.11.00 | M513: =+VLOOKUP(L513,A:B,2,0) -> Costruzione di strade, autostrade e piste aeroportuali | N513: =+VLOOKUP(L513,A:D,4,0) -> F42) Ingegneria civile; F43) Costruzioni specializzate
A514: 33.19.09 | B514: Riparazione di altre apparecchiature nca | C514: 2 | D514: =+VLOOKUP(AtecoCrisi[[#This Row],[COD. CRISI]],Tabella139[],2,0) -> B) Estrazione; C) Manifattura; D) Produzione energia/gas | E514: =+VLOOKUP(C514,$R$2:$X$11,3,FALSE) -> 0.03 | F514: =+VLOOKUP(C514,$R$2:$X$11,4,FALSE) -> 0.076 | G514: =+VLOOKUP(C514,$R$2:$X$11,5,FALSE) -> 0.937 | H514: =+VLOOKUP(C514,$R$2:$X$11,6,FALSE) -> 0.005 | I514: =+VLOOKUP(C514,$R$2:$X$11,7,FALSE) -> 0.049 | L514: 42.12.00 | M514: =+VLOOKUP(L514,A:B,2,0) -> Costruzione di linee ferroviarie e metropolitane | N514: =+VLOOKUP(L514,A:D,4,0) -> F42) Ingegneria civile; F43) Costruzioni specializzate
A515: 33.20.01 | B515: Installazione di motori, generatori e trasformatori elettrici; di apparecchiature per la distribuzione e il controllo dell'elettricità (esclusa l'installazione all'interno degli edifici) | C515: 2 | D515: =+VLOOKUP(AtecoCrisi[[#This Row],[COD. CRISI]],Tabella139[],2,0) -> B) Estrazione; C) Manifattura; D) Produzione energia/gas | E515: =+VLOOKUP(C515,$R$2:$X$11,3,FALSE) -> 0.03 | F515: =+VLOOKUP(C515,$R$2:$X$11,4,FALSE) -> 0.076 | G515: =+VLOOKUP(C515,$R$2:$X$11,5,FALSE) -> 0.937 | H515: =+VLOOKUP(C515,$R$2:$X$11,6,FALSE) -> 0.005 | I515: =+VLOOKUP(C515,$R$2:$X$11,7,FALSE) -> 0.049 | L515: 42.13.00 | M515: =+VLOOKUP(L515,A:B,2,0) -> Costruzione di ponti e gallerie | N515: =+VLOOKUP(L515,A:D,4,0) -> F42) Ingegneria civile; F43) Costruzioni specializzate
...
