Workbook
Name Ac: DatiI!A$14
Name Acq: DatiI!A$34
Name Am: DatiI!A$13
Name Anni: '1'!$B$4:$H$4
Name br: BR!$A$6:$A$131
Name CB: BR!$A$5:$A$78
Name CBG: BR!$A$110:$A$131
Name cbr: BR!$A$6:$L$78
Name Cf: DatiI!A$30
Name Ci: DatiI!A$15
Name CIn: DatiI!A$16
Name Cini: DatiI!A$17
Name Cli: DatiI!A$11
Name Co: DatiI!A$24
Name CODCEE: Tabella4[COD CEE]
Name col: #REF!
Name Cr: DatiI!A$10
Name Cv: DatiI!A$29
Name D: DatiI!A$21
Name E: DatiI!A$31
Name Ebit: DatiI!A$31
Name F: OFFSET(ss!$A$4,0,0,COUNTA(ss!$A$4:$A$2999),2)
Name Fa: DatiI!A$23
Name Fdo: DatiI!A$8
Name For: DatiI!A$35
Name g: Indici!A$3
Name i: Menu!$E$12
Name Il: DatiI!A$6
Name Im: DatiI!A$7
Name Iva: DatiI!A$33
Name L: DatiI!A$12
Name M: DatiI!A$25
Name MOL: DatiI!A$36
Name Mp: DatiI!A$28
Name Of: DatiI!A$37
Name Pb: DatiI!A$20
Name per: DatiI!$D$4:$J$4
Name Pfn: DatiI!A$22
Name Pl: DatiI!A$19
Name Pn: DatiI!A$18
Name Ri: DatiI!A$9
Name Rn: DatiI!A$26
Name Ro: DatiI!A$27
Name s: Menu!$E$8
Name STR: OFFSET(ss!$E$4,1,0,COUNTA(ss!$A$4:$A$2999),1)
Name t: Menu!$N$12
Name TB: IF(t="Abbreviato Cee",1,IF(t="CEE",2,3))
Name V: DatiI!A$32

Sheet Menu
B8: Nome azienda | E8: ALFA SPA
B10: Anno ultimo bilancio | E10: 2024 | H10: Mese chiusura bilancio | K10: 12
B12: Bilancio infrannuale | E12: Sì | G12: 45900 | K12: Tipo Bilancio | N12: Bilancio di Verifica
B15: =+IF(t="Abbreviato Cee","BILANCIO CEE ABBREVIATO","") | G15: =+IF(t="cee","BILANCIO CEE","") | K15: =+IF(t<>"Bilancio di Verifica","CONTO ECONOMICO","") | O15: =+IF(t="Bilancio di Verifica","Bilancio di Verifica","") -> Bilancio di Verifica | AC15: =+IF(t="libero","","")
B18: BILANCIO RICLASSIFICATO | G18: ANALISI PER INDICI | O18: RENDICONTO FINANZIARIO OIC. 10
O22: Manuale d'uso

Sheet 2
A1: =+Menu!B2 -> 0
A3: =+"Stato Patrimoniale" -> Stato Patrimoniale
B4: =+EOMONTH(D4,-12) -> 44926 | D4: =+EOMONTH(F4,-12) -> 45291 | F4: =+EOMONTH(DATE(Menu!E10,Menu!K10,1),0) -> 45657 | H4: =+Menu!G12 -> 45900 | I4: x | J4: codBil
A6: Attivo | B6: =+IF(OR(AND(B166-B276<1,B166-B276>-1),TB<>2),"","Squadratura di "&TEXT(B166-B276,"#.###,00")) | D6: =+IF(OR(AND(D166-D276<1,D166-D276>-1),TB<>2),"","Squadratura di "&TEXT(D166-D276,"#.###,00")) | F6: =+IF(OR(AND(F166-F276<1,F166-F276>-1),TB<>2),"","Squadratura di "&TEXT(F166-F276,"#.###,00")) | H6: =+IF(OR(AND(H166-H276<1,H166-H276>-1),TB<>2),"","Squadratura di "&TEXT(H166-H276,"#.###,00"))
A8: A) Crediti verso soci per versamenti ancora dovuti | J8: 100
A10: B) Immobilizzazioni
A12: I - Immobilizzazioni immateriali:
A14: 1) costi di impianto e di ampliamento
A16: 2) costi di sviluppo
A18: 3) diritti di brevetto industriale e diritti di utilizzazione delle opere dell'ingegno
A20: 4) concessioni, licenze, marchi e diritti simili
A22: 5) avviamento
A24: 6) immobilizzazioni in corso e acconti
A26: 7) altre
A28: Totale | B28: =SUM(B14:B26) -> 0 | D28: =SUM(D14:D26) -> 0 | F28: =SUM(F14:F26) -> 0 | H28: =SUM(H14:H26) -> 0
A30: II - Immobilizzazioni materiali:
A32: 1) terreni e fabbricati
A34: 2) impianti e macchinario
A36: 3) attrezzature industriali e commerciali
A38: 4) altri beni
A40: 5) immobilizzazioni in corso e acconti
A42: Totale | B42: =SUM(B32:B40) -> 0 | D42: =SUM(D32:D40) -> 0 | F42: =SUM(F32:F40) -> 0 | H42: =SUM(H32:H40) -> 0
A44: III - Immobilizzazioni finanziarie:
A46: 1) partecipazioni in:
A48: a) imprese controllate
A50: b) imprese collegate
A52: c) imprese controllanti
A54: d) imprese sottoposte al controllo delle controllanti
A56: d bis) altre imprese
A58: 2) crediti:
A60: a) verso imprese controllate
A62: b) verso imprese collegate
A64: c) verso controllanti
A66: d) verso imprese sottoposte al controllo delle controllanti
... A72: 4) Strumenti finanziari derivati attivi
A74: Totale | B74: =SUM(B46:B72) -> 0 | D74: =SUM(D46:D72) -> 0 | F74: =SUM(F46:F72) -> 0 | H74: =SUM(H46:H72) -> 0 | J74: 30
A76: Totale immobilizzazioni (B) | B76: =+B74+B42+B28 -> 0 | D76: =+D74+D42+D28 -> 0 | F76: =+F74+F42+F28 -> 0 | H76: =+H74+H42+H28 -> 0 | J76: 35
A78: C) Attivo circolante:
A80: I - Rimanenze:
A82: 1) materie prime, sussidiarie e di consumo
...

Sheet 1
A1: =+Menu!B2 -> 0
A3: Stato Patrimoniale ex art. 2435 bis
B4: =+EOMONTH(D4,-12) -> 44926 | D4: =+EOMONTH(F4,-12) -> 45291 | F4: =+EOMONTH(DATE(Menu!E10,Menu!K10,1),0) -> 45657 | H4: =+Menu!G12 -> 45900 | I4: x | J4: cod | K4: x | L4: x | M4: x | N4: x | O4: x | P4: x | Q4: x | R4: x | S4: x | T4: x | U4: x | V4: x | W4: x | X4: x | Y4: x | Z4: x | AA4: x
A6: Attivo | B6: =+IF(OR(AND(B38-B76<1,B38-B76>-1),TB<>1),"","Squadratura di "&TEXT(B38-B76,"#.###,00")) | D6: =+IF(OR(AND(D38-D76<1,D38-D76>-1),TB<>1),"","Squadratura di "&TEXT(D38-D76,"#.###,00")) | F6: =+IF(OR(AND(F38-F76<1,F38-F76>-1),TB<>1),"","Squadratura di "&TEXT(F38-F76,"#.###,00")) | H6: =+IF(OR(AND(H38-H76<1,H38-H76>-1),TB<>1),"","Squadratura di "&TEXT(H38-H76,"#.###,00"))
A8: A) Crediti verso soci per versamenti ancora dovuti | J8: 100
A10: B) Immobilizzazioni, con separata indicazione di quelle concesse in locazione finanziaria:
A12: I - Immobilizzazioni immateriali:
A14: II - Immobilizzazioni materiali:
A16: III - Immobilizzazioni finanziarie | F16: =+D16 -> 0 | H16: =+F16 -> 0 | J16: 30
A18: Totale immobilizzazioni (B); | B18: =SUM(B12:B17) -> 0 | D18: =SUM(D12:D17) -> 0 | F18: =SUM(F12:F17) -> 0 | H18: =SUM(H12:H17) -> 0
A20: C) Attivo circolante:
A22: I - Rimanenze: | J22: 40
A24: II - Crediti (compresi eventualmente Ratei , Risconti e crediti vs soci)
A26: II - Crediti oltre l'es. (compresi eventualmente Ratei , Risconti e crediti vs soci) | J26: 30
A28: III - Attività finanziarie che non costituiscono immobilizzazioni: | J28: 70
A30: IV - Disponibilità liquide: | J30: 80
A32: Totale attivo circolante (C). | B32: =SUM(B22:B30) -> 0 | D32: =SUM(D22:D30) -> 0 | F32: =SUM(F22:F30) -> 0 | H32: =SUM(H22:H30) -> 0
A34: D) Ratei e risconti entro l'esercizio | J34: 52
A36: D) Ratei e risconti oltre l'esercizio | J36: 30
A38: Totale Attivo | B38: =+B32+B18+B8+B34+B36 -> 0 | D38: =+D32+D18+D8+D34+D36 -> 0 | F38: =+F32+F18+F8+F34+F36 -> 0 | G38: =+G32+G18+G8 -> 0 | H38: =+H32+H18+H8+H34+H36 -> 0
A40: Passivo:
A42: A) Patrimonio netto:
A44: I - Capitale. | J44: 90
A46: II - Riserva da soprapprezzo delle azioni. | J46: 120
A48: III - Riserve di rivalutazione. | J48: 130
A50: IV - Riserva legale. | J50: 110
A52: V - Riserve statutarie | J52: 120
A54: VI - Riserva per azioni proprie in portafoglio. | J54: 120
A56: VII - Altre riserve, distintamente indicate. | J56: 120
A58: VIII - Utili (perdite) portati a nuovo. | J58: 140
A60: IX - Utile (perdita) dell'esercizio. | B60: =+CE!B130 -> 0 | D60: =+CE!D130 -> 0 | F60: =+CE!F130 -> 0 | H60: =+CE!H130 -> 0
A62: Totale. | B62: =SUM(B44:B60) -> 0 | D62: =SUM(D44:D60) -> 0 | F62: =SUM(F44:F60) -> 0 | H62: =SUM(H44:H60) -> 0
A64: B) Fondi per rischi e oneri: | J64: 160 | K64: x
A66: C) Trattamento di fine rapporto di lavoro subordinato. | J66: 170
A68: D) Debiti (compresi eventualmente Ratei , Risconti)
A70: D) Debiti oltre l'es. (compresi eventualmente Ratei , Risconti)
A72: E) Ratei e risconti entro l'esercizio | J72: 232
A74: E) Ratei e risconti oltre l'esercizio | J74: 192
A76: Totale Passivo | B76: =+B72+B70+B68+B66+B64+B62+B74 -> 0 | D76: =+D72+D70+D68+D66+D64+D62+D74 -> 0 | F76: =+F72+F70+F68+F66+F64+F62+F74 -> 0 | H76: =+H72+H70+H68+H66+H64+H62+H74 -> 0
A78: Informazioni aggiuntive
...

Sheet CE
A1: =+Menu!B2 -> 0
A3: Conto Economico | B3: =IF(TB=2,+'2'!B3,'1'!B3) -> 0 | D3: =IF(TB=2,+'2'!D3,'1'!D3) -> 0 | F3: =IF(TB=2,+'2'!F3,'1'!F3) -> 0 | H3: =IF(TB=2,+'2'!H3,'1'!H3) -> 0
B4: =+EOMONTH(D4,-12) -> 44926 | C4: . | D4: =+EOMONTH(F4,-12) -> 45291 | E4: . | F4: =+EOMONTH(DATE(Menu!E10,Menu!K10,1),0) -> 45657 | G4: . | H4: =+Menu!G12 -> 45900 | I4: x | J4: codBil | K4: x | L4: CodBil2 | M4: x
I5: X | K5: X | M5: X
A6: A) Valore della produzione:
A8: 1) ricavi delle vendite e delle prestazioni; | J8: 300 | L8: 500
A10: 2) variazioni delle rimanenze di prodotti in corso di lavorazione, semilavorati e finiti; | J10: 310 | L10: 510
A12: 3) variazioni dei lavori in corso su ordinazione; | J12: 310 | L12: 510
A14: 4) incrementi di immobilizzazioni per lavori interni; | J14: 310 | L14: 525
A16: 5) altri ricavi e proventi | B16: =+B18+B20+B22+B24 -> 0 | D16: =+D18+D20+D22+D24 -> 0 | F16: =+F18+F20+F22+F24 -> 0 | H16: =+H18+H20+H22+H24 -> 0
A18: 5a) ricavi vari | J18: 320 | L18: 620
A20: 5b) contributi in conto esercizio | J20: 315 | L20: 620
A22: 5c) contributi in conto capitale | J22: 315 | L22: 620
A24: 5-1) proventi straordinari | J24: 440 | L24: 620
A26: Totale. | B26: =SUM(B8:B16) -> 0 | D26: =SUM(D8:D16) -> 0 | F26: =SUM(F8:F16) -> 0 | H26: =SUM(H8:H16) -> 0
A28: B) Costi della produzione:
A30: 6) per materie prime, sussidiarie, di consumo e di merci; | J30: 330 | L30: 530
A32: 7) per servizi; | J32: 360
A34: 8) per godimento di beni di terzi; | J34: 370
A36: 9) per il personale: | B36: =SUM(B38:B46) -> 0 | D36: =SUM(D38:D46) -> 0 | F36: =SUM(F38:F46) -> 0 | H36: =SUM(H38:H46) -> 0
A38: a) salari e stipendi; | J38: 390
A40: b) oneri sociali; | D40: =+B40*1.2 -> 0 | F40: =+D40*1.2 -> 0 | H40: =+F40*1.2 -> 0 | J40: 390
A42: c) trattamento di fine rapporto; | D42: =+B42*1.2 -> 0 | F42: =+D42*1.2 -> 0 | H42: =+F42*1.2 -> 0 | J42: 400
A44: d) trattamento di quiescenza e simili; | J44: 400
A46: e) altri costi; | J46: 390
A48: 10) ammortamenti e svalutazioni: | B48: =SUM(B50:B56) -> 0 | D48: =SUM(D50:D56) -> 0 | F48: =SUM(F50:F56) -> 0 | H48: =SUM(H50:H56) -> 0 | J48: 410
A50: a) ammortamento delle immobilizzazioni immateriali;
A52: b) ammortamento delle immobilizzazioni materiali; | D52: =+D50*2 -> 0 | F52: =+F50*2 -> 0 | H52: =+H50*2 -> 0
A54: c) altre svalutazioni delle immobilizzazioni;
A56: d) svalutazioni dei crediti compresi nell'attivo circolante e delle disponibilità liquide; | L56: 595
A58: 11) variazioni delle rimanenze di materie prime, sussidiarie, di consumo e merci; | J58: 340 | L58: 520
A60: 12) accantonamenti per rischi; | J60: 415 | L60: 603
A62: 13) altri accantonamenti; | J62: 415 | L62: 603
A64: 14) oneri diversi di gestione. | B64: =+B66+B68 -> 0 | D64: =+D66+D68 -> 0 | F64: =+F66+F68 -> 0 | H64: =+H66+H68 -> 0
A66: a) oneri diversi di gestione. | J66: 380 | L66: 600
A68: b) oneri straordinari | J68: 450 | L68: 620
A70: Totale B | B70: =+SUM(B50:B64,B36,B30:B34) -> 0 | D70: =+SUM(D50:D64,D36,D30:D34) -> 0 | F70: =+SUM(F50:F64,F36,F30:F34) -> 0 | H70: =+SUM(H50:H64,H36,H30:H34) -> 0
A72: Differenza tra valore e costi della produzione (A - B). | B72: =+B26+B70 -> 0 | D72: =+D26+D70 -> 0 | F72: =+F26+F70 -> 0 | H72: =+H26+H70 -> 0
A74: C) Proventi e oneri finanziari:
A76: 15) proventi da partecipazioni | B76: =SUM(B78:B84) -> 0 | D76: =SUM(D78:D84) -> 0 | F76: =SUM(F78:F84) -> 0 | H76: =SUM(H78:H84) -> 0
...

Sheet 3
A3: Bilancio di Verifica
A4: Copiare Bilancio di verifica e riclassificare in base ai codici contenuti nel foglio BR e riportati a lato
B6: Quadratura | C6: =+ROUND(SUM(C8:C792),0) -> 0 | K6: Elenco Codici
A7: Codice | B7: Descrizione | C7: Saldo | D7: Periodo | E7: Codice Suggerito | F7: Inserimento codice | G7: Codice Assegnato | H7: Descrizione
A8: 03/05/501 | B8: SPESE COSTITUZIONE E MODIF. | C8: 2086.45 | D8: 45657 | E8: =+IF(A8="","",VLOOKUP(A8,$A$7:H8,6,0)) -> 10 | F8: 10 | G8: =+IF(F8>0,F8,E8) -> 10 | H8: =+IFERROR(IF(A8="","",VLOOKUP(G8,cbr,2,0)),"Codice non inserito") -> IMMOBILIZZ. IMMATERIALI
A9: 04/05/005 | B9: F/AMM COSTI IMPIANTO | C9: -251.21 | D9: 45657 | E9: =+IF(A9="","",VLOOKUP(A9,$A$7:H9,6,0)) -> 12 | F9: 12 | G9: =+IF(F9>0,F9,E9) -> 12 | H9: =+IFERROR(IF(A9="","",VLOOKUP(G9,cbr,2,0)),"Codice non inserito") -> FDO IMM. IMMAT.
A10: 06/05/015 | B10: FABBRICATI IND.LI. E COMM.LI | C10: 700 | D10: 45657 | E10: =+IF(A10="","",VLOOKUP(A10,$A$7:H10,6,0)) -> 20 | F10: 20 | G10: =+IF(F10>0,F10,E10) -> 20 | H10: =+IFERROR(IF(A10="","",VLOOKUP(G10,cbr,2,0)),"Codice non inserito") -> IMMOBILIZZ. MATERIALI
A11: 06/15/005 | B11: ATTREZZAT. IND.LI E COMM.LI | C11: 7550.77 | D11: 45657 | E11: =+IF(A11="","",VLOOKUP(A11,$A$7:H11,6,0)) -> 20 | F11: 20 | G11: =+IF(F11>0,F11,E11) -> 20 | H11: =+IFERROR(IF(A11="","",VLOOKUP(G11,cbr,2,0)),"Codice non inserito") -> IMMOBILIZZ. MATERIALI
A12: 06/20/005 | B12: MOBILI E MACCHINE ORD. D'UFFICIO | C12: 5848.16 | D12: 45657 | E12: =+IF(A12="","",VLOOKUP(A12,$A$7:H12,6,0)) -> 20 | F12: 20 | G12: =+IF(F12>0,F12,E12) -> 20 | H12: =+IFERROR(IF(A12="","",VLOOKUP(G12,cbr,2,0)),"Codice non inserito") -> IMMOBILIZZ. MATERIALI
A13: 06/20/501 | B13: CELLULARI | C13: 3806.65 | D13: 45657 | E13: =+IF(A13="","",VLOOKUP(A13,$A$7:H13,6,0)) -> 20 | F13: 20 | G13: =+IF(F13>0,F13,E13) -> 20 | H13: =+IFERROR(IF(A13="","",VLOOKUP(G13,cbr,2,0)),"Codice non inserito") -> IMMOBILIZZ. MATERIALI
A14: 06/25/015 | B14: AUTOCARRI/AUTOVETTURE | C14: 76695.22 | D14: 45657 | E14: =+IF(A14="","",VLOOKUP(A14,$A$7:H14,6,0)) -> 20 | F14: 20 | G14: =+IF(F14>0,F14,E14) -> 20 | H14: =+IFERROR(IF(A14="","",VLOOKUP(G14,cbr,2,0)),"Codice non inserito") -> IMMOBILIZZ. MATERIALI
A15: 07/05/015 | B15: F/AMM FABBR. IND.LI E COMM.LI. | C15: -63.21 | D15: 45657 | E15: =+IF(A15="","",VLOOKUP(A15,$A$7:H15,6,0)) -> 22 | F15: 22 | G15: =+IF(F15>0,F15,E15) -> 22 | H15: =+IFERROR(IF(A15="","",VLOOKUP(G15,cbr,2,0)),"Codice non inserito") -> FDO IMM. MAT.
A16: 07/15/005 | B16: F/AMM ATTREZ. IND.LI E COMM.LI | C16: -538.19 | D16: 45657 | E16: =+IF(A16="","",VLOOKUP(A16,$A$7:H16,6,0)) -> 22 | F16: 22 | G16: =+IF(F16>0,F16,E16) -> 22 | H16: =+IFERROR(IF(A16="","",VLOOKUP(G16,cbr,2,0)),"Codice non inserito") -> FDO IMM. MAT.
A17: 07/20/005 | B17: F/AMM MOBILI E MACCH. ORD. D'UFF | C17: -405.05 | D17: 45657 | E17: =+IF(A17="","",VLOOKUP(A17,$A$7:H17,6,0)) -> 22 | F17: 22 | G17: =+IF(F17>0,F17,E17) -> 22 | H17: =+IFERROR(IF(A17="","",VLOOKUP(G17,cbr,2,0)),"Codice non inserito") -> FDO IMM. MAT.
A18: 07/20/010 | B18: F/AMM MACCH. ELETTROM. D'UFF. | C18: -386.64 | D18: 45657 | E18: =+IF(A18="","",VLOOKUP(A18,$A$7:H18,6,0)) -> 22 | F18: 22 | G18: =+IF(F18>0,F18,E18) -> 22 | H18: =+IFERROR(IF(A18="","",VLOOKUP(G18,cbr,2,0)),"Codice non inserito") -> FDO IMM. MAT.
A19: 07/25/015 | B19: F/AMM. AUTOCARRI/AUTOVETTURE | C19: -6289.37 | D19: 45657 | E19: =+IF(A19="","",VLOOKUP(A19,$A$7:H19,6,0)) -> 22 | F19: 22 | G19: =+IF(F19>0,F19,E19) -> 22 | H19: =+IFERROR(IF(A19="","",VLOOKUP(G19,cbr,2,0)),"Codice non inserito") -> FDO IMM. MAT.
... A21: 11/05/020 | B21: MATERIALI VARI | C21: 1920.13 | D21: 45657 | E21: =+IF(A21="","",VLOOKUP(A21,$A$7:H21,6,0)) -> 40 | F21: 40 | G21: =+IF(F21>0,F21,E21) -> 40 | H21: =+IFERROR(IF(A21="","",VLOOKUP(G21,cbr,2,0)),"Codice non inserito") -> RIMANENZE
A22: 14/00000 | B22: CREDITI V/CLIENTI | C22: 44739.79 | D22: 45657 | E22: =+IF(A22="","",VLOOKUP(A22,$A$7:H22,6,0)) -> 50 | F22: 50 | G22: 54 | H22: =+IFERROR(IF(A22="","",VLOOKUP(G22,cbr,2,0)),"Codice non inserito") -> ALTRI CREDITI
A23: 15/05/503 | B23: CARTA CARBURANTE | C23: 231.89 | D23: 45657 | E23: =+IF(A23="","",VLOOKUP(A23,$A$7:H23,6,0)) -> 80 | F23: 80 | G23: =+IF(F23>0,F23,E23) -> 80 | H23: =+IFERROR(IF(A23="","",VLOOKUP(G23,cbr,2,0)),"Codice non inserito") -> CASSA E BANCHE
A24: 24/05/001 | B24: BANCA | C24: 117180.65 | D24: 45657 | E24: =+IF(A24="","",VLOOKUP(A24,$A$7:H24,6,0)) -> 80 | F24: 80 | G24: =+IF(F24>0,F24,E24) -> 80 | H24: =+IFERROR(IF(A24="","",VLOOKUP(G24,cbr,2,0)),"Codice non inserito") -> CASSA E BANCHE
A25: 26/10/005 | B25: RISCONTI ATTIVI | C25: 367.54 | D25: 45657 | E25: =+IF(A25="","",VLOOKUP(A25,$A$7:H25,6,0)) -> 54 | F25: 54 | G25: =+IF(F25>0,F25,E25) -> 54 | H25: =+IFERROR(IF(A25="","",VLOOKUP(G25,cbr,2,0)),"Codice non inserito") -> ALTRI CREDITI
A26: 28/05/005 | B26: CAPITALE SOCIALE | C26: -10000 | D26: 45657 | E26: =+IF(A26="","",VLOOKUP(A26,$A$7:H26,6,0)) -> 90 | F26: 90 | G26: =+IF(F26>0,F26,E26) -> 90 | H26: =+IFERROR(IF(A26="","",VLOOKUP(G26,cbr,2,0)),"Codice non inserito") -> CAPITALE
A27: 31/05/005 | B27: DEBITI P/T.F.R. | C27: -1530.97 | D27: 45657 | E27: =+IF(A27="","",VLOOKUP(A27,$A$7:H27,6,0)) -> 170 | F27: 170 | G27: =+IF(F27>0,F27,E27) -> 170 | H27: =+IFERROR(IF(A27="","",VLOOKUP(G27,cbr,2,0)),"Codice non inserito") -> TFR
A28: 34/05/045 | B28: BANCA C/FINANZIAMENTI | C28: -16215.78 | D28: 45657 | E28: =+IF(A28="","",VLOOKUP(A28,$A$7:H28,6,0)) -> 180 | F28: 180 | G28: =+IF(F28>0,F28,E28) -> 180 | H28: =+IFERROR(IF(A28="","",VLOOKUP(G28,cbr,2,0)),"Codice non inserito") -> DEBITI VS BANCHE A MEDIO LUNGO T.
A29: 34/05/501 | B29: FINANZIAMENTO | C29: -3173.25 | D29: 45657 | E29: =+IF(A29="","",VLOOKUP(A29,$A$7:H29,6,0)) -> 180 | F29: 180 | G29: =+IF(F29>0,F29,E29) -> 180 | H29: =+IFERROR(IF(A29="","",VLOOKUP(G29,cbr,2,0)),"Codice non inserito") -> DEBITI VS BANCHE A MEDIO LUNGO T.
A30: 34/05/502 | B30: FINANZIAMENTO | C30: -14508.71 | D30: 45657 | E30: =+IF(A30="","",VLOOKUP(A30,$A$7:H30,6,0)) -> 180 | F30: 180 | G30: =+IF(F30>0,F30,E30) -> 180 | H30: =+IFERROR(IF(A30="","",VLOOKUP(G30,cbr,2,0)),"Codice non inserito") -> DEBITI VS BANCHE A MEDIO LUNGO T.
A31: 36/05/501 | B31: SOCI C/FINANZIAMENTI (INFRUTT.) | C31: -195.75 | D31: 45657 | E31: =+IF(A31="","",VLOOKUP(A31,$A$7:H31,6,0)) -> 150 | F31: 150 | G31: =+IF(F31>0,F31,E31) -> 150 | H31: =+IFERROR(IF(A31="","",VLOOKUP(G31,cbr,2,0)),"Codice non inserito") -> FINANZIAMENTO SOCI E INFRAGR.
A32: 38/05/501 | B32: CLIENTI C/ANTICIPI | C32: 69.5 | D32: 45657 | E32: =+IF(A32="","",VLOOKUP(A32,$A$7:H32,6,0)) -> 192 | F32: 192 | G32: =+IF(F32>0,F32,E32) -> 192 | H32: =+IFERROR(IF(A32="","",VLOOKUP(G32,cbr,2,0)),"Codice non inserito") -> ALTRI DEBITI A M/L
A33: 40/00000 | B33: DEBITI V/FORNITORI | C33: -57641.77 | D33: 45657 | E33: =+IF(A33="","",VLOOKUP(A33,$A$7:H33,6,0)) -> 210 | F33: 210 | G33: =+IF(F33>0,F33,E33) -> 210 | H33: =+IFERROR(IF(A33="","",VLOOKUP(G33,cbr,2,0)),"Codice non inserito") -> FORNITORI
A34: 41/05/005 | B34: FATTURE DA RICEVERE | C34: -2604.64 | D34: 45657 | E34: =+IF(A34="","",VLOOKUP(A34,$A$7:H34,6,0)) -> 210 | F34: 210 | G34: =+IF(F34>0,F34,E34) -> 210 | H34: =+IFERROR(IF(A34="","",VLOOKUP(G34,cbr,2,0)),"Codice non inserito") -> FORNITORI
... A224: 88/20/502 | B224: INTERESSI IVA TRIM. | C224: 56.96 | D224: 45900 | E224: =+IF(A224="","",VLOOKUP(A224,$A$7:H224,6,0)) -> 430 | F224: 430 | G224: =+IF(F224>0,F224,E224) -> 430 | H224: =+IFERROR(IF(A224="","",VLOOKUP(G224,cbr,2,0)),"Codice non inserito") -> ONERI FINANZIARI
E225: =+IF(A225="","",VLOOKUP(A225,$A$7:H225,6,0)) | G225: =+IF(F225>0,F225,E225) | H225: =+IFERROR(IF(A225="","",VLOOKUP(G225,cbr,2,0)),"Codice non inserito")
E226: =+IF(A226="","",VLOOKUP(A226,$A$7:H226,6,0)) | G226: =+IF(F226>0,F226,E226) | H226: =+IFERROR(IF(A226="","",VLOOKUP(G226,cbr,2,0)),"Codice non inserito")
E227: =+IF(A227="","",VLOOKUP(A227,$A$7:H227,6,0)) | G227: =+IF(F227>0,F227,E227) | H227: =+IFERROR(IF(A227="","",VLOOKUP(G227,cbr,2,0)),"Codice non inserito")
E228: =+IF(A228="","",VLOOKUP(A228,$A$7:H228,6,0)) | G228: =+IF(F228>0,F228,E228) | H228: =+IFERROR(IF(A228="","",VLOOKUP(G228,cbr,2,0)),"Codice non inserito")
E229: =+IF(A229="","",VLOOKUP(A229,$A$7:H229,6,0)) | G229: =+IF(F229>0,F229,E229) | H229: =+IFERROR(IF(A229="","",VLOOKUP(G229,cbr,2,0)),"Codice non inserito")
E230: =+IF(A230="","",VLOOKUP(A230,$A$7:H230,6,0)) | G230: =+IF(F230>0,F230,E230) | H230: =+IFERROR(IF(A230="","",VLOOKUP(G230,cbr,2,0)),"Codice non inserito")
E231: =+IF(A231="","",VLOOKUP(A231,$A$7:H231,6,0)) | G231: =+IF(F231>0,F231,E231) | H231: =+IFERROR(IF(A231="","",VLOOKUP(G231,cbr,2,0)),"Codice non inserito")
E232: =+IF(A232="","",VLOOKUP(A232,$A$7:H232,6,0)) | G232: =+IF(F232>0,F232,E232) | H232: =+IFERROR(IF(A232="","",VLOOKUP(G232,cbr,2,0)),"Codice non inserito")
E233: =+IF(A233="","",VLOOKUP(A233,$A$7:H233,6,0)) | G233: =+IF(F233>0,F233,E233) | H233: =+IFERROR(IF(A233="","",VLOOKUP(G233,cbr,2,0)),"Codice non inserito")
...

Sheet BR
B1: =+Menu!B2 -> 0
B4: =+s -> ALFA SPA | D4: =+EOMONTH(F4,-12) -> 44926 | E4: % | F4: =+EOMONTH(H4,-12) -> 45291 | G4: % | H4: =+EOMONTH(DATE(Menu!E10,Menu!K10,1),0) -> 45657 | I4: % | J4: =+Menu!G12 -> 45900 | K4: =+IF(J4=0,"","%") -> %
A5: d | B5: ATTIVO | C5: Voce Bilancio CEE | L5: a
A6: 10 | B6: IMMOBILIZZ. IMMATERIALI | C6: B.I | D6: =+SUMIF('1'!$J:$J,BR!$A6,'1'!B:B)*(TB=1)+SUMIF('2'!$J:$J,BR!$A6,'2'!B:B)*(TB=2)+SUMIFS('3'!$C:$C,'3'!$D:$D,BR!D$4,'3'!$G:$G,BR!$A6)*(TB=3) -> 0 | E6: =+IF(D$21=0,"",D6/D$21) | F6: =+SUMIF('1'!$J:$J,BR!$A6,'1'!D:D)*(TB=1)+SUMIF('2'!$J:$J,BR!$A6,'2'!D:D)*(TB=2)+SUMIFS('3'!$C:$C,'3'!$D:$D,BR!F$4,'3'!$G:$G,BR!$A6)*(TB=3) -> 0 | G6: =+IF(F$21=0,"",F6/F$21) | H6: =+SUMIF('1'!$J:$J,BR!$A6,'1'!F:F)*(TB=1)+SUMIF('2'!$J:$J,BR!$A6,'2'!F:F)*(TB=2)+SUMIFS('3'!$C:$C,'3'!$D:$D,BR!H$4,'3'!$G:$G,BR!$A6)*(TB=3) -> 2086.45 | I6: =+IF(H$21=0,"",H6/H$21) -> 0.0076743457 | J6: =+SUMIF('1'!$J:$J,BR!$A6,'1'!H:H)*(TB=1)+SUMIF('2'!$J:$J,BR!$A6,'2'!H:H)*(TB=2)+SUMIFS('3'!$C:$C,'3'!$D:$D,BR!J$4,'3'!$G:$G,BR!$A6)*(TB=3) -> 2086.45 | K6: =+IF(J$21 =0,"",J6/J$21) -> 0.0063223052 | L6: =+A6 -> 10
A7: 12 | B7: FDO IMM. IMMAT. | D7: =-SUMIF('1'!$J:$J,BR!$A7,'1'!B:B)*(TB=1)-SUMIF('2'!$J:$J,BR!$A7,'2'!B:B)*(TB=2)+SUMIFS('3'!$C:$C,'3'!$D:$D,BR!D$4,'3'!$G:$G,BR!$A7)*(TB=3) -> 0 | E7: =+IF(D$21=0,"",D7/D$21) | F7: =-SUMIF('1'!$J:$J,BR!$A7,'1'!D:D)*(TB=1)-SUMIF('2'!$J:$J,BR!$A7,'2'!D:D)*(TB=2)+SUMIFS('3'!$C:$C,'3'!$D:$D,BR!F$4,'3'!$G:$G,BR!$A7)*(TB=3) -> 0 | G7: =+IF(F$21=0,"",F7/F$21) | H7: =-SUMIF('1'!$J:$J,BR!$A7,'1'!F:F)*(TB=1)-SUMIF('2'!$J:$J,BR!$A7,'2'!F:F)*(TB=2)+SUMIFS('3'!$C:$C,'3'!$D:$D,BR!H$4,'3'!$G:$G,BR!$A7)*(TB=3) -> -251.21 | I7: =+IF(H$21=0,"",H7/H$21) -> -0.00092399645 | J7: =-SUMIF('1'!$J:$J,BR!$A7,'1'!H:H)*(TB=1)-SUMIF('2'!$J:$J,BR!$A7,'2'!H:H)*(TB=2)+SUMIFS('3'!$C:$C,'3'!$D:$D,BR!J$4,'3'!$G:$G,BR!$A7)*(TB=3) -> -528.92 | K7: =+IF(J$21 =0,"",J7/J$21) -> -0.0016027193 | L7: =+A7 -> 12
A8: 20 | B8: IMMOBILIZZ. MATERIALI | C8: B.II | D8: =+SUMIF('1'!$J:$J,BR!$A8,'1'!B:B)*(TB=1)+SUMIF('2'!$J:$J,BR!$A8,'2'!B:B)*(TB=2)+SUMIFS('3'!$C:$C,'3'!$D:$D,BR!D$4,'3'!$G:$G,BR!$A8)*(TB=3) -> 0 | E8: =+IF(D$21=0,"",D8/D$21) | F8: =+SUMIF('1'!$J:$J,BR!$A8,'1'!D:D)*(TB=1)+SUMIF('2'!$J:$J,BR!$A8,'2'!D:D)*(TB=2)+SUMIFS('3'!$C:$C,'3'!$D:$D,BR!F$4,'3'!$G:$G,BR!$A8)*(TB=3) -> 0 | G8: =+IF(F$21=0,"",F8/F$21) | H8: =+SUMIF('1'!$J:$J,BR!$A8,'1'!F:F)*(TB=1)+SUMIF('2'!$J:$J,BR!$A8,'2'!F:F)*(TB=2)+SUMIFS('3'!$C:$C,'3'!$D:$D,BR!H$4,'3'!$G:$G,BR!$A8)*(TB=3) -> 94600.8 | I8: =+IF(H$21=0,"",H8/H$21) -> 0.34795909 | J8: =+SUMIF('1'!$J:$J,BR!$A8,'1'!H:H)*(TB=1)+SUMIF('2'!$J:$J,BR!$A8,'2'!H:H)*(TB=2)+SUMIFS('3'!$C:$C,'3'!$D:$D,BR!J$4,'3'!$G:$G,BR!$A8)*(TB=3) -> 95070.31 | K8: =+IF(J$21 =0,"",J8/J$21) -> 0.28807952 | L8: =+A8 -> 20
A9: 22 | B9: FDO IMM. MAT. | D9: =-SUMIF('1'!$J:$J,BR!$A9,'1'!B:B)*(TB=1)-SUMIF('2'!$J:$J,BR!$A9,'2'!B:B)*(TB=2)+SUMIFS('3'!$C:$C,'3'!$D:$D,BR!D$4,'3'!$G:$G,BR!$A9)*(TB=3) -> 0 | E9: =+IF(D$21=0,"",D9/D$21) | F9: =-SUMIF('1'!$J:$J,BR!$A9,'1'!D:D)*(TB=1)-SUMIF('2'!$J:$J,BR!$A9,'2'!D:D)*(TB=2)+SUMIFS('3'!$C:$C,'3'!$D:$D,BR!F$4,'3'!$G:$G,BR!$A9)*(TB=3) -> 0 | G9: =+IF(F$21=0,"",F9/F$21) | H9: =-SUMIF('1'!$J:$J,BR!$A9,'1'!F:F)*(TB=1)-SUMIF('2'!$J:$J,BR!$A9,'2'!F:F)*(TB=2)+SUMIFS('3'!$C:$C,'3'!$D:$D,BR!H$4,'3'!$G:$G,BR!$A9)*(TB=3) -> -7682.46 | I9: =+IF(H$21=0,"",H9/H$21) -> -0.028257497 | J9: =-SUMIF('1'!$J:$J,BR!$A9,'1'!H:H)*(TB=1)-SUMIF('2'!$J:$J,BR!$A9,'2'!H:H)*(TB=2)+SUMIFS('3'!$C:$C,'3'!$D:$D,BR!J$4,'3'!$G:$G,BR!$A9)*(TB=3) -> -16172.96 | K9: =+IF(J$21 =0,"",J9/J$21) -> -0.049006873 | L9: =+A9 -> 22
A10: 30 | B10: IMMOBILIZZ. FINANZIARIE | C10: B.III + C.II oltre es. | D10: =+SUMIF('1'!$J:$J,BR!$A10,'1'!B:B)*(TB=1)+SUMIF('2'!$J:$J,BR!$A10,'2'!B:B)*(TB=2)+SUMIFS('3'!$C:$C,'3'!$D:$D,BR!D$4,'3'!$G:$G,BR!$A10)*(TB=3) -> 0 | E10: =+IF(D$21=0,"",D10/D$21) | F10: =+SUMIF('1'!$J:$J,BR!$A10,'1'!D:D)*(TB=1)+SUMIF('2'!$J:$J,BR!$A10,'2'!D:D)*(TB=2)+SUMIFS('3'!$C:$C,'3'!$D:$D,BR!F$4,'3'!$G:$G,BR!$A10)*(TB=3) -> 0 | G10: =+IF(F$21=0,"",F10/F$21) | H10: =+SUMIF('1'!$J:$J,BR!$A10,'1'!F:F)*(TB=1)+SUMIF('2'!$J:$J,BR!$A10,'2'!F:F)*(TB=2)+SUMIFS('3'!$C:$C,'3'!$D:$D,BR!H$4,'3'!$G:$G,BR!$A10)*(TB=3) -> 0 | I10: =+IF(H$21=0,"",H10/H$21) -> 0 | J10: =+SUMIF('1'!$J:$J,BR!$A10,'1'!H:H)*(TB=1)+SUMIF('2'!$J:$J,BR!$A10,'2'!H:H)*(TB=2)+SUMIFS('3'!$C:$C,'3'!$D:$D,BR!J$4,'3'!$G:$G,BR!$A10)*(TB=3) -> 0 | K10: =+IF(J$21 =0,"",J10/J$21) -> 0 | L10: 30
A11: 35 | B11: IMMOBILIZZAZIONI | D11: =SUM(D6:D10) -> 0 | E11: =+IF(D$21=0,"",D11/D$21) | F11: =SUM(F6:F10) -> 0 | G11: =+IF(F$21=0,"",F11/F$21) | H11: =SUM(H6:H10) -> 88753.58 | I11: =+IF(H$21=0,"",H11/H$21) -> 0.32645194 | J11: =SUM(J6:J10) -> 80454.88 | K11: =+IF(J$21 =0,"",J11/J$21) -> 0.24379224
A12: 40 | B12: RIMANENZE | C12: C.I | D12: =+SUMIF('1'!$J:$J,BR!$A12,'1'!B:B)*(TB=1)+SUMIF('2'!$J:$J,BR!$A12,'2'!B:B)*(TB=2)+SUMIFS('3'!$C:$C,'3'!$D:$D,BR!D$4,'3'!$G:$G,BR!$A12)*(TB=3) -> 0 | E12: =+IF(D$21=0,"",D12/D$21) | F12: =+SUMIF('1'!$J:$J,BR!$A12,'1'!D:D)*(TB=1)+SUMIF('2'!$J:$J,BR!$A12,'2'!D:D)*(TB=2)+SUMIFS('3'!$C:$C,'3'!$D:$D,BR!F$4,'3'!$G:$G,BR!$A12)*(TB=3) -> 0 | G12: =+IF(F$21=0,"",F12/F$21) | H12: =+SUMIF('1'!$J:$J,BR!$A12,'1'!F:F)*(TB=1)+SUMIF('2'!$J:$J,BR!$A12,'2'!F:F)*(TB=2)+SUMIFS('3'!$C:$C,'3'!$D:$D,BR!H$4,'3'!$G:$G,BR!$A12)*(TB=3) -> 1920.13 | I12: =+IF(H$21=0,"",H12/H$21) -> 0.0070625902 | J12: =+SUMIF('1'!$J:$J,BR!$A12,'1'!H:H)*(TB=1)+SUMIF('2'!$J:$J,BR!$A12,'2'!H:H)*(TB=2)+SUMIFS('3'!$C:$C,'3'!$D:$D,BR!J$4,'3'!$G:$G,BR!$A12)*(TB=3) -> 1920.13 | K12: =+IF(J$21 =0,"",J12/J$21) -> 0.0058183268 | L12: =+A12 -> 40
A13: 50 | B13: CREDITI COMMERCIALI | C13: C.II.1 oppure dettaglio C.II N.I) | D13: =+SUMIF('1'!$J:$J,BR!$A13,'1'!B:B)*(TB=1)+SUMIF('2'!$J:$J,BR!$A13,'2'!B:B)*(TB=2)+SUMIFS('3'!$C:$C,'3'!$D:$D,BR!D$4,'3'!$G:$G,BR!$A13)*(TB=3) -> 0 | E13: =+IF(D$21=0,"",D13/D$21) | F13: =+SUMIF('1'!$J:$J,BR!$A13,'1'!D:D)*(TB=1)+SUMIF('2'!$J:$J,BR!$A13,'2'!D:D)*(TB=2)+SUMIFS('3'!$C:$C,'3'!$D:$D,BR!F$4,'3'!$G:$G,BR!$A13)*(TB=3) -> 0 | G13: =+IF(F$21=0,"",F13/F$21) | H13: =+SUMIF('1'!$J:$J,BR!$A13,'1'!F:F)*(TB=1)+SUMIF('2'!$J:$J,BR!$A13,'2'!F:F)*(TB=2)+SUMIFS('3'!$C:$C,'3'!$D:$D,BR!H$4,'3'!$G:$G,BR!$A13)*(TB=3) -> 0 | I13: =+IF(H$21=0,"",H13/H$21) -> 0 | J13: =+SUMIF('1'!$J:$J,BR!$A13,'1'!H:H)*(TB=1)+SUMIF('2'!$J:$J,BR!$A13,'2'!H:H)*(TB=2)+SUMIFS('3'!$C:$C,'3'!$D:$D,BR!J$4,'3'!$G:$G,BR!$A13)*(TB=3) -> 137151.13 | K13: =+IF(J$21 =0,"",J13/J$21) -> 0.4155917 | L13: 200
A14: 52 | B14: RATEI E RISCONTI ATTIVI | D14: =+SUMIF('1'!$J:$J,BR!$A14,'1'!B:B)*(TB=1)+SUMIF('2'!$J:$J,BR!$A14,'2'!B:B)*(TB=2)+SUMIFS('3'!$C:$C,'3'!$D:$D,BR!D$4,'3'!$G:$G,BR!$A14)*(TB=3) -> 0 | E14: =+IF(D$21=0,"",D14/D$21) | F14: =+SUMIF('1'!$J:$J,BR!$A14,'1'!D:D)*(TB=1)+SUMIF('2'!$J:$J,BR!$A14,'2'!D:D)*(TB=2)+SUMIFS('3'!$C:$C,'3'!$D:$D,BR!F$4,'3'!$G:$G,BR!$A14)*(TB=3) -> 0 | G14: =+IF(F$21=0,"",F14/F$21) | H14: =+SUMIF('1'!$J:$J,BR!$A14,'1'!F:F)*(TB=1)+SUMIF('2'!$J:$J,BR!$A14,'2'!F:F)*(TB=2)+SUMIFS('3'!$C:$C,'3'!$D:$D,BR!H$4,'3'!$G:$G,BR!$A14)*(TB=3) -> 0 | I14: =+IF(H$21=0,"",H14/H$21) -> 0 | J14: =+SUMIF('1'!$J:$J,BR!$A14,'1'!H:H)*(TB=1)+SUMIF('2'!$J:$J,BR!$A14,'2'!H:H)*(TB=2)+SUMIFS('3'!$C:$C,'3'!$D:$D,BR!J$4,'3'!$G:$G,BR!$A14)*(TB=3) -> 0 | K14: =+IF(J$21 =0,"",J14/J$21) -> 0 | L14: 52
A15: 54 | B15: ALTRI CREDITI | D15: =+SUMIF('1'!$J:$J,BR!$A15,'1'!B:B)*(TB=1)+SUMIF('2'!$J:$J,BR!$A15,'2'!B:B)*(TB=2)+SUMIFS('3'!$C:$C,'3'!$D:$D,BR!D$4,'3'!$G:$G,BR!$A15)*(TB=3) -> 0 | E15: =+IF(D$21=0,"",D15/D$21) | F15: =+SUMIF('1'!$J:$J,BR!$A15,'1'!D:D)*(TB=1)+SUMIF('2'!$J:$J,BR!$A15,'2'!D:D)*(TB=2)+SUMIFS('3'!$C:$C,'3'!$D:$D,BR!F$4,'3'!$G:$G,BR!$A15)*(TB=3) -> 0 | G15: =+IF(F$21=0,"",F15/F$21) | H15: =+SUMIF('1'!$J:$J,BR!$A15,'1'!F:F)*(TB=1)+SUMIF('2'!$J:$J,BR!$A15,'2'!F:F)*(TB=2)+SUMIFS('3'!$C:$C,'3'!$D:$D,BR!H$4,'3'!$G:$G,BR!$A15)*(TB=3) -> 63787.09 | I15: =+IF(H$21=0,"",H15/H$21) -> 0.23462061 | J15: =+SUMIF('1'!$J:$J,BR!$A15,'1'!H:H)*(TB=1)+SUMIF('2'!$J:$J,BR!$A15,'2'!H:H)*(TB=2)+SUMIFS('3'!$C:$C,'3'!$D:$D,BR!J$4,'3'!$G:$G,BR!$A15)*(TB=3) -> 43985.39 | K15: =+IF(J$21 =0,"",J15/J$21) -> 0.13328336 | L15: 54
A16: 60 | B16: ALTRI CREDITI E RATEI E RISC. | C16: C.II-C.II.1+D | D16: =SUM(D14:D15) -> 0 | E16: =+IF(D$21=0,"",D16/D$21) | F16: =SUM(F14:F15) -> 0 | G16: =+IF(F$21=0,"",F16/F$21) | H16: =SUM(H14:H15) -> 63787.09 | I16: =+IF(H$21=0,"",H16/H$21) -> 0.23462061 | J16: =SUM(J14:J15) -> 43985.39 | K16: =+IF(J$21 =0,"",J16/J$21) -> 0.13328336 | L16: 240
A17: 65 | B17: CREDITI | C17: C.II entro es. | D17: =SUM(D13:D15) -> 0 | E17: =+IF(D$21=0,"",D17/D$21) | F17: =SUM(F13:F15) -> 0 | G17: =+IF(F$21=0,"",F17/F$21) | H17: =SUM(H13:H15) -> 63787.09 | I17: =+IF(H$21=0,"",H17/H$21) -> 0.23462061 | J17: =SUM(J13:J15) -> 181136.52 | K17: =+IF(J$21 =0,"",J17/J$21) -> 0.54887506
A18: 70 | B18: ALTRE ATTIVITÀ FIN. NON IMMOBILIZZ | C18: C.III | D18: =+SUMIF('1'!$J:$J,BR!$A18,'1'!B:B)*(TB=1)+SUMIF('2'!$J:$J,BR!$A18,'2'!B:B)*(TB=2)+SUMIFS('3'!$C:$C,'3'!$D:$D,BR!D$4,'3'!$G:$G,BR!$A18)*(TB=3) -> 0 | E18: =+IF(D$21=0,"",D18/D$21) | F18: =+SUMIF('1'!$J:$J,BR!$A18,'1'!D:D)*(TB=1)+SUMIF('2'!$J:$J,BR!$A18,'2'!D:D)*(TB=2)+SUMIFS('3'!$C:$C,'3'!$D:$D,BR!F$4,'3'!$G:$G,BR!$A18)*(TB=3) -> 0 | G18: =+IF(F$21=0,"",F18/F$21) | H18: =+SUMIF('1'!$J:$J,BR!$A18,'1'!F:F)*(TB=1)+SUMIF('2'!$J:$J,BR!$A18,'2'!F:F)*(TB=2)+SUMIFS('3'!$C:$C,'3'!$D:$D,BR!H$4,'3'!$G:$G,BR!$A18)*(TB=3) -> 0 | I18: =+IF(H$21=0,"",H18/H$21) -> 0 | J18: =+SUMIF('1'!$J:$J,BR!$A18,'1'!H:H)*(TB=1)+SUMIF('2'!$J:$J,BR!$A18,'2'!H:H)*(TB=2)+SUMIFS('3'!$C:$C,'3'!$D:$D,BR!J$4,'3'!$G:$G,BR!$A18)*(TB=3) -> 0 | K18: =+IF(J$21 =0,"",J18/J$21) -> 0 | L18: 70
A19: 80 | B19: CASSA E BANCHE | C19: C.IV | D19: =+SUMIF('1'!$J:$J,BR!$A19,'1'!B:B)*(TB=1)+SUMIF('2'!$J:$J,BR!$A19,'2'!B:B)*(TB=2)+SUMIFS('3'!$C:$C,'3'!$D:$D,BR!D$4,'3'!$G:$G,BR!$A19)*(TB=3) -> 0 | E19: =+IF(D$21=0,"",D19/D$21) | F19: =+SUMIF('1'!$J:$J,BR!$A19,'1'!D:D)*(TB=1)+SUMIF('2'!$J:$J,BR!$A19,'2'!D:D)*(TB=2)+SUMIFS('3'!$C:$C,'3'!$D:$D,BR!F$4,'3'!$G:$G,BR!$A19)*(TB=3) -> 0 | G19: =+IF(F$21=0,"",F19/F$21) | H19: =+SUMIF('1'!$J:$J,BR!$A19,'1'!F:F)*(TB=1)+SUMIF('2'!$J:$J,BR!$A19,'2'!F:F)*(TB=2)+SUMIFS('3'!$C:$C,'3'!$D:$D,BR!H$4,'3'!$G:$G,BR!$A19)*(TB=3) -> 117412.54 | I19: =+IF(H$21=0,"",H19/H$21) -> 0.43186485 | J19: =+SUMIF('1'!$J:$J,BR!$A19,'1'!H:H)*(TB=1)+SUMIF('2'!$J:$J,BR!$A19,'2'!H:H)*(TB=2)+SUMIFS('3'!$C:$C,'3'!$D:$D,BR!J$4,'3'!$G:$G,BR!$A19)*(TB=3) -> 66502.59 | K19: =+IF(J$21 =0,"",J19/J$21) -> 0.20151438 | L19: 220
A20: 85 | B20: ATTIVO CIRCOLANTE | C20: (C entro es.+D) | D20: =+D17+D12+D18+D19 -> 0 | E20: =+IF(D$21=0,"",D20/D$21) | F20: =+F17+F12+F18+F19 -> 0 | G20: =+IF(F$21=0,"",F20/F$21) | H20: =+H17+H12+H18+H19 -> 183119.76 | I20: =+IF(H$21=0,"",H20/H$21) -> 0.67354806 | J20: =+J17+J12+J18+J19 -> 249559.24 | K20: =+IF(J$21 =0,"",J20/J$21) -> 0.75620776
A21: 89 | B21: TOTALE ATTIVO | D21: =+D11+D20 -> 0 | E21: =+IF(D$21=0,"",D21/D$21) | F21: =+F11+F20 -> 0 | G21: =+IF(F$21=0,"",F21/F$21) | H21: =+H11+H20 -> 271873.34 | I21: =+IF(H$21=0,"",H21/H$21) -> 1 | J21: =+J11+J20 -> 330014.12 | K21: =+IF(J$21 =0,"",J21/J$21) -> 1
B23: VOCI PASSIVO | C23: Voce Bilancio CEE
A24: 90 | B24: CAPITALE | C24: A.I | D24: =-(-SUMIF('1'!$J:$J,BR!$A24,'1'!B:B)*(TB=1)-SUMIF('2'!$J:$J,BR!$A24,'2'!B:B)*(TB=2)+SUMIFS('3'!$C:$C,'3'!$D:$D,BR!D$4,'3'!$G:$G,BR!$A24)*(TB=3)) -> 0 | E24: =+IF(D$21=0,"",D24/D$21) | F24: =-(-SUMIF('1'!$J:$J,BR!$A24,'1'!D:D)*(TB=1)-SUMIF('2'!$J:$J,BR!$A24,'2'!D:D)*(TB=2)+SUMIFS('3'!$C:$C,'3'!$D:$D,BR!F$4,'3'!$G:$G,BR!$A24)*(TB=3)) -> 0 | G24: =+IF(F$21=0,"",F24/F$21) | H24: =-(-SUMIF('1'!$J:$J,BR!$A24,'1'!F:F)*(TB=1)-SUMIF('2'!$J:$J,BR!$A24,'2'!F:F)*(TB=2)+SUMIFS('3'!$C:$C,'3'!$D:$D,BR!H$4,'3'!$G:$G,BR!$A24)*(TB=3)) -> 10000 | I24: =+IF(H$21=0,"",H24/H$21) -> 0.036781834 | J24: =-(-SUMIF('1'!$J:$J,BR!$A24,'1'!H:H)*(TB=1)-SUMIF('2'!$J:$J,BR!$A24,'2'!H:H)*(TB=2)+SUMIFS('3'!$C:$C,'3'!$D:$D,BR!J$4,'3'!$G:$G,BR!$A24)*(TB=3)) -> 10000 | K24: =+IF(J$21 =0,"",J24/J$21) -> 0.030301734 | L24: =+A24 -> 90
A25: 100 | B25: (CAPITALE NON VERSATO) | C25: A (Attivo) | D25: =(-SUMIF('1'!$J:$J,BR!$A25,'1'!B:B)*(TB=1)-SUMIF('2'!$J:$J,BR!$A25,'2'!B:B)*(TB=2)+SUMIFS('3'!$C:$C,'3'!$D:$D,BR!D$4,'3'!$G:$G,BR!$A25)*(TB=3)) -> 0 | E25: =+IF(D$21=0,"",D25/D$21) | F25: =(-SUMIF('1'!$J:$J,BR!$A25,'1'!D:D)*(TB=1)-SUMIF('2'!$J:$J,BR!$A25,'2'!D:D)*(TB=2)+SUMIFS('3'!$C:$C,'3'!$D:$D,BR!F$4,'3'!$G:$G,BR!$A25)*(TB=3)) -> 0 | G25: =+IF(F$21=0,"",F25/F$21) | H25: =(-SUMIF('1'!$J:$J,BR!$A25,'1'!F:F)*(TB=1)-SUMIF('2'!$J:$J,BR!$A25,'2'!F:F)*(TB=2)+SUMIFS('3'!$C:$C,'3'!$D:$D,BR!H$4,'3'!$G:$G,BR!$A25)*(TB=3)) -> 0 | I25: =+IF(H$21=0,"",H25/H$21) -> 0 | J25: =(-SUMIF('1'!$J:$J,BR!$A25,'1'!H:H)*(TB=1)-SUMIF('2'!$J:$J,BR!$A25,'2'!H:H)*(TB=2)+SUMIFS('3'!$C:$C,'3'!$D:$D,BR!J$4,'3'!$G:$G,BR!$A25)*(TB=3)) -> 0 | K25: =+IF(J$21 =0,"",J25/J$21) -> 0 | L25: =+A25 -> 100
A26: 110 | B26: RISERVA LEGALE | C26: A.IV | D26: =-(-SUMIF('1'!$J:$J,BR!$A26,'1'!B:B)*(TB=1)-SUMIF('2'!$J:$J,BR!$A26,'2'!B:B)*(TB=2)+SUMIFS('3'!$C:$C,'3'!$D:$D,BR!D$4,'3'!$G:$G,BR!$A26)*(TB=3)) -> 0 | E26: =+IF(D$21=0,"",D26/D$21) | F26: =-(-SUMIF('1'!$J:$J,BR!$A26,'1'!D:D)*(TB=1)-SUMIF('2'!$J:$J,BR!$A26,'2'!D:D)*(TB=2)+SUMIFS('3'!$C:$C,'3'!$D:$D,BR!F$4,'3'!$G:$G,BR!$A26)*(TB=3)) -> 0 | G26: =+IF(F$21=0,"",F26/F$21) | H26: =-(-SUMIF('1'!$J:$J,BR!$A26,'1'!F:F)*(TB=1)-SUMIF('2'!$J:$J,BR!$A26,'2'!F:F)*(TB=2)+SUMIFS('3'!$C:$C,'3'!$D:$D,BR!H$4,'3'!$G:$G,BR!$A26)*(TB=3)) -> 0 | I26: =+IF(H$21=0,"",H26/H$21) -> 0 | J26: =-(-SUMIF('1'!$J:$J,BR!$A26,'1'!H:H)*(TB=1)-SUMIF('2'!$J:$J,BR!$A26,'2'!H:H)*(TB=2)+SUMIFS('3'!$C:$C,'3'!$D:$D,BR!J$4,'3'!$G:$G,BR!$A26)*(TB=3)) -> 2000 | K26: =+IF(J$21 =0,"",J26/J$21) -> 0.0060603468 | L26: =+A26 -> 110
A27: 120 | B27: ALTRE RISERVE | C27: A.V + A.VI + A.VII | D27: =-(-SUMIF('1'!$J:$J,BR!$A27,'1'!B:B)*(TB=1)-SUMIF('2'!$J:$J,BR!$A27,'2'!B:B)*(TB=2)+SUMIFS('3'!$C:$C,'3'!$D:$D,BR!D$4,'3'!$G:$G,BR!$A27)*(TB=3)) -> 0 | E27: =+IF(D$21=0,"",D27/D$21) | F27: =-(-SUMIF('1'!$J:$J,BR!$A27,'1'!D:D)*(TB=1)-SUMIF('2'!$J:$J,BR!$A27,'2'!D:D)*(TB=2)+SUMIFS('3'!$C:$C,'3'!$D:$D,BR!F$4,'3'!$G:$G,BR!$A27)*(TB=3)) -> 0 | G27: =+IF(F$21=0,"",F27/F$21) | H27: =-(-SUMIF('1'!$J:$J,BR!$A27,'1'!F:F)*(TB=1)-SUMIF('2'!$J:$J,BR!$A27,'2'!F:F)*(TB=2)+SUMIFS('3'!$C:$C,'3'!$D:$D,BR!H$4,'3'!$G:$G,BR!$A27)*(TB=3)) -> 0 | I27: =+IF(H$21=0,"",H27/H$21) -> 0 | J27: =-(-SUMIF('1'!$J:$J,BR!$A27,'1'!H:H)*(TB=1)-SUMIF('2'!$J:$J,BR!$A27,'2'!H:H)*(TB=2)+SUMIFS('3'!$C:$C,'3'!$D:$D,BR!J$4,'3'!$G:$G,BR!$A27)*(TB=3)) -> 0 | K27: =+IF(J$21 =0,"",J27/J$21) -> 0 | L27: =+A27 -> 120
A28: 130 | B28: RISERVE RIVAL. | C28: A.IV | D28: =-(-SUMIF('1'!$J:$J,BR!$A28,'1'!B:B)*(TB=1)-SUMIF('2'!$J:$J,BR!$A28,'2'!B:B)*(TB=2)+SUMIFS('3'!$C:$C,'3'!$D:$D,BR!D$4,'3'!$G:$G,BR!$A28)*(TB=3)) -> 0 | E28: =+IF(D$21=0,"",D28/D$21) | F28: =-(-SUMIF('1'!$J:$J,BR!$A28,'1'!D:D)*(TB=1)-SUMIF('2'!$J:$J,BR!$A28,'2'!D:D)*(TB=2)+SUMIFS('3'!$C:$C,'3'!$D:$D,BR!F$4,'3'!$G:$G,BR!$A28)*(TB=3)) -> 0 | G28: =+IF(F$21=0,"",F28/F$21) | H28: =-(-SUMIF('1'!$J:$J,BR!$A28,'1'!F:F)*(TB=1)-SUMIF('2'!$J:$J,BR!$A28,'2'!F:F)*(TB=2)+SUMIFS('3'!$C:$C,'3'!$D:$D,BR!H$4,'3'!$G:$G,BR!$A28)*(TB=3)) -> 0 | I28: =+IF(H$21=0,"",H28/H$21) -> 0 | J28: =-(-SUMIF('1'!$J:$J,BR!$A28,'1'!H:H)*(TB=1)-SUMIF('2'!$J:$J,BR!$A28,'2'!H:H)*(TB=2)+SUMIFS('3'!$C:$C,'3'!$D:$D,BR!J$4,'3'!$G:$G,BR!$A28)*(TB=3)) -> 0 | K28: =+IF(J$21 =0,"",J28/J$21) -> 0 | L28: =+A28 -> 130
A29: 140 | B29: UTILI ES. PRECEDENTI | C29: A.VIII | D29: =-(-SUMIF('1'!$J:$J,BR!$A29,'1'!B:B)*(TB=1)-SUMIF('2'!$J:$J,BR!$A29,'2'!B:B)*(TB=2)+SUMIFS('3'!$C:$C,'3'!$D:$D,BR!D$4,'3'!$G:$G,BR!$A29)*(TB=3)) -> 0 | E29: =+IF(D$21=0,"",D29/D$21) | F29: =-(-SUMIF('1'!$J:$J,BR!$A29,'1'!D:D)*(TB=1)-SUMIF('2'!$J:$J,BR!$A29,'2'!D:D)*(TB=2)+SUMIFS('3'!$C:$C,'3'!$D:$D,BR!F$4,'3'!$G:$G,BR!$A29)*(TB=3)) -> 0 | G29: =+IF(F$21=0,"",F29/F$21) | H29: =-(-SUMIF('1'!$J:$J,BR!$A29,'1'!F:F)*(TB=1)-SUMIF('2'!$J:$J,BR!$A29,'2'!F:F)*(TB=2)+SUMIFS('3'!$C:$C,'3'!$D:$D,BR!H$4,'3'!$G:$G,BR!$A29)*(TB=3)) -> 0 | I29: =+IF(H$21=0,"",H29/H$21) -> 0 | J29: =-(-SUMIF('1'!$J:$J,BR!$A29,'1'!H:H)*(TB=1)-SUMIF('2'!$J:$J,BR!$A29,'2'!H:H)*(TB=2)+SUMIFS('3'!$C:$C,'3'!$D:$D,BR!J$4,'3'!$G:$G,BR!$A29)*(TB=3)) -> 122642.08 | K29: =+IF(J$21 =0,"",J29/J$21) -> 0.37162677 | L29: 140
B30: UTILE (PERDITA) | C30: A.IX | D30: =D78 -> 0 | E30: =+IF(D$21=0,"",D30/D$21) | F30: =F78 -> 0 | G30: =+IF(F$21=0,"",F30/F$21) | H30: =H78 -> 124642.08 | I30: =+IF(H$21=0,"",H30/H$21) -> 0.45845643 | J30: =J78 -> 22181.68 | K30: =+IF(J$21 =0,"",J30/J$21) -> 0.067214336
A31: 145 | B31: PATRIMONIO NETTO | C31: A | D31: =SUM(D24:D30) -> 0 | E31: =+IF(D$21=0,"",D31/D$21) | F31: =SUM(F24:F30) -> 0 | G31: =+IF(F$21=0,"",F31/F$21) | H31: =SUM(H24:H30) -> 134642.08 | I31: =+IF(H$21=0,"",H31/H$21) -> 0.49523826 | J31: =SUM(J24:J30) -> 156823.76 | K31: =+IF(J$21 =0,"",J31/J$21) -> 0.47520318
A32: 150 | B32: FINANZIAMENTO SOCI E INFRAGR. | C32: D.3 o dett N.I. | D32: =-(-SUMIF('1'!$J:$J,BR!$A32,'1'!B:B)*(TB=1)-SUMIF('2'!$J:$J,BR!$A32,'2'!B:B)*(TB=2)+SUMIFS('3'!$C:$C,'3'!$D:$D,BR!D$4,'3'!$G:$G,BR!$A32)*(TB=3)) -> 0 | E32: =+IF(D$21=0,"",D32/D$21) | F32: =-(-SUMIF('1'!$J:$J,BR!$A32,'1'!D:D)*(TB=1)-SUMIF('2'!$J:$J,BR!$A32,'2'!D:D)*(TB=2)+SUMIFS('3'!$C:$C,'3'!$D:$D,BR!F$4,'3'!$G:$G,BR!$A32)*(TB=3)) -> 0 | G32: =+IF(F$21=0,"",F32/F$21) | H32: =-(-SUMIF('1'!$J:$J,BR!$A32,'1'!F:F)*(TB=1)-SUMIF('2'!$J:$J,BR!$A32,'2'!F:F)*(TB=2)+SUMIFS('3'!$C:$C,'3'!$D:$D,BR!H$4,'3'!$G:$G,BR!$A32)*(TB=3)) -> 195.75 | I32: =+IF(H$21=0,"",H32/H$21) -> 0.0007200044 | J32: =-(-SUMIF('1'!$J:$J,BR!$A32,'1'!H:H)*(TB=1)-SUMIF('2'!$J:$J,BR!$A32,'2'!H:H)*(TB=2)+SUMIFS('3'!$C:$C,'3'!$D:$D,BR!J$4,'3'!$G:$G,BR!$A32)*(TB=3)) -> -18113.92 | K32: =+IF(J$21 =0,"",J32/J$21) -> -0.054888318 | L32: =+A32 -> 150
A33: 160 | B33: FONDI RISCHI | C33: B | D33: =-(-SUMIF('1'!$J:$J,BR!$A33,'1'!B:B)*(TB=1)-SUMIF('2'!$J:$J,BR!$A33,'2'!B:B)*(TB=2)+SUMIFS('3'!$C:$C,'3'!$D:$D,BR!D$4,'3'!$G:$G,BR!$A33)*(TB=3)) -> 0 | E33: =+IF(D$21=0,"",D33/D$21) | F33: =-(-SUMIF('1'!$J:$J,BR!$A33,'1'!D:D)*(TB=1)-SUMIF('2'!$J:$J,BR!$A33,'2'!D:D)*(TB=2)+SUMIFS('3'!$C:$C,'3'!$D:$D,BR!F$4,'3'!$G:$G,BR!$A33)*(TB=3)) -> 0 | G33: =+IF(F$21=0,"",F33/F$21) | H33: =-(-SUMIF('1'!$J:$J,BR!$A33,'1'!F:F)*(TB=1)-SUMIF('2'!$J:$J,BR!$A33,'2'!F:F)*(TB=2)+SUMIFS('3'!$C:$C,'3'!$D:$D,BR!H$4,'3'!$G:$G,BR!$A33)*(TB=3)) -> 0 | I33: =+IF(H$21=0,"",H33/H$21) -> 0 | J33: =-(-SUMIF('1'!$J:$J,BR!$A33,'1'!H:H)*(TB=1)-SUMIF('2'!$J:$J,BR!$A33,'2'!H:H)*(TB=2)+SUMIFS('3'!$C:$C,'3'!$D:$D,BR!J$4,'3'!$G:$G,BR!$A33)*(TB=3)) -> 0 | K33: =+IF(J$21 =0,"",J33/J$21) -> 0 | L33: =+A33 -> 160
A34: 170 | B34: TFR | C34: C | D34: =-(-SUMIF('1'!$J:$J,BR!$A34,'1'!B:B)*(TB=1)-SUMIF('2'!$J:$J,BR!$A34,'2'!B:B)*(TB=2)+SUMIFS('3'!$C:$C,'3'!$D:$D,BR!D$4,'3'!$G:$G,BR!$A34)*(TB=3)) -> 0 | E34: =+IF(D$21=0,"",D34/D$21) | F34: =-(-SUMIF('1'!$J:$J,BR!$A34,'1'!D:D)*(TB=1)-SUMIF('2'!$J:$J,BR!$A34,'2'!D:D)*(TB=2)+SUMIFS('3'!$C:$C,'3'!$D:$D,BR!F$4,'3'!$G:$G,BR!$A34)*(TB=3)) -> 0 | G34: =+IF(F$21=0,"",F34/F$21) | H34: =-(-SUMIF('1'!$J:$J,BR!$A34,'1'!F:F)*(TB=1)-SUMIF('2'!$J:$J,BR!$A34,'2'!F:F)*(TB=2)+SUMIFS('3'!$C:$C,'3'!$D:$D,BR!H$4,'3'!$G:$G,BR!$A34)*(TB=3)) -> 1530.97 | I34: =+IF(H$21=0,"",H34/H$21) -> 0.0056311884 | J34: =-(-SUMIF('1'!$J:$J,BR!$A34,'1'!H:H)*(TB=1)-SUMIF('2'!$J:$J,BR!$A34,'2'!H:H)*(TB=2)+SUMIFS('3'!$C:$C,'3'!$D:$D,BR!J$4,'3'!$G:$G,BR!$A34)*(TB=3)) -> 1530.97 | K34: =+IF(J$21 =0,"",J34/J$21) -> 0.0046391045 | L34: =+A34 -> 170
A35: 180 | B35: DEBITI VS BANCHE A MEDIO LUNGO T. | C35: D.4 oltre | D35: =-(-SUMIF('1'!$J:$J,BR!$A35,'1'!B:B)*(TB=1)-SUMIF('2'!$J:$J,BR!$A35,'2'!B:B)*(TB=2)+SUMIFS('3'!$C:$C,'3'!$D:$D,BR!D$4,'3'!$G:$G,BR!$A35)*(TB=3)) -> 0 | E35: =+IF(D$21=0,"",D35/D$21) | F35: =-(-SUMIF('1'!$J:$J,BR!$A35,'1'!D:D)*(TB=1)-SUMIF('2'!$J:$J,BR!$A35,'2'!D:D)*(TB=2)+SUMIFS('3'!$C:$C,'3'!$D:$D,BR!F$4,'3'!$G:$G,BR!$A35)*(TB=3)) -> 0 | G35: =+IF(F$21=0,"",F35/F$21) | H35: =-(-SUMIF('1'!$J:$J,BR!$A35,'1'!F:F)*(TB=1)-SUMIF('2'!$J:$J,BR!$A35,'2'!F:F)*(TB=2)+SUMIFS('3'!$C:$C,'3'!$D:$D,BR!H$4,'3'!$G:$G,BR!$A35)*(TB=3)) -> 33897.74 | I35: =+IF(H$21=0,"",H35/H$21) -> 0.1246821 | J35: =-(-SUMIF('1'!$J:$J,BR!$A35,'1'!H:H)*(TB=1)-SUMIF('2'!$J:$J,BR!$A35,'2'!H:H)*(TB=2)+SUMIFS('3'!$C:$C,'3'!$D:$D,BR!J$4,'3'!$G:$G,BR!$A35)*(TB=3)) -> 27040.51 | K35: =+IF(J$21 =0,"",J35/J$21) -> 0.081937433 | L35: =+A35 -> 180
A36: 190 | B36: DEBITI TRIB. E CONTRIB. RATEIZZATI OLTRE ES. | C36: D.4 oltre | D36: =-(-SUMIF('1'!$J:$J,BR!$A36,'1'!B:B)*(TB=1)-SUMIF('2'!$J:$J,BR!$A36,'2'!B:B)*(TB=2)+SUMIFS('3'!$C:$C,'3'!$D:$D,BR!D$4,'3'!$G:$G,BR!$A36)*(TB=3)) -> 0 | E36: =+IF(D$21=0,"",D36/D$21) | F36: =-(-SUMIF('1'!$J:$J,BR!$A36,'1'!D:D)*(TB=1)-SUMIF('2'!$J:$J,BR!$A36,'2'!D:D)*(TB=2)+SUMIFS('3'!$C:$C,'3'!$D:$D,BR!F$4,'3'!$G:$G,BR!$A36)*(TB=3)) -> 0 | G36: =+IF(F$21=0,"",F36/F$21) | H36: =-(-SUMIF('1'!$J:$J,BR!$A36,'1'!F:F)*(TB=1)-SUMIF('2'!$J:$J,BR!$A36,'2'!F:F)*(TB=2)+SUMIFS('3'!$C:$C,'3'!$D:$D,BR!H$4,'3'!$G:$G,BR!$A36)*(TB=3)) -> 0 | I36: =+IF(H$21=0,"",H36/H$21) -> 0 | J36: =-(-SUMIF('1'!$J:$J,BR!$A36,'1'!H:H)*(TB=1)-SUMIF('2'!$J:$J,BR!$A36,'2'!H:H)*(TB=2)+SUMIFS('3'!$C:$C,'3'!$D:$D,BR!J$4,'3'!$G:$G,BR!$A36)*(TB=3)) -> 0 | K36: =+IF(J$21 =0,"",J36/J$21) -> 0 | L36: =+A36 -> 190
A37: 192 | B37: ALTRI DEBITI A M/L | C37: D.4 oltre | D37: =-(-SUMIF('1'!$J:$J,BR!$A37,'1'!B:B)*(TB=1)-SUMIF('2'!$J:$J,BR!$A37,'2'!B:B)*(TB=2)+SUMIFS('3'!$C:$C,'3'!$D:$D,BR!D$4,'3'!$G:$G,BR!$A37)*(TB=3)) -> 0 | E37: =+IF(D$21=0,"",D37/D$21) | F37: =-(-SUMIF('1'!$J:$J,BR!$A37,'1'!D:D)*(TB=1)-SUMIF('2'!$J:$J,BR!$A37,'2'!D:D)*(TB=2)+SUMIFS('3'!$C:$C,'3'!$D:$D,BR!F$4,'3'!$G:$G,BR!$A37)*(TB=3)) -> 0 | G37: =+IF(F$21=0,"",F37/F$21) | H37: =-(-SUMIF('1'!$J:$J,BR!$A37,'1'!F:F)*(TB=1)-SUMIF('2'!$J:$J,BR!$A37,'2'!F:F)*(TB=2)+SUMIFS('3'!$C:$C,'3'!$D:$D,BR!H$4,'3'!$G:$G,BR!$A37)*(TB=3)) -> -69.5 | I37: =+IF(H$21=0,"",H37/H$21) -> -0.00025563374 | J37: =-(-SUMIF('1'!$J:$J,BR!$A37,'1'!H:H)*(TB=1)-SUMIF('2'!$J:$J,BR!$A37,'2'!H:H)*(TB=2)+SUMIFS('3'!$C:$C,'3'!$D:$D,BR!J$4,'3'!$G:$G,BR!$A37)*(TB=3)) -> 0 | K37: =+IF(J$21 =0,"",J37/J$21) -> 0 | L37: =+A37 -> 192
A38: 195 | B38: PASSIVITA' CONSOLIDATE | D38: =SUM(D32:D37) -> 0 | E38: =+IF(D$21=0,"",D38/D$21) | F38: =SUM(F32:F37) -> 0 | G38: =+IF(F$21=0,"",F38/F$21) | H38: =SUM(H32:H37) -> 35554.96 | I38: =+IF(H$21=0,"",H38/H$21) -> 0.13077766 | J38: =SUM(J32:J37) -> 10457.56 | K38: =+IF(J$21 =0,"",J38/J$21) -> 0.03168822
A39: 200 | B39: ACCONTI | C39: D.6 | D39: =-(-SUMIF('1'!$J:$J,BR!$A39,'1'!B:B)*(TB=1)-SUMIF('2'!$J:$J,BR!$A39,'2'!B:B)*(TB=2)+SUMIFS('3'!$C:$C,'3'!$D:$D,BR!D$4,'3'!$G:$G,BR!$A39)*(TB=3)) -> 0 | E39: =+IF(D$21=0,"",D39/D$21) | F39: =-(-SUMIF('1'!$J:$J,BR!$A39,'1'!D:D)*(TB=1)-SUMIF('2'!$J:$J,BR!$A39,'2'!D:D)*(TB=2)+SUMIFS('3'!$C:$C,'3'!$D:$D,BR!F$4,'3'!$G:$G,BR!$A39)*(TB=3)) -> 0 | G39: =+IF(F$21=0,"",F39/F$21) | H39: =-(-SUMIF('1'!$J:$J,BR!$A39,'1'!F:F)*(TB=1)-SUMIF('2'!$J:$J,BR!$A39,'2'!F:F)*(TB=2)+SUMIFS('3'!$C:$C,'3'!$D:$D,BR!H$4,'3'!$G:$G,BR!$A39)*(TB=3)) -> 0 | I39: =+IF(H$21=0,"",H39/H$21) -> 0 | J39: =-(-SUMIF('1'!$J:$J,BR!$A39,'1'!H:H)*(TB=1)-SUMIF('2'!$J:$J,BR!$A39,'2'!H:H)*(TB=2)+SUMIFS('3'!$C:$C,'3'!$D:$D,BR!J$4,'3'!$G:$G,BR!$A39)*(TB=3)) -> 0 | K39: =+IF(J$21 =0,"",J39/J$21) -> 0 | L39: =+A39 -> 200
A40: 210 | B40: FORNITORI | C40: D.7 | D40: =-(-SUMIF('1'!$J:$J,BR!$A40,'1'!B:B)*(TB=1)-SUMIF('2'!$J:$J,BR!$A40,'2'!B:B)*(TB=2)+SUMIFS('3'!$C:$C,'3'!$D:$D,BR!D$4,'3'!$G:$G,BR!$A40)*(TB=3)) -> 0 | E40: =+IF(D$21=0,"",D40/D$21) | F40: =-(-SUMIF('1'!$J:$J,BR!$A40,'1'!D:D)*(TB=1)-SUMIF('2'!$J:$J,BR!$A40,'2'!D:D)*(TB=2)+SUMIFS('3'!$C:$C,'3'!$D:$D,BR!F$4,'3'!$G:$G,BR!$A40)*(TB=3)) -> 0 | G40: =+IF(F$21=0,"",F40/F$21) | H40: =-(-SUMIF('1'!$J:$J,BR!$A40,'1'!F:F)*(TB=1)-SUMIF('2'!$J:$J,BR!$A40,'2'!F:F)*(TB=2)+SUMIFS('3'!$C:$C,'3'!$D:$D,BR!H$4,'3'!$G:$G,BR!$A40)*(TB=3)) -> 60246.41 | I40: =+IF(H$21=0,"",H40/H$21) -> 0.22159734 | J40: =-(-SUMIF('1'!$J:$J,BR!$A40,'1'!H:H)*(TB=1)-SUMIF('2'!$J:$J,BR!$A40,'2'!H:H)*(TB=2)+SUMIFS('3'!$C:$C,'3'!$D:$D,BR!J$4,'3'!$G:$G,BR!$A40)*(TB=3)) -> 133395.41 | K40: =+IF(J$21 =0,"",J40/J$21) -> 0.40421122 | L40: =+A40 -> 210
A41: 220 | B41: DEBITI VS. BANCHE | C41: D.4 entro | D41: =-(-SUMIF('1'!$J:$J,BR!$A41,'1'!B:B)*(TB=1)-SUMIF('2'!$J:$J,BR!$A41,'2'!B:B)*(TB=2)+SUMIFS('3'!$C:$C,'3'!$D:$D,BR!D$4,'3'!$G:$G,BR!$A41)*(TB=3)) -> 0 | E41: =+IF(D$21=0,"",D41/D$21) | F41: =-(-SUMIF('1'!$J:$J,BR!$A41,'1'!D:D)*(TB=1)-SUMIF('2'!$J:$J,BR!$A41,'2'!D:D)*(TB=2)+SUMIFS('3'!$C:$C,'3'!$D:$D,BR!F$4,'3'!$G:$G,BR!$A41)*(TB=3)) -> 0 | G41: =+IF(F$21=0,"",F41/F$21) | H41: =-(-SUMIF('1'!$J:$J,BR!$A41,'1'!F:F)*(TB=1)-SUMIF('2'!$J:$J,BR!$A41,'2'!F:F)*(TB=2)+SUMIFS('3'!$C:$C,'3'!$D:$D,BR!H$4,'3'!$G:$G,BR!$A41)*(TB=3)) -> 0 | I41: =+IF(H$21=0,"",H41/H$21) -> 0 | J41: =-(-SUMIF('1'!$J:$J,BR!$A41,'1'!H:H)*(TB=1)-SUMIF('2'!$J:$J,BR!$A41,'2'!H:H)*(TB=2)+SUMIFS('3'!$C:$C,'3'!$D:$D,BR!J$4,'3'!$G:$G,BR!$A41)*(TB=3)) -> 0 | K41: =+IF(J$21 =0,"",J41/J$21) -> 0 | L41: 80
A42: 230 | B42: DEBITI TRIBUTARI E CONTRIBUTIVI | C42: D.12+D.13 | D42: =-(-SUMIF('1'!$J:$J,BR!$A42,'1'!B:B)*(TB=1)-SUMIF('2'!$J:$J,BR!$A42,'2'!B:B)*(TB=2)+SUMIFS('3'!$C:$C,'3'!$D:$D,BR!D$4,'3'!$G:$G,BR!$A42)*(TB=3)) -> 0 | E42: =+IF(D$21=0,"",D42/D$21) | F42: =-(-SUMIF('1'!$J:$J,BR!$A42,'1'!D:D)*(TB=1)-SUMIF('2'!$J:$J,BR!$A42,'2'!D:D)*(TB=2)+SUMIFS('3'!$C:$C,'3'!$D:$D,BR!F$4,'3'!$G:$G,BR!$A42)*(TB=3)) -> 0 | G42: =+IF(F$21=0,"",F42/F$21) | H42: =-(-SUMIF('1'!$J:$J,BR!$A42,'1'!F:F)*(TB=1)-SUMIF('2'!$J:$J,BR!$A42,'2'!F:F)*(TB=2)+SUMIFS('3'!$C:$C,'3'!$D:$D,BR!H$4,'3'!$G:$G,BR!$A42)*(TB=3)) -> 29545.89 | I42: =+IF(H$21=0,"",H42/H$21) -> 0.1086752 | J42: =-(-SUMIF('1'!$J:$J,BR!$A42,'1'!H:H)*(TB=1)-SUMIF('2'!$J:$J,BR!$A42,'2'!H:H)*(TB=2)+SUMIFS('3'!$C:$C,'3'!$D:$D,BR!J$4,'3'!$G:$G,BR!$A42)*(TB=3)) -> 13246.16 | K42: =+IF(J$21 =0,"",J42/J$21) -> 0.040138161 | L42: 230
A43: 232 | B43: RATEI E RISCONTI PASSIVI | D43: =-(-SUMIF('1'!$J:$J,BR!$A43,'1'!B:B)*(TB=1)-SUMIF('2'!$J:$J,BR!$A43,'2'!B:B)*(TB=2)+SUMIFS('3'!$C:$C,'3'!$D:$D,BR!D$4,'3'!$G:$G,BR!$A43)*(TB=3)) -> 0 | E43: =+IF(D$21=0,"",D43/D$21) | F43: =-(-SUMIF('1'!$J:$J,BR!$A43,'1'!D:D)*(TB=1)-SUMIF('2'!$J:$J,BR!$A43,'2'!D:D)*(TB=2)+SUMIFS('3'!$C:$C,'3'!$D:$D,BR!F$4,'3'!$G:$G,BR!$A43)*(TB=3)) -> 0 | G43: =+IF(F$21=0,"",F43/F$21) | H43: =-(-SUMIF('1'!$J:$J,BR!$A43,'1'!F:F)*(TB=1)-SUMIF('2'!$J:$J,BR!$A43,'2'!F:F)*(TB=2)+SUMIFS('3'!$C:$C,'3'!$D:$D,BR!H$4,'3'!$G:$G,BR!$A43)*(TB=3)) -> 0 | I43: =+IF(H$21=0,"",H43/H$21) -> 0 | J43: =-(-SUMIF('1'!$J:$J,BR!$A43,'1'!H:H)*(TB=1)-SUMIF('2'!$J:$J,BR!$A43,'2'!H:H)*(TB=2)+SUMIFS('3'!$C:$C,'3'!$D:$D,BR!J$4,'3'!$G:$G,BR!$A43)*(TB=3)) -> 0 | K43: =+IF(J$21 =0,"",J43/J$21) -> 0 | L43: 232
...

Sheet Indici
B1: =+Menu!B2 -> 0
B3: =+s -> ALFA SPA | D3: =+D4-EDATE(D4,-12) -> 365 | F3: =+F4-D4 -> 365 | H3: =+H4-F4 -> 366 | J3: =+IF(i="Sì",J4-H4,"") -> 243
B4: INDICI DI BILANCIO | D4: =+EOMONTH(F4,-12) -> 44926 | F4: =+EOMONTH(H4,-12) -> 45291 | G4: qp | H4: =+EOMONTH(DATE(Menu!E10,Menu!K10,1),0) -> 45657 | I4: qp | J4: =+IF(i="Sì",Menu!G12,"") -> 45900 | K4: qp
B6: GRADO DI AUTONOMIA FINANZIARIA | D6: =+IF(Ci=0,"",Pn/Ci) | F6: =+IF(Ci=0,"",Pn/Ci) | G6: =+IF(F6>D6,"p","q") -> q | H6: =+IF(Ci=0,"",Pn/Ci) -> 0.49523826 | I6: =+IF(H6>F6,"p","q") -> q | J6: =+IF(Ci=0,"",Pn/Ci) -> 0.47520318 | K6: =+IF(i="Sì",IF(J6>H6,"p","q"),"") -> q
B7: Valore consigliato : > 20%-25%
B8: Indica quanta parte di 1 euro di finanziamenti proviene da mezzi propri; più è alto e più l’impresa si affida all’autofinanziamento per reperire i fondi da investire negli impieghi elencati tra le attività. Viceversa, più è basso e più l’impresa fa ricorso a fonti esterne per finanziare gli investimenti.
B12: =+IFERROR("Al "&TEXT(D$4,"gg/mm/aaaa")&" il capitale investito risultava coperto da capitale proprio per il "& TEXT(D6,"0,00%")&". Pertanto l'azienda risultava finanziata dai terzi per il "&TEXT(1-D6,"0,00%")&".","")
B13: =IFERROR(+"Al "&TEXT(F4,"gg/mm/aaaa")&" il capitale investito risultava coperto da capitale proprio per il "& TEXT(F6,"0,00%")&". Pertanto l'azienda risultava finanziata dai terzi per il "&TEXT(1-F6,"0,00%")&".","")
B14: =+IFERROR("Al "&TEXT(H4,"gg/mm/aaaa")&" il capitale investito risultava coperto da capitale proprio per il "& TEXT(H6,"0,00%")&". Pertanto l'azienda risultava finanziata dai terzi per il "&TEXT(1-H6,"0,00%")&".","") -> Al 31/12/2024 il capitale investito risultava coperto da capitale proprio per il 49,52%. Pertanto l'azienda risultava finanziata dai terzi per il 50,48%.
B15: =+IFERROR(IF(i="No","","Al "&TEXT(J4,"gg/mm/aaaa")&" il capitale investito risultava coperto da capitale proprio per il "& TEXT(J6,"0,00%")&". Pertanto per ogni euro investito nel capitale "&TEXT((1-J6)*100,"#.###")&" centesimi sono stati messi dai terzi"),"") -> Al 31/08/2025 il capitale investito risultava coperto da capitale proprio per il 47,52%. Pertanto per ogni euro investito nel capitale 52 centesimi sono stati messi dai terzi
B16: GRADO DI ELASTICITA' DEGLI IMPIEGHI | D16: =+IF(Ci=0,"",Ac/Ci) | F16: =+IF(Ci=0,"",Ac/Ci) | G16: =+IF(F16>D16,"p","q") -> q | H16: =+IF(Ci=0,"",Ac/Ci) -> 0.67354806 | I16: =+IF(H16>F16,"p","q") -> q | J16: =+IF(Ci=0,"",Ac/Ci) -> 0.75620776 | K16: =+IF(i="Sì",IF(J16>H16,"p","q"),"") -> p
B17: Valore consigliato : < 20%-40%
B18: Evidenzia il peso degli impieghi a breve rispetto al totale degli investimenti e quanto è elastica la struttura attiva del patrimonio. | I18: GRAFICO
B22: =+"Al "&TEXT(D$4,"gg/mm/aaaa")&" la maggiorparte degli impieghi aziendali è rappresentato da "&IF(D16>0.5," attività circolanti. ("&TEXT(D16,"0,00%")&")"," attività immobilizzate. ("&TEXT(1-D16,"0,00%")&")") -> Al 31/12/2022 la maggiorparte degli impieghi aziendali è rappresentato da attività circolanti. ()
B23: =+"Al "&TEXT(F$4,"gg/mm/aaaa")&" la maggiorparte degli impieghi aziendali è rappresentato da "&IF(F16>0.5," attività circolanti. ("&TEXT(F16,"0,00%")&")"," attività immobilizzate. ("&TEXT(1-F16,"0,00%")&")") -> Al 31/12/2023 la maggiorparte degli impieghi aziendali è rappresentato da attività circolanti. ()
B24: =+"Al "&TEXT(H$4,"gg/mm/aaaa")&" la maggiorparte degli impieghi aziendali è rappresentato da "&IF(H16>0.5," attività circolanti. ("&TEXT(H16,"0,00%")&")"," attività immobilizzate. ("&TEXT(1-H16,"0,00%")&")") -> Al 31/12/2024 la maggiorparte degli impieghi aziendali è rappresentato da attività circolanti. (67,35%)
B25: =+IF(i="No","","Al "&TEXT(J$4,"gg/mm/aaaa")&" la maggiorparte degli impieghi aziendali è rappresentato da "&IF(J16>0.5," attività circolanti. ("&TEXT(J16,"0,00%")&")"," attività immobilizzate. ("&TEXT(1-J16,"0,00%")&")")) -> Al 31/08/2025 la maggiorparte degli impieghi aziendali è rappresentato da attività circolanti. (75,62%)
A26: inv | B26: GRADO DI INDEBITAMENTO CORRENTE | D26: =+IF(Ci=0,"",Pb/Ci) | F26: =+IF(Ci=0,"",Pb/Ci) | G26: =+IF(F26>D26,"p","q") -> q | H26: =+IF(Ci=0,"",Pb/Ci) -> 0.37398408 | I26: =+IF(H26>F26,"p","q") -> q | J26: =+IF(Ci=0,"",Pb/Ci) -> 0.4931086 | K26: =+IF(i="Sì",IF(J26>H26,"p","q"),"") -> p
B27: Valore soglia : < 30% - 40%
B28: Fornisce il peso dell’indebitamento a breve rispetto al totale delle fonti finanziarie. Un elevato indebitamento corrente può essere pericoloso, soprattutto quando finanzia investimenti a lungo termine, oppure quando l’azienda avrà a breve bisogno di investimento per adeguamento impianti e macchinari. | I28: GRAFICO
B32: =IFERROR(+"Al "&TEXT(D$4,"gg/mm/aaaa")&IF(D26>0.4," l'azienda è eccessivamente sbilanciata sui debiti a breve "," l'azienda utilizzava il debito a breve in maniera non prevalente rispetto alle altre fonti di finanziamento ")&". Per ogni 100 euro di fonti finanziarie "&TEXT(D26*100,"#.###")&" sono formati da debiti a breve","")
B33: =IFERROR(+"Al "&TEXT(F$4,"gg/mm/aaaa")&IF(F26>0.4," l'azienda è eccessivamente sbilanciata sui debiti a breve "," l'azienda utilizzava il debito a breve in maniera non prevalente rispetto alle altre fonti di finanziamento ")&". Per ogni 100 euro di fonti finanziarie "&TEXT(F26*100,"#.###")&" sono formati da debiti a breve","")
B34: =+IFERROR("Al "&TEXT(H$4,"gg/mm/aaaa")&IF(H26>0.4," l'azienda è eccessivamente sbilanciata sui debiti a breve "," l'azienda utilizzava il debito a breve in maniera non prevalente rispetto alle altre fonti di finanziamento ")&". Per ogni 100 euro di fonti finanziarie "&TEXT(H26*100,"#.###")&" sono formati da debiti a breve","") -> Al 31/12/2024 l'azienda utilizzava il debito a breve in maniera non prevalente rispetto alle altre fonti di finanziamento . Per ogni 100 euro di fonti finanziarie 37 sono formati da debiti a breve
B35: =+IFERROR(IF(i="No","","Al "&TEXT(J$4,"gg/mm/aaaa")&IF(J26>0.4," l'azienda è eccessivamente sbilanciata sui debiti a breve "," l'azienda utilizzava il debito a breve in maniera non prevalente rispetto alle altre fonti di finanziamento ")&". Per ogni 100 euro di fonti finanziarie "&TEXT(J26*100,"#.###")&" sono formati da debiti a breve"),"") -> Al 31/08/2025 l'azienda è eccessivamente sbilanciata sui debiti a breve . Per ogni 100 euro di fonti finanziarie 49 sono formati da debiti a breve
B36: GRADO DI AMMORTAMENTO | D36: =+IF(Il=0,"",-Fdo/Il) | F36: =+IF(Il=0,"",-Fdo/Il) | G36: =+IF(F36>D36,"p","q") -> q | H36: =+IF(Il=0,"",-Fdo/Il) -> 0.082054976 | I36: =+IF(H36>F36,"p","q") -> q | J36: =+IF(Il=0,"",Fdo/Il) -> -0.17190651 | K36: =+IF(i="Sì",IF(J36>H36,"p","q"),"") -> q
B38: Indica il grado di obsolescenza dell'attivo fisso. Valori a 1 potrebbero connotare un'azienda con necessità di nuovi investimenti per il rinnovo di macchinari. | I38: GRAFICO
B42: =+"Al "&TEXT(D$4,"gg/mm/aaaa")&" le immobilizzazioni erano in media ammortizzate per il "&TEXT(D36,"0,0%") -> Al 31/12/2022 le immobilizzazioni erano in media ammortizzate per il
B43: =+"Al "&TEXT(F$4,"gg/mm/aaaa")&" le immobilizzazioni erano in media ammortizzate per il "&TEXT(F36,"0,0%") -> Al 31/12/2023 le immobilizzazioni erano in media ammortizzate per il
B44: =+"Al "&TEXT(H$4,"gg/mm/aaaa")&" le immobilizzazioni erano in media ammortizzate per il "&TEXT(H36,"0,0%") -> Al 31/12/2024 le immobilizzazioni erano in media ammortizzate per il 8,2%
B45: =+IF(i="No","","Al "&TEXT(J$4,"gg/mm/aaaa")&TEXT(H$4,"gg/mm/aaaa")&" le immobilizzazioni erano in media ammortizzate per il "&TEXT(H36,"0,0%")) -> Al 31/08/202531/12/2024 le immobilizzazioni erano in media ammortizzate per il 8,2%
B46: INCIDENZA DI AMMORTAMENTO | D46: =+IF(Il=0,"",Am/Il) | F46: =+IF(Il=0,"",Am/Il) | G46: =+IF(F46>D46,"p","q") -> q | H46: =+IF(Il=0,"",Am/Il) -> 0.082054976 | I46: =+IF(H46>F46,"p","q") -> q | J46: =+IF(Il=0,"",Am/Il) -> 0.090248069 | K46: =+IF(J46>H46,"p","q") -> p
B48: La differenza tra i valori dell'indice in due periodi, consente di capire la propensione ai nuovi investimenti. La diminuzione dell'indice, contemporaneo ad una diminuzione del grado di ammortamento, potrebbe invece derivare da un cambiamento nella politica d'ammortamento che, se non giustificata e in presenza di risultati economici nn particolarmente positivi, potrebbe gettare dubbi sulla veridicità e la correttezza delle scelte di bilancio. | I48: GRAFICO
B52: =+"Al "&TEXT(D$4,"gg/mm/aaaa")&" gli ammortamenti dell'esercizio erano pari al "&TEXT(D46,"0,0%")&" del valore delle immobilizzazioni lorde" -> Al 31/12/2022 gli ammortamenti dell'esercizio erano pari al del valore delle immobilizzazioni lorde
B53: =+"Al "&TEXT(F$4,"gg/mm/aaaa")&" gli ammortamenti dell'esercizio erano pari al "&TEXT(F46,"0,0%")&" del valore delle immobilizzazioni lorde" -> Al 31/12/2023 gli ammortamenti dell'esercizio erano pari al del valore delle immobilizzazioni lorde
B54: =+"Al "&TEXT(H$4,"gg/mm/aaaa")&" gli ammortamenti dell'esercizio erano pari al "&TEXT(H46,"0,0%")&" del valore delle immobilizzazioni lorde" -> Al 31/12/2024 gli ammortamenti dell'esercizio erano pari al 8,2% del valore delle immobilizzazioni lorde
B55: =+IF(i="No","","Al "&TEXT(J$4,"gg/mm/aaaa")&" gli ammortamenti dell'esercizio erano pari al "&TEXT(H46,"0,0%")&" del valore delle immobilizzazioni lorde") -> Al 31/08/2025 gli ammortamenti dell'esercizio erano pari al 8,2% del valore delle immobilizzazioni lorde
B56: MARGINE DI STRUTTURA | D56: =+IF(Im=0,"",Pn-Im) | F56: =+IF(Im=0,"",Pn-Im) | G56: =+IF(F56>D56,"p","q") -> q | H56: =+IF(Im=0,"",Pn-Im) -> 45888.5 | I56: =+IF(H56>F56,"p","q") -> q | J56: =+IF(Im=0,"",Pn-Im) -> 76368.88 | K56: =+IF(J56>H56,"p","q") -> p
B58: COPERTURA DELLE IMM. CON CAPITALE PROPRIO | D58: =+IF(Im=0,"",Pn/Im) | F58: =+IF(Im=0,"",Pn/Im) | G58: =+IF(F58>D58,"p","q") -> q | H58: =+IF(Im=0,"",Pn/Im) -> 1.5170327 | I58: =+IF(H58>F58,"p","q") -> q | J58: =+IF(Im=0,"",Pn/Im) -> 1.9492138 | K58: =+IF(J58>H58,"p","q") -> p
B59: Valore soglia: 90% - 100%
B60: MARGINE DI SICUREZZA | D60: =+IF(Im=0,"",Pn+Pl-Im) | F60: =+IF(Im=0,"",Pn+Pl-Im) | G60: =+IF(F60>D60,"p","q") -> q | H60: =+IF(Im=0,"",Pn+Pl-Im) -> 81443.46 | I60: =+IF(H60>F60,"p","q") -> q | J60: =+IF(Im=0,"",Pn+Pl-Im) -> 86826.44 | K60: =+IF(J60>H60,"p","q") -> p
...

Sheet DatiI
B1: =+Menu!B2 -> 0
B2: Dr Alessandro Mattavelli ©
B3: Dati di base per gli indici di bilancio | D3: =+s -> ALFA SPA
D4: =+EOMONTH(F4,-12) -> 44926 | F4: =+EOMONTH(H4,-12) -> 45291 | H4: =+EOMONTH(DATE(Menu!E10,Menu!K10,1),0) -> 45657 | J4: =+Menu!G12 -> 45900 | K4: x
A6: Il | B6: Immobilizzazioni Lorde | D6: =+BR!D6+BR!D8+BR!D10 -> 0 | F6: =+BR!F6+BR!F8+BR!F10 -> 0 | H6: =+BR!H6+BR!H8+BR!H10 -> 96687.25 | J6: =+BR!J6+BR!J8+BR!J10 -> 97156.76
A7: Im | B7: I: Immobilizzazioni Nette o Attivo Fisso | D7: =+BR!D86 -> 0 | F7: =+BR!F86 -> 0 | H7: =+BR!H86 -> 88753.58 | J7: =+BR!J86 -> 80454.88
A8: Fdo | B8: Fdo: Fondi di ammortamento | D8: =+BR!D7+BR!D9 -> 0 | F8: =+BR!F7+BR!F9 -> 0 | H8: =+BR!H7+BR!H9 -> -7933.67 | J8: =+BR!J7+BR!J9 -> -16701.88
A9: Ri | B9: R: Rimanenze | D9: =+BR!D87 -> 0 | F9: =+BR!F87 -> 0 | H9: =+BR!H87 -> 1920.13 | J9: =+BR!J87 -> 1920.13
A10: Cr | B10: C: Crediti | D10: =+BR!D17 -> 0 | F10: =+BR!F17 -> 0 | H10: =+BR!H17 -> 63787.09 | J10: =+BR!J17 -> 181136.52
A11: Cli | B11: Cli: Crediti Commerciali | D11: =+BR!D13 -> 0 | F11: =+BR!F13 -> 0 | H11: =+BR!H13 -> 0 | J11: =+BR!J13 -> 137151.13
A12: L | B12: L: Liquidità | D12: =+BR!D19 -> 0 | F12: =+BR!F19 -> 0 | H12: =+BR!H19 -> 117412.54 | J12: =+BR!J19 -> 66502.59
A13: Am | B13: Ammortamenti | D13: =-BR!D67 -> 0 | F13: =-BR!F67 -> 0 | H13: =-BR!H67 -> 7933.67 | J13: =-BR!J67 -> 8768.21
A14: Ac | B14: R + C + L = AC: Attivo Circolante o Corrente | D14: =+BR!D20 -> 0 | F14: =+BR!F20 -> 0 | H14: =+BR!H20 -> 183119.76 | J14: =+BR!J20 -> 249559.24
A15: Ci | B15: Capitale Investito | D15: =+BR!D21 -> 0 | F15: =+BR!F21 -> 0 | H15: =+BR!H21 -> 271873.34 | J15: =+BR!J21 -> 330014.12
A16: Cin | B16: Capitale Investito Netto | D16: =+BR!D94 -> 0 | F16: =+BR!F94 -> 0 | H16: =+BR!H94 -> 51127.28 | J16: =+BR!J94 -> 117361.68
A17: Cini | B17: Capitale Investito Netto Iniziale | F17: =+D16 -> 0 | H17: =+F16 -> 0 | J17: =+H16 -> 51127.28
A18: Pn | B18: PN: Patrimonio Netto o Mezzi Propri | D18: =+BR!D99 -> 0 | F18: =+BR!F99 -> 0 | H18: =+BR!H99 -> 134642.08 | J18: =+BR!J99 -> 156823.76
A19: Pl | B19: PL: Passività Medio Lungo | D19: =+BR!D38 -> 0 | F19: =+BR!F38 -> 0 | H19: =+BR!H38 -> 35554.96 | J19: =+BR!J38 -> 10457.56
A20: Pb | B20: PB: Passività Correnti | D20: =+BR!D46 -> 0 | F20: =+BR!F46 -> 0 | H20: =+BR!H46 -> 101676.3 | J20: =+BR!J46 -> 162732.8
A21: D | B21: PB + PL = D: Debiti o Mezzi di Terzi | D21: =+BR!D47 -> 0 | F21: =+BR!F47 -> 0 | H21: =+BR!H47 -> 137231.26 | J21: =+BR!J47 -> 173190.36
A22: Pfn | B22: PFN = Posizione Finanziaria Netta | D22: =+BR!D105 -> 0 | F22: =+BR!F105 -> 0 | H22: =+BR!H105 -> -83514.8 | J22: =+BR!J105 -> -39462.08
A23: Fa | B23: F= Fatturato | D23: =+BR!D52 -> 0 | F23: =+BR!F52 -> 0 | H23: =+BR!H52 -> 938760.35 | J23: =+BR!J52*J40 -> 767476.65
A24: Co | B24: Co = Consumi | D24: =-(BR!D111+BR!D112+BR!D114) -> 0 | F24: =-(BR!F111+BR!F112+BR!F114) -> 0 | H24: =-(BR!H111+BR!H112+BR!H114) -> 0 | J24: =-(BR!J111+BR!J112+BR!J114)*J40 -> 0
A25: M | B25: M = F-C = Margine di prodotto | D25: =+BR!D59 -> 0 | F25: =+BR!F59 -> 0 | H25: =+BR!H59 -> 854512.35 | J25: =+BR!J59 -> 435817.31
A26: Rn | B26: Reddito Netto | D26: =+BR!D78 -> 0 | F26: =+BR!F78 -> 0 | H26: =+BR!H78 -> 124642.08 | J26: =+BR!J78*J40 -> 33318.161
A27: Ro | B27: Reddito Operativo | D27: =+BR!D69 -> 0 | F27: =+BR!F69 -> 0 | H27: =+BR!H69 -> 184949.43 | J27: =+BR!J69*J40 -> 36282.757
