Workbook
Name Beni: B[Bene]
Name Cat: Gruppi[Cat]
Name ic: DATI!$A$24
Name IR: RIGHT(DATI!$D$24,4)="IRES"
Name p: DATI!$A$1
Name Prat: Tabella3[Nome Pratica]
Name Ris: CalcoloRapido!A$12
Name ristr: Tabelle!$AF$8
Name t: DATI!$E$24
Name Tipi: TipoSoc[TIPO]
Name Tipim: TipoImm[Tipologia]
Name Valfisc: CalcoloRapido!A$8
Name Valnorm: CalcoloRapido!A$6
Name Valnormù: CalcoloRapido!A$6
Name VC: CalcoloRapido!A$7
Name VF: DATI!$E$33
Name VN: DATI!$E$32
Name VOE: CalcoloRapido!A$6
Name VP_1: CalcoloRapido!A$9

Sheet Foglio1
B2: ID | C2: CODTRIB | D2: DESCR
B3: 1 | C3: 1836 | D3: Imposta sostitutiva per l’assegnazione, cessione dei beni ai soci o società trasformate
B4: 2 | C4: 1837 | D4: Imposta sostitutiva sulle riserve in sospensione d’imposta annullate per effetto dell’assegnazione dei beni ai soci o società trasformate
B5: 3 | C5: 1127 | D5: Imposta sostitutiva per l’estromissione dei beni immobili strumentali dall’impresa individuale
B7: =DATI!$D$89 -> F24 DA VERSARE ENTRO IL 30/11/2025 | E7: INT | F7: DEC
B8: Codice tributo (assegnazione, cessione e società trasformate) | D8: =IF(DATI!I34>0,Foglio1!C3,"") -> 1836
B9: Importo 60% cod 1836 | D9: =(IF(DATI!$I$34>0,ROUND(DATI!$I$34*60%,2),"")) -> 5191.2 | E9: =+IFERROR(+IF(D9>0,(+TRUNC(D9)),""),"") -> 5191 | F9: =+IF(D9>0,+RIGHT(D9,2),"") -> ,2
B10: Importo 60% cod 1837 | D10: =IF(DATI!$I$36>0,ROUND(DATI!$I$36*60%,2),0) -> 0 | E10: =+IFERROR(+IF(D10>0,(+TRUNC(D10)),""),"") | F10: =+IF(D10>0,+RIGHT(D10,2),"")
B11: Tot importi | D11: =IFERROR(IF(D8>0,D9+D10,""),0) -> 5191.2 | E11: =+IFERROR(+IF(D11>0,(+TRUNC(D11)),""),"") -> 5191 | F11: =+IF(D11>0,+RIGHT(D11,2),"") -> ,2
B13: =DATI!$D$103 -> F24 DA VERSARE ENTRO IL 30/09/2025
B14: Codice tributo sospensione d'imposte | D14: =IF(DATI!I36>0,Foglio1!C4,"")
B15: Importo 40% cod 1836 | D15: =IF(DATI!$I$34>0,ROUND(DATI!$I$34*40%,2),"") -> 3460.8 | E15: =+IFERROR(+IF(D15>0,(+TRUNC(D15)),""),"") -> 3460 | F15: =+IF(D15>0,+RIGHT(D15,2),"") -> ,8
B16: Importo 40% cod 1837 | D16: =IF(DATI!$I$36>0,ROUND(DATI!$I$36*40%,2),0) -> 0 | E16: =+IFERROR(+IF(D16>0,(+TRUNC(D16)),""),"") | F16: =+IF(D16>0,+RIGHT(D16,2),"")
B17: Tot Importi | D17: =IFERROR(IF(D14>0,D15+D16,""),0) -> 3460.8 | E17: =+IFERROR(+IF(D17>0,(+TRUNC(D17)),""),"") -> 3460 | F17: =+IF(D17>0,+RIGHT(D17,2),"") -> ,8
B19: Anno di riferimento | D19: 2024
B20: Anno di riferimento | D20: =+IF(DATI!I36>0,2017,"")
B21: Anno di riferimento | D21: 2024
B22: Anno di riferimento | D22: =+IF(DATI!I36>0,2018,"")
B25: 0 0 | D25: =+IF(DATI!$I$34>0,Foglio1!B25,"") -> 0 0
B26: 0 0 | D26: =+IF(DATI!$I$36>0,Foglio1!B26,"")
B27: 0 0 | D27: =IF(DATI!I34>0,B27,"") -> 0 0

Sheet DATI
A1: 1
C7: Studio | H7: Cliente
C9: Ind. Studio | H9: Indirizzo
C11: Cap-Città | H11: Cap-Città
C13: P. IVA - C.F. | H13: P. IVA - C.F.
B18: =+"Simulazione operazione di "&B19&" agevolata relativa a beni immobili e mobili registrati di "&I7&" redatta da "&D7 -> Simulazione operazione di Assegnazione agevolata relativa a beni immobili e mobili registrati di redatta da
B19: =+OFFSET(Tabelle!AT1,A1,0) -> Assegnazione
D22: Nome | E22: Alpha SPA | K22: Quadro di controllo
A23: TRUE | D23: Tipo società | E23: Società a responsabilità limitata | G23: IRAP | H23: 0.039 | K23: I soci sono tutti agevolabili | N23: =+IFERROR(SUM(A_1[Agevolabile])/COUNTA(A_1[Nome]),"") -> 1
A24: FALSE | D24: =+"Imposta applicabile alle cessioni: "&VLOOKUP(E23,TipoSoc[],2,0) -> Imposta applicabile alle cessioni: IRES | E24: 0.24 | K24: Gli immobili sono tutti agevolabili | N24: =+IFERROR(SUM(B[Agevolabile])/COUNTA(B[Bene]),"") -> 1
A25: TRUE | D25: Comodo | H25: =+IF(RIGHT(D24,4)="IRES","Dividendi imponibili per il socio","NESSUNA TASSAZIONE DEI DIVIDENDI SUL SOCIO. RILEVA L'EVENTUALE SOTTOZERO") -> Dividendi imponibili per il socio | K25: La ripartizione delle quote somma 100% | N25: =+SUMPRODUCT(A_1[Quota partecipazione al momento dell''operazione],Soci!$A$7:$A$106) -> 100
A26: TRUE | K26: Tutti i beni in tabella sono stati assegnati | N26: =+(Assegnazione!$H$3=Beni!$H$3)*1 -> 1
D27: Aliquota applicabile | E27: =(A25*1+A26*1+A28*1>1)*2.5%+8% -> 0.105 | K27: Il patrimonio netto si è ridotto correttamente | N27: =+OR('Tassazione Soci'!$G$8=VF,p<>1)*1 -> 1
A28: FALSE
B30: Riepilogo Operazione
D32: Totale valore normale o di cessione Beni (A) | E32: =+Assegnazione!M3 -> 302400 | H32: Imposte sostitutive con agevolazione | K32: Imposte indirette | N32: Altre imposte
D33: - Totale valore fiscale (B) | E33: =+Assegnazione!H3 -> 220000 | H33: =+B19 -> Assegnazione
D34: = Base imponibile (A-B) (*) | E34: =+I34/E27 -> 82400 | H34: ="Imposta sostitutiva: "&TEXT(E27,"0,00%") -> Imposta sostitutiva: 10,50% | I34: =+Assegnazione!V3 -> 8652 | K34: IVA | L34: =+Assegnazione!R3 -> 0 | N34: Dirette sui soci | O34: =+'Tassazione Soci'!O12 -> 57200
D35: Effetti contabili | K35: Rettifica della detrazione | L35: =+'Rettifica della detrazione'!F3 -> 50000
D36: Ricavi - Variazioni delle rimanenze | E36: =+(SUMIF(B[Iscritto a Bilancio come],"Rimanenze",B[Valore contabile attribuito])-SUMIF(B[Iscritto a Bilancio come],"Rimanenze",B[Valore netto contabile fiscalmente riconosciuto]))*(p<3) -> 0 | H36: Affrancamento Riserve: 13% | I36: =+'Tassazione Soci'!J9 -> 0 | K36: Registro e IC | L36: =+Assegnazione!Y3+Assegnazione!Z3 -> 600 | N36: IRAP | O36: =+Assegnazione!Q3-SUMPRODUCT(Assegnazione[Agevolabile],Assegnazione[IRAP]) -> 0
D37: =+IF(E37>0,"Plusvalenza","Minusvalenza") -> Minusvalenza | E37: =+(SUMIF(B[Iscritto a Bilancio come],"<>"&"Rimanenze",B[Valore contabile attribuito])-SUMIF(B[Iscritto a Bilancio come],"<>"&"Rimanenze",B[Valore netto contabile fiscalmente riconosciuto]))*(p<3) -> 0 | H37: I rata (30/09/26) | I37: =+(I34+I36)*0.6 -> 5191.2
D38: Effetti sull'imponibile IRES | E38: =+E37*AND(p=2,E37<0) -> 0 | H38: II rata (30/11/26) | I38: =+I37/0.6*0.4 -> 3460.8 | K38: Indirette non agevolate | L38: =+SUMIF(Assegnazione[Agevolabile],0,Assegnazione[Ipotecaria e catastale senza agevolazione])+SUMIF(Assegnazione[Agevolabile],0,Assegnazione[Imposta di registro senza agevolazione]) -> 0 | N38: Dirette non ag. | O38: =+SUMIF(Assegnazione[Agevolabile],0,Assegnazione[Tassazione diretta senza agevolazione])+SUMIF(Assegnazione[Agevolabile],0,Assegnazione[IRAP]) -> 0
D39: Effetti sull'imponibile IRAP | E39: =+(E36<0)*E36+E37*(E37<0) -> 0
D40: Effetto sul ROL | E40: =+E36+E37 -> 0 | K40: Tassazione su finanziamenti | L40: =+'Tassazione Soci'!J11 -> 0
D41: Futura tassazione della distribuzione delle riserve generate | J41: COSTO OPERAZIONE CON AGEVOLAZIONE | L41: =+I34+I36+L34+L35+L36+L38+O34+O36+O38+L40 -> 116452
D42: Riserve generate | E42: =+(E36+E37)*(SUM(E36:E37)>0) -> 0 | J42: COSTO CESSIONE SENZA AGEVOLAZIONE | L42: =+Assegnazione!U3 -> 34520
D43: Riserve che NON daranno luogo a tassazione | E43: =+MIN(E42,E34) -> 0 | J43: RISPARMIO | L43: =+L42-L41 -> -81932
D44: Riserve che daranno luogo a tassazione | E44: =+E42-E43 -> 0 | J44: Valore normale assegnato | L44: =+Beni!G3 -> 300000
S45: =+IF(L44=0,"","Costo operazione: "&TEXT(L41/L44,"0,0%")&" su valore normale assegnato pari a "&TEXT(L44,"€ 0.000"))&IF(L43>0," Conseguendo un risparmio di €"&TEXT(L43,"#.##0"),"") -> Costo operazione: 38,8% su valore normale assegnato pari a € 300.000
D46: (*) I componenti positivi sono assoggettati a imposta sostitutiva al netto dei componenti negativi realizzati solo su beni merce
H64: =+Assegnazione!V3/DATI!E27-DATI!I64 -> 82400 | I64: =+SUMIF(Assegnazione[Tipologia],"Altri Beni",Assegnazione[Imposta sostitutiva])/E27 -> 0 | K64: =+IF(E27>8%,"X","") -> X | N64: =+I34 -> 8652 | O64: =+N64*0.6 -> 5191.2
H65: =+'Tassazione Soci'!J7 -> 0 | N65: =+H65*13% -> 0 | O65: =+N65*0.6 -> 0
H68: costo normale beni immobili | I68: c. fiscalmente riconosciuto beni immobili | J68: differenza | L68: imponibile RQ84
H69: =+SUMIF(B[Tipologia],"<>Altri Beni",B[Valore normale]) -> 300000 | I69: =+SUMIF(B[Tipologia],"<>Altri Beni",B[Valore netto contabile fiscalmente riconosciuto]) -> 220000 | J69: =+H69-I69 -> 80000 | L69: =+H69-H73 -> 300000
H72: costo normale beni mobili | I72: c. fiscalmente riconosciuto beni mobili | J72: differenza | L72: imp sost L 208/15 | N72: imp sost L 232/16
H73: =+SUMIF(B[Tipologia],"Altri Beni",B[Valore normale]) -> 0 | I73: =+SUMIF(B[Tipologia],"Altri Beni",B[Valore netto contabile fiscalmente riconosciuto]) -> 0 | J73: =+H73-I73 -> 0 | N73: =I34 -> 8652
H75: riserve in sospensione annullate | L75: imp sost L 208/15 ris in sosp | N75: imp sost L 232/16 ris in sosp
H76: =+'Tassazione Soci'!D8 -> 0 | N76: ='Tassazione Soci'!J9 -> 0
D77: MODELLO REDDITI 2025
D89: F24 DA VERSARE ENTRO IL 30/11/2025
...

Sheet Società
A5: Dati di bilancio | B5: Ante operazioni | D5: Valori annullati | F5: Valori residui
A6: Capitale sociale | B6: 800000 | D6: =+'Tassazione Soci'!E9 -> 0 | F6: =+B6-D6 -> 800000
A7: Riserve di utili | B7: 600000 | D7: =+'Tassazione Soci'!B9 -> 220000 | F7: =+B7-D7 -> 380000
A8: Riserve di capitale | B8: 500000 | D8: =+'Tassazione Soci'!C9 -> 0 | F8: =+B8-D8 -> 500000
A9: Ris. in sosp. di imposta | B9: 100000 | D9: =+'Tassazione Soci'!D9 -> 0 | F9: =+B9-D9 -> 100000
A10: PATRIMONIO NETTO | B10: =SUM(B6:B9) -> 2000000 | D10: =SUM(D6:D9) -> 220000 | F10: =SUM(F6:F9) -> 1780000

Sheet Soci
B3: In questa e nelle prossime tabelle compilare le sole colonne con l'intestazione scritta in nero.
B4: Soci (o nudi proprietari) al | C4: 45930 | E4: =+SUM(A_1[Quota partecipazione al momento dell''operazione]) -> 1 | F4: =+SUM(A_1[Costo della Partecipaz.]) -> 200000 | G4: =+IF(p=3,IF(COUNTIF(A_1[Agevolabile],0)=0,"","Risultano nuovi soci rispetto alla compagine al 30/09/2015: trasformazione non possibile"),"")
B5: Nome | C5: Data iscrizione libro soci | D5: Tipo (PF) | E5: Quota partecipazione al momento dell'operazione | F5: Costo della Partecipaz. | G5: Aliquota Marginale socio/Tassazione sostitutiva | H5: QUOTA TAX DIVIDENDI (100%-58,14%-5%-40%) | I5: Agevolabile
A6: 100 | B6: Socio X | C6: 45292 | D6: PF | E6: 0.5 | F6: 100000 | G6: 0.26 | H6: 1 | I6: =+IF(A_1[[#This Row],[Nome]]="","",(A_1[[#This Row],[Data iscrizione libro soci]]<=$C$4)*1) -> 1
A7: 100 | B7: Socio Y | C7: 45930 | D7: PF | E7: 0.5 | F7: 100000 | G7: 0.26 | H7: 1 | I7: =+IF(A_1[[#This Row],[Nome]]="","",(A_1[[#This Row],[Data iscrizione libro soci]]<=$C$4)*1) -> 1
A8: 100 | I8: =+IF(A_1[[#This Row],[Nome]]="","",(A_1[[#This Row],[Data iscrizione libro soci]]<=$C$4)*1)
A9: 100 | I9: =+IF(A_1[[#This Row],[Nome]]="","",(A_1[[#This Row],[Data iscrizione libro soci]]<=$C$4)*1)
A10: 100 | I10: =+IF(A_1[[#This Row],[Nome]]="","",(A_1[[#This Row],[Data iscrizione libro soci]]<=$C$4)*1)
A11: 100 | I11: =+IF(A_1[[#This Row],[Nome]]="","",(A_1[[#This Row],[Data iscrizione libro soci]]<=$C$4)*1)
A12: 100 | I12: =+IF(A_1[[#This Row],[Nome]]="","",(A_1[[#This Row],[Data iscrizione libro soci]]<=$C$4)*1)
A13: 100 | I13: =+IF(A_1[[#This Row],[Nome]]="","",(A_1[[#This Row],[Data iscrizione libro soci]]<=$C$4)*1)
A14: 100 | I14: =+IF(A_1[[#This Row],[Nome]]="","",(A_1[[#This Row],[Data iscrizione libro soci]]<=$C$4)*1)
A15: 100 | I15: =+IF(A_1[[#This Row],[Nome]]="","",(A_1[[#This Row],[Data iscrizione libro soci]]<=$C$4)*1)
A16: 100 | I16: =+IF(A_1[[#This Row],[Nome]]="","",(A_1[[#This Row],[Data iscrizione libro soci]]<=$C$4)*1)
A17: 100 | I17: =+IF(A_1[[#This Row],[Nome]]="","",(A_1[[#This Row],[Data iscrizione libro soci]]<=$C$4)*1)
A18: 100 | I18: =+IF(A_1[[#This Row],[Nome]]="","",(A_1[[#This Row],[Data iscrizione libro soci]]<=$C$4)*1)
A19: 100 | I19: =+IF(A_1[[#This Row],[Nome]]="","",(A_1[[#This Row],[Data iscrizione libro soci]]<=$C$4)*1)
... A105: 100 | I105: =+IF(A_1[[#This Row],[Nome]]="","",(A_1[[#This Row],[Data iscrizione libro soci]]<=$C$4)*1)
A106: 100

Sheet Beni
A3: Beni assegnati | G3: =SUM(B[Valore normale]) -> 300000 | H3: =SUM(B[Valore netto contabile fiscalmente riconosciuto]) -> 220000 | I3: =SUM(B[Valore contabile attribuito]) -> 220000 | N3: =SUM(B[Valore catastale]) -> 302400 | Q3: =SUM(B[Valore ai fini dell''imposta di registro]) -> 302400 | R3: =+(SUM(B[Imponibile Imposta sostitutiva])>0)*1*SUM(B[Imponibile Imposta sostitutiva]) -> 82400 | S3: =SUM(B[Iva se dovuta]) -> 0 | T3: =SUM(B[Imposta di registro (fissa + prop) senza agevolazione]) -> 200 | U3: =SUM(B[Ipotecaria e catastale senza agevolazione]) -> 12000 | V3: =SUM(B[Imposta di registro in misura fissa agevolata]) -> 200 | W3: =SUM(B[Imposta di registro prop. Agevolata]) -> 0 | X3: =SUM(B[Totale imposta di registro])*(p<3)+200*(p=3) -> 200 | Y3: =SUM(B[Ipotecaria catastale agevolata]) -> 400
A4: Bene | B4: Anno Acquisizione o ultimazione | C4: Tipologia | D4: Strumentale per destinazione | E4: Categoria Catastale | F4: Rendita catastale | G4: Valore normale | H4: Valore netto contabile fiscalmente riconosciuto | I4: Valore contabile attribuito | J4: Valore inserito manualmente | K4: Iscritto a Bilancio come | L4: Imponibile Iva | M4: Opzione per prezzo-valore (s/n) | N4: Valore catastale | O4: Agevolabile | P4: Valore ai fini dell'atto | Q4: Valore ai fini dell'imposta di registro | R4: Imponibile Imposta sostitutiva | S4: Iva se dovuta | T4: Imposta di registro (fissa + prop) senza agevolazione | U4: Ipotecaria e catastale senza agevolazione | V4: Imposta di registro in misura fissa agevolata | W4: Imposta di registro prop. Agevolata | X4: Totale imposta di registro | Y4: Ipotecaria catastale agevolata | Z4: Fattura
A5: Capannone | B5: 2024 | C5: Immobili Strumentali >5 anni o no Iva per opzione | D5: No | E5: D | F5: 4800 | G5: 300000 | H5: 220000 | I5: 220000 | K5: Immobilizzazioni | M5: s | N5: =+IF(B[[#This Row],[Categoria Catastale]]="",0,VLOOKUP(B[[#This Row],[Categoria Catastale]],Gruppi[],6,0)*B[[#This Row],[Rendita catastale]]) -> 302400 | O5: =+IF(A5="","",IF(D5="Sì",0,1)) -> 1 | P5: =+IF(B[[#This Row],[Valore inserito manualmente]]>0,B[[#This Row],[Valore inserito manualmente]],B[[#This Row],[Valore catastale]]) -> 302400 | Q5: =+IF(OR(B[[#This Row],[Opzione per prezzo-valore (s/n)]]="s",B[[#This Row],[Valore inserito manualmente]]=0),B[[#This Row],[Valore catastale]],B[[#This Row],[Valore inserito manualmente]]) -> 302400 | R5: =IF(OR(B[[#This Row],[Valore ai fini dell''atto]]>B[[#This Row],[Valore netto contabile fiscalmente riconosciuto]],B[[#This Row],[Iscritto a Bilancio come]]="Rimanenze"),B[[#This Row],[Valore ai fini dell''atto]]-B[[#This Row],[Valore netto contabile fiscalmente riconosciuto]],0) -> 82400 | S5: =+IF(B[[#This Row],[Bene]]="","",VLOOKUP(B[[#This Row],[Tipologia]],TipoImm[],3,0)*B[[#This Row],[Imponibile Iva]]) -> 0 | T5: =+IF(B[[#This Row],[Bene]]="","",VLOOKUP(B[[#This Row],[Tipologia]],TipoImm[],6,0)*B[[#This Row],[Valore catastale]]+VLOOKUP(B[[#This Row],[Tipologia]],TipoImm[],4,0)) -> 200 | U5: =+IF(B[[#This Row],[Bene]]="","",VLOOKUP(B[[#This Row],[Tipologia]],TipoImm[],8,0)*B[[#This Row],[Valore normale]]+VLOOKUP(B[[#This Row],[Tipologia]],TipoImm[],9,0)) -> 12000 | V5: =+IF(OR(B[[#This Row],[Bene]]="",B[[#This Row],[Agevolabile]]=0),0,VLOOKUP(B[[#This Row],[Tipologia]],TipoImm[],5,0)) -> 200 | W5: =+IF(B[[#This Row],[Bene]]="",0,IFERROR(MAX(1000,IF(OR(B[[#This Row],[Bene]]="",B[[#This Row],[Agevolabile]]=0,B[[#This Row],[Bene]]=0),0,VLOOKUP(B[[#This Row],[Tipologia]],TipoImm[],7,0))*B[[#This Row],[Valore catastale]]),""))*(IFERROR(VLOOKUP(B[[#This Row],[Tipologia]],TipoImm[],7,0),0)>0) -> 0 | X5: =SUM(B[[#This Row],[Imposta di registro in misura fissa agevolata]:[Imposta di registro prop. Agevolata]]) -> 200 | Y5: =+IF(B[[#This Row],[Bene]]="",0,VLOOKUP(B[[#This Row],[Tipologia]],TipoImm[],10,0)) -> 400 | Z5: =+IF(p=3,"",IF(B[[#This Row],[Tipologia]]="","",VLOOKUP(B[[#This Row],[Tipologia]],TipoImm[],MATCH($Z$4,Tabelle!$AF$1:$AR$1,0),0))) -> Esente art. 10 c.1 n 8 ter
N6: =+IF(B[[#This Row],[Categoria Catastale]]="",0,VLOOKUP(B[[#This Row],[Categoria Catastale]],Gruppi[],6,0)*B[[#This Row],[Rendita catastale]]) -> 0 | O6: =+IF(A6="","",IF(D6="Sì",0,1)) | P6: =+IF(B[[#This Row],[Valore inserito manualmente]]>0,B[[#This Row],[Valore inserito manualmente]],B[[#This Row],[Valore catastale]]) -> 0 | Q6: =+IF(OR(B[[#This Row],[Opzione per prezzo-valore (s/n)]]="s",B[[#This Row],[Valore inserito manualmente]]=0),B[[#This Row],[Valore catastale]],B[[#This Row],[Valore inserito manualmente]]) -> 0 | R6: =IF(OR(B[[#This Row],[Valore ai fini dell''atto]]>B[[#This Row],[Valore netto contabile fiscalmente riconosciuto]],B[[#This Row],[Iscritto a Bilancio come]]="Rimanenze"),B[[#This Row],[Valore ai fini dell''atto]]-B[[#This Row],[Valore netto contabile fiscalmente riconosciuto]],0) -> 0 | S6: =+IF(B[[#This Row],[Bene]]="","",VLOOKUP(B[[#This Row],[Tipologia]],TipoImm[],3,0)*B[[#This Row],[Imponibile Iva]]) | T6: =+IF(B[[#This Row],[Bene]]="","",VLOOKUP(B[[#This Row],[Tipologia]],TipoImm[],6,0)*B[[#This Row],[Valore catastale]]+VLOOKUP(B[[#This Row],[Tipologia]],TipoImm[],4,0)) | U6: =+IF(B[[#This Row],[Bene]]="","",VLOOKUP(B[[#This Row],[Tipologia]],TipoImm[],8,0)*B[[#This Row],[Valore normale]]+VLOOKUP(B[[#This Row],[Tipologia]],TipoImm[],9,0)) | V6: =+IF(OR(B[[#This Row],[Bene]]="",B[[#This Row],[Agevolabile]]=0),0,VLOOKUP(B[[#This Row],[Tipologia]],TipoImm[],5,0)) -> 0 | W6: =+IF(B[[#This Row],[Bene]]="",0,IFERROR(MAX(1000,IF(OR(B[[#This Row],[Bene]]="",B[[#This Row],[Agevolabile]]=0,B[[#This Row],[Bene]]=0),0,VLOOKUP(B[[#This Row],[Tipologia]],TipoImm[],7,0))*B[[#This Row],[Valore catastale]]),""))*(IFERROR(VLOOKUP(B[[#This Row],[Tipologia]],TipoImm[],7,0),0)>0) -> 0 | X6: =SUM(B[[#This Row],[Imposta di registro in misura fissa agevolata]:[Imposta di registro prop. Agevolata]]) -> 0 | Y6: =+IF(B[[#This Row],[Bene]]="",0,VLOOKUP(B[[#This Row],[Tipologia]],TipoImm[],10,0)) -> 0 | Z6: =+IF(p=3,"",IF(B[[#This Row],[Tipologia]]="","",VLOOKUP(B[[#This Row],[Tipologia]],TipoImm[],MATCH($Z$4,Tabelle!$AF$1:$AR$1,0),0)))
N7: =+IF(B[[#This Row],[Categoria Catastale]]="",0,VLOOKUP(B[[#This Row],[Categoria Catastale]],Gruppi[],6,0)*B[[#This Row],[Rendita catastale]]) -> 0 | O7: =+IF(A7="","",IF(D7="Sì",0,1)) | P7: =+IF(B[[#This Row],[Valore inserito manualmente]]>0,B[[#This Row],[Valore inserito manualmente]],B[[#This Row],[Valore catastale]]) -> 0 | Q7: =+IF(OR(B[[#This Row],[Opzione per prezzo-valore (s/n)]]="s",B[[#This Row],[Valore inserito manualmente]]=0),B[[#This Row],[Valore catastale]],B[[#This Row],[Valore inserito manualmente]]) -> 0 | R7: =IF(OR(B[[#This Row],[Valore ai fini dell''atto]]>B[[#This Row],[Valore netto contabile fiscalmente riconosciuto]],B[[#This Row],[Iscritto a Bilancio come]]="Rimanenze"),B[[#This Row],[Valore ai fini dell''atto]]-B[[#This Row],[Valore netto contabile fiscalmente riconosciuto]],0) -> 0 | S7: =+IF(B[[#This Row],[Bene]]="","",VLOOKUP(B[[#This Row],[Tipologia]],TipoImm[],3,0)*B[[#This Row],[Imponibile Iva]]) | T7: =+IF(B[[#This Row],[Bene]]="","",VLOOKUP(B[[#This Row],[Tipologia]],TipoImm[],6,0)*B[[#This Row],[Valore catastale]]+VLOOKUP(B[[#This Row],[Tipologia]],TipoImm[],4,0)) | U7: =+IF(B[[#This Row],[Bene]]="","",VLOOKUP(B[[#This Row],[Tipologia]],TipoImm[],8,0)*B[[#This Row],[Valore normale]]+VLOOKUP(B[[#This Row],[Tipologia]],TipoImm[],9,0)) | V7: =+IF(OR(B[[#This Row],[Bene]]="",B[[#This Row],[Agevolabile]]=0),0,VLOOKUP(B[[#This Row],[Tipologia]],TipoImm[],5,0)) -> 0 | W7: =+IF(B[[#This Row],[Bene]]="",0,IFERROR(MAX(1000,IF(OR(B[[#This Row],[Bene]]="",B[[#This Row],[Agevolabile]]=0,B[[#This Row],[Bene]]=0),0,VLOOKUP(B[[#This Row],[Tipologia]],TipoImm[],7,0))*B[[#This Row],[Valore catastale]]),""))*(IFERROR(VLOOKUP(B[[#This Row],[Tipologia]],TipoImm[],7,0),0)>0) -> 0 | X7: =SUM(B[[#This Row],[Imposta di registro in misura fissa agevolata]:[Imposta di registro prop. Agevolata]]) -> 0 | Y7: =+IF(B[[#This Row],[Bene]]="",0,VLOOKUP(B[[#This Row],[Tipologia]],TipoImm[],10,0)) -> 0 | Z7: =+IF(p=3,"",IF(B[[#This Row],[Tipologia]]="","",VLOOKUP(B[[#This Row],[Tipologia]],TipoImm[],MATCH($Z$4,Tabelle!$AF$1:$AR$1,0),0)))
N8: =+IF(B[[#This Row],[Categoria Catastale]]="",0,VLOOKUP(B[[#This Row],[Categoria Catastale]],Gruppi[],6,0)*B[[#This Row],[Rendita catastale]]) -> 0 | O8: =+IF(A8="","",IF(D8="Sì",0,1)) | P8: =+IF(B[[#This Row],[Valore inserito manualmente]]>0,B[[#This Row],[Valore inserito manualmente]],B[[#This Row],[Valore catastale]]) -> 0 | Q8: =+IF(OR(B[[#This Row],[Opzione per prezzo-valore (s/n)]]="s",B[[#This Row],[Valore inserito manualmente]]=0),B[[#This Row],[Valore catastale]],B[[#This Row],[Valore inserito manualmente]]) -> 0 | R8: =IF(OR(B[[#This Row],[Valore ai fini dell''atto]]>B[[#This Row],[Valore netto contabile fiscalmente riconosciuto]],B[[#This Row],[Iscritto a Bilancio come]]="Rimanenze"),B[[#This Row],[Valore ai fini dell''atto]]-B[[#This Row],[Valore netto contabile fiscalmente riconosciuto]],0) -> 0 | S8: =+IF(B[[#This Row],[Bene]]="","",VLOOKUP(B[[#This Row],[Tipologia]],TipoImm[],3,0)*B[[#This Row],[Imponibile Iva]]) | T8: =+IF(B[[#This Row],[Bene]]="","",VLOOKUP(B[[#This Row],[Tipologia]],TipoImm[],6,0)*B[[#This Row],[Valore catastale]]+VLOOKUP(B[[#This Row],[Tipologia]],TipoImm[],4,0)) | U8: =+IF(B[[#This Row],[Bene]]="","",VLOOKUP(B[[#This Row],[Tipologia]],TipoImm[],8,0)*B[[#This Row],[Valore normale]]+VLOOKUP(B[[#This Row],[Tipologia]],TipoImm[],9,0)) | V8: =+IF(OR(B[[#This Row],[Bene]]="",B[[#This Row],[Agevolabile]]=0),0,VLOOKUP(B[[#This Row],[Tipologia]],TipoImm[],5,0)) -> 0 | W8: =+IF(B[[#This Row],[Bene]]="",0,IFERROR(MAX(1000,IF(OR(B[[#This Row],[Bene]]="",B[[#This Row],[Agevolabile]]=0,B[[#This Row],[Bene]]=0),0,VLOOKUP(B[[#This Row],[Tipologia]],TipoImm[],7,0))*B[[#This Row],[Valore catastale]]),""))*(IFERROR(VLOOKUP(B[[#This Row],[Tipologia]],TipoImm[],7,0),0)>0) -> 0 | X8: =SUM(B[[#This Row],[Imposta di registro in misura fissa agevolata]:[Imposta di registro prop. Agevolata]]) -> 0 | Y8: =+IF(B[[#This Row],[Bene]]="",0,VLOOKUP(B[[#This Row],[Tipologia]],TipoImm[],10,0)) -> 0 | Z8: =+IF(p=3,"",IF(B[[#This Row],[Tipologia]]="","",VLOOKUP(B[[#This Row],[Tipologia]],TipoImm[],MATCH($Z$4,Tabelle!$AF$1:$AR$1,0),0)))
N9: =+IF(B[[#This Row],[Categoria Catastale]]="",0,VLOOKUP(B[[#This Row],[Categoria Catastale]],Gruppi[],6,0)*B[[#This Row],[Rendita catastale]]) -> 0 | O9: =+IF(A9="","",IF(D9="Sì",0,1)) | P9: =+IF(B[[#This Row],[Valore inserito manualmente]]>0,B[[#This Row],[Valore inserito manualmente]],B[[#This Row],[Valore catastale]]) -> 0 | Q9: =+IF(OR(B[[#This Row],[Opzione per prezzo-valore (s/n)]]="s",B[[#This Row],[Valore inserito manualmente]]=0),B[[#This Row],[Valore catastale]],B[[#This Row],[Valore inserito manualmente]]) -> 0 | R9: =IF(OR(B[[#This Row],[Valore ai fini dell''atto]]>B[[#This Row],[Valore netto contabile fiscalmente riconosciuto]],B[[#This Row],[Iscritto a Bilancio come]]="Rimanenze"),B[[#This Row],[Valore ai fini dell''atto]]-B[[#This Row],[Valore netto contabile fiscalmente riconosciuto]],0) -> 0 | S9: =+IF(B[[#This Row],[Bene]]="","",VLOOKUP(B[[#This Row],[Tipologia]],TipoImm[],3,0)*B[[#This Row],[Imponibile Iva]]) | T9: =+IF(B[[#This Row],[Bene]]="","",VLOOKUP(B[[#This Row],[Tipologia]],TipoImm[],6,0)*B[[#This Row],[Valore catastale]]+VLOOKUP(B[[#This Row],[Tipologia]],TipoImm[],4,0)) | U9: =+IF(B[[#This Row],[Bene]]="","",VLOOKUP(B[[#This Row],[Tipologia]],TipoImm[],8,0)*B[[#This Row],[Valore normale]]+VLOOKUP(B[[#This Row],[Tipologia]],TipoImm[],9,0)) | V9: =+IF(OR(B[[#This Row],[Bene]]="",B[[#This Row],[Agevolabile]]=0),0,VLOOKUP(B[[#This Row],[Tipologia]],TipoImm[],5,0)) -> 0 | W9: =+IF(B[[#This Row],[Bene]]="",0,IFERROR(MAX(1000,IF(OR(B[[#This Row],[Bene]]="",B[[#This Row],[Agevolabile]]=0,B[[#This Row],[Bene]]=0),0,VLOOKUP(B[[#This Row],[Tipologia]],TipoImm[],7,0))*B[[#This Row],[Valore catastale]]),""))*(IFERROR(VLOOKUP(B[[#This Row],[Tipologia]],TipoImm[],7,0),0)>0) -> 0 | X9: =SUM(B[[#This Row],[Imposta di registro in misura fissa agevolata]:[Imposta di registro prop. Agevolata]]) -> 0 | Y9: =+IF(B[[#This Row],[Bene]]="",0,VLOOKUP(B[[#This Row],[Tipologia]],TipoImm[],10,0)) -> 0 | Z9: =+IF(p=3,"",IF(B[[#This Row],[Tipologia]]="","",VLOOKUP(B[[#This Row],[Tipologia]],TipoImm[],MATCH($Z$4,Tabelle!$AF$1:$AR$1,0),0)))
N10: =+IF(B[[#This Row],[Categoria Catastale]]="",0,VLOOKUP(B[[#This Row],[Categoria Catastale]],Gruppi[],6,0)*B[[#This Row],[Rendita catastale]]) -> 0 | O10: =+IF(A10="","",IF(D10="Sì",0,1)) | P10: =+IF(B[[#This Row],[Valore inserito manualmente]]>0,B[[#This Row],[Valore inserito manualmente]],B[[#This Row],[Valore catastale]]) -> 0 | Q10: =+IF(OR(B[[#This Row],[Opzione per prezzo-valore (s/n)]]="s",B[[#This Row],[Valore inserito manualmente]]=0),B[[#This Row],[Valore catastale]],B[[#This Row],[Valore inserito manualmente]]) -> 0 | R10: =IF(OR(B[[#This Row],[Valore ai fini dell''atto]]>B[[#This Row],[Valore netto contabile fiscalmente riconosciuto]],B[[#This Row],[Iscritto a Bilancio come]]="Rimanenze"),B[[#This Row],[Valore ai fini dell''atto]]-B[[#This Row],[Valore netto contabile fiscalmente riconosciuto]],0) -> 0 | S10: =+IF(B[[#This Row],[Bene]]="","",VLOOKUP(B[[#This Row],[Tipologia]],TipoImm[],3,0)*B[[#This Row],[Imponibile Iva]]) | T10: =+IF(B[[#This Row],[Bene]]="","",VLOOKUP(B[[#This Row],[Tipologia]],TipoImm[],6,0)*B[[#This Row],[Valore catastale]]+VLOOKUP(B[[#This Row],[Tipologia]],TipoImm[],4,0)) | U10: =+IF(B[[#This Row],[Bene]]="","",VLOOKUP(B[[#This Row],[Tipologia]],TipoImm[],8,0)*B[[#This Row],[Valore normale]]+VLOOKUP(B[[#This Row],[Tipologia]],TipoImm[],9,0)) | V10: =+IF(OR(B[[#This Row],[Bene]]="",B[[#This Row],[Agevolabile]]=0),0,VLOOKUP(B[[#This Row],[Tipologia]],TipoImm[],5,0)) -> 0 | W10: =+IF(B[[#This Row],[Bene]]="",0,IFERROR(MAX(1000,IF(OR(B[[#This Row],[Bene]]="",B[[#This Row],[Agevolabile]]=0,B[[#This Row],[Bene]]=0),0,VLOOKUP(B[[#This Row],[Tipologia]],TipoImm[],7,0))*B[[#This Row],[Valore catastale]]),""))*(IFERROR(VLOOKUP(B[[#This Row],[Tipologia]],TipoImm[],7,0),0)>0) -> 0 | X10: =SUM(B[[#This Row],[Imposta di registro in misura fissa agevolata]:[Imposta di registro prop. Agevolata]]) -> 0 | Y10: =+IF(B[[#This Row],[Bene]]="",0,VLOOKUP(B[[#This Row],[Tipologia]],TipoImm[],10,0)) -> 0 | Z10: =+IF(p=3,"",IF(B[[#This Row],[Tipologia]]="","",VLOOKUP(B[[#This Row],[Tipologia]],TipoImm[],MATCH($Z$4,Tabelle!$AF$1:$AR$1,0),0)))
N11: =+IF(B[[#This Row],[Categoria Catastale]]="",0,VLOOKUP(B[[#This Row],[Categoria Catastale]],Gruppi[],6,0)*B[[#This Row],[Rendita catastale]]) -> 0 | O11: =+IF(A11="","",IF(D11="Sì",0,1)) | P11: =+IF(B[[#This Row],[Valore inserito manualmente]]>0,B[[#This Row],[Valore inserito manualmente]],B[[#This Row],[Valore catastale]]) -> 0 | Q11: =+IF(OR(B[[#This Row],[Opzione per prezzo-valore (s/n)]]="s",B[[#This Row],[Valore inserito manualmente]]=0),B[[#This Row],[Valore catastale]],B[[#This Row],[Valore inserito manualmente]]) -> 0 | R11: =IF(OR(B[[#This Row],[Valore ai fini dell''atto]]>B[[#This Row],[Valore netto contabile fiscalmente riconosciuto]],B[[#This Row],[Iscritto a Bilancio come]]="Rimanenze"),B[[#This Row],[Valore ai fini dell''atto]]-B[[#This Row],[Valore netto contabile fiscalmente riconosciuto]],0) -> 0 | S11: =+IF(B[[#This Row],[Bene]]="","",VLOOKUP(B[[#This Row],[Tipologia]],TipoImm[],3,0)*B[[#This Row],[Imponibile Iva]]) | T11: =+IF(B[[#This Row],[Bene]]="","",VLOOKUP(B[[#This Row],[Tipologia]],TipoImm[],6,0)*B[[#This Row],[Valore catastale]]+VLOOKUP(B[[#This Row],[Tipologia]],TipoImm[],4,0)) | U11: =+IF(B[[#This Row],[Bene]]="","",VLOOKUP(B[[#This Row],[Tipologia]],TipoImm[],8,0)*B[[#This Row],[Valore normale]]+VLOOKUP(B[[#This Row],[Tipologia]],TipoImm[],9,0)) | V11: =+IF(OR(B[[#This Row],[Bene]]="",B[[#This Row],[Agevolabile]]=0),0,VLOOKUP(B[[#This Row],[Tipologia]],TipoImm[],5,0)) -> 0 | W11: =+IF(B[[#This Row],[Bene]]="",0,IFERROR(MAX(1000,IF(OR(B[[#This Row],[Bene]]="",B[[#This Row],[Agevolabile]]=0,B[[#This Row],[Bene]]=0),0,VLOOKUP(B[[#This Row],[Tipologia]],TipoImm[],7,0))*B[[#This Row],[Valore catastale]]),""))*(IFERROR(VLOOKUP(B[[#This Row],[Tipologia]],TipoImm[],7,0),0)>0) -> 0 | X11: =SUM(B[[#This Row],[Imposta di registro in misura fissa agevolata]:[Imposta di registro prop. Agevolata]]) -> 0 | Y11: =+IF(B[[#This Row],[Bene]]="",0,VLOOKUP(B[[#This Row],[Tipologia]],TipoImm[],10,0)) -> 0 | Z11: =+IF(p=3,"",IF(B[[#This Row],[Tipologia]]="","",VLOOKUP(B[[#This Row],[Tipologia]],TipoImm[],MATCH($Z$4,Tabelle!$AF$1:$AR$1,0),0)))
N12: =+IF(B[[#This Row],[Categoria Catastale]]="",0,VLOOKUP(B[[#This Row],[Categoria Catastale]],Gruppi[],6,0)*B[[#This Row],[Rendita catastale]]) -> 0 | O12: =+IF(A12="","",IF(D12="Sì",0,1)) | P12: =+IF(B[[#This Row],[Valore inserito manualmente]]>0,B[[#This Row],[Valore inserito manualmente]],B[[#This Row],[Valore catastale]]) -> 0 | Q12: =+IF(OR(B[[#This Row],[Opzione per prezzo-valore (s/n)]]="s",B[[#This Row],[Valore inserito manualmente]]=0),B[[#This Row],[Valore catastale]],B[[#This Row],[Valore inserito manualmente]]) -> 0 | R12: =IF(OR(B[[#This Row],[Valore ai fini dell''atto]]>B[[#This Row],[Valore netto contabile fiscalmente riconosciuto]],B[[#This Row],[Iscritto a Bilancio come]]="Rimanenze"),B[[#This Row],[Valore ai fini dell''atto]]-B[[#This Row],[Valore netto contabile fiscalmente riconosciuto]],0) -> 0 | S12: =+IF(B[[#This Row],[Bene]]="","",VLOOKUP(B[[#This Row],[Tipologia]],TipoImm[],3,0)*B[[#This Row],[Imponibile Iva]]) | T12: =+IF(B[[#This Row],[Bene]]="","",VLOOKUP(B[[#This Row],[Tipologia]],TipoImm[],6,0)*B[[#This Row],[Valore catastale]]+VLOOKUP(B[[#This Row],[Tipologia]],TipoImm[],4,0)) | U12: =+IF(B[[#This Row],[Bene]]="","",VLOOKUP(B[[#This Row],[Tipologia]],TipoImm[],8,0)*B[[#This Row],[Valore normale]]+VLOOKUP(B[[#This Row],[Tipologia]],TipoImm[],9,0)) | V12: =+IF(OR(B[[#This Row],[Bene]]="",B[[#This Row],[Agevolabile]]=0),0,VLOOKUP(B[[#This Row],[Tipologia]],TipoImm[],5,0)) -> 0 | W12: =+IF(B[[#This Row],[Bene]]="",0,IFERROR(MAX(1000,IF(OR(B[[#This Row],[Bene]]="",B[[#This Row],[Agevolabile]]=0,B[[#This Row],[Bene]]=0),0,VLOOKUP(B[[#This Row],[Tipologia]],TipoImm[],7,0))*B[[#This Row],[Valore catastale]]),""))*(IFERROR(VLOOKUP(B[[#This Row],[Tipologia]],TipoImm[],7,0),0)>0) -> 0 | X12: =SUM(B[[#This Row],[Imposta di registro in misura fissa agevolata]:[Imposta di registro prop. Agevolata]]) -> 0 | Y12: =+IF(B[[#This Row],[Bene]]="",0,VLOOKUP(B[[#This Row],[Tipologia]],TipoImm[],10,0)) -> 0 | Z12: =+IF(p=3,"",IF(B[[#This Row],[Tipologia]]="","",VLOOKUP(B[[#This Row],[Tipologia]],TipoImm[],MATCH($Z$4,Tabelle!$AF$1:$AR$1,0),0)))
N13: =+IF(B[[#This Row],[Categoria Catastale]]="",0,VLOOKUP(B[[#This Row],[Categoria Catastale]],Gruppi[],6,0)*B[[#This Row],[Rendita catastale]]) -> 0 | O13: =+IF(A13="","",IF(D13="Sì",0,1)) | P13: =+IF(B[[#This Row],[Valore inserito manualmente]]>0,B[[#This Row],[Valore inserito manualmente]],B[[#This Row],[Valore catastale]]) -> 0 | Q13: =+IF(OR(B[[#This Row],[Opzione per prezzo-valore (s/n)]]="s",B[[#This Row],[Valore inserito manualmente]]=0),B[[#This Row],[Valore catastale]],B[[#This Row],[Valore inserito manualmente]]) -> 0 | R13: =IF(OR(B[[#This Row],[Valore ai fini dell''atto]]>B[[#This Row],[Valore netto contabile fiscalmente riconosciuto]],B[[#This Row],[Iscritto a Bilancio come]]="Rimanenze"),B[[#This Row],[Valore ai fini dell''atto]]-B[[#This Row],[Valore netto contabile fiscalmente riconosciuto]],0) -> 0 | S13: =+IF(B[[#This Row],[Bene]]="","",VLOOKUP(B[[#This Row],[Tipologia]],TipoImm[],3,0)*B[[#This Row],[Imponibile Iva]]) | T13: =+IF(B[[#This Row],[Bene]]="","",VLOOKUP(B[[#This Row],[Tipologia]],TipoImm[],6,0)*B[[#This Row],[Valore catastale]]+VLOOKUP(B[[#This Row],[Tipologia]],TipoImm[],4,0)) | U13: =+IF(B[[#This Row],[Bene]]="","",VLOOKUP(B[[#This Row],[Tipologia]],TipoImm[],8,0)*B[[#This Row],[Valore normale]]+VLOOKUP(B[[#This Row],[Tipologia]],TipoImm[],9,0)) | V13: =+IF(OR(B[[#This Row],[Bene]]="",B[[#This Row],[Agevolabile]]=0),0,VLOOKUP(B[[#This Row],[Tipologia]],TipoImm[],5,0)) -> 0 | W13: =+IF(B[[#This Row],[Bene]]="",0,IFERROR(MAX(1000,IF(OR(B[[#This Row],[Bene]]="",B[[#This Row],[Agevolabile]]=0,B[[#This Row],[Bene]]=0),0,VLOOKUP(B[[#This Row],[Tipologia]],TipoImm[],7,0))*B[[#This Row],[Valore catastale]]),""))*(IFERROR(VLOOKUP(B[[#This Row],[Tipologia]],TipoImm[],7,0),0)>0) -> 0 | X13: =SUM(B[[#This Row],[Imposta di registro in misura fissa agevolata]:[Imposta di registro prop. Agevolata]]) -> 0 | Y13: =+IF(B[[#This Row],[Bene]]="",0,VLOOKUP(B[[#This Row],[Tipologia]],TipoImm[],10,0)) -> 0 | Z13: =+IF(p=3,"",IF(B[[#This Row],[Tipologia]]="","",VLOOKUP(B[[#This Row],[Tipologia]],TipoImm[],MATCH($Z$4,Tabelle!$AF$1:$AR$1,0),0)))
N14: =+IF(B[[#This Row],[Categoria Catastale]]="",0,VLOOKUP(B[[#This Row],[Categoria Catastale]],Gruppi[],6,0)*B[[#This Row],[Rendita catastale]]) -> 0 | O14: =+IF(A14="","",IF(D14="Sì",0,1)) | P14: =+IF(B[[#This Row],[Valore inserito manualmente]]>0,B[[#This Row],[Valore inserito manualmente]],B[[#This Row],[Valore catastale]]) -> 0 | Q14: =+IF(OR(B[[#This Row],[Opzione per prezzo-valore (s/n)]]="s",B[[#This Row],[Valore inserito manualmente]]=0),B[[#This Row],[Valore catastale]],B[[#This Row],[Valore inserito manualmente]]) -> 0 | R14: =IF(OR(B[[#This Row],[Valore ai fini dell''atto]]>B[[#This Row],[Valore netto contabile fiscalmente riconosciuto]],B[[#This Row],[Iscritto a Bilancio come]]="Rimanenze"),B[[#This Row],[Valore ai fini dell''atto]]-B[[#This Row],[Valore netto contabile fiscalmente riconosciuto]],0) -> 0 | S14: =+IF(B[[#This Row],[Bene]]="","",VLOOKUP(B[[#This Row],[Tipologia]],TipoImm[],3,0)*B[[#This Row],[Imponibile Iva]]) | T14: =+IF(B[[#This Row],[Bene]]="","",VLOOKUP(B[[#This Row],[Tipologia]],TipoImm[],6,0)*B[[#This Row],[Valore catastale]]+VLOOKUP(B[[#This Row],[Tipologia]],TipoImm[],4,0)) | U14: =+IF(B[[#This Row],[Bene]]="","",VLOOKUP(B[[#This Row],[Tipologia]],TipoImm[],8,0)*B[[#This Row],[Valore normale]]+VLOOKUP(B[[#This Row],[Tipologia]],TipoImm[],9,0)) | V14: =+IF(OR(B[[#This Row],[Bene]]="",B[[#This Row],[Agevolabile]]=0),0,VLOOKUP(B[[#This Row],[Tipologia]],TipoImm[],5,0)) -> 0 | W14: =+IF(B[[#This Row],[Bene]]="",0,IFERROR(MAX(1000,IF(OR(B[[#This Row],[Bene]]="",B[[#This Row],[Agevolabile]]=0,B[[#This Row],[Bene]]=0),0,VLOOKUP(B[[#This Row],[Tipologia]],TipoImm[],7,0))*B[[#This Row],[Valore catastale]]),""))*(IFERROR(VLOOKUP(B[[#This Row],[Tipologia]],TipoImm[],7,0),0)>0) -> 0 | X14: =SUM(B[[#This Row],[Imposta di registro in misura fissa agevolata]:[Imposta di registro prop. Agevolata]]) -> 0 | Y14: =+IF(B[[#This Row],[Bene]]="",0,VLOOKUP(B[[#This Row],[Tipologia]],TipoImm[],10,0)) -> 0 | Z14: =+IF(p=3,"",IF(B[[#This Row],[Tipologia]]="","",VLOOKUP(B[[#This Row],[Tipologia]],TipoImm[],MATCH($Z$4,Tabelle!$AF$1:$AR$1,0),0)))
N15: =+IF(B[[#This Row],[Categoria Catastale]]="",0,VLOOKUP(B[[#This Row],[Categoria Catastale]],Gruppi[],6,0)*B[[#This Row],[Rendita catastale]]) -> 0 | O15: =+IF(A15="","",IF(D15="Sì",0,1)) | P15: =+IF(B[[#This Row],[Valore inserito manualmente]]>0,B[[#This Row],[Valore inserito manualmente]],B[[#This Row],[Valore catastale]]) -> 0 | Q15: =+IF(OR(B[[#This Row],[Opzione per prezzo-valore (s/n)]]="s",B[[#This Row],[Valore inserito manualmente]]=0),B[[#This Row],[Valore catastale]],B[[#This Row],[Valore inserito manualmente]]) -> 0 | R15: =IF(OR(B[[#This Row],[Valore ai fini dell''atto]]>B[[#This Row],[Valore netto contabile fiscalmente riconosciuto]],B[[#This Row],[Iscritto a Bilancio come]]="Rimanenze"),B[[#This Row],[Valore ai fini dell''atto]]-B[[#This Row],[Valore netto contabile fiscalmente riconosciuto]],0) -> 0 | S15: =+IF(B[[#This Row],[Bene]]="","",VLOOKUP(B[[#This Row],[Tipologia]],TipoImm[],3,0)*B[[#This Row],[Imponibile Iva]]) | T15: =+IF(B[[#This Row],[Bene]]="","",VLOOKUP(B[[#This Row],[Tipologia]],TipoImm[],6,0)*B[[#This Row],[Valore catastale]]+VLOOKUP(B[[#This Row],[Tipologia]],TipoImm[],4,0)) | U15: =+IF(B[[#This Row],[Bene]]="","",VLOOKUP(B[[#This Row],[Tipologia]],TipoImm[],8,0)*B[[#This Row],[Valore normale]]+VLOOKUP(B[[#This Row],[Tipologia]],TipoImm[],9,0)) | V15: =+IF(OR(B[[#This Row],[Bene]]="",B[[#This Row],[Agevolabile]]=0),0,VLOOKUP(B[[#This Row],[Tipologia]],TipoImm[],5,0)) -> 0 | W15: =+IF(B[[#This Row],[Bene]]="",0,IFERROR(MAX(1000,IF(OR(B[[#This Row],[Bene]]="",B[[#This Row],[Agevolabile]]=0,B[[#This Row],[Bene]]=0),0,VLOOKUP(B[[#This Row],[Tipologia]],TipoImm[],7,0))*B[[#This Row],[Valore catastale]]),""))*(IFERROR(VLOOKUP(B[[#This Row],[Tipologia]],TipoImm[],7,0),0)>0) -> 0 | X15: =SUM(B[[#This Row],[Imposta di registro in misura fissa agevolata]:[Imposta di registro prop. Agevolata]]) -> 0 | Y15: =+IF(B[[#This Row],[Bene]]="",0,VLOOKUP(B[[#This Row],[Tipologia]],TipoImm[],10,0)) -> 0 | Z15: =+IF(p=3,"",IF(B[[#This Row],[Tipologia]]="","",VLOOKUP(B[[#This Row],[Tipologia]],TipoImm[],MATCH($Z$4,Tabelle!$AF$1:$AR$1,0),0)))
N16: =+IF(B[[#This Row],[Categoria Catastale]]="",0,VLOOKUP(B[[#This Row],[Categoria Catastale]],Gruppi[],6,0)*B[[#This Row],[Rendita catastale]]) -> 0 | O16: =+IF(A16="","",IF(D16="Sì",0,1)) | P16: =+IF(B[[#This Row],[Valore inserito manualmente]]>0,B[[#This Row],[Valore inserito manualmente]],B[[#This Row],[Valore catastale]]) -> 0 | Q16: =+IF(OR(B[[#This Row],[Opzione per prezzo-valore (s/n)]]="s",B[[#This Row],[Valore inserito manualmente]]=0),B[[#This Row],[Valore catastale]],B[[#This Row],[Valore inserito manualmente]]) -> 0 | R16: =IF(OR(B[[#This Row],[Valore ai fini dell''atto]]>B[[#This Row],[Valore netto contabile fiscalmente riconosciuto]],B[[#This Row],[Iscritto a Bilancio come]]="Rimanenze"),B[[#This Row],[Valore ai fini dell''atto]]-B[[#This Row],[Valore netto contabile fiscalmente riconosciuto]],0) -> 0 | S16: =+IF(B[[#This Row],[Bene]]="","",VLOOKUP(B[[#This Row],[Tipologia]],TipoImm[],3,0)*B[[#This Row],[Imponibile Iva]]) | T16: =+IF(B[[#This Row],[Bene]]="","",VLOOKUP(B[[#This Row],[Tipologia]],TipoImm[],6,0)*B[[#This Row],[Valore catastale]]+VLOOKUP(B[[#This Row],[Tipologia]],TipoImm[],4,0)) | U16: =+IF(B[[#This Row],[Bene]]="","",VLOOKUP(B[[#This Row],[Tipologia]],TipoImm[],8,0)*B[[#This Row],[Valore normale]]+VLOOKUP(B[[#This Row],[Tipologia]],TipoImm[],9,0)) | V16: =+IF(OR(B[[#This Row],[Bene]]="",B[[#This Row],[Agevolabile]]=0),0,VLOOKUP(B[[#This Row],[Tipologia]],TipoImm[],5,0)) -> 0 | W16: =+IF(B[[#This Row],[Bene]]="",0,IFERROR(MAX(1000,IF(OR(B[[#This Row],[Bene]]="",B[[#This Row],[Agevolabile]]=0,B[[#This Row],[Bene]]=0),0,VLOOKUP(B[[#This Row],[Tipologia]],TipoImm[],7,0))*B[[#This Row],[Valore catastale]]),""))*(IFERROR(VLOOKUP(B[[#This Row],[Tipologia]],TipoImm[],7,0),0)>0) -> 0 | X16: =SUM(B[[#This Row],[Imposta di registro in misura fissa agevolata]:[Imposta di registro prop. Agevolata]]) -> 0 | Y16: =+IF(B[[#This Row],[Bene]]="",0,VLOOKUP(B[[#This Row],[Tipologia]],TipoImm[],10,0)) -> 0 | Z16: =+IF(p=3,"",IF(B[[#This Row],[Tipologia]]="","",VLOOKUP(B[[#This Row],[Tipologia]],TipoImm[],MATCH($Z$4,Tabelle!$AF$1:$AR$1,0),0)))
N17: =+IF(B[[#This Row],[Categoria Catastale]]="",0,VLOOKUP(B[[#This Row],[Categoria Catastale]],Gruppi[],6,0)*B[[#This Row],[Rendita catastale]]) -> 0 | O17: =+IF(A17="","",IF(D17="Sì",0,1)) | P17: =+IF(B[[#This Row],[Valore inserito manualmente]]>0,B[[#This Row],[Valore inserito manualmente]],B[[#This Row],[Valore catastale]]) -> 0 | Q17: =+IF(OR(B[[#This Row],[Opzione per prezzo-valore (s/n)]]="s",B[[#This Row],[Valore inserito manualmente]]=0),B[[#This Row],[Valore catastale]],B[[#This Row],[Valore inserito manualmente]]) -> 0 | R17: =IF(OR(B[[#This Row],[Valore ai fini dell''atto]]>B[[#This Row],[Valore netto contabile fiscalmente riconosciuto]],B[[#This Row],[Iscritto a Bilancio come]]="Rimanenze"),B[[#This Row],[Valore ai fini dell''atto]]-B[[#This Row],[Valore netto contabile fiscalmente riconosciuto]],0) -> 0 | S17: =+IF(B[[#This Row],[Bene]]="","",VLOOKUP(B[[#This Row],[Tipologia]],TipoImm[],3,0)*B[[#This Row],[Imponibile Iva]]) | T17: =+IF(B[[#This Row],[Bene]]="","",VLOOKUP(B[[#This Row],[Tipologia]],TipoImm[],6,0)*B[[#This Row],[Valore catastale]]+VLOOKUP(B[[#This Row],[Tipologia]],TipoImm[],4,0)) | U17: =+IF(B[[#This Row],[Bene]]="","",VLOOKUP(B[[#This Row],[Tipologia]],TipoImm[],8,0)*B[[#This Row],[Valore normale]]+VLOOKUP(B[[#This Row],[Tipologia]],TipoImm[],9,0)) | V17: =+IF(OR(B[[#This Row],[Bene]]="",B[[#This Row],[Agevolabile]]=0),0,VLOOKUP(B[[#This Row],[Tipologia]],TipoImm[],5,0)) -> 0 | W17: =+IF(B[[#This Row],[Bene]]="",0,IFERROR(MAX(1000,IF(OR(B[[#This Row],[Bene]]="",B[[#This Row],[Agevolabile]]=0,B[[#This Row],[Bene]]=0),0,VLOOKUP(B[[#This Row],[Tipologia]],TipoImm[],7,0))*B[[#This Row],[Valore catastale]]),""))*(IFERROR(VLOOKUP(B[[#This Row],[Tipologia]],TipoImm[],7,0),0)>0) -> 0 | X17: =SUM(B[[#This Row],[Imposta di registro in misura fissa agevolata]:[Imposta di registro prop. Agevolata]]) -> 0 | Y17: =+IF(B[[#This Row],[Bene]]="",0,VLOOKUP(B[[#This Row],[Tipologia]],TipoImm[],10,0)) -> 0 | Z17: =+IF(p=3,"",IF(B[[#This Row],[Tipologia]]="","",VLOOKUP(B[[#This Row],[Tipologia]],TipoImm[],MATCH($Z$4,Tabelle!$AF$1:$AR$1,0),0)))
... N104: =+IF(B[[#This Row],[Categoria Catastale]]="",0,VLOOKUP(B[[#This Row],[Categoria Catastale]],Gruppi[],6,0)*B[[#This Row],[Rendita catastale]]) -> 0 | O104: =+IF(A104="","",IF(D104="Sì",0,1)) | P104: =+IF(B[[#This Row],[Valore inserito manualmente]]>0,B[[#This Row],[Valore inserito manualmente]],B[[#This Row],[Valore catastale]]) -> 0 | Q104: =+IF(OR(B[[#This Row],[Opzione per prezzo-valore (s/n)]]="s",B[[#This Row],[Valore inserito manualmente]]=0),B[[#This Row],[Valore catastale]],B[[#This Row],[Valore inserito manualmente]]) -> 0 | R104: =IF(OR(B[[#This Row],[Valore ai fini dell''atto]]>B[[#This Row],[Valore netto contabile fiscalmente riconosciuto]],B[[#This Row],[Iscritto a Bilancio come]]="Rimanenze"),B[[#This Row],[Valore ai fini dell''atto]]-B[[#This Row],[Valore netto contabile fiscalmente riconosciuto]],0) -> 0 | S104: =+IF(B[[#This Row],[Bene]]="","",VLOOKUP(B[[#This Row],[Tipologia]],TipoImm[],3,0)*B[[#This Row],[Imponibile Iva]]) | T104: =+IF(B[[#This Row],[Bene]]="","",VLOOKUP(B[[#This Row],[Tipologia]],TipoImm[],6,0)*B[[#This Row],[Valore catastale]]+VLOOKUP(B[[#This Row],[Tipologia]],TipoImm[],4,0)) | U104: =+IF(B[[#This Row],[Bene]]="","",VLOOKUP(B[[#This Row],[Tipologia]],TipoImm[],8,0)*B[[#This Row],[Valore normale]]+VLOOKUP(B[[#This Row],[Tipologia]],TipoImm[],9,0)) | V104: =+IF(OR(B[[#This Row],[Bene]]="",B[[#This Row],[Agevolabile]]=0),0,VLOOKUP(B[[#This Row],[Tipologia]],TipoImm[],5,0)) -> 0 | W104: =+IF(B[[#This Row],[Bene]]="",0,IFERROR(MAX(1000,IF(OR(B[[#This Row],[Bene]]="",B[[#This Row],[Agevolabile]]=0,B[[#This Row],[Bene]]=0),0,VLOOKUP(B[[#This Row],[Tipologia]],TipoImm[],7,0))*B[[#This Row],[Valore catastale]]),""))*(IFERROR(VLOOKUP(B[[#This Row],[Tipologia]],TipoImm[],7,0),0)>0) -> 0 | X104: =SUM(B[[#This Row],[Imposta di registro in misura fissa agevolata]:[Imposta di registro prop. Agevolata]]) -> 0 | Y104: =+IF(B[[#This Row],[Bene]]="",0,VLOOKUP(B[[#This Row],[Tipologia]],TipoImm[],10,0)) -> 0 | Z104: =+IF(p=3,"",IF(B[[#This Row],[Tipologia]]="","",VLOOKUP(B[[#This Row],[Tipologia]],TipoImm[],MATCH($Z$4,Tabelle!$AF$1:$AR$1,0),0)))

Sheet Tabelle
A1: TIPO | B1: Tassazione | D1: Cat | E1: Base | F1: Molt. | G1: Magg. | H1: Ult. Riv. | I1: Val. Cat. | J1: Agevolabile | L1: Cat | M1: Descr | N1: Moltiplicatore | O1: Prima Casa | R1: TIPO | S1: TAX | V1: TIPO BENE | W1: TIPO SOCIETA' | X1: IMPONIBILE | Y1: Tipologia | Z1: IVA | AA1: Registro | AB1: Ipotecaria Catastale | AC1: agevolabile | AD1: AnniRett | AF1: Tipologia | AG1: Immobili | AH1: IVA | AI1: RegistroFisso | AJ1: RegistroAG | AK1: RegProp | AL1: RegPropAG | AM1: IpocatProp | AN1: IpoCat | AO1: IpoCatAG | AP1: Agevolabile | AQ1: Fattura | AS1: IdPratica | AT1: Nome Pratica
A2: Società per azioni | B2: IRES | D2: Terreni | E2: Reddito Dominicale | F2: 75 | G2: 1.25 | H2: 0.2 | I2: =+Gruppi[[#This Row],[Molt.]]*Gruppi[[#This Row],[Magg.]]*(1+Gruppi[[#This Row],[Ult. Riv.]]) -> 112.5 | L2: A/1 | M2: Abitazioni di tipo signorile | N2: 120 | O2: 120 | R2: PF | S2: 0.4972 | V2: Immobili abitativi | W2: Impresa di costruzione o ristrutturazione che ha ultimato l'intervento da non oltre 5 anni | X2: imponibile per obbligo | Y2: Prima Casa | Z2: 0.04 | AA2: 200 | AB2: 400 | AC2: 1 | AD2: 10 | AF2: Immobili abitativi da costruttrici <5 anni (Iva per obbligo) o Iva per opzione | AG2: Sì | AH2: 0.1 | AI2: 200 | AJ2: 200 | AN2: 400 | AO2: 400 | AP2: 1 | AQ2: Imponibile 10% | AS2: 1 | AT2: Assegnazione
A3: Società in accomandita per azioni | B3: IRES | D3: A (escluso A/10) | E3: Rendita Catastale | F3: 100 | G3: 1.05 | H3: 0.2 | I3: =+Gruppi[[#This Row],[Molt.]]*Gruppi[[#This Row],[Magg.]]*(1+Gruppi[[#This Row],[Ult. Riv.]]) -> 126 | L3: A/2 | M3: Abitazioni di tipo civile | N3: 120 | O3: 110 | R3: PG | S3: 1 | V3: Immobili abitativi | W3: Impresa di costruzione o ristrutturazione che ha ultimato l'intervento da non oltre 5 anni | X3: imponibile per obbligo | Y3: Case non A/1, A/8 o A/9 | Z3: 0.1 | AA3: 200 | AB3: 400 | AC3: 1 | AD3: 10 | AF3: Immobili abitativi - Prima casa da impresa costr. (< 5 anni o Iva per opzione) | AG3: Sì | AH3: 0.04 | AI3: 200 | AJ3: 200 | AN3: 400 | AO3: 400 | AP3: 1 | AQ3: Imponibile 4% | AS3: 2 | AT3: Cessione
A4: Società a responsabilità limitata | B4: IRES | D4: A prima casa | E4: Rendita Catastale | F4: 100 | G4: 1.05 | H4: 0.1 | I4: =+Gruppi[[#This Row],[Molt.]]*Gruppi[[#This Row],[Magg.]]*(1+Gruppi[[#This Row],[Ult. Riv.]]) -> 115.5 | L4: A/3 | M4: Abitazioni di tipo economico | N4: 120 | O4: 110 | R4: PEX | S4: 0.05 | V4: Immobili abitativi | W4: Impresa di costruzione o ristrutturazione che ha ultimato l'intervento da non oltre 5 anni | X4: imponibile per obbligo | Y4: Lusso | Z4: 0.22 | AA4: 200 | AB4: 400 | AC4: 1 | AD4: 10 | AF4: Immobili lusso da impresa costr. (< 5 anni o Iva per opzione) | AG4: Sì | AH4: 0.22 | AI4: 200 | AJ4: 200 | AN4: 400 | AO4: 400 | AP4: 1 | AQ4: Imponibile 22% | AS4: 3 | AT4: =+IF(DATI!$A$23,"Trasformazione","") -> Trasformazione
A5: Società in nome collettivo | B5: IRPEF | D5: A/10 | E5: Rendita Catastale | F5: 50 | G5: 1.04 | H5: 0.2 | I5: 63 | L5: A/4 | M5: Abitazioni di tipo popolare | N5: 120 | O5: 110 | V5: Immobili abitativi | W5: Impresa di costruzione o ristrutturazione che ha ultimato l'intervento da oltre 5 anni | X5: imponibile per opzione | Z5: 0 | AA5: 200 | AB5: 400 | AC5: 1 | AD5: 10 | AF5: Immobili abitativi (>5 anni o Opzione no IVA) | AG5: Sì | AK5: 0.09 | AL5: 0.045 | AN5: 100 | AO5: 100 | AP5: 1 | AQ5: Esente art. 10 c.1 n 8 bis
A6: Società in accomandita semplice | B6: IRPEF | D6: B | E6: Rendita Catastale | F6: 100 | G6: 1.05 | H6: 0.68 | I6: =+Gruppi[[#This Row],[Molt.]]*Gruppi[[#This Row],[Magg.]]*(1+Gruppi[[#This Row],[Ult. Riv.]]) -> 176.4 | L6: A/5 | M6: Abitazioni di tipo ultrapopolare | N6: 120 | O6: 110 | V6: Immobili abitativi | W6: Impresa di costruzione o ristrutturazione che ha ultimato l'intervento da oltre 5 anni | X6: imponibile per obbligo | Y6: Non Prima casa | Z6: 0.22 | AA6: 0.045 | AB6: 100 | AC6: 1 | AD6: 10 | AF6: Immobili abitativi - Prima casa (>5 anni o Opzione no IVA) | AG6: Sì | AK6: 0.02 | AL6: 0.01 | AN6: 100 | AO6: 100 | AP6: 1 | AQ6: Esente art. 10 c.1 n 8 bis
A7: Società trasparente | B7: IRPEF | D7: C (escluso C/1) | E7: Rendita Catastale | F7: 100 | G7: 1.05 | H7: 0.2 | I7: =+Gruppi[[#This Row],[Molt.]]*Gruppi[[#This Row],[Magg.]]*(1+Gruppi[[#This Row],[Ult. Riv.]]) -> 126 | L7: A/6 | M7: Abitazioni di tipo rurale | N7: 120 | O7: 110 | V7: Immobili abitativi | W7: Impresa di costruzione o ristrutturazione che ha ultimato l'intervento da oltre 5 anni | X7: imponibile per obbligo | Y7: Prima Casa | Z7: 0.22 | AA7: 0.01 | AB7: 100 | AC7: 1 | AD7: 10 | AF7: Immobili abitativi acquistati senza addebito IVA | AG7: Sì | AK7: 0.09 | AL7: 0.045 | AN7: 100 | AO7: 100 | AQ7: Fuori campo IVA
D8: C/1 | E8: Rendita Catastale | F8: 34 | G8: 1.05 | H8: 0.2 | I8: =+Gruppi[[#This Row],[Molt.]]*Gruppi[[#This Row],[Magg.]]*(1+Gruppi[[#This Row],[Ult. Riv.]]) -> 42.84 | L8: A/7 | M8: Abitazioni in villini | N8: 120 | O8: 120 | V8: Immobili abitativi | W8: Altri soggetti IVA diversi dall'impresa di costruzione o ristrutturazione | X8: Esente | Y8: Non Prima casa | Z8: 0 | AA8: 0.045 | AB8: 100 | AC8: 1 | AD8: 10 | AF8: Immobili abitativi - Prima casa acquistati senza addebito IVA | AG8: Sì | AK8: 0.02 | AL8: 0.01 | AN8: 100 | AO8: 100 | AQ8: Fuori campo IVA
D9: D | E9: Rendita Catastale | F9: 50 | G9: 1.05 | H9: 0.2 | I9: =+Gruppi[[#This Row],[Molt.]]*Gruppi[[#This Row],[Magg.]]*(1+Gruppi[[#This Row],[Ult. Riv.]]) -> 63 | L9: A/8 | M9: Abitazioni in ville | N9: 120 | O9: 120 | V9: Immobili abitativi | W9: Altri soggetti IVA diversi dall'impresa di costruzione o ristrutturazione | X9: Esente | Y9: Prima Casa | Z9: 0 | AA9: 0.01 | AB9: 100 | AC9: 1 | AD9: 10 | AF9: Immobili Strumentali <5 anni (Iva per obbligo) o Iva per opzione | AG9: Sì | AH9: 0.22 | AI9: 200 | AJ9: 200 | AM9: 0.04 | AO9: 400 | AP9: 1 | AQ9: Imponibile 22%
D10: E | E10: Rendita Catastale | F10: 34 | G10: 1.05 | H10: 0.2 | I10: =+Gruppi[[#This Row],[Molt.]]*Gruppi[[#This Row],[Magg.]]*(1+Gruppi[[#This Row],[Ult. Riv.]]) -> 42.84 | L10: A/9 | M10: Castelli, palazzi di eminenti pregi artistici o storici | N10: 120 | O10: 110 | V10: Immobili abitativi | W10: Chiunque ha acquistato il fabbricato senza addebito dell'IVA (solo assegnazioni) | X10: Fuori Campo | Y10: Non Prima casa | Z10: 0 | AA10: 0.045 | AB10: 100 | AC10: 1 | AD10: 10 | AF10: Immobili Strumentali >5 anni o no Iva per opzione | AG10: Sì | AI10: 200 | AJ10: 200 | AM10: 0.04 | AO10: 400 | AP10: 1 | AQ10: Esente art. 10 c.1 n 8 ter
L11: A/10 | M11: Uffici e studi privati | N11: 60 | V11: Immobili abitativi | W11: Chiunque ha acquistato il fabbricato senza addebito dell'IVA (solo assegnazioni) | X11: Fuori Campo | Y11: Prima Casa | Z11: 0 | AA11: 0.01 | AB11: 100 | AC11: 1 | AD11: 10 | AF11: Immobili strumentali acquistati senza addebito IVA dest. Commerciale | AG11: Sì | AK11: 0.04 | AL11: 0.02 | AM11: 0.03 | AO11: 400 | AP11: 1 | AQ11: Fuori campo IVA
L12: A/11 | M12: Abitazioni ed alloggi tipici dei luoghi | N12: 120 | V12: Immobili strumentali | W12: Impresa di costruzione o ristrutturazione che ha ultimato l'intervento da non oltre 5 anni | X12: imponibile per obbligo | Z12: 0.22 | AA12: 200 | AB12: 400 | AC12: 1 | AD12: 10 | AF12: Immobili strumentali acquistato senza addebito IVA altre destinazioni | AG12: Sì | AK12: 0.09 | AL12: 0.045 | AO12: 100 | AP12: 1 | AQ12: Fuori campo IVA
L13: B/1 | M13: Collegi e convitti, educandati; ricoveri; orfanotrofi; ospizi; conventi; | N13: 168 | V13: Immobili strumentali | W13: Impresa di costruzione o ristrutturazione che ha ultimato l'intervento da oltre 5 anni | X13: Esente in assenza di opzione | Z13: 0.22 | AA13: 200 | AB13: 400 | AC13: 1 | AD13: 10 | AF13: Terreno Edificabile | AG13: No | AH13: 0.22 | AI13: 200 | AJ13: 200 | AN13: 400 | AO13: 400 | AP13: 1 | AQ13: Imponibile 22%
L14: B/2 | M14: Case di cura ed ospedali (senza fine di lucro) | N14: 168 | V14: Immobili strumentali | W14: Altri soggetti IVA diversi dall'impresa di costruzione o ristrutturazione | X14: imponibile per opzione | Z14: 0 | AA14: 200 | AB14: 400 | AC14: 1 | AD14: 10 | AF14: Terreno Edificabile acquistato FUORI CAMPO IVA | AG14: No | AH14: 0.22 | AK14: 0.09 | AL14: 0.045 | AN14: 100 | AO14: 100 | AP14: 1 | AQ14: Imponibile 22%
L15: B/3 | M15: Prigioni e riformatori | N15: 168 | V15: Immobili strumentali | W15: Chiunque ha acquistato il fabbricato senza addebito dell'IVA (solo assegnazioni) | X15: Fuori Campo | Z15: 0 | AA15: 0.045 | AB15: 400 | AC15: 1 | AD15: 10 | AF15: Terreno Agricolo | AG15: No | AH15: 0 | AK15: 0.15 | AL15: 0.075 | AN15: 100 | AO15: 100 | AP15: 1 | AQ15: Fuori campo IVA
L16: B/4 | M16: Uffici pubblici | N16: 168 | V16: Immobili strumentali | W16: Chiunque ha acquistato il fabbricato senza addebito dell'IVA (solo assegnazioni) | X16: Fuori Campo | Z16: 0 | AA16: 0.02 | AB16: 100 | AC16: 1 | AD16: 10 | AF16: Terreno Agricolo (cessionario Colt. Diretto o IAP) | AG16: No | AH16: 0 | AI16: 200 | AJ16: 200 | AM16: 0.01 | AN16: 200 | AO16: 400 | AP16: 1 | AQ16: Fuori campo IVA
L17: B/5 | M17: Scuole e laboratori scientifici | N17: 168 | V17: Terreno Edificabile | W17: Chiunque | X17: Imponibile | Z17: 0.22 | AA17: 200 | AB17: 400 | AC17: 1 | AD17: 10 | AF17: Terreno non Edificabile né Agricolo | AG17: No | AH17: 0 | AK17: 0.09 | AL17: 0.045 | AN17: 100 | AO17: 100 | AP17: 1 | AQ17: Esente
A18: Ver. 11.5 | L18: B/6 | M18: Biblioteche, pinacoteche, musei, gallerie, accademie che non hanno sede in edifici della categoria A/9 | N18: 168 | V18: Terreno Agricolo | W18: Chiunque | X18: Fuori Campo (cessionario IAP) | Z18: 0 | AA18: 200 | AB18: 400 | AD18: 10 | AF18: Altri Beni | AG18: Sì | AH18: 0.22 | AP18: 1 | AQ18: Imponibile 22%
L19: B/7 | M19: Cappelle ed oratori non destinati all’esercizio pubblico del culto | N19: 168 | V19: Terreno Agricolo | W19: Chiunque | X19: Fuori Campo (altri casi) | Z19: 0 | AA19: 0.075 | AB19: 100 | AC19: 1 | AD19: 10
L20: B/8 | M20: Magazzini sotterranei per depositi di derrate | N20: 168 | V20: Terreno non Edificabile né Agricolo | W20: Chiunque | X20: Fuori Campo | Z20: 0 | AA20: 0.045 | AB20: 100 | AC20: 1 | AD20: 10
L21: C/1 | M21: Negozi e botteghe | N21: 40.8 | V21: Atri Beni | W21: Chiunque | Z21: 0.22 | AA21: 0 | AB21: 0 | AC21: 1 | AD21: 5
L22: C/2 | M22: Magazzini e locali di deposito | N22: 120
L23: C/3 | M23: Laboratori per arti e mestieri | N23: 120
L24: C/4 | M24: Fabbricati e locali per esercizi sportivi (senza fine di lucro) | N24: 120
L25: C/5 | M25: Stabilimenti balneari e di acque curative (senza fine di lucro) | N25: 120
L26: C/6 | M26: Stalle, scuderie, rimesse, autorimesse (senza fine di lucro) | N26: 120
L27: C/7 | M27: Tettoie chiuse od aperte | N27: 120
L28: D/1 | M28: Opifici | N28: 60
L29: D/2 | M29: Alberghi e pensioni (con fine di lucro) | N29: 60
L30: D/3 | M30: Teatri, cinematografi, sale per concerti e spettacoli e simili (con fine di lucro) | N30: 60
L31: D/4 | M31: Case di cura ed ospedali (con fine di lucro) | N31: 60
L32: D/5 | M32: Istituto di credito, cambio e assicurazione (con fine di lucro) | N32: 60
L33: D/6 | M33: Fabbricati e locali per esercizi sportivi (con fine di lucro) | N33: 60
... L37: D/10 | M37: Fabbricati per funzioni produttive connesse alle attività agricole. | N37: 60

Sheet Assegnazione
AA2: Totale Tassazione agevolata | AB2: Risparmio
A3: =+DATI!B19 -> Assegnazione | H3: =+SUM(Assegnazione[Valore Fiscalmente riconosciuto]) -> 220000 | I3: =+SUM(Assegnazione[Valore Normale]) -> 300000 | L3: =+SUM(Assegnazione[Valore Catastale]) -> 302400 | M3: =+SUM(Assegnazione[Valore ai fini dell''atto]) -> 302400 | N3: =+SUM(Assegnazione[Valore fiscale ai fini della Tassazione soci]) -> 220000 | P3: =+SUM(Assegnazione[Tassazione diretta senza agevolazione]) -> 19200 | Q3: =+SUM(Assegnazione[IRAP]) -> 3120 | R3: =+SUM(Assegnazione[Iva se dovuta]) -> 0 | S3: =+SUM(Assegnazione[Imposta di registro senza agevolazione]) -> 200 | T3: =+SUM(Assegnazione[Ipotecaria e catastale senza agevolazione]) -> 12000 | U3: =+SUM(Assegnazione[Tassazione totale senza agevolazione]) -> 34520 | V3: =+Beni!R3*DATI!$E$27 -> 8652 | W3: =+SUM(Assegnazione[Imposta di registro in misura fissa]) -> 200 | Y3: =+SUM(Assegnazione[Imposta di registro agevolata])*(p<3)+(p=3)*200 -> 200 | Z3: =+SUM(Assegnazione[Ipotecaria catastale agevolata]) -> 400 | AA3: =+Y3+Z3+V3 -> 9252 | AB3: =+U3-AA3 -> 25268
A4: Bene | B4: Quota di assegnazione | C4: Socio | D4: Imponibile IVA | E4: Valore dichiarato in atto (se diverso da catastale) | F4: Tipologia | G4: Agevolabile | H4: Valore Fiscalmente riconosciuto | I4: Valore Normale | J4: % Assegnata | K4: % Capitale | L4: Valore Catastale | M4: Valore ai fini dell'atto | N4: Valore fiscale ai fini della Tassazione soci | O4: Opzione per prezzo-valore (s/n) | P4: Tassazione diretta senza agevolazione | Q4: IRAP | R4: Iva se dovuta | S4: Imposta di registro senza agevolazione | T4: Ipotecaria e catastale senza agevolazione | U4: Tassazione totale senza agevolazione | V4: Imposta sostitutiva | W4: Imposta di registro in misura fissa | X4: Imposta di registro prop. | Y4: Imposta di registro agevolata | Z4: Ipotecaria catastale agevolata
A5: Capannone | B5: 0.5 | C5: Socio X | D5: =+SUMIF(B[Bene],Assegnazione[[#This Row],[Bene]],B[Imponibile Iva])*Assegnazione[[#This Row],[Quota di assegnazione]] -> 0 | E5: =+SUMIF(B[Bene],Assegnazione[[#This Row],[Bene]],B[Valore inserito manualmente])*Assegnazione[[#This Row],[Quota di assegnazione]] -> 0 | F5: =+IF(A5="","",VLOOKUP(Assegnazione[[#This Row],[Bene]],B[],3,0)) -> Immobili Strumentali >5 anni o no Iva per opzione | G5: =+IFERROR(VLOOKUP(Assegnazione[[#This Row],[Bene]],B[],MATCH("Agevolabile",Beni!$A$4:$AC$4,0),0)*VLOOKUP(Assegnazione[[#This Row],[Socio]],A_1[],8,0),"") -> 1 | H5: =+SUMIF(B[Bene],Assegnazione[[#This Row],[Bene]],B[Valore netto contabile fiscalmente riconosciuto])*Assegnazione[[#This Row],[Quota di assegnazione]] -> 110000 | I5: =+SUMIF(B[Bene],Assegnazione[[#This Row],[Bene]],B[Valore normale])*Assegnazione[[#This Row],[Quota di assegnazione]] -> 150000 | J5: =+IF(Assegnazione[[#This Row],[Bene]]="",0,SUMIF(Assegnazione[Socio],Assegnazione[[#This Row],[Socio]],Assegnazione[Valore Normale])/$I$3) -> 0.5 | K5: =IF(Assegnazione[[#This Row],[Bene]]="","",SUMIF(A_1[Nome],Assegnazione[[#This Row],[Socio]],A_1[Quota partecipazione al momento dell''operazione])) -> 0.5 | L5: =+SUMIF(B[Bene],Assegnazione[[#This Row],[Bene]],B[Valore catastale])*Assegnazione[[#This Row],[Quota di assegnazione]] -> 151200 | M5: =+IF(OR(Assegnazione[[#This Row],[Valore dichiarato in atto (se diverso da catastale)]]>0,Assegnazione[[#This Row],[Agevolabile]]=0),Assegnazione[[#This Row],[Valore dichiarato in atto (se diverso da catastale)]],Assegnazione[[#This Row],[Valore Catastale]]) -> 151200 | N5: =+MIN(Assegnazione[[#This Row],[Valore ai fini dell''atto]],Assegnazione[[#This Row],[Valore Fiscalmente riconosciuto]]) -> 110000 | O5: =+IFERROR(VLOOKUP(Assegnazione[[#This Row],[Bene]],B[],MATCH($O$4,Beni!$A$4:$Z$4,0),0),"") -> s | P5: =+IF(Assegnazione[[#This Row],[Valore Fiscalmente riconosciuto]]>Assegnazione[[#This Row],[Valore Normale]],0,(Assegnazione[[#This Row],[Valore Normale]]-Assegnazione[[#This Row],[Valore Fiscalmente riconosciuto]])*t) -> 9600 | Q5: =+IF(Assegnazione[[#This Row],[Valore Fiscalmente riconosciuto]]>Assegnazione[[#This Row],[Valore Normale]],0,(Assegnazione[[#This Row],[Valore Normale]]-Assegnazione[[#This Row],[Valore Fiscalmente riconosciuto]])*DATI!$H$23) -> 1560 | R5: =+SUMIF(B[Bene],Assegnazione[[#This Row],[Bene]],B[Iva se dovuta])*Assegnazione[[#This Row],[Quota di assegnazione]] -> 0 | S5: =+SUMIF(B[Bene],Assegnazione[[#This Row],[Bene]],B[Imposta di registro (fissa + prop) senza agevolazione])*Assegnazione[[#This Row],[Quota di assegnazione]] -> 100 | T5: =+SUMIF(B[Bene],Assegnazione[[#This Row],[Bene]],B[Ipotecaria e catastale senza agevolazione])*Assegnazione[[#This Row],[Quota di assegnazione]] -> 6000 | U5: =+SUM(Assegnazione[[#This Row],[Tassazione diretta senza agevolazione]:[Ipotecaria e catastale senza agevolazione]]) -> 17260 | V5: =+SUMIF(B[Bene],Assegnazione[[#This Row],[Bene]],B[Imponibile Imposta sostitutiva])*Assegnazione[[#This Row],[Quota di assegnazione]]*DATI!$E$27 -> 4326 | W5: =+SUMIF(B[Bene],Assegnazione[[#This Row],[Bene]],B[Imposta di registro in misura fissa agevolata])*Assegnazione[[#This Row],[Quota di assegnazione]] -> 100 | X5: =+SUMIF(B[Bene],Assegnazione[[#This Row],[Bene]],B[Imposta di registro prop. Agevolata])*Assegnazione[[#This Row],[Quota di assegnazione]] -> 0 | Y5: =+IFERROR(Assegnazione[[#This Row],[Imposta di registro in misura fissa]]+Assegnazione[[#This Row],[Imposta di registro prop.]],"") -> 100 | Z5: =+SUMIF(B[Bene],Assegnazione[[#This Row],[Bene]],B[Ipotecaria catastale agevolata])*Assegnazione[[#This Row],[Quota di assegnazione]] -> 200
