Workbook
Name Bi: [1]COEFFICIENTI!$U$40:$Z$55
Name CE: CE!$B$7:$E$32
Name CE01.: CE!A$8
Name CE01T.: CE!A$34
Name CE02.: CE!A$9
Name CE03.: CE!A$10
Name CE04.: CE!A$11
Name CE05.: CE!A$12
Name CE06.: CE!A$13
Name CE06T.: CE!A$35
Name CE07.: CE!A$14
Name CE08.: CE!A$15
Name CE09.: CE!A$16
Name CE10.: CE!A$17
Name CE11.: CE!A$18
Name CE12.: CE!A$19
Name CE13.: CE!A$20
Name CE14.: CE!A$21
Name CE15.: CE!A$22
Name CE16.: CE!A$23
Name CE17.: CE!A$24
Name CE18.: CE!A$25
Name CE19.: CE!A$26
Name CE20.: CE!A$27
Name CE21.: CE!A$28
Name CE22.: CE!A$29
Name CE23.: CE!A$30
Name CE24.: CE!A$31
Name CE25.: CE!A$32
Name SP: SP!$A$11:$D$34
Name SP01.: SP!A$12
Name SP02.: SP!A$13
Name SP03.: SP!A$14
Name SP04.: SP!A$15
Name SP05.: SP!A$16
Name SP06.: SP!A$17
Name SP07.: SP!A$18
Name SP08.: SP!A$19
Name SP09.: SP!A$20
Name SP10.: SP!A$21
Name SP11.: SP!A$22
Name SP12.: SP!A$23
Name SP13.: SP!A$24
Name SP14.: SP!A$25
Name SP15.: SP!A$26
Name SP16.: SP!A$27
Name SP17.: SP!A$28
Name SP18.: SP!A$29
Name SP19.: SP!A$30
Name SP20.: SP!A$31
Name SP21.: SP!A$32
Name SP22.: SP!A$33
Name SP23.: SP!A$34

Sheet SP
A6: ANNO BILANCIO 1 | C6: 2023
A8: ANNO BILANCIO 2 | C8: 2024
A11: CODICE | B11: DESCRIZIONE | C11: =+C6 -> 2023 | D11: =+C8 -> 2024
A12: SP01 | B12: Crediti verso soci per versamenti ancora dovuti
A13: SP02 | B13: Totale immobilizzazioni immateriali
A14: SP03 | B14: Totale immobilizzazioni materiali | C14: 3597 | D14: 3970
A15: SP04 | B15: Totale immobilizzazioni finanziarie
A16: SP05 | B16: Totale Immobilizzazioni | C16: =SUM(C13:C15) -> 3597 | D16: =SUM(D13:D15) -> 3970
A17: SP06 | B17: Totale rimanenze
A18: SP07 | B18: Crediti esigibili entro l'esercizio successivo | C18: 82093 | D18: 60589
A19: SP08 | B19: Crediti esigibili oltre l'esercizio successivo
A20: SP09 | B20: Totale Crediti | C20: =+SUM(C18:C19) -> 82093 | D20: =+SUM(D18:D19) -> 60589
A21: SP10 | B21: Attività finanziarie che non costituiscono immobilizzazioni
A22: SP11 | B22: Disponibilità liquide | C22: 30153 | D22: 49883
A23: SP12 | B23: Totale attivo circolante | C23: =+C22+C21+C20+C17 -> 112246 | D23: =+D22+D21+D20+D17 -> 110472
A24: SP13 | B24: Totale ratei e risconti | C24: 7448 | D24: 5047
A25: SP14 | B25: Totale Attivo | C25: =+C24+C23+C16+C12 -> 123291 | D25: =+D24+D23+D16+D12 -> 119489
A26: SP15 | B26: Patrimonio netto | C26: 29851 | D26: 22031
A27: SP16 | B27: Di cui Utile (Perdita) di esercizio | C27: 9289 | D27: 3980
A28: SP17 | B28: Totale fondi per rischi e oneri
A29: SP18 | B29: Trattamento di fine rapporto di lavoro subordinato | C29: 23861 | D29: 28869
A30: SP19 | B30: Debiti esigibili entro l'esercizio successivo | C30: 64163 | D30: 64733
A31: SP20 | B31: Debiti esigibili oltre l'esercizio successivo | C31: 4480 | D31: 3815
A32: SP21 | B32: Totale debiti | C32: =SUM(C30:C31) -> 68643 | D32: =SUM(D30:D31) -> 68548
A33: SP22 | B33: Totale ratei e risconti | C33: 936 | D33: 41
A34: SP23 | B34: Totale Passivo | C34: =+C33+C32+C29+C28+C26 -> 123291 | D34: =+D33+D32+D29+D28+D26 -> 119489

Sheet CE
B7: CODICE | C7: DESCRIZIONE | D7: =+SP!C11 -> 2023 | E7: =+SP!D11 -> 2024
B8: CE01 | C8: Ricavi delle vendite e delle prestazioni | D8: 271268 | E8: 255388
B9: CE02 | C9: Variazione rimanenze prodotti in corso di lavorazione, semilavorati e finiti | H9: DATI AGGIUNTIVI
B10: CE03 | C10: Variazione dei lavori in corso su ordinazione
B11: CE04 | C11: Incrementi di immobilizzazioni per lavori interni | H11: Dettaglio costi per servizi
B12: CE05 | C12: Totale altri ricavi e proventi | D12: 13 | E12: 805 | H12: =+D7 -> 2023 | I12: =+E7 -> 2024
B13: CE06 | C13: Totale valore della produzione | D13: =SUM(D8:D12) -> 271281 | E13: =SUM(E8:E12) -> 256193 | G13: Servizi produzione | H13: 51394 | I13: 56917
B14: CE07 | C14: Costi per materie prime, sussidiarie, di consumo e di merci | D14: 3901 | E14: 1721 | G14: Altri servizi
B15: CE08 | C15: Costi per servizi | D15: 51394 | E15: 56917 | H15: =+D15 -> 51394 | I15: =+E15 -> 56917
B16: CE09 | C16: Costi per godimento di beni di terzi | D16: 57233 | E16: 35517 | H16: Dettaglio costi del personale
B17: CE10 | C17: Totale costi per il personale | D17: 134612 | E17: 149309 | H17: =+D7 -> 2023 | I17: =+E7 -> 2024
B18: CE11 | C18: Ammortamento delle immobilizzazioni immateriali | G18: Personale produzione | H18: 134612 | I18: 149309
B19: CE12 | C19: Ammortamento delle immobilizzazioni materiali | D19: 3488 | E19: 3148 | G19: Altro personale
B20: CE13 | C20: Totale ammortamenti e svalutazioni | D20: =SUM(D18:D19) -> 3488 | E20: =SUM(E18:E19) -> 3148 | G20: Altri costi del personale
B21: CE14 | C21: Variazione delle rimanenze di materie prime, sussidiarie, di consumo e merci | H21: =+D17 -> 134612 | I21: =+E17 -> 149309
B22: CE15 | C22: Accantonamento per rischi
B23: CE16 | C23: Altri accantonamenti
B24: CE17 | C24: Oneri diversi di gestione | D24: 5405 | E24: 3535
B25: CE18 | C25: Totale costi della produzione | D25: =+SUM(D14:D19,D21:D24) -> 256033 | E25: =+SUM(E14:E19,E21:E24) -> 250147
B26: CE19 | C26: Totale interessi e altri oneri finanziari | D26: 736 | E26: 764
B27: CE20 | C27: Totale proventi e oneri finanziari
B28: CE21 | C28: Totale delle rettifiche di valore di attività finanziarie
B29: CE22 | C29: Totale delle partite straordinarie
B30: CE23 | C30: Risultato prima delle imposte | D30: =D13-SUM(D25:D29) -> 14512 | E30: =E13-SUM(E25:E29) -> 5282
B31: CE24 | C31: Totale delle imposte sul reddito dell'esercizio, correnti, differite e anticipate | D31: 5223 | E31: 1302
B32: CE25 | C32: Utile (perdita) di esercizio | D32: =+D30-D31 -> 9289 | E32: =+E30-E31 -> 3980
B34: CE01 t-1 | C34: Totale valore della produzione anno precedente | D34: 306816 | E34: 271268
B35: CE06 t-1 | C35: Totale valore della produzione anno precedente | D35: 306822 | E35: 271281
C38: PN | D38: =+SP!C26 -> 29851 | E38: =+SP!D26 -> 22031
C39: ROE | D39: =+D32/D38 -> 0.31117885 | E39: =+E32/E38 -> 0.18065453
C41: UTILE/VENDITE | D41: =+D32/D8 -> 0.034242889 | E41: =+E32/E8 -> 0.015584131
B42: x | C42: VENDITE/ATTIVO | D42: =+D8/SP!C34 -> 2.2002255 | E42: =+E8/SP!D34 -> 2.1373348
B43: x | C43: ATTIVO/PATRIMONIO NETTO | D43: =+SP!C25/SP!C26 -> 4.1302134 | E43: =+SP!D25/SP!D26 -> 5.4236757
D44: =+D41*D42*D43 -> 0.31117885 | E44: =+E41*E42*E43 -> 0.18065453
C46: RO | D46: =+D13-D25 -> 15248 | E46: =+E13-E25 -> 6046
C47: RN/RO | D47: =+D32/D46 -> 0.60919465 | E47: =+E32/E46 -> 0.65828647
B48: =B43 -> x | C48: =C43 -> ATTIVO/PATRIMONIO NETTO | D48: =D43 -> 4.1302134 | E48: =E43 -> 5.4236757
B49: X | C49: ROI | D49: =+D46/SP!C34 -> 0.12367488 | E49: =+E46/SP!D34 -> 0.0505988
D50: =+D47*D48*D49 -> 0.31117885 | E50: =+E47*E48*E49 -> 0.18065453
C52: INTERESSI | D52: =+D26 -> 736 | E52: =+E26 -> 764
...

Sheet CE ricl. e ROE
A1: CONTO ECONOMICO RICLASSIFICATO
A2: cursore | B2: Descrizione | C2: 2023 | D2: 2024 | R2: =+SP!C6 -> 2023 | S2: =+SP!C8 -> 2024
A3: 1 | B3: Vendite | C3: =+CE!D8 -> 271268 | D3: =+CE!E8 -> 255388 | H3: Prima Scomposizione | R3: =+CE!D32/SP!C26 -> 0.31117885 | S3: =+CE!E32/SP!D26 -> 0.18065453
A4: 2 | B4: Delta rimanenze PF e SML | C4: =+CE!D9+CE!D10-CE!D21 -> 0 | D4: =+CE!E9+CE!E10-CE!E21 -> 0 | H4: ROE = RN/CN = RO/TA * TA/CN * RN/RO | R4: =R7*R17*R19 -> 0.25371308 | S4: =S7*S17*S19 -> 0.11879892 | U4: =+C23/SP!C26 -> 0.31117885 | V4: =+IF(U4=R4,"OK","ATTENZIONE") -> ATTENZIONE
A5: 3 | B5: Altri ricavi operativi | C5: =+CE!D11+CE!D12 -> 13 | D5: =+CE!E11+CE!E12 -> 805 | I5: RO/TA = ROA ovvero Return On Assets
A6: 1+2+3=A | B6: Valore della produzione | C6: =SUM(C3:C5) -> 271281 | D6: =SUM(D3:D5) -> 256193
A7: 4 | B7: Costo delle MP | C7: =+CE!D14 -> 3901 | D7: =+CE!E14 -> 1721 | J7: ROA = Operating profit margin * Turnover ratio | R7: =$R$9*$R$15 -> 0.10083569 | S7: =$S$9*$S$15 -> 0.033273912
A8: 5 | B8: Altri costi di produzione | C8: =+CE!H13+CE!D16 -> 108627 | D8: =+CE!I13+CE!E16 -> 92434
A9: 6 | B9: Costi del personale di produzione | C9: =+CE!H18 -> 134612 | D9: =+CE!I18 -> 149309 | K9: Operating profit margin = (Net income + Interest expense) / Gross revenue | R9: =($R$24+CE!$E$26)/$C$13 -> 0.81532878 | S9: =($S$24+CE!$E$26)/$D$13 -> 0.65760278
A10: 4+5+6=B | B10: Valore della produzione | C10: =SUM(C7:C9) -> 247140 | D10: =SUM(D7:D9) -> 243464
A11: A-B=C | B11: Margine industriale | C11: =+C6-C10 -> 24141 | D11: =+D6-D10 -> 12729 | E11: Gross profit | L11: Net Income = Net operating income + Other income - Interest expense | R11: =+$C$18+(IF($C$19>0,$C$19,0))+(IF($C$20>0,$C$20,0))-CE!$D$26 -> 14512 | S11: =+$D$18+(IF($D$19>0,$D$19,0))+(IF($D$20>0,$D$20,0))-CE!$E$26 -> 5282
A12: 7 | B12: Costi variabili di vendita | C12: =+CE!H14+CE!D24 -> 5405 | D12: =+CE!I14+CE!E24 -> 3535
A13: C-7=D | B13: Margine lordo | C13: =+C11-C12 -> 18736 | D13: =+D11-D12 -> 9194 | E13: Gross margin (revenue) | L13: Net operating income = Gross revenue - fixed expense - variable expense | R13: =+$C$13-$C$10-$C$12-$C$14-$C$15 -> -233809 | S13: =+$D$13-$D$10-$D$12-$D$14-$D$15 -> -237805
A14: 8 | B14: Costi del personale G&A | C14: =+CE!H19 -> 0 | D14: =+CE!I19 -> 0
A15: 9 | B15: Altri costi del personale | C15: =+CE!H20 -> 0 | D15: =+CE!I20 -> 0 | J15: ROI | K15: Turnover ratio = Gross revenue / Total Assets | R15: =$C$18/SP!$C$25 -> 0.12367488 | S15: =$D$18/SP!$D$25 -> 0.0505988 | U15: =$C$13/SP!$C$16 -> 5.2087851
A16: D-8-9=E | B16: Margine operativo lordo (MOL) | C16: =+C13-C14-C15 -> 18736 | D16: =+D13-D14-D15 -> 9194 | E16: EBITDA
A17: 10 | B17: Ammortamenti e svalutazioni | C17: =+CE!D18+CE!D19+CE!D22+CE!D23 -> 3488 | D17: =+CE!E18+CE!E19+CE!E22+CE!E23 -> 3148 | I17: TA / CN | R17: =SP!C25/SP!C26 -> 4.1302134 | S17: =SP!D25/SP!D26 -> 5.4236757 | U17: =+SP!C25/SP!C26 -> 4.1302134
A18: E-10=F | B18: Reddito operativo | C18: =+C16-C17 -> 15248 | D18: =+D16-D17 -> 6046 | E18: EBIT
A19: 11 | B19: Altri ricavi (spese) straordinarie | C19: =-CE!D29 -> 0 | D19: =-CE!E29 -> 0 | I19: RN / RO | R19: =+C23/C18 -> 0.60919465 | S19: =+D23/D18 -> 0.65828647 | U19: =+C23/C18 -> 0.60919465
A20: 12 | B20: Ricavi (oneri) finanziari | C20: =-CE!D26-CE!D27-CE!D28 -> -736 | D20: =-CE!E26-CE!E27-CE!E28 -> -764 | J20: RN / RO = Utile netto / Operating profit margin
A21: F+11+12=G | B21: Utile (perdita) ante imposte | C21: =+C18+C19+C20 -> 14512 | D21: =+D18+D19+D20 -> 5282 | E21: EBT
A22: 13 | B22: Imposte | C22: =+CE!D31 -> 5223 | D22: =+CE!E31 -> 1302 | K22: Operating profit margin = (Net income + Interest expense) / Gross revenue | R22: =($R$24+CE!$E$26)/$C$13 -> 0.81532878 | S22: =($S$24+CE!$E$26)/$D$13 -> 0.65760278
A23: G-13=H | B23: Utile (perdita) netto | C23: =+C21-C22 -> 9289 | D23: =+D21-D22 -> 3980 | E23: NET PROFIT
C24: =+C23-CE!D32 -> 0 | D24: =+D23-CE!E32 -> 0 | E24: Check must be zero | L24: Net Income = Net operating income + Other income - Interest expense | R24: =+$C$18+(IF($C$19>0,$C$19,0))+(IF($C$20>0,$C$20,0))-CE!D26 -> 14512 | S24: =+$D$18+(IF($D$19>0,$D$19,0))+(IF($D$20>0,$D$20,0))-CE!$E$26 -> 5282
L26: Net operating income = Gross revenue - fixed expense - variable expense | R26: =+$C$13-$C$10-$C$12-$C$14-$C$15 -> -233809 | S26: =+$D$13-$D$10-$D$12-$D$14-$D$15 -> -237805
H31: DuPont:
I32: ROE= RO/CI ×RN/RO×CI/PN
H34: Seconda Scomposizione
H35: ROE = RN/CP = RN/Ricavi * Ricavi/TA * TA/CP | R35: =+IFERROR(R36*R37*R38,"") -> 0.31117885 | S35: =+IFERROR(S36*S37*S38,"") -> 0.18065453
I36: RN/Ricavi | R36: =+IFERROR(C23/C3,"") -> 0.034242889 | S36: =+IFERROR(D23/D3,"") -> 0.015584131
I37: Ricavi/TA = Rotazione CI | R37: =+IFERROR(C3/SP!C25,"") -> 2.2002255 | S37: =+IFERROR(D3/SP!D25,"") -> 2.1373348
I38: TA/CP = TA/CN = Rap. Ind. | R38: =+IFERROR(SP!C25/SP!C26,"") -> 4.1302134 | S38: =+IFERROR(SP!D25/SP!D26,"") -> 5.4236757
H41: Spread decomposition del ROE
H43: ROE = ROI + (ROI - ROD) × (Debiti / Patrimonio Netto) | R43: =+(R44+R46*R47)*R48 -> 0.31117885 | S43: =+(S44+S46*S47)*S48 -> 0.18065453
I44: Roi | R44: =+IFERROR(+'CE ricl. e ROE'!R15,"") -> 0.12367488 | S44: =+IFERROR(+'CE ricl. e ROE'!S15,"") -> 0.0505988
I45: Rod
I46: Roi - ROD | R46: =R44-IFERROR(-'CE ricl. e ROE'!C20/(SP!C34-SP!C26),"") -> 0.11579817 | S46: =S44-IFERROR(-'CE ricl. e ROE'!D20/(SP!D34-SP!D26),"") -> 0.042759526
I47: Debiti/PN | R47: =+(SP!C34-SP!C26)/SP!C26 -> 3.1302134 | S47: =+(SP!D34-SP!D26)/SP!D26 -> 4.4236757
I48: 1-t | R48: =1-C22/C21 -> 0.64009096 | S48: =1-D22/D21 -> 0.75350246

Sheet ROE
AY8: =+CE!$D$7 -> 2023
AY9: =+IFERROR(+'CE ricl. e ROE'!R4,"") -> 0.25371308
AY11: =+CE!$E$7 -> 2024
AY12: =+IFERROR(+'CE ricl. e ROE'!S4,"") -> 0.11879892
Q18: =+$AY$8 -> 2023 | AV18: =+$AY$8 -> 2023 | BZ18: =+$AY$8 -> 2023
Q19: =+IFERROR(+'CE ricl. e ROE'!R19,"") -> 0.60919465 | AV19: =+IFERROR(+'CE ricl. e ROE'!R17,"") -> 4.1302134 | BZ19: =+IFERROR(+'CE ricl. e ROE'!R15,"") -> 0.12367488
Q21: =+$AY$11 -> 2024 | AV21: =+$AY$11 -> 2024 | BZ21: =+$AY$11 -> 2024
Q22: =+IFERROR(+'CE ricl. e ROE'!S19,"") -> 0.65828647 | AV22: =+IFERROR(+'CE ricl. e ROE'!S17,"") -> 5.4236757 | BZ22: =+IFERROR(+'CE ricl. e ROE'!S15,"") -> 0.0505988
R30: =+$AY$8 -> 2023 | BA30: =+$AY$8 -> 2023 | CM30: =+$AY$8 -> 2023
R31: =+IFERROR(-'CE ricl. e ROE'!C20/(SP!C30+SP!C31),"") -> 0.010722142 | BA31: =+IFERROR(+'CE ricl. e ROE'!C3/SP!C25,"") -> 2.2002255 | CM31: =+IFERROR(+'CE ricl. e ROE'!C23/'CE ricl. e ROE'!C6,"") -> 0.034241248
R33: =+$AY$11 -> 2024 | BA33: =+$AY$11 -> 2024 | CM33: =+$AY$11 -> 2024
R34: =+IFERROR(-'CE ricl. e ROE'!D20/(SP!D30+SP!D31),"") -> 0.011145475 | BA34: =+IFERROR(+'CE ricl. e ROE'!D3/SP!D25,"") -> 2.1373348 | CM34: =+IFERROR(+'CE ricl. e ROE'!D23/'CE ricl. e ROE'!D6,"") -> 0.015535163
AZ43: =+$AY$8 -> 2023 | CF43: =+$AY$8 -> 2023 | DT43: =+$AY$8 -> 2023
AZ44: =+SP!C25 -> 123291 | CF44: =+'CE ricl. e ROE'!C3 -> 271268 | DT44: =+'CE ricl. e ROE'!C23 -> 9289
AZ46: =+$AY$11 -> 2024 | CF46: =+$AY$11 -> 2024 | DT46: =+$AY$11 -> 2024
AZ47: =+SP!D25 -> 119489 | CF47: =+'CE ricl. e ROE'!D3 -> 255388 | DT47: =+'CE ricl. e ROE'!D23 -> 3980
