Workbook
Name d: InserimentoDati!$F$5
Name giallo: Foglio2!$A$4
Name nodip: InserimentoDati!$A$7
Name rosso: Foglio2!$A$2
Name Semaf1: INDIRECT(InserimentoDati!$L$26)
Name Semaf2: INDIRECT(InserimentoDati!$L$34)
Name Semaf3: INDIRECT(InserimentoDati!$L$20)
Name Semaf4: INDIRECT(InserimentoDati!$L$43)
Name Semaf5: INDIRECT(InserimentoDati!$L$51)
Name Semaf6: INDIRECT(InserimentoDati!$L$59)
Name Semaf7: INDIRECT(InserimentoDati!$L$68)
Name Semaf8: INDIRECT(InserimentoDati!$L$8)
Name verde: Foglio2!$A$3

Sheet InserimentoDati
C2: Istruzioni: Compilare le parti in azzurro
D4: Nome Impresa | F4: ALFA S.R.L.
D5: Data verifica | F5: 45657
D6: Tipo impresa | F6: Azienda individuale
A7: FALSE | D7: Impresa senza lavoratori subordinati
L8: =+IF(SUM(K14:K16)=3,"verde",IF(SUM(K14:K16)=6,"rosso","giallo")) -> giallo | M8: =+VLOOKUP(L8,L10:M12,2,0) -> l'assetto dell'azienda appare non del tutto adeguato alle finalità di cui all'art. 3 del Codice della crisi di impresa e dell'insolvenza, per motivazioni di seguito descritte.
C10: =+F4 -> ALFA S.R.L. | L10: verde | M10: l'assetto dell'azienda appare adeguato alle finalità di cui all'art. 3 del Codice della crisi di impresa e dell'insolvenza, per motivazioni di seguito descritte.
C11: VERIFICA ADEGUATO ASSETTO | L11: giallo | M11: l'assetto dell'azienda appare non del tutto adeguato alle finalità di cui all'art. 3 del Codice della crisi di impresa e dell'insolvenza, per motivazioni di seguito descritte.
C12: L'assetto aziendale è idoneo a: | L12: rosso | M12: l'assetto dell'azienda non appare adeguato alle finalità di cui all'art. 3 del Codice della crisi di impresa e dell'insolvenza, per motivazioni di seguito descritte.
D14: a) rilevare eventuali squilibri di carattere patrimoniale o economico-finanziario, rapportati alle specifiche caratteristiche dell’impresa e dell’attività imprenditoriale svolta dal debitore; | K14: 1 | L14: =+"- L'azienda "&IF(K14=1,"è in grado di ","non è in grado di ")&MID(D14,4,250) -> - L'azienda è in grado di rilevare eventuali squilibri di carattere patrimoniale o economico-finanziario, rapportati alle specifiche caratteristiche dell’impresa e dell’attività imprenditoriale svolta dal debitore;
D15: b) verificare la sostenibilità dei debiti e le prospettive di continuità aziendale almeno per i dodici mesi successivi e rilevare i segnali di cui al comma 4; | K15: 2 | L15: =+"- L'azienda "&IF(K15=1,"è in grado di ","non è in grado di ")&MID(D15,4,250) -> - L'azienda non è in grado di verificare la sostenibilità dei debiti e le prospettive di continuità aziendale almeno per i dodici mesi successivi e rilevare i segnali di cui al comma 4;
D16: c) ricavare le informazioni necessarie a utilizzare la lista di controllo particolareggiata (cd check list) e a effettuare il test pratico per la verifica della ragionevole perseguibilità del risanamento di cui all’articolo 13, al comma 2. | K16: 1 | L16: =+"- L'azienda "&IF(K16=1,"è in grado di ","non è in grado di ")&MID(D16,4,250) -> - L'azienda è in grado di ricavare le informazioni necessarie a utilizzare la lista di controllo particolareggiata (cd check list) e a effettuare il test pratico per la verifica della ragionevole perseguibilità del risanamento di cui all’articolo 13, al comma 2.
C18: VERIFICA INDICATORI
A20: 0.5 | C20: Debiti scaduti da oltre 90gg / Debiti Totali < 0,5 | J20: {=+Tabella15[Indicatore]} -> 0.16666667 | L20: =+IF(InserimentoDati!J20>=InserimentoDati!A20,"rosso",IF(InserimentoDati!J20>0,"giallo","verde")) -> giallo | M20: =+VLOOKUP(L20,L22:M24,2,0) -> Si segnala che alla data del 31/12/2024 esistono debiti scaduti per Euro 10.000, pari al 16,67% del totale dei debiti. Sebbene la soglia prevista dal codice della crisi non sia ancora stata superata, si raccomanda un attento monitoraggio per non peggiorare la situazione.
D22: Voce di Bilancio | E22: Scaduti da oltre 90 gg | F22: Altri | G22: Totale | H22: Indicatore | L22: verde | M22: Non si segnalano debiti scaduti superiori a 90 giorni.
D23: Debiti | E23: 10000 | F23: 50000 | G23: =+Tabella15[[#This Row],[Scaduti da oltre 90 gg]]+Tabella15[[#This Row],[Altri]] -> 60000 | H23: =+Tabella15[[#This Row],[Scaduti da oltre 90 gg]]/Tabella15[[#This Row],[Totale]] -> 0.16666667 | L23: giallo | M23: =+"Si segnala che alla data del "&TEXT(d,"gg/mm/aaaa")& " esistono debiti scaduti per Euro "&TEXT(E23,"#.000")&", pari al "&TEXT(J20,"0,00%")&" del totale dei debiti. "&CHAR(10)&"Sebbene la soglia prevista dal codice della crisi non sia ancora stata superata, si raccomanda un attento monitoraggio per non peggiorare la situazione." -> Si segnala che alla data del 31/12/2024 esistono debiti scaduti per Euro 10.000, pari al 16,67% del totale dei debiti. Sebbene la soglia prevista dal codice della crisi non sia ancora stata superata, si raccomanda un attento monitoraggio per non peggiorare la situazione.
L24: rosso | M24: ="Si segnala che alla data del "& TEXT(d,"gg/mm/aaaa")& " esistono debiti scaduti per Euro "& TEXT(E23,"#.000")& ", pari a "&TEXT(J20,"0,00")& " il totale dei debiti. "& CHAR(10)&"Tale dato configura una situazione di crisi, cui occorre porre riparo." -> Si segnala che alla data del 31/12/2024 esistono debiti scaduti per Euro 10.000, pari a 0,17 il totale dei debiti. Tale dato configura una situazione di crisi, cui occorre porre riparo.
A26: 2 | C26: Debiti vs dipendenti (scaduti da 30gg)/Importo retribuzioni < 2 | J26: {=+Tabella1[Indicatore]} -> 2.5 | L26: =+IF(InserimentoDati!J26>=InserimentoDati!A26,"rosso",IF(InserimentoDati!J26>0,"giallo","verde")) -> rosso | M26: =+VLOOKUP(L26,L28:M30,2,0) -> si segnala che alla data del 31/12/2024 esistono debiti scaduti per Euro 200.000, pari a 2,50 volte l'importo delle retribuzioni. Tale dato configura una situazione di crisi, cui occorre porre riparo. | Y26: •l'esistenza di crediti affidati per la riscossione, autodichiarati o definitivamente accertati e scaduti da oltre novanta giorni, superiori,
D28: Importo delle retribuzioni | G28: 80000 | L28: verde | M28: non si segnalano debiti scaduti verso dipendenti superiori a 30 giorni | Y28: •per le imprese individuali, all'importo di euro 100.000,
L29: giallo | M29: =+"si segnala che alla data del "&TEXT(d,"gg/mm/aaaa")& " esistono debiti scaduti verso dipendenti per Euro "&TEXT(E31,"#.000")&", pari a "&TEXT(J26,"0,00")&" l'importo delle retribuzioni. "&CHAR(10)&"Sebbene la soglia prevista dal codice della crisinon sia ancora stata superata, si raccomanda un attento monitoraggio per non peggiorare la situazione." -> si segnala che alla data del 31/12/2024 esistono debiti scaduti verso dipendenti per Euro 200.000, pari a 2,50 l'importo delle retribuzioni. Sebbene la soglia prevista dal codice della crisinon sia ancora stata superata, si raccomanda un attento monitoraggio per non peggiorare la situazione.
D30: Voce di Bilancio | E30: Scaduti da oltre 30 gg | F30: Altri | G30: Totale | H30: Indicatore | L30: rosso | M30: ="si segnala che alla data del "& TEXT(d,"gg/mm/aaaa")& " esistono debiti scaduti per Euro "& TEXT(E31,"#.000")& ", pari a "&TEXT(J26,"0,00")& " volte l'importo delle retribuzioni. "& CHAR(10)&"Tale dato configura una situazione di crisi, cui occorre porre riparo." -> si segnala che alla data del 31/12/2024 esistono debiti scaduti per Euro 200.000, pari a 2,50 volte l'importo delle retribuzioni. Tale dato configura una situazione di crisi, cui occorre porre riparo.
D31: Debiti Vs Dipendenti | E31: 200000 | F31: 30000 | G31: =+Tabella1[[#This Row],[Scaduti da oltre 30 gg]]+Tabella1[[#This Row],[Altri]] -> 230000 | H31: =+IFERROR(Tabella1[[#This Row],[Scaduti da oltre 30 gg]]/G28,0) -> 2.5
A34: 0.05 | C34: Sconfini oltre 60 gg / Totale esposizioni > 0,05 | J34: =+Tabella13[[#Totals],[Indicatore]] -> 0.032258065 | L34: =+IF(InserimentoDati!J34>=InserimentoDati!A34,"rosso",IF(InserimentoDati!J34>0,"giallo","verde")) -> giallo | M34: =+VLOOKUP(L34,L36:M38,2,0) -> Si segnala che alla data del 31/12/2024 esistono debiti verso banche scaduti da più di 60 giorni per Euro 1.000, pari a 0,03 il totale delle esposizioni Sebbene la soglia prevista dal codice della crisinon sia ancora stata superata, si raccomanda un attento monitoraggio per non peggiorare la situazione.
D36: Voce di Bilancio | E36: Scaduti da oltre 60 gg | F36: Altri | G36: Totale | H36: Indicatore | L36: verde | M36: Non si segnalano sconfini superiori a 60 giorni
D37: Autoliquidanti | E37: 1000 | F37: 30000 | G37: =+Tabella13[[#This Row],[Scaduti da oltre 60 gg]]+Tabella13[[#This Row],[Altri]] -> 31000 | H37: =+IFERROR(Tabella13[[#This Row],[Scaduti da oltre 60 gg]]/Tabella13[[#This Row],[Totale]],0) -> 0.032258065 | L37: giallo | M37: =+"Si segnala che alla data del "&TEXT(d,"gg/mm/aaaa")& " esistono debiti verso banche scaduti da più di 60 giorni per Euro "&TEXT(E40,"#.000")&", pari a "&TEXT(J34,"0,00")&" il totale delle esposizioni "&CHAR(10)&"Sebbene la soglia prevista dal codice della crisinon sia ancora stata superata, si raccomanda un attento monitoraggio per non peggiorare la situazione." -> Si segnala che alla data del 31/12/2024 esistono debiti verso banche scaduti da più di 60 giorni per Euro 1.000, pari a 0,03 il totale delle esposizioni Sebbene la soglia prevista dal codice della crisinon sia ancora stata superata, si raccomanda un attento monitoraggio per non peggiorare la situazione.
D38: Rischi a revoca | G38: =+Tabella13[[#This Row],[Scaduti da oltre 60 gg]]+Tabella13[[#This Row],[Altri]] -> 0 | H38: =+IFERROR(Tabella13[[#This Row],[Scaduti da oltre 60 gg]]/G35,0) -> 0 | L38: rosso | M38: ="Si segnala che alla data del "& TEXT(d,"gg/mm/aaaa")& " esistono sconfini perduranti oltre i 60 giorni per Euro "& TEXT(E40,"#.000")& ", pari al "&TEXT(J34,"0,00%")& " del totale delle esposizioni verso istituti di credito. "& CHAR(10)&"Tale dato configura una situazione di crisi, cui occorre porre riparo." -> Si segnala che alla data del 31/12/2024 esistono sconfini perduranti oltre i 60 giorni per Euro 1.000, pari al 3,23% del totale delle esposizioni verso istituti di credito. Tale dato configura una situazione di crisi, cui occorre porre riparo.
D39: Rischi a scadenza | G39: =+Tabella13[[#This Row],[Scaduti da oltre 60 gg]]+Tabella13[[#This Row],[Altri]] -> 0 | H39: =+IFERROR(Tabella13[[#This Row],[Scaduti da oltre 60 gg]]/G36,0) -> 0
D40: Totale | E40: =SUBTOTAL(109,Tabella13[Scaduti da oltre 60 gg]) -> 1000 | F40: =SUBTOTAL(109,Tabella13[Altri]) -> 30000 | G40: =SUBTOTAL(109,Tabella13[Totale]) -> 31000 | H40: =+IFERROR(Tabella13[[#Totals],[Scaduti da oltre 60 gg]]/Tabella13[[#Totals],[Totale]],0) -> 0.032258065
A43: =+IF(A7,5000,MAX(15000,G45*0.3)) -> 15000 | C43: Contributi INPS scaduti da oltre 90 gg | J43: {=+Tabella134[Indicatore]} -> 6000 | L43: =+IF(InserimentoDati!J43>=InserimentoDati!A43,"rosso",IF(InserimentoDati!J43>0,"giallo","verde")) -> giallo | M43: =+VLOOKUP(L43,L45:M47,2,0) -> Si segnala che alla data del 31/12/2024 non sono stati versati contributi INPS da oltre 90 giorni per Euro 6.000, pari al 600,00% dlel'importo dei contributi dovuti per l'anno precedente. Sebbene la soglia prevista dal codice della crisinon sia ancora stata superata, si raccomanda un attento monitoraggio per non peggiorare la situazione.
M44: =+"L'azienda "&IF(nodip,"non "," ")&" dispone di lavoratori subordinati o parasubordinati." -> L'azienda dispone di lavoratori subordinati o parasubordinati.
D45: Contributi dovuti nell'anno precedente | G45: 1000 | L45: verde | M45: Non si segnalano contributi INPS non versati da oltre 90 giorni
L46: giallo | M46: =+"Si segnala che alla data del "&TEXT(d,"gg/mm/aaaa")& " non sono stati versati contributi INPS da oltre 90 giorni per Euro "&TEXT(E48,"#.000")&", pari al "&TEXT(IFERROR(J43/G45,0),"0,00%")&" dlel'importo dei contributi dovuti per l'anno precedente. "&CHAR(10)&"Sebbene la soglia prevista dal codice della crisinon sia ancora stata superata, si raccomanda un attento monitoraggio per non peggiorare la situazione." -> Si segnala che alla data del 31/12/2024 non sono stati versati contributi INPS da oltre 90 giorni per Euro 6.000, pari al 600,00% dlel'importo dei contributi dovuti per l'anno precedente. Sebbene la soglia prevista dal codice della crisinon sia ancora stata superata, si raccomanda un attento monitoraggio per non peggiorare la situazione.
D47: Voce di Bilancio | E47: Scaduti da oltre 90 gg | F47: Altri | G47: Totale | H47: Indicatore | L47: rosso | M47: ="Si segnala che alla data del "& TEXT(d,"gg/mm/aaaa")& " non sono stati versati contributi INPS da oltre 90 giorni per "& TEXT(E48,"#.000")& ", pari al "&TEXT(IFERROR(J43/G45,0),"0,00%")& " dei contributi dovuti nell'esercizio precedente "& CHAR(10)&"Tale dato configura una situazione di crisi, cui occorre porre riparo." -> Si segnala che alla data del 31/12/2024 non sono stati versati contributi INPS da oltre 90 giorni per 6.000, pari al 600,00% dei contributi dovuti nell'esercizio precedente Tale dato configura una situazione di crisi, cui occorre porre riparo.
D48: Contributi INPS | E48: 6000 | F48: 30000 | G48: =+Tabella134[[#This Row],[Scaduti da oltre 90 gg]]+Tabella134[[#This Row],[Altri]] -> 36000 | H48: =+Tabella134[[#This Row],[Scaduti da oltre 90 gg]] -> 6000
A51: 5000 | C51: Contributi INAIL scaduti da oltre 90 gg | J51: {=+Tabella1346[Indicatore]} -> 0 | L51: =+IF(InserimentoDati!J51>=InserimentoDati!A51,"rosso",IF(InserimentoDati!J51>0,"giallo","verde")) -> verde | M51: =+VLOOKUP(L51,L53:M55,2,0) -> Non si segnalano contributi INAIL non versati da oltre 90 giorni
L53: verde | M53: Non si segnalano contributi INAIL non versati da oltre 90 giorni
L54: giallo | M54: =+"Si segnala che alla data del "&TEXT(d,"gg/mm/aaaa")& " non sono stati versati contributi INAIL da oltre 90 giorni per Euro "&TEXT(E56,"#.000")&", pari al "&TEXT(IFERROR(J51/G53,0),"0,00%")&" dlel'importo dei contributi dovuti per l'anno precedente. "&CHAR(10)&"Sebbene la soglia prevista dal codice della crisinon sia ancora stata superata, si raccomanda un attento monitoraggio per non peggiorare la situazione." -> Si segnala che alla data del 31/12/2024 non sono stati versati contributi INAIL da oltre 90 giorni per Euro 000, pari al 0,00% dlel'importo dei contributi dovuti per l'anno precedente. Sebbene la soglia prevista dal codice della crisinon sia ancora stata superata, si raccomanda un attento monitoraggio per non peggiorare la situazione.
D55: Voce di Bilancio | E55: Scaduti da oltre 90 gg | F55: Altri | G55: Totale | H55: Indicatore | L55: rosso | M55: ="Si segnala che alla data del "& TEXT(d,"gg/mm/aaaa")& " non sono stati versati contributi da oltre 90 giorni per "& TEXT(E56,"#.000")& ", pari al "&TEXT(IFERROR(J51/G53,0),"0,00%")& " dei contributi dovuti nell'esercizio precedente "& CHAR(10)&"Tale dato configura una situazione di crisi, cui occorre porre riparo." -> Si segnala che alla data del 31/12/2024 non sono stati versati contributi da oltre 90 giorni per 000, pari al 0,00% dei contributi dovuti nell'esercizio precedente Tale dato configura una situazione di crisi, cui occorre porre riparo.
D56: Contributi INAIL | F56: 30000 | G56: =+Tabella1346[[#This Row],[Scaduti da oltre 90 gg]]+Tabella1346[[#This Row],[Altri]] -> 30000 | H56: =+Tabella1346[[#This Row],[Scaduti da oltre 90 gg]] -> 0
A59: =10%*G61 -> 100000 | C59: Debiti IVA Scaduti | J59: {=+Tabella13467[Indicatore]} -> 21000 | L59: =+IF(J59>20000,"rosso", IF( AND(InserimentoDati!J59>=InserimentoDati!A59,J59>5000), "rosso",IF(InserimentoDati!J59>0,"giallo","verde"))) -> rosso | M59: =+VLOOKUP(L59,L61:M63,2,0) -> Si segnala che alla data del 31/12/2024 non è stata versata IVA per 21.000, pari al 2,10% del volume d'affari dell'anno di imposta precedente Tale dato configura una situazione di crisi, cui occorre porre riparo.
...

Sheet Foglio2
A2: rosso
A3: verde
A4: giallo

Sheet Relazione
B2: =+InserimentoDati!F4 -> ALFA S.R.L.
B3: =+d -> 45657
B4: Relazione in merito alla verifica dell'adeguato assetto e alla presenza di segnali indicativi di uno stato di crisi e/o difficoltà economica e finanziaria
B6: Caratteristiche dell'assetto dell'impresa
A7: Dall'esame dell'assetto contabile, amministrativo e organizzativo dell'impresa è emerso che | B7: =+A7&InserimentoDati!M8 -> Dall'esame dell'assetto contabile, amministrativo e organizzativo dell'impresa è emerso che l'assetto dell'azienda appare non del tutto adeguato alle finalità di cui all'art. 3 del Codice della crisi di impresa e dell'insolvenza, per motivazioni di seguito descritte.
B8: =+InserimentoDati!L14 -> - L'azienda è in grado di rilevare eventuali squilibri di carattere patrimoniale o economico-finanziario, rapportati alle specifiche caratteristiche dell’impresa e dell’attività imprenditoriale svolta dal debitore;
B9: =+InserimentoDati!L15 -> - L'azienda non è in grado di verificare la sostenibilità dei debiti e le prospettive di continuità aziendale almeno per i dodici mesi successivi e rilevare i segnali di cui al comma 4;
B10: =+InserimentoDati!L16 -> - L'azienda è in grado di ricavare le informazioni necessarie a utilizzare la lista di controllo particolareggiata (cd check list) e a effettuare il test pratico per la verifica della ragionevole perseguibilità del risanamento di cui all’articolo 13, al comma 2.
B12: Esame dei segnali rilevatori di uno stato di crisi
B13: =+InserimentoDati!M20 -> Si segnala che alla data del 31/12/2024 esistono debiti scaduti per Euro 10.000, pari al 16,67% del totale dei debiti. Sebbene la soglia prevista dal codice della crisi non sia ancora stata superata, si raccomanda un attento monitoraggio per non peggiorare la situazione.
A14: Per quanto riguarda i dipendenti, | B14: =+A14&InserimentoDati!M26 -> Per quanto riguarda i dipendenti, si segnala che alla data del 31/12/2024 esistono debiti scaduti per Euro 200.000, pari a 2,50 volte l'importo delle retribuzioni. Tale dato configura una situazione di crisi, cui occorre porre riparo.
A15: Dall'esame della Centrale Rischi è emerso quanto di seguito riportato. | B15: =+A15&CHAR(10)&InserimentoDati!M34 -> Dall'esame della Centrale Rischi è emerso quanto di seguito riportato. Si segnala che alla data del 31/12/2024 esistono debiti verso banche scaduti da più di 60 giorni per Euro 1.000, pari a 0,03 il totale delle esposizioni Sebbene la soglia prevista dal codice della crisinon sia ancora stata superata, si raccomanda un attento monitoraggio per non peggiorare la situazione.
A16: La verifica della regolarità contributiva ha condotto agli esiti che seguono. | B16: =+A16 -> La verifica della regolarità contributiva ha condotto agli esiti che seguono.
B17: =+InserimentoDati!M43 -> Si segnala che alla data del 31/12/2024 non sono stati versati contributi INPS da oltre 90 giorni per Euro 6.000, pari al 600,00% dlel'importo dei contributi dovuti per l'anno precedente. Sebbene la soglia prevista dal codice della crisinon sia ancora stata superata, si raccomanda un attento monitoraggio per non peggiorare la situazione.
B18: =+InserimentoDati!M51 -> Non si segnalano contributi INAIL non versati da oltre 90 giorni
A19: Infine per quanto riguarda i debiti tributari, | B19: =+A19&InserimentoDati!M68 -> Infine per quanto riguarda i debiti tributari, si segnala che alla data del 31/12/2024 sussistono debiti affidati per la riscossione, autodichiarati o definitivamente accertati e scaduti da oltre novanta giorni per 200.000 Tale dato configura una situazione di crisi, cui occorre porre riparo.
B21: Conclusioni in merito a quanto rilevato
A22: Dall'esame dei segnali che denotano uno stato di difficolta e/o di crisi, risulta che | B22: =+A22&InserimentoDati!N74 -> Dall'esame dei segnali che denotano uno stato di difficolta e/o di crisi, risulta che 3 indicatori hanno superato le soglie e 3 indicatori presentano valori degni di attenzione. La situazione ai sensi dell'art. 3 ccii denota uno stato di crisi e impone di assumere senza indugio le iniziative necessarie a farvi fronte.

Sheet Relazione Compatta (Solo 365)
A2: Relazione in formato compatto (Disponibile solo con Excel 365)
A3: =+InserimentoDati!F4 -> ALFA S.R.L.
A4: =+d -> 45657
A5: {=+_xlfn._xlws.FILTER(Relazione!B6:B1048576,Relazione!B6:B1048576>0)} -> Caratteristiche dell'assetto dell'impresa
A6: Dall'esame dell'assetto contabile, amministrativo e organizzativo dell'impresa è emerso che l'assetto dell'azienda appare non del tutto adeguato alle finalità di cui all'art. 3 del Codice della crisi di impresa e dell'insolvenza, per motivazioni di seguito descritte.
A7: - L'azienda è in grado di rilevare eventuali squilibri di carattere patrimoniale o economico-finanziario, rapportati alle specifiche caratteristiche dell’impresa e dell’attività imprenditoriale svolta dal debitore;
A8: - L'azienda non è in grado di verificare la sostenibilità dei debiti e le prospettive di continuità aziendale almeno per i dodici mesi successivi e rilevare i segnali di cui al comma 4;
A9: - L'azienda è in grado di ricavare le informazioni necessarie a utilizzare la lista di controllo particolareggiata (cd check list) e a effettuare il test pratico per la verifica della ragionevole perseguibilità del risanamento di cui all’articolo 13, al comma 2.
A10: Esame dei segnali rilevatori di uno stato di crisi
A11: Si segnala che alla data del 31/12/2024 esistono debiti scaduti per Euro 10.000, pari al 16,67% del totale dei debiti. Sebbene la soglia prevista dal codice della crisi non sia ancora stata superata, si raccomanda un attento monitoraggio per non peggiorare la situazione.
A12: Per quanto riguarda i dipendenti, si segnala che alla data del 31/12/2024 esistono debiti scaduti per Euro 200.000, pari a 2,50 volte l'importo delle retribuzioni. Tale dato configura una situazione di crisi, cui occorre porre riparo.
A13: Dall'esame della Centrale Rischi è emerso quanto di seguito riportato. Si segnala che alla data del 31/12/2024 esistono debiti verso banche scaduti da più di 60 giorni per Euro 1.000, pari a 0,03 il totale delle esposizioni Sebbene la soglia prevista dal codice della crisinon sia ancora stata superata, si raccomanda un attento monitoraggio per non peggiorare la situazione.
A14: La verifica della regolarità contributiva ha condotto agli esiti che seguono.
A15: Si segnala che alla data del 31/12/2024 non sono stati versati contributi INPS da oltre 90 giorni per Euro 6.000, pari al 600,00% dlel'importo dei contributi dovuti per l'anno precedente. Sebbene la soglia prevista dal codice della crisinon sia ancora stata superata, si raccomanda un attento monitoraggio per non peggiorare la situazione.
A16: Non si segnalano contributi INAIL non versati da oltre 90 giorni
A17: Infine per quanto riguarda i debiti tributari, si segnala che alla data del 31/12/2024 sussistono debiti affidati per la riscossione, autodichiarati o definitivamente accertati e scaduti da oltre novanta giorni per 200.000 Tale dato configura una situazione di crisi, cui occorre porre riparo.
... A19: Dall'esame dei segnali che denotano uno stato di difficolta e/o di crisi, risulta che 3 indicatori hanno superato le soglie e 3 indicatori presentano valori degni di attenzione. La situazione ai sensi dell'art. 3 ccii denota uno stato di crisi e impone di assumere senza indugio le iniziative necessarie a farvi fronte.
